Workbook

Sheet Mapa de Carga Planeada
A1: MAPA DE CARGA PLANEADA
A2: TEMPLATE COM DADOS DE EXEMPLO — os resultados desta folha são calculados a partir da folha «Detalhe do Planeamento». Preencha apenas o Momento de Avaliação e substitua os exemplos na folha de detalhe.
A3: Campo editável | D3: Campos calculados — não alterar | G3: Resultado a rever quando assinalado
A5: IDENTIFICAÇÃO
A6: Próximo Momento de Avaliação | D6: m1+m2
A7: Sprints abrangidos pelo acumulado | D7: =IF(COUNTA('Detalhe do Planeamento'!$A$7:$A$26)=0,"",IF(COUNTA('Detalhe do Planeamento'!$A$7:$A$26)=1,'Detalhe do Planeamento'!$A$7,'Detalhe do Planeamento'!$A$7&" a "&INDEX('Detalhe do Planeamento'!$A$7:$A$26,COUNTA('Detalhe do Planeamento'!$A$7:$A$26)))) -> Sprint 01
A8: Número de alunos considerado | D8: =COUNTIF('Listas de apoio'!$G$5:$G$8,"<>") -> 4
A9: Limite máximo do QCTP | D9: ='Listas de apoio'!$J$9 -> 1.1
A11: RESUMO ACUMULADO POR ALUNO
A12: Aluno | B12: PExe acumulados | C12: PRev acumulados | D12: PAud acumulados | E12: PSecr acumulados | F12: CTP acumulada do aluno
A13: =IF('Listas de apoio'!G5="","",'Listas de apoio'!G5) -> André Filipe Moreira Mesquita | B13: =IF($A13="","",SUMIFS('Detalhe do Planeamento'!$F$54:$F$153,'Detalhe do Planeamento'!$E$54:$E$153,$A13)) -> 60 | C13: =IF($A13="","",SUMIFS('Detalhe do Planeamento'!$H$54:$H$153,'Detalhe do Planeamento'!$G$54:$G$153,$A13)) -> 18 | D13: =IF($A13="","",SUMIFS('Detalhe do Planeamento'!$J$54:$J$153,'Detalhe do Planeamento'!$I$54:$I$153,$A13)) -> 3 | E13: =IF($A13="","",SUMIFS('Detalhe do Planeamento'!$C$7:$C$26,'Detalhe do Planeamento'!$B$7:$B$26,$A13)) -> 0 | F13: =IF($A13="","",SUM(B13:E13)) -> 81
A14: =IF('Listas de apoio'!G6="","",'Listas de apoio'!G6) -> Gonçalo Dinis Magalhães Teixeira | B14: =IF($A14="","",SUMIFS('Detalhe do Planeamento'!$F$54:$F$153,'Detalhe do Planeamento'!$E$54:$E$153,$A14)) -> 24 | C14: =IF($A14="","",SUMIFS('Detalhe do Planeamento'!$H$54:$H$153,'Detalhe do Planeamento'!$G$54:$G$153,$A14)) -> 0 | D14: =IF($A14="","",SUMIFS('Detalhe do Planeamento'!$J$54:$J$153,'Detalhe do Planeamento'!$I$54:$I$153,$A14)) -> 6 | E14: =IF($A14="","",SUMIFS('Detalhe do Planeamento'!$C$7:$C$26,'Detalhe do Planeamento'!$B$7:$B$26,$A14)) -> 10 | F14: =IF($A14="","",SUM(B14:E14)) -> 40
A15: =IF('Listas de apoio'!G7="","",'Listas de apoio'!G7) -> Gonçalo Magalhães Ribeiro | B15: =IF($A15="","",SUMIFS('Detalhe do Planeamento'!$F$54:$F$153,'Detalhe do Planeamento'!$E$54:$E$153,$A15)) -> 48 | C15: =IF($A15="","",SUMIFS('Detalhe do Planeamento'!$H$54:$H$153,'Detalhe do Planeamento'!$G$54:$G$153,$A15)) -> 18 | D15: =IF($A15="","",SUMIFS('Detalhe do Planeamento'!$J$54:$J$153,'Detalhe do Planeamento'!$I$54:$I$153,$A15)) -> 3 | E15: =IF($A15="","",SUMIFS('Detalhe do Planeamento'!$C$7:$C$26,'Detalhe do Planeamento'!$B$7:$B$26,$A15)) -> 0 | F15: =IF($A15="","",SUM(B15:E15)) -> 69
A16: =IF('Listas de apoio'!G8="","",'Listas de apoio'!G8) -> Ivan Cristiano Silva Mendes | B16: =IF($A16="","",SUMIFS('Detalhe do Planeamento'!$F$54:$F$153,'Detalhe do Planeamento'!$E$54:$E$153,$A16)) -> 54 | C16: =IF($A16="","",SUMIFS('Detalhe do Planeamento'!$H$54:$H$153,'Detalhe do Planeamento'!$G$54:$G$153,$A16)) -> 57 | D16: =IF($A16="","",SUMIFS('Detalhe do Planeamento'!$J$54:$J$153,'Detalhe do Planeamento'!$I$54:$I$153,$A16)) -> 19 | E16: =IF($A16="","",SUMIFS('Detalhe do Planeamento'!$C$7:$C$26,'Detalhe do Planeamento'!$B$7:$B$26,$A16)) -> 0 | F16: =IF($A16="","",SUM(B16:E16)) -> 130
A17: Total do grupo | B17: =SUM(B13:B16) -> 186 | C17: =SUM(C13:C16) -> 93 | D17: =SUM(D13:D16) -> 31 | E17: =SUM(E13:E16) -> 10 | F17: =SUM(F13:F16) -> 320
A19: DEMONSTRAÇÃO DO EQUILÍBRIO
A20: Fórmula ou verificação | E20: Valor calculado
A21: CTPmax = max(CTP1, …, CTPn) | E21: =IF(COUNT(F13:F16)=0,"",MAX(F13:F16)) -> 130
A22: CTPmin = min(CTP1, …, CTPn) | E22: =IF(COUNT(F13:F16)=0,"",MIN(F13:F16)) -> 40
A23: QCTP = CTPmax / CTPmin | E23: =IF(OR(E22="",E22=0),"",E21/E22) -> 3.25
A24: QCTP arredondado a duas casas decimais | E24: =IF(E23="","",ROUND(E23,2)) -> 3.25
A25: Verificação do limite | E25: =IF(E22="","Por preencher",IF(E22=0,"CTPmin = 0 — quociente indefinido",IF(E24<=$D$9,"QCTP <= 1,10","QCTP > 1,10"))) -> QCTP > 1,10
A26: Conclusão | E26: =IF(E22="","Por preencher",IF(E22=0,"Incumprimento grave — CTPmin = 0",IF(E24<=$D$9,"Cumpre o limite máximo permitido.","Não cumpre o limite máximo permitido."))) -> Não cumpre o limite máximo permitido.
A28: CONTROLO ACUMULADO APÓS CADA SPRINT PLANNING
A29: Sprint | B29: =IF(A13="","","CTP — "&A13) -> CTP — André Filipe Moreira Mesquita | C29: =IF(A14="","","CTP — "&A14) -> CTP — Gonçalo Dinis Magalhães Teixeira | D29: =IF(A15="","","CTP — "&A15) -> CTP — Gonçalo Magalhães Ribeiro | E29: =IF(A16="","","CTP — "&A16) -> CTP — Ivan Cristiano Silva Mendes | F29: CTPmax | G29: CTPmin | H29: QCTP | I29: Resultado
A30: =IF('Detalhe do Planeamento'!A7="","",'Detalhe do Planeamento'!A7) -> Sprint 01 | B30: =IF(OR($A30="",B$29=""),"",SUMIFS('Detalhe do Planeamento'!$F$54:$F$153,'Detalhe do Planeamento'!$A$54:$A$153,"<="&$A30,'Detalhe do Planeamento'!$E$54:$E$153,RIGHT(B$29,LEN(B$29)-6))+SUMIFS('Detalhe do Planeamento'!$H$54:$H$153,'Detalhe do Planeamento'!$A$54:$A$153,"<="&$A30,'Detalhe do Planeamento'!$G$54:$G$153,RIGHT(B$29,LEN(B$29)-6))+SUMIFS('Detalhe do Planeamento'!$J$54:$J$153,'Detalhe do Planeamento'!$A$54:$A$153,"<="&$A30,'Detalhe do Planeamento'!$I$54:$I$153,RIGHT(B$29,LEN(B$29)-6))+SUMIFS('Detalhe do Planeamento'!$C$7:$C$26,'Detalhe do Planeamento'!$A$7:$A$26,"<="&$A30,'Detalhe do Planeamento'!$B$7:$B$26,RIGHT(B$29,LEN(B$29)-6))) -> 81 | C30: =IF(OR($A30="",C$29=""),"",SUMIFS('Detalhe do Planeamento'!$F$54:$F$153,'Detalhe do Planeamento'!$A$54:$A$153,"<="&$A30,'Detalhe do Planeamento'!$E$54:$E$153,RIGHT(C$29,LEN(C$29)-6))+SUMIFS('Detalhe do Planeamento'!$H$54:$H$153,'Detalhe do Planeamento'!$A$54:$A$153,"<="&$A30,'Detalhe do Planeamento'!$G$54:$G$153,RIGHT(C$29,LEN(C$29)-6))+SUMIFS('Detalhe do Planeamento'!$J$54:$J$153,'Detalhe do Planeamento'!$A$54:$A$153,"<="&$A30,'Detalhe do Planeamento'!$I$54:$I$153,RIGHT(C$29,LEN(C$29)-6))+SUMIFS('Detalhe do Planeamento'!$C$7:$C$26,'Detalhe do Planeamento'!$A$7:$A$26,"<="&$A30,'Detalhe do Planeamento'!$B$7:$B$26,RIGHT(C$29,LEN(C$29)-6))) -> 40 | D30: =IF(OR($A30="",D$29=""),"",SUMIFS('Detalhe do Planeamento'!$F$54:$F$153,'Detalhe do Planeamento'!$A$54:$A$153,"<="&$A30,'Detalhe do Planeamento'!$E$54:$E$153,RIGHT(D$29,LEN(D$29)-6))+SUMIFS('Detalhe do Planeamento'!$H$54:$H$153,'Detalhe do Planeamento'!$A$54:$A$153,"<="&$A30,'Detalhe do Planeamento'!$G$54:$G$153,RIGHT(D$29,LEN(D$29)-6))+SUMIFS('Detalhe do Planeamento'!$J$54:$J$153,'Detalhe do Planeamento'!$A$54:$A$153,"<="&$A30,'Detalhe do Planeamento'!$I$54:$I$153,RIGHT(D$29,LEN(D$29)-6))+SUMIFS('Detalhe do Planeamento'!$C$7:$C$26,'Detalhe do Planeamento'!$A$7:$A$26,"<="&$A30,'Detalhe do Planeamento'!$B$7:$B$26,RIGHT(D$29,LEN(D$29)-6))) -> 69 | E30: =IF(OR($A30="",E$29=""),"",SUMIFS('Detalhe do Planeamento'!$F$54:$F$153,'Detalhe do Planeamento'!$A$54:$A$153,"<="&$A30,'Detalhe do Planeamento'!$E$54:$E$153,RIGHT(E$29,LEN(E$29)-6))+SUMIFS('Detalhe do Planeamento'!$H$54:$H$153,'Detalhe do Planeamento'!$A$54:$A$153,"<="&$A30,'Detalhe do Planeamento'!$G$54:$G$153,RIGHT(E$29,LEN(E$29)-6))+SUMIFS('Detalhe do Planeamento'!$J$54:$J$153,'Detalhe do Planeamento'!$A$54:$A$153,"<="&$A30,'Detalhe do Planeamento'!$I$54:$I$153,RIGHT(E$29,LEN(E$29)-6))+SUMIFS('Detalhe do Planeamento'!$C$7:$C$26,'Detalhe do Planeamento'!$A$7:$A$26,"<="&$A30,'Detalhe do Planeamento'!$B$7:$B$26,RIGHT(E$29,LEN(E$29)-6))) -> 130 | F30: =IF(COUNT(B30:E30)=0,"",MAX(B30:E30)) -> 130 | G30: =IF(COUNT(B30:E30)=0,"",MIN(B30:E30)) -> 40 | H30: =IF(OR(G30="",G30=0),"",F30/G30) -> 3.25 | I30: =IF(G30="","",IF(G30=0,"Incumprimento grave — CTPmin = 0",IF(ROUND(H30,2)<=$D$9,"Cumpre","Não cumpre"))) -> Não cumpre
A31: =IF('Detalhe do Planeamento'!A8="","",'Detalhe do Planeamento'!A8) | B31: =IF(OR($A31="",B$29=""),"",SUMIFS('Detalhe do Planeamento'!$F$54:$F$153,'Detalhe do Planeamento'!$A$54:$A$153,"<="&$A31,'Detalhe do Planeamento'!$E$54:$E$153,RIGHT(B$29,LEN(B$29)-6))+SUMIFS('Detalhe do Planeamento'!$H$54:$H$153,'Detalhe do Planeamento'!$A$54:$A$153,"<="&$A31,'Detalhe do Planeamento'!$G$54:$G$153,RIGHT(B$29,LEN(B$29)-6))+SUMIFS('Detalhe do Planeamento'!$J$54:$J$153,'Detalhe do Planeamento'!$A$54:$A$153,"<="&$A31,'Detalhe do Planeamento'!$I$54:$I$153,RIGHT(B$29,LEN(B$29)-6))+SUMIFS('Detalhe do Planeamento'!$C$7:$C$26,'Detalhe do Planeamento'!$A$7:$A$26,"<="&$A31,'Detalhe do Planeamento'!$B$7:$B$26,RIGHT(B$29,LEN(B$29)-6))) | C31: =IF(OR($A31="",C$29=""),"",SUMIFS('Detalhe do Planeamento'!$F$54:$F$153,'Detalhe do Planeamento'!$A$54:$A$153,"<="&$A31,'Detalhe do Planeamento'!$E$54:$E$153,RIGHT(C$29,LEN(C$29)-6))+SUMIFS('Detalhe do Planeamento'!$H$54:$H$153,'Detalhe do Planeamento'!$A$54:$A$153,"<="&$A31,'Detalhe do Planeamento'!$G$54:$G$153,RIGHT(C$29,LEN(C$29)-6))+SUMIFS('Detalhe do Planeamento'!$J$54:$J$153,'Detalhe do Planeamento'!$A$54:$A$153,"<="&$A31,'Detalhe do Planeamento'!$I$54:$I$153,RIGHT(C$29,LEN(C$29)-6))+SUMIFS('Detalhe do Planeamento'!$C$7:$C$26,'Detalhe do Planeamento'!$A$7:$A$26,"<="&$A31,'Detalhe do Planeamento'!$B$7:$B$26,RIGHT(C$29,LEN(C$29)-6))) | D31: =IF(OR($A31="",D$29=""),"",SUMIFS('Detalhe do Planeamento'!$F$54:$F$153,'Detalhe do Planeamento'!$A$54:$A$153,"<="&$A31,'Detalhe do Planeamento'!$E$54:$E$153,RIGHT(D$29,LEN(D$29)-6))+SUMIFS('Detalhe do Planeamento'!$H$54:$H$153,'Detalhe do Planeamento'!$A$54:$A$153,"<="&$A31,'Detalhe do Planeamento'!$G$54:$G$153,RIGHT(D$29,LEN(D$29)-6))+SUMIFS('Detalhe do Planeamento'!$J$54:$J$153,'Detalhe do Planeamento'!$A$54:$A$153,"<="&$A31,'Detalhe do Planeamento'!$I$54:$I$153,RIGHT(D$29,LEN(D$29)-6))+SUMIFS('Detalhe do Planeamento'!$C$7:$C$26,'Detalhe do Planeamento'!$A$7:$A$26,"<="&$A31,'Detalhe do Planeamento'!$B$7:$B$26,RIGHT(D$29,LEN(D$29)-6))) | E31: =IF(OR($A31="",E$29=""),"",SUMIFS('Detalhe do Planeamento'!$F$54:$F$153,'Detalhe do Planeamento'!$A$54:$A$153,"<="&$A31,'Detalhe do Planeamento'!$E$54:$E$153,RIGHT(E$29,LEN(E$29)-6))+SUMIFS('Detalhe do Planeamento'!$H$54:$H$153,'Detalhe do Planeamento'!$A$54:$A$153,"<="&$A31,'Detalhe do Planeamento'!$G$54:$G$153,RIGHT(E$29,LEN(E$29)-6))+SUMIFS('Detalhe do Planeamento'!$J$54:$J$153,'Detalhe do Planeamento'!$A$54:$A$153,"<="&$A31,'Detalhe do Planeamento'!$I$54:$I$153,RIGHT(E$29,LEN(E$29)-6))+SUMIFS('Detalhe do Planeamento'!$C$7:$C$26,'Detalhe do Planeamento'!$A$7:$A$26,"<="&$A31,'Detalhe do Planeamento'!$B$7:$B$26,RIGHT(E$29,LEN(E$29)-6))) | F31: =IF(COUNT(B31:E31)=0,"",MAX(B31:E31)) | G31: =IF(COUNT(B31:E31)=0,"",MIN(B31:E31)) | H31: =IF(OR(G31="",G31=0),"",F31/G31) | I31: =IF(G31="","",IF(G31=0,"Incumprimento grave — CTPmin = 0",IF(ROUND(H31,2)<=$D$9,"Cumpre","Não cumpre")))
A32: =IF('Detalhe do Planeamento'!A9="","",'Detalhe do Planeamento'!A9) | B32: =IF(OR($A32="",B$29=""),"",SUMIFS('Detalhe do Planeamento'!$F$54:$F$153,'Detalhe do Planeamento'!$A$54:$A$153,"<="&$A32,'Detalhe do Planeamento'!$E$54:$E$153,RIGHT(B$29,LEN(B$29)-6))+SUMIFS('Detalhe do Planeamento'!$H$54:$H$153,'Detalhe do Planeamento'!$A$54:$A$153,"<="&$A32,'Detalhe do Planeamento'!$G$54:$G$153,RIGHT(B$29,LEN(B$29)-6))+SUMIFS('Detalhe do Planeamento'!$J$54:$J$153,'Detalhe do Planeamento'!$A$54:$A$153,"<="&$A32,'Detalhe do Planeamento'!$I$54:$I$153,RIGHT(B$29,LEN(B$29)-6))+SUMIFS('Detalhe do Planeamento'!$C$7:$C$26,'Detalhe do Planeamento'!$A$7:$A$26,"<="&$A32,'Detalhe do Planeamento'!$B$7:$B$26,RIGHT(B$29,LEN(B$29)-6))) | C32: =IF(OR($A32="",C$29=""),"",SUMIFS('Detalhe do Planeamento'!$F$54:$F$153,'Detalhe do Planeamento'!$A$54:$A$153,"<="&$A32,'Detalhe do Planeamento'!$E$54:$E$153,RIGHT(C$29,LEN(C$29)-6))+SUMIFS('Detalhe do Planeamento'!$H$54:$H$153,'Detalhe do Planeamento'!$A$54:$A$153,"<="&$A32,'Detalhe do Planeamento'!$G$54:$G$153,RIGHT(C$29,LEN(C$29)-6))+SUMIFS('Detalhe do Planeamento'!$J$54:$J$153,'Detalhe do Planeamento'!$A$54:$A$153,"<="&$A32,'Detalhe do Planeamento'!$I$54:$I$153,RIGHT(C$29,LEN(C$29)-6))+SUMIFS('Detalhe do Planeamento'!$C$7:$C$26,'Detalhe do Planeamento'!$A$7:$A$26,"<="&$A32,'Detalhe do Planeamento'!$B$7:$B$26,RIGHT(C$29,LEN(C$29)-6))) | D32: =IF(OR($A32="",D$29=""),"",SUMIFS('Detalhe do Planeamento'!$F$54:$F$153,'Detalhe do Planeamento'!$A$54:$A$153,"<="&$A32,'Detalhe do Planeamento'!$E$54:$E$153,RIGHT(D$29,LEN(D$29)-6))+SUMIFS('Detalhe do Planeamento'!$H$54:$H$153,'Detalhe do Planeamento'!$A$54:$A$153,"<="&$A32,'Detalhe do Planeamento'!$G$54:$G$153,RIGHT(D$29,LEN(D$29)-6))+SUMIFS('Detalhe do Planeamento'!$J$54:$J$153,'Detalhe do Planeamento'!$A$54:$A$153,"<="&$A32,'Detalhe do Planeamento'!$I$54:$I$153,RIGHT(D$29,LEN(D$29)-6))+SUMIFS('Detalhe do Planeamento'!$C$7:$C$26,'Detalhe do Planeamento'!$A$7:$A$26,"<="&$A32,'Detalhe do Planeamento'!$B$7:$B$26,RIGHT(D$29,LEN(D$29)-6))) | E32: =IF(OR($A32="",E$29=""),"",SUMIFS('Detalhe do Planeamento'!$F$54:$F$153,'Detalhe do Planeamento'!$A$54:$A$153,"<="&$A32,'Detalhe do Planeamento'!$E$54:$E$153,RIGHT(E$29,LEN(E$29)-6))+SUMIFS('Detalhe do Planeamento'!$H$54:$H$153,'Detalhe do Planeamento'!$A$54:$A$153,"<="&$A32,'Detalhe do Planeamento'!$G$54:$G$153,RIGHT(E$29,LEN(E$29)-6))+SUMIFS('Detalhe do Planeamento'!$J$54:$J$153,'Detalhe do Planeamento'!$A$54:$A$153,"<="&$A32,'Detalhe do Planeamento'!$I$54:$I$153,RIGHT(E$29,LEN(E$29)-6))+SUMIFS('Detalhe do Planeamento'!$C$7:$C$26,'Detalhe do Planeamento'!$A$7:$A$26,"<="&$A32,'Detalhe do Planeamento'!$B$7:$B$26,RIGHT(E$29,LEN(E$29)-6))) | F32: =IF(COUNT(B32:E32)=0,"",MAX(B32:E32)) | G32: =IF(COUNT(B32:E32)=0,"",MIN(B32:E32)) | H32: =IF(OR(G32="",G32=0),"",F32/G32) | I32: =IF(G32="","",IF(G32=0,"Incumprimento grave — CTPmin = 0",IF(ROUND(H32,2)<=$D$9,"Cumpre","Não cumpre")))
A33: =IF('Detalhe do Planeamento'!A10="","",'Detalhe do Planeamento'!A10) | B33: =IF(OR($A33="",B$29=""),"",SUMIFS('Detalhe do Planeamento'!$F$54:$F$153,'Detalhe do Planeamento'!$A$54:$A$153,"<="&$A33,'Detalhe do Planeamento'!$E$54:$E$153,RIGHT(B$29,LEN(B$29)-6))+SUMIFS('Detalhe do Planeamento'!$H$54:$H$153,'Detalhe do Planeamento'!$A$54:$A$153,"<="&$A33,'Detalhe do Planeamento'!$G$54:$G$153,RIGHT(B$29,LEN(B$29)-6))+SUMIFS('Detalhe do Planeamento'!$J$54:$J$153,'Detalhe do Planeamento'!$A$54:$A$153,"<="&$A33,'Detalhe do Planeamento'!$I$54:$I$153,RIGHT(B$29,LEN(B$29)-6))+SUMIFS('Detalhe do Planeamento'!$C$7:$C$26,'Detalhe do Planeamento'!$A$7:$A$26,"<="&$A33,'Detalhe do Planeamento'!$B$7:$B$26,RIGHT(B$29,LEN(B$29)-6))) | C33: =IF(OR($A33="",C$29=""),"",SUMIFS('Detalhe do Planeamento'!$F$54:$F$153,'Detalhe do Planeamento'!$A$54:$A$153,"<="&$A33,'Detalhe do Planeamento'!$E$54:$E$153,RIGHT(C$29,LEN(C$29)-6))+SUMIFS('Detalhe do Planeamento'!$H$54:$H$153,'Detalhe do Planeamento'!$A$54:$A$153,"<="&$A33,'Detalhe do Planeamento'!$G$54:$G$153,RIGHT(C$29,LEN(C$29)-6))+SUMIFS('Detalhe do Planeamento'!$J$54:$J$153,'Detalhe do Planeamento'!$A$54:$A$153,"<="&$A33,'Detalhe do Planeamento'!$I$54:$I$153,RIGHT(C$29,LEN(C$29)-6))+SUMIFS('Detalhe do Planeamento'!$C$7:$C$26,'Detalhe do Planeamento'!$A$7:$A$26,"<="&$A33,'Detalhe do Planeamento'!$B$7:$B$26,RIGHT(C$29,LEN(C$29)-6))) | D33: =IF(OR($A33="",D$29=""),"",SUMIFS('Detalhe do Planeamento'!$F$54:$F$153,'Detalhe do Planeamento'!$A$54:$A$153,"<="&$A33,'Detalhe do Planeamento'!$E$54:$E$153,RIGHT(D$29,LEN(D$29)-6))+SUMIFS('Detalhe do Planeamento'!$H$54:$H$153,'Detalhe do Planeamento'!$A$54:$A$153,"<="&$A33,'Detalhe do Planeamento'!$G$54:$G$153,RIGHT(D$29,LEN(D$29)-6))+SUMIFS('Detalhe do Planeamento'!$J$54:$J$153,'Detalhe do Planeamento'!$A$54:$A$153,"<="&$A33,'Detalhe do Planeamento'!$I$54:$I$153,RIGHT(D$29,LEN(D$29)-6))+SUMIFS('Detalhe do Planeamento'!$C$7:$C$26,'Detalhe do Planeamento'!$A$7:$A$26,"<="&$A33,'Detalhe do Planeamento'!$B$7:$B$26,RIGHT(D$29,LEN(D$29)-6))) | E33: =IF(OR($A33="",E$29=""),"",SUMIFS('Detalhe do Planeamento'!$F$54:$F$153,'Detalhe do Planeamento'!$A$54:$A$153,"<="&$A33,'Detalhe do Planeamento'!$E$54:$E$153,RIGHT(E$29,LEN(E$29)-6))+SUMIFS('Detalhe do Planeamento'!$H$54:$H$153,'Detalhe do Planeamento'!$A$54:$A$153,"<="&$A33,'Detalhe do Planeamento'!$G$54:$G$153,RIGHT(E$29,LEN(E$29)-6))+SUMIFS('Detalhe do Planeamento'!$J$54:$J$153,'Detalhe do Planeamento'!$A$54:$A$153,"<="&$A33,'Detalhe do Planeamento'!$I$54:$I$153,RIGHT(E$29,LEN(E$29)-6))+SUMIFS('Detalhe do Planeamento'!$C$7:$C$26,'Detalhe do Planeamento'!$A$7:$A$26,"<="&$A33,'Detalhe do Planeamento'!$B$7:$B$26,RIGHT(E$29,LEN(E$29)-6))) | F33: =IF(COUNT(B33:E33)=0,"",MAX(B33:E33)) | G33: =IF(COUNT(B33:E33)=0,"",MIN(B33:E33)) | H33: =IF(OR(G33="",G33=0),"",F33/G33) | I33: =IF(G33="","",IF(G33=0,"Incumprimento grave — CTPmin = 0",IF(ROUND(H33,2)<=$D$9,"Cumpre","Não cumpre")))
A34: =IF('Detalhe do Planeamento'!A11="","",'Detalhe do Planeamento'!A11) | B34: =IF(OR($A34="",B$29=""),"",SUMIFS('Detalhe do Planeamento'!$F$54:$F$153,'Detalhe do Planeamento'!$A$54:$A$153,"<="&$A34,'Detalhe do Planeamento'!$E$54:$E$153,RIGHT(B$29,LEN(B$29)-6))+SUMIFS('Detalhe do Planeamento'!$H$54:$H$153,'Detalhe do Planeamento'!$A$54:$A$153,"<="&$A34,'Detalhe do Planeamento'!$G$54:$G$153,RIGHT(B$29,LEN(B$29)-6))+SUMIFS('Detalhe do Planeamento'!$J$54:$J$153,'Detalhe do Planeamento'!$A$54:$A$153,"<="&$A34,'Detalhe do Planeamento'!$I$54:$I$153,RIGHT(B$29,LEN(B$29)-6))+SUMIFS('Detalhe do Planeamento'!$C$7:$C$26,'Detalhe do Planeamento'!$A$7:$A$26,"<="&$A34,'Detalhe do Planeamento'!$B$7:$B$26,RIGHT(B$29,LEN(B$29)-6))) | C34: =IF(OR($A34="",C$29=""),"",SUMIFS('Detalhe do Planeamento'!$F$54:$F$153,'Detalhe do Planeamento'!$A$54:$A$153,"<="&$A34,'Detalhe do Planeamento'!$E$54:$E$153,RIGHT(C$29,LEN(C$29)-6))+SUMIFS('Detalhe do Planeamento'!$H$54:$H$153,'Detalhe do Planeamento'!$A$54:$A$153,"<="&$A34,'Detalhe do Planeamento'!$G$54:$G$153,RIGHT(C$29,LEN(C$29)-6))+SUMIFS('Detalhe do Planeamento'!$J$54:$J$153,'Detalhe do Planeamento'!$A$54:$A$153,"<="&$A34,'Detalhe do Planeamento'!$I$54:$I$153,RIGHT(C$29,LEN(C$29)-6))+SUMIFS('Detalhe do Planeamento'!$C$7:$C$26,'Detalhe do Planeamento'!$A$7:$A$26,"<="&$A34,'Detalhe do Planeamento'!$B$7:$B$26,RIGHT(C$29,LEN(C$29)-6))) | D34: =IF(OR($A34="",D$29=""),"",SUMIFS('Detalhe do Planeamento'!$F$54:$F$153,'Detalhe do Planeamento'!$A$54:$A$153,"<="&$A34,'Detalhe do Planeamento'!$E$54:$E$153,RIGHT(D$29,LEN(D$29)-6))+SUMIFS('Detalhe do Planeamento'!$H$54:$H$153,'Detalhe do Planeamento'!$A$54:$A$153,"<="&$A34,'Detalhe do Planeamento'!$G$54:$G$153,RIGHT(D$29,LEN(D$29)-6))+SUMIFS('Detalhe do Planeamento'!$J$54:$J$153,'Detalhe do Planeamento'!$A$54:$A$153,"<="&$A34,'Detalhe do Planeamento'!$I$54:$I$153,RIGHT(D$29,LEN(D$29)-6))+SUMIFS('Detalhe do Planeamento'!$C$7:$C$26,'Detalhe do Planeamento'!$A$7:$A$26,"<="&$A34,'Detalhe do Planeamento'!$B$7:$B$26,RIGHT(D$29,LEN(D$29)-6))) | E34: =IF(OR($A34="",E$29=""),"",SUMIFS('Detalhe do Planeamento'!$F$54:$F$153,'Detalhe do Planeamento'!$A$54:$A$153,"<="&$A34,'Detalhe do Planeamento'!$E$54:$E$153,RIGHT(E$29,LEN(E$29)-6))+SUMIFS('Detalhe do Planeamento'!$H$54:$H$153,'Detalhe do Planeamento'!$A$54:$A$153,"<="&$A34,'Detalhe do Planeamento'!$G$54:$G$153,RIGHT(E$29,LEN(E$29)-6))+SUMIFS('Detalhe do Planeamento'!$J$54:$J$153,'Detalhe do Planeamento'!$A$54:$A$153,"<="&$A34,'Detalhe do Planeamento'!$I$54:$I$153,RIGHT(E$29,LEN(E$29)-6))+SUMIFS('Detalhe do Planeamento'!$C$7:$C$26,'Detalhe do Planeamento'!$A$7:$A$26,"<="&$A34,'Detalhe do Planeamento'!$B$7:$B$26,RIGHT(E$29,LEN(E$29)-6))) | F34: =IF(COUNT(B34:E34)=0,"",MAX(B34:E34)) | G34: =IF(COUNT(B34:E34)=0,"",MIN(B34:E34)) | H34: =IF(OR(G34="",G34=0),"",F34/G34) | I34: =IF(G34="","",IF(G34=0,"Incumprimento grave — CTPmin = 0",IF(ROUND(H34,2)<=$D$9,"Cumpre","Não cumpre")))
A35: =IF('Detalhe do Planeamento'!A12="","",'Detalhe do Planeamento'!A12) | B35: =IF(OR($A35="",B$29=""),"",SUMIFS('Detalhe do Planeamento'!$F$54:$F$153,'Detalhe do Planeamento'!$A$54:$A$153,"<="&$A35,'Detalhe do Planeamento'!$E$54:$E$153,RIGHT(B$29,LEN(B$29)-6))+SUMIFS('Detalhe do Planeamento'!$H$54:$H$153,'Detalhe do Planeamento'!$A$54:$A$153,"<="&$A35,'Detalhe do Planeamento'!$G$54:$G$153,RIGHT(B$29,LEN(B$29)-6))+SUMIFS('Detalhe do Planeamento'!$J$54:$J$153,'Detalhe do Planeamento'!$A$54:$A$153,"<="&$A35,'Detalhe do Planeamento'!$I$54:$I$153,RIGHT(B$29,LEN(B$29)-6))+SUMIFS('Detalhe do Planeamento'!$C$7:$C$26,'Detalhe do Planeamento'!$A$7:$A$26,"<="&$A35,'Detalhe do Planeamento'!$B$7:$B$26,RIGHT(B$29,LEN(B$29)-6))) | C35: =IF(OR($A35="",C$29=""),"",SUMIFS('Detalhe do Planeamento'!$F$54:$F$153,'Detalhe do Planeamento'!$A$54:$A$153,"<="&$A35,'Detalhe do Planeamento'!$E$54:$E$153,RIGHT(C$29,LEN(C$29)-6))+SUMIFS('Detalhe do Planeamento'!$H$54:$H$153,'Detalhe do Planeamento'!$A$54:$A$153,"<="&$A35,'Detalhe do Planeamento'!$G$54:$G$153,RIGHT(C$29,LEN(C$29)-6))+SUMIFS('Detalhe do Planeamento'!$J$54:$J$153,'Detalhe do Planeamento'!$A$54:$A$153,"<="&$A35,'Detalhe do Planeamento'!$I$54:$I$153,RIGHT(C$29,LEN(C$29)-6))+SUMIFS('Detalhe do Planeamento'!$C$7:$C$26,'Detalhe do Planeamento'!$A$7:$A$26,"<="&$A35,'Detalhe do Planeamento'!$B$7:$B$26,RIGHT(C$29,LEN(C$29)-6))) | D35: =IF(OR($A35="",D$29=""),"",SUMIFS('Detalhe do Planeamento'!$F$54:$F$153,'Detalhe do Planeamento'!$A$54:$A$153,"<="&$A35,'Detalhe do Planeamento'!$E$54:$E$153,RIGHT(D$29,LEN(D$29)-6))+SUMIFS('Detalhe do Planeamento'!$H$54:$H$153,'Detalhe do Planeamento'!$A$54:$A$153,"<="&$A35,'Detalhe do Planeamento'!$G$54:$G$153,RIGHT(D$29,LEN(D$29)-6))+SUMIFS('Detalhe do Planeamento'!$J$54:$J$153,'Detalhe do Planeamento'!$A$54:$A$153,"<="&$A35,'Detalhe do Planeamento'!$I$54:$I$153,RIGHT(D$29,LEN(D$29)-6))+SUMIFS('Detalhe do Planeamento'!$C$7:$C$26,'Detalhe do Planeamento'!$A$7:$A$26,"<="&$A35,'Detalhe do Planeamento'!$B$7:$B$26,RIGHT(D$29,LEN(D$29)-6))) | E35: =IF(OR($A35="",E$29=""),"",SUMIFS('Detalhe do Planeamento'!$F$54:$F$153,'Detalhe do Planeamento'!$A$54:$A$153,"<="&$A35,'Detalhe do Planeamento'!$E$54:$E$153,RIGHT(E$29,LEN(E$29)-6))+SUMIFS('Detalhe do Planeamento'!$H$54:$H$153,'Detalhe do Planeamento'!$A$54:$A$153,"<="&$A35,'Detalhe do Planeamento'!$G$54:$G$153,RIGHT(E$29,LEN(E$29)-6))+SUMIFS('Detalhe do Planeamento'!$J$54:$J$153,'Detalhe do Planeamento'!$A$54:$A$153,"<="&$A35,'Detalhe do Planeamento'!$I$54:$I$153,RIGHT(E$29,LEN(E$29)-6))+SUMIFS('Detalhe do Planeamento'!$C$7:$C$26,'Detalhe do Planeamento'!$A$7:$A$26,"<="&$A35,'Detalhe do Planeamento'!$B$7:$B$26,RIGHT(E$29,LEN(E$29)-6))) | F35: =IF(COUNT(B35:E35)=0,"",MAX(B35:E35)) | G35: =IF(COUNT(B35:E35)=0,"",MIN(B35:E35)) | H35: =IF(OR(G35="",G35=0),"",F35/G35) | I35: =IF(G35="","",IF(G35=0,"Incumprimento grave — CTPmin = 0",IF(ROUND(H35,2)<=$D$9,"Cumpre","Não cumpre")))
A36: =IF('Detalhe do Planeamento'!A13="","",'Detalhe do Planeamento'!A13) | B36: =IF(OR($A36="",B$29=""),"",SUMIFS('Detalhe do Planeamento'!$F$54:$F$153,'Detalhe do Planeamento'!$A$54:$A$153,"<="&$A36,'Detalhe do Planeamento'!$E$54:$E$153,RIGHT(B$29,LEN(B$29)-6))+SUMIFS('Detalhe do Planeamento'!$H$54:$H$153,'Detalhe do Planeamento'!$A$54:$A$153,"<="&$A36,'Detalhe do Planeamento'!$G$54:$G$153,RIGHT(B$29,LEN(B$29)-6))+SUMIFS('Detalhe do Planeamento'!$J$54:$J$153,'Detalhe do Planeamento'!$A$54:$A$153,"<="&$A36,'Detalhe do Planeamento'!$I$54:$I$153,RIGHT(B$29,LEN(B$29)-6))+SUMIFS('Detalhe do Planeamento'!$C$7:$C$26,'Detalhe do Planeamento'!$A$7:$A$26,"<="&$A36,'Detalhe do Planeamento'!$B$7:$B$26,RIGHT(B$29,LEN(B$29)-6))) | C36: =IF(OR($A36="",C$29=""),"",SUMIFS('Detalhe do Planeamento'!$F$54:$F$153,'Detalhe do Planeamento'!$A$54:$A$153,"<="&$A36,'Detalhe do Planeamento'!$E$54:$E$153,RIGHT(C$29,LEN(C$29)-6))+SUMIFS('Detalhe do Planeamento'!$H$54:$H$153,'Detalhe do Planeamento'!$A$54:$A$153,"<="&$A36,'Detalhe do Planeamento'!$G$54:$G$153,RIGHT(C$29,LEN(C$29)-6))+SUMIFS('Detalhe do Planeamento'!$J$54:$J$153,'Detalhe do Planeamento'!$A$54:$A$153,"<="&$A36,'Detalhe do Planeamento'!$I$54:$I$153,RIGHT(C$29,LEN(C$29)-6))+SUMIFS('Detalhe do Planeamento'!$C$7:$C$26,'Detalhe do Planeamento'!$A$7:$A$26,"<="&$A36,'Detalhe do Planeamento'!$B$7:$B$26,RIGHT(C$29,LEN(C$29)-6))) | D36: =IF(OR($A36="",D$29=""),"",SUMIFS('Detalhe do Planeamento'!$F$54:$F$153,'Detalhe do Planeamento'!$A$54:$A$153,"<="&$A36,'Detalhe do Planeamento'!$E$54:$E$153,RIGHT(D$29,LEN(D$29)-6))+SUMIFS('Detalhe do Planeamento'!$H$54:$H$153,'Detalhe do Planeamento'!$A$54:$A$153,"<="&$A36,'Detalhe do Planeamento'!$G$54:$G$153,RIGHT(D$29,LEN(D$29)-6))+SUMIFS('Detalhe do Planeamento'!$J$54:$J$153,'Detalhe do Planeamento'!$A$54:$A$153,"<="&$A36,'Detalhe do Planeamento'!$I$54:$I$153,RIGHT(D$29,LEN(D$29)-6))+SUMIFS('Detalhe do Planeamento'!$C$7:$C$26,'Detalhe do Planeamento'!$A$7:$A$26,"<="&$A36,'Detalhe do Planeamento'!$B$7:$B$26,RIGHT(D$29,LEN(D$29)-6))) | E36: =IF(OR($A36="",E$29=""),"",SUMIFS('Detalhe do Planeamento'!$F$54:$F$153,'Detalhe do Planeamento'!$A$54:$A$153,"<="&$A36,'Detalhe do Planeamento'!$E$54:$E$153,RIGHT(E$29,LEN(E$29)-6))+SUMIFS('Detalhe do Planeamento'!$H$54:$H$153,'Detalhe do Planeamento'!$A$54:$A$153,"<="&$A36,'Detalhe do Planeamento'!$G$54:$G$153,RIGHT(E$29,LEN(E$29)-6))+SUMIFS('Detalhe do Planeamento'!$J$54:$J$153,'Detalhe do Planeamento'!$A$54:$A$153,"<="&$A36,'Detalhe do Planeamento'!$I$54:$I$153,RIGHT(E$29,LEN(E$29)-6))+SUMIFS('Detalhe do Planeamento'!$C$7:$C$26,'Detalhe do Planeamento'!$A$7:$A$26,"<="&$A36,'Detalhe do Planeamento'!$B$7:$B$26,RIGHT(E$29,LEN(E$29)-6))) | F36: =IF(COUNT(B36:E36)=0,"",MAX(B36:E36)) | G36: =IF(COUNT(B36:E36)=0,"",MIN(B36:E36)) | H36: =IF(OR(G36="",G36=0),"",F36/G36) | I36: =IF(G36="","",IF(G36=0,"Incumprimento grave — CTPmin = 0",IF(ROUND(H36,2)<=$D$9,"Cumpre","Não cumpre")))
A37: =IF('Detalhe do Planeamento'!A14="","",'Detalhe do Planeamento'!A14) | B37: =IF(OR($A37="",B$29=""),"",SUMIFS('Detalhe do Planeamento'!$F$54:$F$153,'Detalhe do Planeamento'!$A$54:$A$153,"<="&$A37,'Detalhe do Planeamento'!$E$54:$E$153,RIGHT(B$29,LEN(B$29)-6))+SUMIFS('Detalhe do Planeamento'!$H$54:$H$153,'Detalhe do Planeamento'!$A$54:$A$153,"<="&$A37,'Detalhe do Planeamento'!$G$54:$G$153,RIGHT(B$29,LEN(B$29)-6))+SUMIFS('Detalhe do Planeamento'!$J$54:$J$153,'Detalhe do Planeamento'!$A$54:$A$153,"<="&$A37,'Detalhe do Planeamento'!$I$54:$I$153,RIGHT(B$29,LEN(B$29)-6))+SUMIFS('Detalhe do Planeamento'!$C$7:$C$26,'Detalhe do Planeamento'!$A$7:$A$26,"<="&$A37,'Detalhe do Planeamento'!$B$7:$B$26,RIGHT(B$29,LEN(B$29)-6))) | C37: =IF(OR($A37="",C$29=""),"",SUMIFS('Detalhe do Planeamento'!$F$54:$F$153,'Detalhe do Planeamento'!$A$54:$A$153,"<="&$A37,'Detalhe do Planeamento'!$E$54:$E$153,RIGHT(C$29,LEN(C$29)-6))+SUMIFS('Detalhe do Planeamento'!$H$54:$H$153,'Detalhe do Planeamento'!$A$54:$A$153,"<="&$A37,'Detalhe do Planeamento'!$G$54:$G$153,RIGHT(C$29,LEN(C$29)-6))+SUMIFS('Detalhe do Planeamento'!$J$54:$J$153,'Detalhe do Planeamento'!$A$54:$A$153,"<="&$A37,'Detalhe do Planeamento'!$I$54:$I$153,RIGHT(C$29,LEN(C$29)-6))+SUMIFS('Detalhe do Planeamento'!$C$7:$C$26,'Detalhe do Planeamento'!$A$7:$A$26,"<="&$A37,'Detalhe do Planeamento'!$B$7:$B$26,RIGHT(C$29,LEN(C$29)-6))) | D37: =IF(OR($A37="",D$29=""),"",SUMIFS('Detalhe do Planeamento'!$F$54:$F$153,'Detalhe do Planeamento'!$A$54:$A$153,"<="&$A37,'Detalhe do Planeamento'!$E$54:$E$153,RIGHT(D$29,LEN(D$29)-6))+SUMIFS('Detalhe do Planeamento'!$H$54:$H$153,'Detalhe do Planeamento'!$A$54:$A$153,"<="&$A37,'Detalhe do Planeamento'!$G$54:$G$153,RIGHT(D$29,LEN(D$29)-6))+SUMIFS('Detalhe do Planeamento'!$J$54:$J$153,'Detalhe do Planeamento'!$A$54:$A$153,"<="&$A37,'Detalhe do Planeamento'!$I$54:$I$153,RIGHT(D$29,LEN(D$29)-6))+SUMIFS('Detalhe do Planeamento'!$C$7:$C$26,'Detalhe do Planeamento'!$A$7:$A$26,"<="&$A37,'Detalhe do Planeamento'!$B$7:$B$26,RIGHT(D$29,LEN(D$29)-6))) | E37: =IF(OR($A37="",E$29=""),"",SUMIFS('Detalhe do Planeamento'!$F$54:$F$153,'Detalhe do Planeamento'!$A$54:$A$153,"<="&$A37,'Detalhe do Planeamento'!$E$54:$E$153,RIGHT(E$29,LEN(E$29)-6))+SUMIFS('Detalhe do Planeamento'!$H$54:$H$153,'Detalhe do Planeamento'!$A$54:$A$153,"<="&$A37,'Detalhe do Planeamento'!$G$54:$G$153,RIGHT(E$29,LEN(E$29)-6))+SUMIFS('Detalhe do Planeamento'!$J$54:$J$153,'Detalhe do Planeamento'!$A$54:$A$153,"<="&$A37,'Detalhe do Planeamento'!$I$54:$I$153,RIGHT(E$29,LEN(E$29)-6))+SUMIFS('Detalhe do Planeamento'!$C$7:$C$26,'Detalhe do Planeamento'!$A$7:$A$26,"<="&$A37,'Detalhe do Planeamento'!$B$7:$B$26,RIGHT(E$29,LEN(E$29)-6))) | F37: =IF(COUNT(B37:E37)=0,"",MAX(B37:E37)) | G37: =IF(COUNT(B37:E37)=0,"",MIN(B37:E37)) | H37: =IF(OR(G37="",G37=0),"",F37/G37) | I37: =IF(G37="","",IF(G37=0,"Incumprimento grave — CTPmin = 0",IF(ROUND(H37,2)<=$D$9,"Cumpre","Não cumpre")))
A38: =IF('Detalhe do Planeamento'!A15="","",'Detalhe do Planeamento'!A15) | B38: =IF(OR($A38="",B$29=""),"",SUMIFS('Detalhe do Planeamento'!$F$54:$F$153,'Detalhe do Planeamento'!$A$54:$A$153,"<="&$A38,'Detalhe do Planeamento'!$E$54:$E$153,RIGHT(B$29,LEN(B$29)-6))+SUMIFS('Detalhe do Planeamento'!$H$54:$H$153,'Detalhe do Planeamento'!$A$54:$A$153,"<="&$A38,'Detalhe do Planeamento'!$G$54:$G$153,RIGHT(B$29,LEN(B$29)-6))+SUMIFS('Detalhe do Planeamento'!$J$54:$J$153,'Detalhe do Planeamento'!$A$54:$A$153,"<="&$A38,'Detalhe do Planeamento'!$I$54:$I$153,RIGHT(B$29,LEN(B$29)-6))+SUMIFS('Detalhe do Planeamento'!$C$7:$C$26,'Detalhe do Planeamento'!$A$7:$A$26,"<="&$A38,'Detalhe do Planeamento'!$B$7:$B$26,RIGHT(B$29,LEN(B$29)-6))) | C38: =IF(OR($A38="",C$29=""),"",SUMIFS('Detalhe do Planeamento'!$F$54:$F$153,'Detalhe do Planeamento'!$A$54:$A$153,"<="&$A38,'Detalhe do Planeamento'!$E$54:$E$153,RIGHT(C$29,LEN(C$29)-6))+SUMIFS('Detalhe do Planeamento'!$H$54:$H$153,'Detalhe do Planeamento'!$A$54:$A$153,"<="&$A38,'Detalhe do Planeamento'!$G$54:$G$153,RIGHT(C$29,LEN(C$29)-6))+SUMIFS('Detalhe do Planeamento'!$J$54:$J$153,'Detalhe do Planeamento'!$A$54:$A$153,"<="&$A38,'Detalhe do Planeamento'!$I$54:$I$153,RIGHT(C$29,LEN(C$29)-6))+SUMIFS('Detalhe do Planeamento'!$C$7:$C$26,'Detalhe do Planeamento'!$A$7:$A$26,"<="&$A38,'Detalhe do Planeamento'!$B$7:$B$26,RIGHT(C$29,LEN(C$29)-6))) | D38: =IF(OR($A38="",D$29=""),"",SUMIFS('Detalhe do Planeamento'!$F$54:$F$153,'Detalhe do Planeamento'!$A$54:$A$153,"<="&$A38,'Detalhe do Planeamento'!$E$54:$E$153,RIGHT(D$29,LEN(D$29)-6))+SUMIFS('Detalhe do Planeamento'!$H$54:$H$153,'Detalhe do Planeamento'!$A$54:$A$153,"<="&$A38,'Detalhe do Planeamento'!$G$54:$G$153,RIGHT(D$29,LEN(D$29)-6))+SUMIFS('Detalhe do Planeamento'!$J$54:$J$153,'Detalhe do Planeamento'!$A$54:$A$153,"<="&$A38,'Detalhe do Planeamento'!$I$54:$I$153,RIGHT(D$29,LEN(D$29)-6))+SUMIFS('Detalhe do Planeamento'!$C$7:$C$26,'Detalhe do Planeamento'!$A$7:$A$26,"<="&$A38,'Detalhe do Planeamento'!$B$7:$B$26,RIGHT(D$29,LEN(D$29)-6))) | E38: =IF(OR($A38="",E$29=""),"",SUMIFS('Detalhe do Planeamento'!$F$54:$F$153,'Detalhe do Planeamento'!$A$54:$A$153,"<="&$A38,'Detalhe do Planeamento'!$E$54:$E$153,RIGHT(E$29,LEN(E$29)-6))+SUMIFS('Detalhe do Planeamento'!$H$54:$H$153,'Detalhe do Planeamento'!$A$54:$A$153,"<="&$A38,'Detalhe do Planeamento'!$G$54:$G$153,RIGHT(E$29,LEN(E$29)-6))+SUMIFS('Detalhe do Planeamento'!$J$54:$J$153,'Detalhe do Planeamento'!$A$54:$A$153,"<="&$A38,'Detalhe do Planeamento'!$I$54:$I$153,RIGHT(E$29,LEN(E$29)-6))+SUMIFS('Detalhe do Planeamento'!$C$7:$C$26,'Detalhe do Planeamento'!$A$7:$A$26,"<="&$A38,'Detalhe do Planeamento'!$B$7:$B$26,RIGHT(E$29,LEN(E$29)-6))) | F38: =IF(COUNT(B38:E38)=0,"",MAX(B38:E38)) | G38: =IF(COUNT(B38:E38)=0,"",MIN(B38:E38)) | H38: =IF(OR(G38="",G38=0),"",F38/G38) | I38: =IF(G38="","",IF(G38=0,"Incumprimento grave — CTPmin = 0",IF(ROUND(H38,2)<=$D$9,"Cumpre","Não cumpre")))
A39: =IF('Detalhe do Planeamento'!A16="","",'Detalhe do Planeamento'!A16) | B39: =IF(OR($A39="",B$29=""),"",SUMIFS('Detalhe do Planeamento'!$F$54:$F$153,'Detalhe do Planeamento'!$A$54:$A$153,"<="&$A39,'Detalhe do Planeamento'!$E$54:$E$153,RIGHT(B$29,LEN(B$29)-6))+SUMIFS('Detalhe do Planeamento'!$H$54:$H$153,'Detalhe do Planeamento'!$A$54:$A$153,"<="&$A39,'Detalhe do Planeamento'!$G$54:$G$153,RIGHT(B$29,LEN(B$29)-6))+SUMIFS('Detalhe do Planeamento'!$J$54:$J$153,'Detalhe do Planeamento'!$A$54:$A$153,"<="&$A39,'Detalhe do Planeamento'!$I$54:$I$153,RIGHT(B$29,LEN(B$29)-6))+SUMIFS('Detalhe do Planeamento'!$C$7:$C$26,'Detalhe do Planeamento'!$A$7:$A$26,"<="&$A39,'Detalhe do Planeamento'!$B$7:$B$26,RIGHT(B$29,LEN(B$29)-6))) | C39: =IF(OR($A39="",C$29=""),"",SUMIFS('Detalhe do Planeamento'!$F$54:$F$153,'Detalhe do Planeamento'!$A$54:$A$153,"<="&$A39,'Detalhe do Planeamento'!$E$54:$E$153,RIGHT(C$29,LEN(C$29)-6))+SUMIFS('Detalhe do Planeamento'!$H$54:$H$153,'Detalhe do Planeamento'!$A$54:$A$153,"<="&$A39,'Detalhe do Planeamento'!$G$54:$G$153,RIGHT(C$29,LEN(C$29)-6))+SUMIFS('Detalhe do Planeamento'!$J$54:$J$153,'Detalhe do Planeamento'!$A$54:$A$153,"<="&$A39,'Detalhe do Planeamento'!$I$54:$I$153,RIGHT(C$29,LEN(C$29)-6))+SUMIFS('Detalhe do Planeamento'!$C$7:$C$26,'Detalhe do Planeamento'!$A$7:$A$26,"<="&$A39,'Detalhe do Planeamento'!$B$7:$B$26,RIGHT(C$29,LEN(C$29)-6))) | D39: =IF(OR($A39="",D$29=""),"",SUMIFS('Detalhe do Planeamento'!$F$54:$F$153,'Detalhe do Planeamento'!$A$54:$A$153,"<="&$A39,'Detalhe do Planeamento'!$E$54:$E$153,RIGHT(D$29,LEN(D$29)-6))+SUMIFS('Detalhe do Planeamento'!$H$54:$H$153,'Detalhe do Planeamento'!$A$54:$A$153,"<="&$A39,'Detalhe do Planeamento'!$G$54:$G$153,RIGHT(D$29,LEN(D$29)-6))+SUMIFS('Detalhe do Planeamento'!$J$54:$J$153,'Detalhe do Planeamento'!$A$54:$A$153,"<="&$A39,'Detalhe do Planeamento'!$I$54:$I$153,RIGHT(D$29,LEN(D$29)-6))+SUMIFS('Detalhe do Planeamento'!$C$7:$C$26,'Detalhe do Planeamento'!$A$7:$A$26,"<="&$A39,'Detalhe do Planeamento'!$B$7:$B$26,RIGHT(D$29,LEN(D$29)-6))) | E39: =IF(OR($A39="",E$29=""),"",SUMIFS('Detalhe do Planeamento'!$F$54:$F$153,'Detalhe do Planeamento'!$A$54:$A$153,"<="&$A39,'Detalhe do Planeamento'!$E$54:$E$153,RIGHT(E$29,LEN(E$29)-6))+SUMIFS('Detalhe do Planeamento'!$H$54:$H$153,'Detalhe do Planeamento'!$A$54:$A$153,"<="&$A39,'Detalhe do Planeamento'!$G$54:$G$153,RIGHT(E$29,LEN(E$29)-6))+SUMIFS('Detalhe do Planeamento'!$J$54:$J$153,'Detalhe do Planeamento'!$A$54:$A$153,"<="&$A39,'Detalhe do Planeamento'!$I$54:$I$153,RIGHT(E$29,LEN(E$29)-6))+SUMIFS('Detalhe do Planeamento'!$C$7:$C$26,'Detalhe do Planeamento'!$A$7:$A$26,"<="&$A39,'Detalhe do Planeamento'!$B$7:$B$26,RIGHT(E$29,LEN(E$29)-6))) | F39: =IF(COUNT(B39:E39)=0,"",MAX(B39:E39)) | G39: =IF(COUNT(B39:E39)=0,"",MIN(B39:E39)) | H39: =IF(OR(G39="",G39=0),"",F39/G39) | I39: =IF(G39="","",IF(G39=0,"Incumprimento grave — CTPmin = 0",IF(ROUND(H39,2)<=$D$9,"Cumpre","Não cumpre")))
A40: =IF('Detalhe do Planeamento'!A17="","",'Detalhe do Planeamento'!A17) | B40: =IF(OR($A40="",B$29=""),"",SUMIFS('Detalhe do Planeamento'!$F$54:$F$153,'Detalhe do Planeamento'!$A$54:$A$153,"<="&$A40,'Detalhe do Planeamento'!$E$54:$E$153,RIGHT(B$29,LEN(B$29)-6))+SUMIFS('Detalhe do Planeamento'!$H$54:$H$153,'Detalhe do Planeamento'!$A$54:$A$153,"<="&$A40,'Detalhe do Planeamento'!$G$54:$G$153,RIGHT(B$29,LEN(B$29)-6))+SUMIFS('Detalhe do Planeamento'!$J$54:$J$153,'Detalhe do Planeamento'!$A$54:$A$153,"<="&$A40,'Detalhe do Planeamento'!$I$54:$I$153,RIGHT(B$29,LEN(B$29)-6))+SUMIFS('Detalhe do Planeamento'!$C$7:$C$26,'Detalhe do Planeamento'!$A$7:$A$26,"<="&$A40,'Detalhe do Planeamento'!$B$7:$B$26,RIGHT(B$29,LEN(B$29)-6))) | C40: =IF(OR($A40="",C$29=""),"",SUMIFS('Detalhe do Planeamento'!$F$54:$F$153,'Detalhe do Planeamento'!$A$54:$A$153,"<="&$A40,'Detalhe do Planeamento'!$E$54:$E$153,RIGHT(C$29,LEN(C$29)-6))+SUMIFS('Detalhe do Planeamento'!$H$54:$H$153,'Detalhe do Planeamento'!$A$54:$A$153,"<="&$A40,'Detalhe do Planeamento'!$G$54:$G$153,RIGHT(C$29,LEN(C$29)-6))+SUMIFS('Detalhe do Planeamento'!$J$54:$J$153,'Detalhe do Planeamento'!$A$54:$A$153,"<="&$A40,'Detalhe do Planeamento'!$I$54:$I$153,RIGHT(C$29,LEN(C$29)-6))+SUMIFS('Detalhe do Planeamento'!$C$7:$C$26,'Detalhe do Planeamento'!$A$7:$A$26,"<="&$A40,'Detalhe do Planeamento'!$B$7:$B$26,RIGHT(C$29,LEN(C$29)-6))) | D40: =IF(OR($A40="",D$29=""),"",SUMIFS('Detalhe do Planeamento'!$F$54:$F$153,'Detalhe do Planeamento'!$A$54:$A$153,"<="&$A40,'Detalhe do Planeamento'!$E$54:$E$153,RIGHT(D$29,LEN(D$29)-6))+SUMIFS('Detalhe do Planeamento'!$H$54:$H$153,'Detalhe do Planeamento'!$A$54:$A$153,"<="&$A40,'Detalhe do Planeamento'!$G$54:$G$153,RIGHT(D$29,LEN(D$29)-6))+SUMIFS('Detalhe do Planeamento'!$J$54:$J$153,'Detalhe do Planeamento'!$A$54:$A$153,"<="&$A40,'Detalhe do Planeamento'!$I$54:$I$153,RIGHT(D$29,LEN(D$29)-6))+SUMIFS('Detalhe do Planeamento'!$C$7:$C$26,'Detalhe do Planeamento'!$A$7:$A$26,"<="&$A40,'Detalhe do Planeamento'!$B$7:$B$26,RIGHT(D$29,LEN(D$29)-6))) | E40: =IF(OR($A40="",E$29=""),"",SUMIFS('Detalhe do Planeamento'!$F$54:$F$153,'Detalhe do Planeamento'!$A$54:$A$153,"<="&$A40,'Detalhe do Planeamento'!$E$54:$E$153,RIGHT(E$29,LEN(E$29)-6))+SUMIFS('Detalhe do Planeamento'!$H$54:$H$153,'Detalhe do Planeamento'!$A$54:$A$153,"<="&$A40,'Detalhe do Planeamento'!$G$54:$G$153,RIGHT(E$29,LEN(E$29)-6))+SUMIFS('Detalhe do Planeamento'!$J$54:$J$153,'Detalhe do Planeamento'!$A$54:$A$153,"<="&$A40,'Detalhe do Planeamento'!$I$54:$I$153,RIGHT(E$29,LEN(E$29)-6))+SUMIFS('Detalhe do Planeamento'!$C$7:$C$26,'Detalhe do Planeamento'!$A$7:$A$26,"<="&$A40,'Detalhe do Planeamento'!$B$7:$B$26,RIGHT(E$29,LEN(E$29)-6))) | F40: =IF(COUNT(B40:E40)=0,"",MAX(B40:E40)) | G40: =IF(COUNT(B40:E40)=0,"",MIN(B40:E40)) | H40: =IF(OR(G40="",G40=0),"",F40/G40) | I40: =IF(G40="","",IF(G40=0,"Incumprimento grave — CTPmin = 0",IF(ROUND(H40,2)<=$D$9,"Cumpre","Não cumpre")))
A41: =IF('Detalhe do Planeamento'!A18="","",'Detalhe do Planeamento'!A18) | B41: =IF(OR($A41="",B$29=""),"",SUMIFS('Detalhe do Planeamento'!$F$54:$F$153,'Detalhe do Planeamento'!$A$54:$A$153,"<="&$A41,'Detalhe do Planeamento'!$E$54:$E$153,RIGHT(B$29,LEN(B$29)-6))+SUMIFS('Detalhe do Planeamento'!$H$54:$H$153,'Detalhe do Planeamento'!$A$54:$A$153,"<="&$A41,'Detalhe do Planeamento'!$G$54:$G$153,RIGHT(B$29,LEN(B$29)-6))+SUMIFS('Detalhe do Planeamento'!$J$54:$J$153,'Detalhe do Planeamento'!$A$54:$A$153,"<="&$A41,'Detalhe do Planeamento'!$I$54:$I$153,RIGHT(B$29,LEN(B$29)-6))+SUMIFS('Detalhe do Planeamento'!$C$7:$C$26,'Detalhe do Planeamento'!$A$7:$A$26,"<="&$A41,'Detalhe do Planeamento'!$B$7:$B$26,RIGHT(B$29,LEN(B$29)-6))) | C41: =IF(OR($A41="",C$29=""),"",SUMIFS('Detalhe do Planeamento'!$F$54:$F$153,'Detalhe do Planeamento'!$A$54:$A$153,"<="&$A41,'Detalhe do Planeamento'!$E$54:$E$153,RIGHT(C$29,LEN(C$29)-6))+SUMIFS('Detalhe do Planeamento'!$H$54:$H$153,'Detalhe do Planeamento'!$A$54:$A$153,"<="&$A41,'Detalhe do Planeamento'!$G$54:$G$153,RIGHT(C$29,LEN(C$29)-6))+SUMIFS('Detalhe do Planeamento'!$J$54:$J$153,'Detalhe do Planeamento'!$A$54:$A$153,"<="&$A41,'Detalhe do Planeamento'!$I$54:$I$153,RIGHT(C$29,LEN(C$29)-6))+SUMIFS('Detalhe do Planeamento'!$C$7:$C$26,'Detalhe do Planeamento'!$A$7:$A$26,"<="&$A41,'Detalhe do Planeamento'!$B$7:$B$26,RIGHT(C$29,LEN(C$29)-6))) | D41: =IF(OR($A41="",D$29=""),"",SUMIFS('Detalhe do Planeamento'!$F$54:$F$153,'Detalhe do Planeamento'!$A$54:$A$153,"<="&$A41,'Detalhe do Planeamento'!$E$54:$E$153,RIGHT(D$29,LEN(D$29)-6))+SUMIFS('Detalhe do Planeamento'!$H$54:$H$153,'Detalhe do Planeamento'!$A$54:$A$153,"<="&$A41,'Detalhe do Planeamento'!$G$54:$G$153,RIGHT(D$29,LEN(D$29)-6))+SUMIFS('Detalhe do Planeamento'!$J$54:$J$153,'Detalhe do Planeamento'!$A$54:$A$153,"<="&$A41,'Detalhe do Planeamento'!$I$54:$I$153,RIGHT(D$29,LEN(D$29)-6))+SUMIFS('Detalhe do Planeamento'!$C$7:$C$26,'Detalhe do Planeamento'!$A$7:$A$26,"<="&$A41,'Detalhe do Planeamento'!$B$7:$B$26,RIGHT(D$29,LEN(D$29)-6))) | E41: =IF(OR($A41="",E$29=""),"",SUMIFS('Detalhe do Planeamento'!$F$54:$F$153,'Detalhe do Planeamento'!$A$54:$A$153,"<="&$A41,'Detalhe do Planeamento'!$E$54:$E$153,RIGHT(E$29,LEN(E$29)-6))+SUMIFS('Detalhe do Planeamento'!$H$54:$H$153,'Detalhe do Planeamento'!$A$54:$A$153,"<="&$A41,'Detalhe do Planeamento'!$G$54:$G$153,RIGHT(E$29,LEN(E$29)-6))+SUMIFS('Detalhe do Planeamento'!$J$54:$J$153,'Detalhe do Planeamento'!$A$54:$A$153,"<="&$A41,'Detalhe do Planeamento'!$I$54:$I$153,RIGHT(E$29,LEN(E$29)-6))+SUMIFS('Detalhe do Planeamento'!$C$7:$C$26,'Detalhe do Planeamento'!$A$7:$A$26,"<="&$A41,'Detalhe do Planeamento'!$B$7:$B$26,RIGHT(E$29,LEN(E$29)-6))) | F41: =IF(COUNT(B41:E41)=0,"",MAX(B41:E41)) | G41: =IF(COUNT(B41:E41)=0,"",MIN(B41:E41)) | H41: =IF(OR(G41="",G41=0),"",F41/G41) | I41: =IF(G41="","",IF(G41=0,"Incumprimento grave — CTPmin = 0",IF(ROUND(H41,2)<=$D$9,"Cumpre","Não cumpre")))
... A49: =IF('Detalhe do Planeamento'!A26="","",'Detalhe do Planeamento'!A26) | B49: =IF(OR($A49="",B$29=""),"",SUMIFS('Detalhe do Planeamento'!$F$54:$F$153,'Detalhe do Planeamento'!$A$54:$A$153,"<="&$A49,'Detalhe do Planeamento'!$E$54:$E$153,RIGHT(B$29,LEN(B$29)-6))+SUMIFS('Detalhe do Planeamento'!$H$54:$H$153,'Detalhe do Planeamento'!$A$54:$A$153,"<="&$A49,'Detalhe do Planeamento'!$G$54:$G$153,RIGHT(B$29,LEN(B$29)-6))+SUMIFS('Detalhe do Planeamento'!$J$54:$J$153,'Detalhe do Planeamento'!$A$54:$A$153,"<="&$A49,'Detalhe do Planeamento'!$I$54:$I$153,RIGHT(B$29,LEN(B$29)-6))+SUMIFS('Detalhe do Planeamento'!$C$7:$C$26,'Detalhe do Planeamento'!$A$7:$A$26,"<="&$A49,'Detalhe do Planeamento'!$B$7:$B$26,RIGHT(B$29,LEN(B$29)-6))) | C49: =IF(OR($A49="",C$29=""),"",SUMIFS('Detalhe do Planeamento'!$F$54:$F$153,'Detalhe do Planeamento'!$A$54:$A$153,"<="&$A49,'Detalhe do Planeamento'!$E$54:$E$153,RIGHT(C$29,LEN(C$29)-6))+SUMIFS('Detalhe do Planeamento'!$H$54:$H$153,'Detalhe do Planeamento'!$A$54:$A$153,"<="&$A49,'Detalhe do Planeamento'!$G$54:$G$153,RIGHT(C$29,LEN(C$29)-6))+SUMIFS('Detalhe do Planeamento'!$J$54:$J$153,'Detalhe do Planeamento'!$A$54:$A$153,"<="&$A49,'Detalhe do Planeamento'!$I$54:$I$153,RIGHT(C$29,LEN(C$29)-6))+SUMIFS('Detalhe do Planeamento'!$C$7:$C$26,'Detalhe do Planeamento'!$A$7:$A$26,"<="&$A49,'Detalhe do Planeamento'!$B$7:$B$26,RIGHT(C$29,LEN(C$29)-6))) | D49: =IF(OR($A49="",D$29=""),"",SUMIFS('Detalhe do Planeamento'!$F$54:$F$153,'Detalhe do Planeamento'!$A$54:$A$153,"<="&$A49,'Detalhe do Planeamento'!$E$54:$E$153,RIGHT(D$29,LEN(D$29)-6))+SUMIFS('Detalhe do Planeamento'!$H$54:$H$153,'Detalhe do Planeamento'!$A$54:$A$153,"<="&$A49,'Detalhe do Planeamento'!$G$54:$G$153,RIGHT(D$29,LEN(D$29)-6))+SUMIFS('Detalhe do Planeamento'!$J$54:$J$153,'Detalhe do Planeamento'!$A$54:$A$153,"<="&$A49,'Detalhe do Planeamento'!$I$54:$I$153,RIGHT(D$29,LEN(D$29)-6))+SUMIFS('Detalhe do Planeamento'!$C$7:$C$26,'Detalhe do Planeamento'!$A$7:$A$26,"<="&$A49,'Detalhe do Planeamento'!$B$7:$B$26,RIGHT(D$29,LEN(D$29)-6))) | E49: =IF(OR($A49="",E$29=""),"",SUMIFS('Detalhe do Planeamento'!$F$54:$F$153,'Detalhe do Planeamento'!$A$54:$A$153,"<="&$A49,'Detalhe do Planeamento'!$E$54:$E$153,RIGHT(E$29,LEN(E$29)-6))+SUMIFS('Detalhe do Planeamento'!$H$54:$H$153,'Detalhe do Planeamento'!$A$54:$A$153,"<="&$A49,'Detalhe do Planeamento'!$G$54:$G$153,RIGHT(E$29,LEN(E$29)-6))+SUMIFS('Detalhe do Planeamento'!$J$54:$J$153,'Detalhe do Planeamento'!$A$54:$A$153,"<="&$A49,'Detalhe do Planeamento'!$I$54:$I$153,RIGHT(E$29,LEN(E$29)-6))+SUMIFS('Detalhe do Planeamento'!$C$7:$C$26,'Detalhe do Planeamento'!$A$7:$A$26,"<="&$A49,'Detalhe do Planeamento'!$B$7:$B$26,RIGHT(E$29,LEN(E$29)-6))) | F49: =IF(COUNT(B49:E49)=0,"",MAX(B49:E49)) | G49: =IF(COUNT(B49:E49)=0,"",MIN(B49:E49)) | H49: =IF(OR(G49="",G49=0),"",F49/G49) | I49: =IF(G49="","",IF(G49=0,"Incumprimento grave — CTPmin = 0",IF(ROUND(H49,2)<=$D$9,"Cumpre","Não cumpre")))

Sheet Detalhe do Planeamento
A1: DETALHE DO PLANEAMENTO
A2: FOLHA DE INTRODUÇÃO DE DADOS — substitua os exemplos pelos dados reais. Preencha as células amarelas; as células azuis contêm fórmulas e não devem ser alteradas. Consulte a folha «Instruções» antes de utilizar o template.
A3: Campos editáveis — substituir os exemplos | E3: Campos calculados — não alterar | H3: Erros e incoerências — consultar Validação
A5: SPRINTS E SECRETARIADO
A6: Sprint | B6: Secretário | C6: Pontuação Máxima do Secretariado
A7: Sprint 01 | B7: Gonçalo Dinis Magalhães Teixeira | C7: =IF(B7="","",'Listas de apoio'!$J$8) -> 10
C9: =IF(B9="","",'Listas de apoio'!$J$8)
C10: =IF(B10="","",'Listas de apoio'!$J$8)
C11: =IF(B11="","",'Listas de apoio'!$J$8)
C12: =IF(B12="","",'Listas de apoio'!$J$8)
C13: =IF(B13="","",'Listas de apoio'!$J$8)
C14: =IF(B14="","",'Listas de apoio'!$J$8)
C15: =IF(B15="","",'Listas de apoio'!$J$8)
C16: =IF(B16="","",'Listas de apoio'!$J$8)
C17: =IF(B17="","",'Listas de apoio'!$J$8)
C18: =IF(B18="","",'Listas de apoio'!$J$8)
C19: =IF(B19="","",'Listas de apoio'!$J$8)
C20: =IF(B20="","",'Listas de apoio'!$J$8)
... C26: =IF(B26="","",'Listas de apoio'!$J$8)
A28: FONTES DOCUMENTAIS
A29: Sprint | B29: Sprint Backlog — versão editável (XLS/XLSX) | E29: Sprint Backlog — versão congelada (PDF) | H29: Ata do Sprint Planning
A30: Sprint 01 | B30: /projeto/01-artefactos-de-gestao/01.04-backlog-de-projeto/m1-s01-sprint-backlog-v01.xlsx | E30: /projeto/01-artefactos-de-gestao/01.03-reunioes-de-grupo/m1-20260919-s01-sprint-backlog-v01.xlsx | H30: /projeto/01-artefactos-de-gestao/01.03-reunioes-de-grupo/01.03.03-reunioes-de-sprint-planning/01.03.03.02-atas/m1-20260919-ata-sprint-planning-v01.pdf
A51: TAREFAS PLANEADAS
A52: Transcreva os dados mínimos de cada tarefa a partir do Sprint Backlog aprovado. Cada Issue é registada uma única vez, no Sprint em que recebeu o orçamento e as atribuições iniciais. As transferências posteriores não alteram este mapa.
A53: Sprint | B53: Issue | C53: Tarefa | D53: Orçamento da tarefa | E53: Executor inicialmente atribuído | F53: PExe | G53: Revisor inicialmente atribuído | H53: PRev | I53: Auditor inicialmente atribuído | J53: PAud
A54: Sprint 01 | B54: I001 | C54: Elaborar Proposta de Sistema | D54: 50 | E54: Gonçalo Magalhães Ribeiro | F54: =IF(OR(D54="",E54=""),"",D54*'Listas de apoio'!$J$5) -> 30 | G54: Ivan Cristiano Silva Mendes | H54: 15 | I54: Ivan Cristiano Silva Mendes | J54: =IF(OR(D54="",I54=""),"",D54*'Listas de apoio'!$J$7) -> 5
A55: Sprint 01 | B55: I002 | C55: Elaborar Declaração de Âmbito | D55: 50 | E55: André Filipe Moreira Mesquita | F55: =IF(OR(D55="",E55=""),"",D55*'Listas de apoio'!$J$5) -> 30 | G55: Ivan Cristiano Silva Mendes | H55: =IF(OR(D55="",G55=""),"",D55*'Listas de apoio'!$J$6) -> 15 | I55: Ivan Cristiano Silva Mendes | J55: =IF(OR(D55="",I55=""),"",D55*'Listas de apoio'!$J$7) -> 5
A56: Sprint 01 | B56: I003 | C56: Preparar Checklist de Controlo de Artefactos (CCA) | D56: 30 | E56: Ivan Cristiano Silva Mendes | F56: =IF(OR(D56="",E56=""),"",D56*'Listas de apoio'!$J$5) -> 18 | G56: Gonçalo Magalhães Ribeiro | H56: =IF(OR(D56="",G56=""),"",D56*'Listas de apoio'!$J$6) -> 9 | I56: Gonçalo Dinis Magalhães Teixeira | J56: =IF(OR(D56="",I56=""),"",D56*'Listas de apoio'!$J$7) -> 3
A57: Sprint 01 | B57: I004 | C57: Obter e arquivar homologação da PS, DA e CCA | D57: 10 | E57: Ivan Cristiano Silva Mendes | F57: =IF(OR(D57="",E57=""),"",D57*'Listas de apoio'!$J$5) -> 6 | G57: André Filipe Moreira Mesquita | H57: =IF(OR(D57="",G57=""),"",D57*'Listas de apoio'!$J$6) -> 3 | I57: Gonçalo Magalhães Ribeiro | J57: =IF(OR(D57="",I57=""),"",D57*'Listas de apoio'!$J$7) -> 1
A58: Sprint 01 | B58: I005 | C58: Elaborar Regulamento Interno do Grupo | D58: 30 | E58: Ivan Cristiano Silva Mendes | F58: =IF(OR(D58="",E58=""),"",D58*'Listas de apoio'!$J$5) -> 18 | G58: Gonçalo Magalhães Ribeiro | H58: =IF(OR(D58="",G58=""),"",D58*'Listas de apoio'!$J$6) -> 9 | I58: André Filipe Moreira Mesquita | J58: =IF(OR(D58="",I58=""),"",D58*'Listas de apoio'!$J$7) -> 3
A59: Sprint 01 | B59: I006 | C59: Elaborar Plano de Qualidade do Processo | D59: 50 | E59: André Filipe Moreira Mesquita | F59: =IF(OR(D59="",E59=""),"",D59*'Listas de apoio'!$J$5) -> 30 | G59: Ivan Cristiano Silva Mendes | H59: =IF(OR(D59="",G59=""),"",D59*'Listas de apoio'!$J$6) -> 15 | I59: Ivan Cristiano Silva Mendes | J59: =IF(OR(D59="",I59=""),"",D59*'Listas de apoio'!$J$7) -> 5
A60: Sprint 01 | B60: I007 | C60: Elaborar Definition of Ready | D60: 20 | E60: Gonçalo Dinis Magalhães Teixeira | F60: =IF(OR(D60="",E60=""),"",D60*'Listas de apoio'!$J$5) -> 12 | G60: Ivan Cristiano Silva Mendes | H60: =IF(OR(D60="",G60=""),"",D60*'Listas de apoio'!$J$6) -> 6 | I60: Ivan Cristiano Silva Mendes | J60: =IF(OR(D60="",I60=""),"",D60*'Listas de apoio'!$J$7) -> 2
A61: Sprint 01 | B61: I008 | C61: Elaborar Definition of Done | D61: 20 | E61: Gonçalo Dinis Magalhães Teixeira | F61: =IF(OR(D61="",E61=""),"",D61*'Listas de apoio'!$J$5) -> 12 | G61: Ivan Cristiano Silva Mendes | H61: =IF(OR(D61="",G61=""),"",D61*'Listas de apoio'!$J$6) -> 6 | I61: Ivan Cristiano Silva Mendes | J61: =IF(OR(D61="",I61=""),"",D61*'Listas de apoio'!$J$7) -> 2
A62: Sprint 01 | B62: I009 | C62: Definir Critérios de Qualidade dos Requisitos | D62: 30 | E62: Gonçalo Magalhães Ribeiro | F62: =IF(OR(D62="",E62=""),"",D62*'Listas de apoio'!$J$5) -> 18 | G62: André Filipe Moreira Mesquita | H62: =IF(OR(D62="",G62=""),"",D62*'Listas de apoio'!$J$6) -> 9 | I62: Gonçalo Dinis Magalhães Teixeira | J62: =IF(OR(D62="",I62=""),"",D62*'Listas de apoio'!$J$7) -> 3
A63: Sprint 01 | B63: I010 | C63: Preparar Grelha de Rotação de Papéis | D63: 20 | E63: Ivan Cristiano Silva Mendes | F63: =IF(OR(D63="",E63=""),"",D63*'Listas de apoio'!$J$5) -> 12 | G63: André Filipe Moreira Mesquita | H63: =IF(OR(D63="",G63=""),"",D63*'Listas de apoio'!$J$6) -> 6 | I63: Gonçalo Magalhães Ribeiro | J63: =IF(OR(D63="",I63=""),"",D63*'Listas de apoio'!$J$7) -> 2
F64: =IF(OR(D64="",E64=""),"",D64*'Listas de apoio'!$J$5) | H64: =IF(OR(D64="",G64=""),"",D64*'Listas de apoio'!$J$6) | J64: =IF(OR(D64="",I64=""),"",D64*'Listas de apoio'!$J$7)
F65: =IF(OR(D65="",E65=""),"",D65*'Listas de apoio'!$J$5) | H65: =IF(OR(D65="",G65=""),"",D65*'Listas de apoio'!$J$6) | J65: =IF(OR(D65="",I65=""),"",D65*'Listas de apoio'!$J$7)
F66: =IF(OR(D66="",E66=""),"",D66*'Listas de apoio'!$J$5) | H66: =IF(OR(D66="",G66=""),"",D66*'Listas de apoio'!$J$6) | J66: =IF(OR(D66="",I66=""),"",D66*'Listas de apoio'!$J$7)
F67: =IF(OR(D67="",E67=""),"",D67*'Listas de apoio'!$J$5) | H67: =IF(OR(D67="",G67=""),"",D67*'Listas de apoio'!$J$6) | J67: =IF(OR(D67="",I67=""),"",D67*'Listas de apoio'!$J$7)
F68: =IF(OR(D68="",E68=""),"",D68*'Listas de apoio'!$J$5) | H68: =IF(OR(D68="",G68=""),"",D68*'Listas de apoio'!$J$6) | J68: =IF(OR(D68="",I68=""),"",D68*'Listas de apoio'!$J$7)
...

Sheet Validação
A1: VALIDAÇÃO
A2: Esta folha identifica omissões e incoerências. Os resultados assinalados como «Rever» devem ser corrigidos antes da reunião e da geração do PDF assinado.
A4: Verificação | B4: Resultado | C4: Estado | D4: Interpretação
A5: Total de Sprints registados | B5: =COUNTIF('Detalhe do Planeamento'!$A$7:$A$26,"<>") -> 1 | C5: Informação | D5: Número de Sprints incluídos no Momento de Avaliação.
A6: Total de tarefas planeadas | B6: =COUNTIF('Detalhe do Planeamento'!$B$54:$B$153,"<>") -> 10 | C6: Informação | D6: Número de Issues registadas uma única vez no mapa.
A7: Total de pontos planeados do grupo | B7: ='Mapa de Carga Planeada'!F17 -> 320 | C7: Informação | D7: Soma das CTP individuais, incluindo os Secretariados.
A8: Sprints repetidos no quadro do Secretariado | B8: =SUMPRODUCT(--('Detalhe do Planeamento'!$A$7:$A$26<>""),--(COUNTIF('Detalhe do Planeamento'!$A$7:$A$26,'Detalhe do Planeamento'!$A$7:$A$26)>1)) -> 0 | C8: =IF(B8=0,"OK","Rever") -> OK | D8: Deve ser 0. Cada Sprint surge uma única vez no quadro do Secretariado.
A9: Sprints sem Secretário | B9: =SUMPRODUCT(--('Detalhe do Planeamento'!$A$7:$A$26<>""),--('Detalhe do Planeamento'!$B$7:$B$26="")) -> 0 | C9: =IF(B9=0,"OK","Rever") -> OK | D9: Deve ser 0. Cada Sprint tem um Secretário designado.
A10: Sprints sem referência ao Sprint Backlog editável (XLS/XLSX) | B10: =SUMPRODUCT(--('Detalhe do Planeamento'!$A$30:$A$49<>""),--('Detalhe do Planeamento'!$B$30:$B$49="")) -> 0 | C10: =IF(B10=0,"OK","Rever") -> OK | D10: Deve ser 0. Identifique a versão editável considerada.
A11: Sprints sem referência ao Sprint Backlog PDF | B11: =SUMPRODUCT(--('Detalhe do Planeamento'!$A$30:$A$49<>""),--('Detalhe do Planeamento'!$E$30:$E$49="")) -> 0 | C11: =IF(B11=0,"OK","Rever") -> OK | D11: Deve ser 0. Identifique o PDF congelado e assinado.
A12: Sprints sem referência à ata do Sprint Planning | B12: =SUMPRODUCT(--('Detalhe do Planeamento'!$A$30:$A$49<>""),--('Detalhe do Planeamento'!$H$30:$H$49="")) -> 0 | C12: =IF(B12=0,"OK","Rever") -> OK | D12: Deve ser 0. Identifique a ata que aprovou o planeamento.
A13: Tarefas sem Sprint | B13: =SUMPRODUCT(--('Detalhe do Planeamento'!$B$54:$B$153<>""),--('Detalhe do Planeamento'!$A$54:$A$153="")) -> 0 | C13: =IF(B13=0,"OK","Rever") -> OK | D13: Deve ser 0. Todas as tarefas pertencem ao Sprint onde foram inicialmente planeadas.
A14: Linhas de tarefa sem Issue | B14: =SUMPRODUCT(--('Detalhe do Planeamento'!$A$54:$A$153<>""),--('Detalhe do Planeamento'!$B$54:$B$153="")) -> 0 | C14: =IF(B14=0,"OK","Rever") -> OK | D14: Deve ser 0. Todas as tarefas têm uma Issue inequívoca.
A15: Issues repetidas no Momento de Avaliação | B15: =SUMPRODUCT(--('Detalhe do Planeamento'!$B$54:$B$153<>""),--(COUNTIF('Detalhe do Planeamento'!$B$54:$B$153,'Detalhe do Planeamento'!$B$54:$B$153)>1)) -> 0 | C15: =IF(B15=0,"OK","Rever") -> OK | D15: Deve ser 0. Uma tarefa que continue noutro Sprint não recebe novo orçamento nem é novamente contabilizada.
A16: Tarefas cujo Sprint não consta do quadro de Sprints | B16: =SUMPRODUCT(--('Detalhe do Planeamento'!$A$54:$A$153<>""),--ISNA(MATCH('Detalhe do Planeamento'!$A$54:$A$153,'Detalhe do Planeamento'!$A$7:$A$26,0))) -> 0 | C16: =IF(B16=0,"OK","Rever") -> OK | D16: Deve ser 0. O Sprint indicado em cada tarefa deve existir no quadro «Sprints e Secretariado» da folha «Detalhe do Planeamento».
A17: Tarefas com orçamento não permitido | B17: =SUMPRODUCT(--('Detalhe do Planeamento'!$B$54:$B$153<>""),--('Detalhe do Planeamento'!$D$54:$D$153<>10),--('Detalhe do Planeamento'!$D$54:$D$153<>20),--('Detalhe do Planeamento'!$D$54:$D$153<>30),--('Detalhe do Planeamento'!$D$54:$D$153<>50),--('Detalhe do Planeamento'!$D$54:$D$153<>80),--('Detalhe do Planeamento'!$D$54:$D$153<>130)) -> 0 | C17: =IF(B17=0,"OK","Rever") -> OK | D17: Deve ser 0. Use apenas 10, 20, 30, 50, 80 ou 130 pontos.
A18: Tarefas sem os três responsáveis | B18: =SUMPRODUCT(--('Detalhe do Planeamento'!$B$54:$B$153<>""),--((('Detalhe do Planeamento'!$E$54:$E$153="")+('Detalhe do Planeamento'!$G$54:$G$153="")+('Detalhe do Planeamento'!$I$54:$I$153=""))>0)) -> 0 | C18: =IF(B18=0,"OK","Rever") -> OK | D18: Deve ser 0. Todas as tarefas têm Executor, Revisor e Auditor.
A19: Tarefas com o mesmo aluno em mais de um papel | B19: =SUMPRODUCT(--('Detalhe do Planeamento'!$B$54:$B$153<>""),--('Detalhe do Planeamento'!$E$54:$E$153<>""),--('Detalhe do Planeamento'!$G$54:$G$153<>""),--('Detalhe do Planeamento'!$I$54:$I$153<>""),--((('Detalhe do Planeamento'!$E$54:$E$153='Detalhe do Planeamento'!$G$54:$G$153)+('Detalhe do Planeamento'!$E$54:$E$153='Detalhe do Planeamento'!$I$54:$I$153)+('Detalhe do Planeamento'!$G$54:$G$153='Detalhe do Planeamento'!$I$54:$I$153))>0)) -> 5 | C19: =IF(B19=0,"OK","Rever") -> Rever | D19: Deve ser 0. Executor, Revisor e Auditor são alunos diferentes.
A20: Responsáveis que não pertencem ao grupo | B20: =SUMPRODUCT(--('Detalhe do Planeamento'!$E$54:$E$153<>""),--ISNA(MATCH('Detalhe do Planeamento'!$E$54:$E$153,'Listas de apoio'!$G$5:$G$8,0)))+SUMPRODUCT(--('Detalhe do Planeamento'!$G$54:$G$153<>""),--ISNA(MATCH('Detalhe do Planeamento'!$G$54:$G$153,'Listas de apoio'!$G$5:$G$8,0)))+SUMPRODUCT(--('Detalhe do Planeamento'!$I$54:$I$153<>""),--ISNA(MATCH('Detalhe do Planeamento'!$I$54:$I$153,'Listas de apoio'!$G$5:$G$8,0))) -> 0 | C20: =IF(B20=0,"OK","Rever") -> OK | D20: Deve ser 0. Todos os responsáveis devem constar da lista de alunos do grupo.
A21: Tarefas em que PExe não corresponde a 60% do orçamento | B21: {=SUMPRODUCT(--('Detalhe do Planeamento'!$B$54:$B$153<>""),--('Detalhe do Planeamento'!$F$54:$F$153<>'Detalhe do Planeamento'!$D$54:$D$153*'Listas de apoio'!$J$5))} -> 0 | C21: =IF(B21=0,"OK","Rever") -> OK | D21: Deve ser 0. Em cada tarefa, PExe deve ser igual a 60% do respetivo orçamento.
A22: Tarefas em que PRev não corresponde a 30% do orçamento | B22: {=SUMPRODUCT(--('Detalhe do Planeamento'!$B$54:$B$153<>""),--('Detalhe do Planeamento'!$H$54:$H$153<>'Detalhe do Planeamento'!$D$54:$D$153*'Listas de apoio'!$J$6))} -> 0 | C22: =IF(B22=0,"OK","Rever") -> OK | D22: Deve ser 0. Em cada tarefa, PRev deve ser igual a 30% do respetivo orçamento.
A23: Tarefas em que PAud não corresponde a 10% do orçamento | B23: {=SUMPRODUCT(--('Detalhe do Planeamento'!$B$54:$B$153<>""),--('Detalhe do Planeamento'!$J$54:$J$153<>'Detalhe do Planeamento'!$D$54:$D$153*'Listas de apoio'!$J$7))} -> 0 | C23: =IF(B23=0,"OK","Rever") -> OK | D23: Deve ser 0. Em cada tarefa, PAud deve ser igual a 10% do respetivo orçamento.
A24: Tarefas em que a soma das parcelas não corresponde ao orçamento | B24: {=SUMPRODUCT(--('Detalhe do Planeamento'!$B$54:$B$153<>""),--((IFERROR('Detalhe do Planeamento'!$F$54:$F$153*1,0)+IFERROR('Detalhe do Planeamento'!$H$54:$H$153*1,0)+IFERROR('Detalhe do Planeamento'!$J$54:$J$153*1,0))<>IFERROR('Detalhe do Planeamento'!$D$54:$D$153*1,0)))} -> 0 | C24: =IF(B24=0,"OK","Rever") -> OK | D24: Deve ser 0. Em cada tarefa, a soma PExe + PRev + PAud deve ser igual ao orçamento total aprovado.
A25: Diferença entre o total de PExe e 60% dos orçamentos | B25: =ABS(SUM('Detalhe do Planeamento'!$F$54:$F$153)-SUM('Detalhe do Planeamento'!$D$54:$D$153)*'Listas de apoio'!$J$5) -> 0 | C25: =IF(B25=0,"OK","Rever") -> OK | D25: Deve ser 0. A soma das parcelas de Execução de todas as tarefas deve ser igual a 60% da soma dos respetivos orçamentos.
A26: Diferença entre o total de PRev e 30% dos orçamentos | B26: =ABS(SUM('Detalhe do Planeamento'!$H$54:$H$153)-SUM('Detalhe do Planeamento'!$D$54:$D$153)*'Listas de apoio'!$J$6) -> 0 | C26: =IF(B26=0,"OK","Rever") -> OK | D26: Deve ser 0. A soma das parcelas de Revisão de todas as tarefas deve ser igual a 30% da soma dos respetivos orçamentos.
A27: Diferença entre o total de PAud e 10% dos orçamentos | B27: =ABS(SUM('Detalhe do Planeamento'!$J$54:$J$153)-SUM('Detalhe do Planeamento'!$D$54:$D$153)*'Listas de apoio'!$J$7) -> 0 | C27: =IF(B27=0,"OK","Rever") -> OK | D27: Deve ser 0. A soma das parcelas de Auditoria de todas as tarefas deve ser igual a 10% da soma dos respetivos orçamentos.
A28: Diferença entre a CTP total do grupo e o total planeado | B28: =ABS('Mapa de Carga Planeada'!$F$17-(SUM('Detalhe do Planeamento'!$D$54:$D$153)+SUM('Detalhe do Planeamento'!$C$7:$C$26))) -> 0 | C28: =IF(B28=0,"OK","Rever") -> OK | D28: Deve ser 0. A soma das CTP individuais deve ser igual à soma dos orçamentos de todas as tarefas normais mais os 10 pontos máximos de cada Secretariado registado.
A29: Sprints com CTP mínima igual a zero | B29: =COUNTIF('Mapa de Carga Planeada'!$I$30:$I$49,"Incumprimento grave*") -> 0 | C29: =IF(B29=0,"OK","Rever") -> OK | D29: Deve ser 0. CTPmin = 0 torna o quociente indefinido e constitui incumprimento grave.
A30: Sprints com QCTP superior a 1,10 | B30: =COUNTIF('Mapa de Carga Planeada'!$I$30:$I$49,"Não cumpre") -> 1 | C30: =IF(B30=0,"OK","Rever") -> Rever | D30: Deve ser 0. O acumulado de cada Sprint Planning deve respeitar o limite 1,10.

Sheet Instruções
A1: INSTRUÇÕES
A2: Leia estas instruções antes de preencher o template. O Mapa de Carga Planeada mede o compromisso inicialmente planeado e não os pontos efetivamente obtidos.
A3: Passo | B3: Ação | C3: Regra | D3: Resultado esperado
A4: 1 | B4: Copiar e renomear | C4: Mantenha o template original em 01.01-templates. Crie uma cópia na pasta 01.06-avaliacao-interna-do-grupo e aplique a nomenclatura da milestone e da versão reais. O ficheiro editável pode ser mantido em formato XLS ou XLSX. O formato XLSM não é permitido e não devem ser utilizadas macros. Quando existam versões XLS e XLSX do mesmo conteúdo, estas devem manter-se coerentes. | D4: Ficheiro operacional corretamente identificado.
A5: 2 | B5: Identificar os alunos | C5: Na folha Listas de apoio, substitua Aluno A, Aluno B, Aluno C e Aluno D pelos nomes reais. Num grupo de três alunos, deixe a quarta célula vazia. | D5: Listas suspensas e cálculos ajustados à dimensão do grupo.
A6: 3 | B6: Selecionar o Momento de Avaliação | C6: Na folha Mapa de Carga Planeada, selecione m1+m2, m3 ou m4. O mapa não pode misturar cargas pertencentes a Momentos de Avaliação diferentes. | D6: Acumulado limitado ao Momento de Avaliação em curso.
