Workbook
Name Alunos: 'Listas de apoio'!$A$5:$A$12
Name Atrasos: 'Listas de apoio'!$S$5:$S$10
Name Origens: 'Listas de apoio'!$E$5:$E$7
Name Papeis: 'Listas de apoio'!$C$5:$C$8
Name Qualidade_Auditor: 'Listas de apoio'!$M$5:$M$7
Name Qualidade_Executor: 'Listas de apoio'!$G$5:$G$9
Name Qualidade_Revisor: 'Listas de apoio'!$J$5:$J$8
Name Qualidade_Secretario: 'Listas de apoio'!$P$5:$P$7
Name SprintsRegistados: 'Detalhe da Pontuação'!$A$6:$A$14

Sheet Mapa de Pontuação Individual
A1: MAPA DE PONTUAÇÃO INDIVIDUAL | B1: MAPA DE PONTUAÇÃO INDIVIDUAL | C1: MAPA DE PONTUAÇÃO INDIVIDUAL | D1: MAPA DE PONTUAÇÃO INDIVIDUAL | E1: MAPA DE PONTUAÇÃO INDIVIDUAL | F1: MAPA DE PONTUAÇÃO INDIVIDUAL | G1: MAPA DE PONTUAÇÃO INDIVIDUAL | H1: MAPA DE PONTUAÇÃO INDIVIDUAL
A2: RESUMO CALCULADO — este mapa sustenta os resultados apreciados nos Sprint Reviews e os valores acumulados utilizados no fecho do Momento de Avaliação. Preencha os campos amarelos e a folha «Detalhe da Pontuação»; não altere as células azuis. | B2: RESUMO CALCULADO — este mapa sustenta os valores resumidos na ata de Sprint Review. Preencha os campos amarelos e a folha «Detalhe da Pontuação»; não altere as células azuis. | C2: RESUMO CALCULADO — este mapa sustenta os valores resumidos na ata de Sprint Review. Preencha os campos amarelos e a folha «Detalhe da Pontuação»; não altere as células azuis. | D2: RESUMO CALCULADO — este mapa sustenta os valores resumidos na ata de Sprint Review. Preencha os campos amarelos e a folha «Detalhe da Pontuação»; não altere as células azuis. | E2: RESUMO CALCULADO — este mapa sustenta os valores resumidos na ata de Sprint Review. Preencha os campos amarelos e a folha «Detalhe da Pontuação»; não altere as células azuis. | F2: RESUMO CALCULADO — este mapa sustenta os valores resumidos na ata de Sprint Review. Preencha os campos amarelos e a folha «Detalhe da Pontuação»; não altere as células azuis. | G2: RESUMO CALCULADO — este mapa sustenta os valores resumidos na ata de Sprint Review. Preencha os campos amarelos e a folha «Detalhe da Pontuação»; não altere as células azuis. | H2: RESUMO CALCULADO — este mapa sustenta os valores resumidos na ata de Sprint Review. Preencha os campos amarelos e a folha «Detalhe da Pontuação»; não altere as células azuis.
A4: IDENTIFICAÇÃO DO MOMENTO DE AVALIAÇÃO | B4: IDENTIFICAÇÃO DO MOMENTO DE AVALIAÇÃO | C4: IDENTIFICAÇÃO DO MOMENTO DE AVALIAÇÃO | D4: IDENTIFICAÇÃO DO MOMENTO DE AVALIAÇÃO | E4: IDENTIFICAÇÃO DO MOMENTO DE AVALIAÇÃO | F4: IDENTIFICAÇÃO DO MOMENTO DE AVALIAÇÃO | G4: IDENTIFICAÇÃO DO MOMENTO DE AVALIAÇÃO | H4: IDENTIFICAÇÃO DO MOMENTO DE AVALIAÇÃO
A5: Momento de Avaliação | B5: m1+m2
A6: Sprints abrangidos | B6: Sprint 01, Sprint 02
A7: Número de alunos considerado — n | B7: =COUNTA('Listas de apoio'!A5:A12) -> 4
A8: Referência da autorização para n diferente de 4 | B8: Não aplicável — n = 4
A9: Orçamento Total do Grupo — B_T | B9: =SUM('Detalhe da Pontuação'!H18:H88) -> 800
A10: Total de Pontos Efetivamente Obtidos do grupo | B10: =SUM('Detalhe da Pontuação'!Z18:Z88) -> 800
A12: RESUMO POR ALUNO | B12: RESUMO POR ALUNO | C12: RESUMO POR ALUNO | D12: RESUMO POR ALUNO | E12: RESUMO POR ALUNO | F12: RESUMO POR ALUNO | G12: RESUMO POR ALUNO | H12: RESUMO POR ALUNO
A13: Aluno | B13: PEO Executor | C13: PEO Revisor | D13: PEO Auditor | E13: PEO Secretário | F13: P_i | G13: IB_i | H13: NI_i
A14: ='Listas de apoio'!A5 -> André Filipe Moreira Mesquita | B14: =IF($A14="","",SUMIFS('Detalhe da Pontuação'!$Z$18:$Z$88,'Detalhe da Pontuação'!$D$18:$D$88,$A14,'Detalhe da Pontuação'!$E$18:$E$88,"Executor")) -> 138 | C14: =IF($A14="","",SUMIFS('Detalhe da Pontuação'!$Z$18:$Z$88,'Detalhe da Pontuação'!$D$18:$D$88,$A14,'Detalhe da Pontuação'!$E$18:$E$88,"Revisor")) -> 42 | D14: =IF($A14="","",SUMIFS('Detalhe da Pontuação'!$Z$18:$Z$88,'Detalhe da Pontuação'!$D$18:$D$88,$A14,'Detalhe da Pontuação'!$E$18:$E$88,"Auditor")) -> 20 | E14: =IF($A14="","",SUMIFS('Detalhe da Pontuação'!$Z$18:$Z$88,'Detalhe da Pontuação'!$D$18:$D$88,$A14,'Detalhe da Pontuação'!$E$18:$E$88,"Secretário")) -> 0 | F14: =IF($A14="","",SUM($B14:$E14)) -> 200 | G14: =IF(OR($A14="",$B$9=0),"",20*$B$7*$F14/$B$9) -> 20 | H14: =IF(NOT(ISNUMBER($G14)),"",MIN(20,$G14)) -> 20
A15: ='Listas de apoio'!A6 -> Gonçalo Dinis Magalhães Teixeira | B15: =IF($A15="","",SUMIFS('Detalhe da Pontuação'!$Z$18:$Z$88,'Detalhe da Pontuação'!$D$18:$D$88,$A15,'Detalhe da Pontuação'!$E$18:$E$88,"Executor")) -> 150 | C15: =IF($A15="","",SUMIFS('Detalhe da Pontuação'!$Z$18:$Z$88,'Detalhe da Pontuação'!$D$18:$D$88,$A15,'Detalhe da Pontuação'!$E$18:$E$88,"Revisor")) -> 30 | D15: =IF($A15="","",SUMIFS('Detalhe da Pontuação'!$Z$18:$Z$88,'Detalhe da Pontuação'!$D$18:$D$88,$A15,'Detalhe da Pontuação'!$E$18:$E$88,"Auditor")) -> 10 | E15: =IF($A15="","",SUMIFS('Detalhe da Pontuação'!$Z$18:$Z$88,'Detalhe da Pontuação'!$D$18:$D$88,$A15,'Detalhe da Pontuação'!$E$18:$E$88,"Secretário")) -> 10 | F15: =IF($A15="","",SUM($B15:$E15)) -> 200 | G15: =IF(OR($A15="",$B$9=0),"",20*$B$7*$F15/$B$9) -> 20 | H15: =IF(NOT(ISNUMBER($G15)),"",MIN(20,$G15)) -> 20
A16: ='Listas de apoio'!A7 -> Gonçalo Magalhães Ribeiro | B16: =IF($A16="","",SUMIFS('Detalhe da Pontuação'!$Z$18:$Z$88,'Detalhe da Pontuação'!$D$18:$D$88,$A16,'Detalhe da Pontuação'!$E$18:$E$88,"Executor")) -> 96 | C16: =IF($A16="","",SUMIFS('Detalhe da Pontuação'!$Z$18:$Z$88,'Detalhe da Pontuação'!$D$18:$D$88,$A16,'Detalhe da Pontuação'!$E$18:$E$88,"Revisor")) -> 78 | D16: =IF($A16="","",SUMIFS('Detalhe da Pontuação'!$Z$18:$Z$88,'Detalhe da Pontuação'!$D$18:$D$88,$A16,'Detalhe da Pontuação'!$E$18:$E$88,"Auditor")) -> 16 | E16: =IF($A16="","",SUMIFS('Detalhe da Pontuação'!$Z$18:$Z$88,'Detalhe da Pontuação'!$D$18:$D$88,$A16,'Detalhe da Pontuação'!$E$18:$E$88,"Secretário")) -> 10 | F16: =IF($A16="","",SUM($B16:$E16)) -> 200 | G16: =IF(OR($A16="",$B$9=0),"",20*$B$7*$F16/$B$9) -> 20 | H16: =IF(NOT(ISNUMBER($G16)),"",MIN(20,$G16)) -> 20
A17: ='Listas de apoio'!A8 -> Ivan Cristiano Silva Mendes | B17: =IF($A17="","",SUMIFS('Detalhe da Pontuação'!$Z$18:$Z$88,'Detalhe da Pontuação'!$D$18:$D$88,$A17,'Detalhe da Pontuação'!$E$18:$E$88,"Executor")) -> 84 | C17: =IF($A17="","",SUMIFS('Detalhe da Pontuação'!$Z$18:$Z$88,'Detalhe da Pontuação'!$D$18:$D$88,$A17,'Detalhe da Pontuação'!$E$18:$E$88,"Revisor")) -> 84 | D17: =IF($A17="","",SUMIFS('Detalhe da Pontuação'!$Z$18:$Z$88,'Detalhe da Pontuação'!$D$18:$D$88,$A17,'Detalhe da Pontuação'!$E$18:$E$88,"Auditor")) -> 32 | E17: =IF($A17="","",SUMIFS('Detalhe da Pontuação'!$Z$18:$Z$88,'Detalhe da Pontuação'!$D$18:$D$88,$A17,'Detalhe da Pontuação'!$E$18:$E$88,"Secretário")) -> 0 | F17: =IF($A17="","",SUM($B17:$E17)) -> 200 | G17: =IF(OR($A17="",$B$9=0),"",20*$B$7*$F17/$B$9) -> 20 | H17: =IF(NOT(ISNUMBER($G17)),"",MIN(20,$G17)) -> 20
A18: Grupo | B18: =SUM(B14:B17) -> 468 | C18: =SUM(C14:C17) -> 234 | D18: =SUM(D14:D17) -> 78 | E18: =SUM(E14:E17) -> 20 | F18: =SUM(F14:F17) -> 800
A20: FÓRMULAS APLICADAS | B20: FÓRMULAS APLICADAS | C20: FÓRMULAS APLICADAS | D20: FÓRMULAS APLICADAS | E20: FÓRMULAS APLICADAS | F20: FÓRMULAS APLICADAS | G20: FÓRMULAS APLICADAS | H20: FÓRMULAS APLICADAS
A21: Fórmula | B21: Resultado calculado | C21: Leitura do exemplo
A22: P_i = Σ PEO_i | B22: =F14 -> 200 | C22: P_A no Momento de Avaliação
A23: IB_i = (20 × n × P_i) / B_T | B23: =G14 -> 20 | C23: IB_A antes do limite máximo
A24: NI_i = min(20; IB_i) | B24: =H14 -> 20 | C24: NI_A depois da aplicação do limite máximo
A26: RESULTADOS POR SPRINT | B26: RESULTADOS POR SPRINT | C26: RESULTADOS POR SPRINT | D26: RESULTADOS POR SPRINT | E26: RESULTADOS POR SPRINT | F26: RESULTADOS POR SPRINT
A27: Sprint | B27: =$A$14 -> André Filipe Moreira Mesquita | C27: =$A$15 -> Gonçalo Dinis Magalhães Teixeira | D27: =$A$16 -> Gonçalo Magalhães Ribeiro | E27: =$A$17 -> Ivan Cristiano Silva Mendes | F27: Total do Sprint
A28: =IF('Detalhe da Pontuação'!A6="","",'Detalhe da Pontuação'!A6) -> S01 | B28: =IF($A28="","",SUMIFS('Detalhe da Pontuação'!$Z$18:$Z$88,'Detalhe da Pontuação'!$A$18:$A$88,$A28,'Detalhe da Pontuação'!$D$18:$D$88,B$27)) -> 81 | C28: =IF($A28="","",SUMIFS('Detalhe da Pontuação'!$Z$18:$Z$88,'Detalhe da Pontuação'!$A$18:$A$88,$A28,'Detalhe da Pontuação'!$D$18:$D$88,C$27)) -> 40 | D28: =IF($A28="","",SUMIFS('Detalhe da Pontuação'!$Z$18:$Z$88,'Detalhe da Pontuação'!$A$18:$A$88,$A28,'Detalhe da Pontuação'!$D$18:$D$88,D$27)) -> 69 | E28: =IF($A28="","",SUMIFS('Detalhe da Pontuação'!$Z$18:$Z$88,'Detalhe da Pontuação'!$A$18:$A$88,$A28,'Detalhe da Pontuação'!$D$18:$D$88,E$27)) -> 130 | F28: =IF($A28="","",SUM(B28:E28)) -> 320
A29: S02 | B29: =IF($A29="","",SUMIFS('Detalhe da Pontuação'!$Z$18:$Z$88,'Detalhe da Pontuação'!$A$18:$A$88,$A29,'Detalhe da Pontuação'!$D$18:$D$88,B$27)) -> 119 | C29: =IF($A29="","",SUMIFS('Detalhe da Pontuação'!$Z$18:$Z$88,'Detalhe da Pontuação'!$A$18:$A$88,$A29,'Detalhe da Pontuação'!$D$18:$D$88,C$27)) -> 160 | D29: =IF($A29="","",SUMIFS('Detalhe da Pontuação'!$Z$18:$Z$88,'Detalhe da Pontuação'!$A$18:$A$88,$A29,'Detalhe da Pontuação'!$D$18:$D$88,D$27)) -> 131 | E29: =IF($A29="","",SUMIFS('Detalhe da Pontuação'!$Z$18:$Z$88,'Detalhe da Pontuação'!$A$18:$A$88,$A29,'Detalhe da Pontuação'!$D$18:$D$88,E$27)) -> 70 | F29: =IF($A29="","",SUM(B29:E29)) -> 480
A30: =IF('Detalhe da Pontuação'!A8="","",'Detalhe da Pontuação'!A8) | B30: =IF($A30="","",SUMIFS('Detalhe da Pontuação'!$Z$89:$Z$260,'Detalhe da Pontuação'!$A$89:$A$260,$A30,'Detalhe da Pontuação'!$D$89:$D$260,B$27)) | C30: =IF($A30="","",SUMIFS('Detalhe da Pontuação'!$Z$89:$Z$260,'Detalhe da Pontuação'!$A$89:$A$260,$A30,'Detalhe da Pontuação'!$D$89:$D$260,C$27)) | D30: =IF($A30="","",SUMIFS('Detalhe da Pontuação'!$Z$89:$Z$260,'Detalhe da Pontuação'!$A$89:$A$260,$A30,'Detalhe da Pontuação'!$D$89:$D$260,D$27)) | E30: =IF($A30="","",SUMIFS('Detalhe da Pontuação'!$Z$89:$Z$260,'Detalhe da Pontuação'!$A$89:$A$260,$A30,'Detalhe da Pontuação'!$D$89:$D$260,E$27)) | F30: =IF($A30="","",SUM(B30:E30))
A31: =IF('Detalhe da Pontuação'!A9="","",'Detalhe da Pontuação'!A9) | B31: =IF($A31="","",SUMIFS('Detalhe da Pontuação'!$Z$89:$Z$260,'Detalhe da Pontuação'!$A$89:$A$260,$A31,'Detalhe da Pontuação'!$D$89:$D$260,B$27)) | C31: =IF($A31="","",SUMIFS('Detalhe da Pontuação'!$Z$89:$Z$260,'Detalhe da Pontuação'!$A$89:$A$260,$A31,'Detalhe da Pontuação'!$D$89:$D$260,C$27)) | D31: =IF($A31="","",SUMIFS('Detalhe da Pontuação'!$Z$89:$Z$260,'Detalhe da Pontuação'!$A$89:$A$260,$A31,'Detalhe da Pontuação'!$D$89:$D$260,D$27)) | E31: =IF($A31="","",SUMIFS('Detalhe da Pontuação'!$Z$89:$Z$260,'Detalhe da Pontuação'!$A$89:$A$260,$A31,'Detalhe da Pontuação'!$D$89:$D$260,E$27)) | F31: =IF($A31="","",SUM(B31:E31))
A32: =IF('Detalhe da Pontuação'!A10="","",'Detalhe da Pontuação'!A10) | B32: =IF($A32="","",SUMIFS('Detalhe da Pontuação'!$Z$89:$Z$260,'Detalhe da Pontuação'!$A$89:$A$260,$A32,'Detalhe da Pontuação'!$D$89:$D$260,B$27)) | C32: =IF($A32="","",SUMIFS('Detalhe da Pontuação'!$Z$89:$Z$260,'Detalhe da Pontuação'!$A$89:$A$260,$A32,'Detalhe da Pontuação'!$D$89:$D$260,C$27)) | D32: =IF($A32="","",SUMIFS('Detalhe da Pontuação'!$Z$89:$Z$260,'Detalhe da Pontuação'!$A$89:$A$260,$A32,'Detalhe da Pontuação'!$D$89:$D$260,D$27)) | E32: =IF($A32="","",SUMIFS('Detalhe da Pontuação'!$Z$89:$Z$260,'Detalhe da Pontuação'!$A$89:$A$260,$A32,'Detalhe da Pontuação'!$D$89:$D$260,E$27)) | F32: =IF($A32="","",SUM(B32:E32))
A33: =IF('Detalhe da Pontuação'!A11="","",'Detalhe da Pontuação'!A11) | B33: =IF($A33="","",SUMIFS('Detalhe da Pontuação'!$Z$89:$Z$260,'Detalhe da Pontuação'!$A$89:$A$260,$A33,'Detalhe da Pontuação'!$D$89:$D$260,B$27)) | C33: =IF($A33="","",SUMIFS('Detalhe da Pontuação'!$Z$89:$Z$260,'Detalhe da Pontuação'!$A$89:$A$260,$A33,'Detalhe da Pontuação'!$D$89:$D$260,C$27)) | D33: =IF($A33="","",SUMIFS('Detalhe da Pontuação'!$Z$89:$Z$260,'Detalhe da Pontuação'!$A$89:$A$260,$A33,'Detalhe da Pontuação'!$D$89:$D$260,D$27)) | E33: =IF($A33="","",SUMIFS('Detalhe da Pontuação'!$Z$89:$Z$260,'Detalhe da Pontuação'!$A$89:$A$260,$A33,'Detalhe da Pontuação'!$D$89:$D$260,E$27)) | F33: =IF($A33="","",SUM(B33:E33))
A34: =IF('Detalhe da Pontuação'!A12="","",'Detalhe da Pontuação'!A12) | B34: =IF($A34="","",SUMIFS('Detalhe da Pontuação'!$Z$89:$Z$260,'Detalhe da Pontuação'!$A$89:$A$260,$A34,'Detalhe da Pontuação'!$D$89:$D$260,B$27)) | C34: =IF($A34="","",SUMIFS('Detalhe da Pontuação'!$Z$89:$Z$260,'Detalhe da Pontuação'!$A$89:$A$260,$A34,'Detalhe da Pontuação'!$D$89:$D$260,C$27)) | D34: =IF($A34="","",SUMIFS('Detalhe da Pontuação'!$Z$89:$Z$260,'Detalhe da Pontuação'!$A$89:$A$260,$A34,'Detalhe da Pontuação'!$D$89:$D$260,D$27)) | E34: =IF($A34="","",SUMIFS('Detalhe da Pontuação'!$Z$89:$Z$260,'Detalhe da Pontuação'!$A$89:$A$260,$A34,'Detalhe da Pontuação'!$D$89:$D$260,E$27)) | F34: =IF($A34="","",SUM(B34:E34))
A35: =IF('Detalhe da Pontuação'!A13="","",'Detalhe da Pontuação'!A13) | B35: =IF($A35="","",SUMIFS('Detalhe da Pontuação'!$Z$89:$Z$260,'Detalhe da Pontuação'!$A$89:$A$260,$A35,'Detalhe da Pontuação'!$D$89:$D$260,B$27)) | C35: =IF($A35="","",SUMIFS('Detalhe da Pontuação'!$Z$89:$Z$260,'Detalhe da Pontuação'!$A$89:$A$260,$A35,'Detalhe da Pontuação'!$D$89:$D$260,C$27)) | D35: =IF($A35="","",SUMIFS('Detalhe da Pontuação'!$Z$89:$Z$260,'Detalhe da Pontuação'!$A$89:$A$260,$A35,'Detalhe da Pontuação'!$D$89:$D$260,D$27)) | E35: =IF($A35="","",SUMIFS('Detalhe da Pontuação'!$Z$89:$Z$260,'Detalhe da Pontuação'!$A$89:$A$260,$A35,'Detalhe da Pontuação'!$D$89:$D$260,E$27)) | F35: =IF($A35="","",SUM(B35:E35))
A36: =IF('Detalhe da Pontuação'!A14="","",'Detalhe da Pontuação'!A14) | B36: =IF($A36="","",SUMIFS('Detalhe da Pontuação'!$Z$89:$Z$260,'Detalhe da Pontuação'!$A$89:$A$260,$A36,'Detalhe da Pontuação'!$D$89:$D$260,B$27)) | C36: =IF($A36="","",SUMIFS('Detalhe da Pontuação'!$Z$89:$Z$260,'Detalhe da Pontuação'!$A$89:$A$260,$A36,'Detalhe da Pontuação'!$D$89:$D$260,C$27)) | D36: =IF($A36="","",SUMIFS('Detalhe da Pontuação'!$Z$89:$Z$260,'Detalhe da Pontuação'!$A$89:$A$260,$A36,'Detalhe da Pontuação'!$D$89:$D$260,D$27)) | E36: =IF($A36="","",SUMIFS('Detalhe da Pontuação'!$Z$89:$Z$260,'Detalhe da Pontuação'!$A$89:$A$260,$A36,'Detalhe da Pontuação'!$D$89:$D$260,E$27)) | F36: =IF($A36="","",SUM(B36:E36))
A37: Total do Momento de Avaliação | B37: =SUM(B28:B36) -> 200 | C37: =SUM(C28:C36) -> 200 | D37: =SUM(D28:D36) -> 200 | E37: =SUM(E28:E36) -> 200 | F37: =SUM(F28:F36) -> 800

Sheet Detalhe da Pontuação
A1: DETALHE DA PONTUAÇÃO | B1: DETALHE DA PONTUAÇÃO | C1: DETALHE DA PONTUAÇÃO | D1: DETALHE DA PONTUAÇÃO | E1: DETALHE DA PONTUAÇÃO | F1: DETALHE DA PONTUAÇÃO | G1: DETALHE DA PONTUAÇÃO | H1: DETALHE DA PONTUAÇÃO | I1: DETALHE DA PONTUAÇÃO | J1: DETALHE DA PONTUAÇÃO | K1: DETALHE DA PONTUAÇÃO | L1: DETALHE DA PONTUAÇÃO | M1: DETALHE DA PONTUAÇÃO | N1: DETALHE DA PONTUAÇÃO | O1: DETALHE DA PONTUAÇÃO | P1: DETALHE DA PONTUAÇÃO | Q1: DETALHE DA PONTUAÇÃO | R1: DETALHE DA PONTUAÇÃO | S1: DETALHE DA PONTUAÇÃO | T1: DETALHE DA PONTUAÇÃO | U1: DETALHE DA PONTUAÇÃO | V1: DETALHE DA PONTUAÇÃO | W1: DETALHE DA PONTUAÇÃO | X1: DETALHE DA PONTUAÇÃO | Y1: DETALHE DA PONTUAÇÃO | Z1: DETALHE DA PONTUAÇÃO
A2: PREENCHIMENTO PRINCIPAL — prepare este mapa como suporte ao Sprint Review. Use a última versão cumulativa do Sprint Backlog formalmente aprovada antes da reunião, incluindo todas as transferências ocorridas. Os campos amarelos são editáveis; os campos azuis são calculados. | B2: PREENCHIMENTO PRINCIPAL — prepare este mapa como suporte ao Sprint Review. Use a última versão cumulativa do Sprint Backlog formalmente aprovada antes da reunião, incluindo todas as transferências ocorridas. Os campos amarelos são editáveis; os campos azuis são calculados. | C2: PREENCHIMENTO PRINCIPAL — prepare este mapa como suporte ao Sprint Review. Use a última versão cumulativa do Sprint Backlog formalmente aprovada antes da reunião, incluindo todas as transferências ocorridas. Os campos amarelos são editáveis; os campos azuis são calculados. | D2: PREENCHIMENTO PRINCIPAL — prepare este mapa como suporte ao Sprint Review. Use a última versão cumulativa do Sprint Backlog formalmente aprovada antes da reunião, incluindo todas as transferências ocorridas. Os campos amarelos são editáveis; os campos azuis são calculados. | E2: PREENCHIMENTO PRINCIPAL — prepare este mapa como suporte ao Sprint Review. Use a última versão cumulativa do Sprint Backlog formalmente aprovada antes da reunião, incluindo todas as transferências ocorridas. Os campos amarelos são editáveis; os campos azuis são calculados. | F2: PREENCHIMENTO PRINCIPAL — prepare este mapa como suporte ao Sprint Review. Use a última versão cumulativa do Sprint Backlog formalmente aprovada antes da reunião, incluindo todas as transferências ocorridas. Os campos amarelos são editáveis; os campos azuis são calculados. | G2: PREENCHIMENTO PRINCIPAL — prepare este mapa como suporte ao Sprint Review. Use a última versão cumulativa do Sprint Backlog formalmente aprovada antes da reunião, incluindo todas as transferências ocorridas. Os campos amarelos são editáveis; os campos azuis são calculados. | H2: PREENCHIMENTO PRINCIPAL — prepare este mapa como suporte ao Sprint Review. Use a última versão cumulativa do Sprint Backlog formalmente aprovada antes da reunião, incluindo todas as transferências ocorridas. Os campos amarelos são editáveis; os campos azuis são calculados. | I2: PREENCHIMENTO PRINCIPAL — prepare este mapa como suporte ao Sprint Review. Use a última versão cumulativa do Sprint Backlog formalmente aprovada antes da reunião, incluindo todas as transferências ocorridas. Os campos amarelos são editáveis; os campos azuis são calculados. | J2: PREENCHIMENTO PRINCIPAL — prepare este mapa como suporte ao Sprint Review. Use a última versão cumulativa do Sprint Backlog formalmente aprovada antes da reunião, incluindo todas as transferências ocorridas. Os campos amarelos são editáveis; os campos azuis são calculados. | K2: PREENCHIMENTO PRINCIPAL — prepare este mapa como suporte ao Sprint Review. Use a última versão cumulativa do Sprint Backlog formalmente aprovada antes da reunião, incluindo todas as transferências ocorridas. Os campos amarelos são editáveis; os campos azuis são calculados. | L2: PREENCHIMENTO PRINCIPAL — prepare este mapa como suporte ao Sprint Review. Use a última versão cumulativa do Sprint Backlog formalmente aprovada antes da reunião, incluindo todas as transferências ocorridas. Os campos amarelos são editáveis; os campos azuis são calculados. | M2: PREENCHIMENTO PRINCIPAL — prepare este mapa como suporte ao Sprint Review. Use a última versão cumulativa do Sprint Backlog formalmente aprovada antes da reunião, incluindo todas as transferências ocorridas. Os campos amarelos são editáveis; os campos azuis são calculados. | N2: PREENCHIMENTO PRINCIPAL — prepare este mapa como suporte ao Sprint Review. Use a última versão cumulativa do Sprint Backlog formalmente aprovada antes da reunião, incluindo todas as transferências ocorridas. Os campos amarelos são editáveis; os campos azuis são calculados. | O2: PREENCHIMENTO PRINCIPAL — prepare este mapa como suporte ao Sprint Review. Use a última versão cumulativa do Sprint Backlog formalmente aprovada antes da reunião, incluindo todas as transferências ocorridas. Os campos amarelos são editáveis; os campos azuis são calculados. | P2: PREENCHIMENTO PRINCIPAL — prepare este mapa como suporte ao Sprint Review. Use a última versão cumulativa do Sprint Backlog formalmente aprovada antes da reunião, incluindo todas as transferências ocorridas. Os campos amarelos são editáveis; os campos azuis são calculados. | Q2: PREENCHIMENTO PRINCIPAL — prepare este mapa como suporte ao Sprint Review. Use a última versão cumulativa do Sprint Backlog formalmente aprovada antes da reunião, incluindo todas as transferências ocorridas. Os campos amarelos são editáveis; os campos azuis são calculados. | R2: PREENCHIMENTO PRINCIPAL — prepare este mapa como suporte ao Sprint Review. Use a última versão cumulativa do Sprint Backlog formalmente aprovada antes da reunião, incluindo todas as transferências ocorridas. Os campos amarelos são editáveis; os campos azuis são calculados. | S2: PREENCHIMENTO PRINCIPAL — prepare este mapa como suporte ao Sprint Review. Use a última versão cumulativa do Sprint Backlog formalmente aprovada antes da reunião, incluindo todas as transferências ocorridas. Os campos amarelos são editáveis; os campos azuis são calculados. | T2: PREENCHIMENTO PRINCIPAL — prepare este mapa como suporte ao Sprint Review. Use a última versão cumulativa do Sprint Backlog formalmente aprovada antes da reunião, incluindo todas as transferências ocorridas. Os campos amarelos são editáveis; os campos azuis são calculados. | U2: PREENCHIMENTO PRINCIPAL — prepare este mapa como suporte ao Sprint Review. Use a última versão cumulativa do Sprint Backlog formalmente aprovada antes da reunião, incluindo todas as transferências ocorridas. Os campos amarelos são editáveis; os campos azuis são calculados. | V2: PREENCHIMENTO PRINCIPAL — prepare este mapa como suporte ao Sprint Review. Use a última versão cumulativa do Sprint Backlog formalmente aprovada antes da reunião, incluindo todas as transferências ocorridas. Os campos amarelos são editáveis; os campos azuis são calculados. | W2: PREENCHIMENTO PRINCIPAL — prepare este mapa como suporte ao Sprint Review. Use a última versão cumulativa do Sprint Backlog formalmente aprovada antes da reunião, incluindo todas as transferências ocorridas. Os campos amarelos são editáveis; os campos azuis são calculados. | X2: PREENCHIMENTO PRINCIPAL — prepare este mapa como suporte ao Sprint Review. Use a última versão cumulativa do Sprint Backlog formalmente aprovada antes da reunião, incluindo todas as transferências ocorridas. Os campos amarelos são editáveis; os campos azuis são calculados. | Y2: PREENCHIMENTO PRINCIPAL — prepare este mapa como suporte ao Sprint Review. Use a última versão cumulativa do Sprint Backlog formalmente aprovada antes da reunião, incluindo todas as transferências ocorridas. Os campos amarelos são editáveis; os campos azuis são calculados. | Z2: PREENCHIMENTO PRINCIPAL — prepare este mapa como suporte ao Sprint Review. Use a última versão cumulativa do Sprint Backlog formalmente aprovada antes da reunião, incluindo todas as transferências ocorridas. Os campos amarelos são editáveis; os campos azuis são calculados.
A4: SPRINTS E FONTES DOCUMENTAIS | B4: SPRINTS E FONTES DOCUMENTAIS | C4: SPRINTS E FONTES DOCUMENTAIS
A5: Sprint | B5: Sprint Backlog vigente — versão editável (XLS/XLSX) | I5: Sprint Backlog vigente — PDF assinado
A6: S01 | B6: /projeto/01-artefactos-de-gestao/01.04-backlog-de-projeto/m1-s01-sprint-backlog-v01.xlsx | I6: /projeto/01-artefactos-de-gestao/01.04-backlog-de-projeto/m1-s01-sprint-backlog-v01.pdf
A7: S02 | B7: /projeto/01-artefactos-de-gestao/01.04-backlog-de-projeto/m2-s02-sprint-backlog-v01.xlsx | I7: /projeto/01-artefactos-de-gestao/01.04-backlog-de-projeto/m2-s02-20261007-sprint-backlog-v01.pdf
A16: LINHAS DE PONTUAÇÃO POR SPRINT, ISSUE, ALUNO E PAPEL | B16: LINHAS DE PONTUAÇÃO POR SPRINT, ISSUE, ALUNO E PAPEL | C16: LINHAS DE PONTUAÇÃO POR SPRINT, ISSUE, ALUNO E PAPEL | D16: LINHAS DE PONTUAÇÃO POR SPRINT, ISSUE, ALUNO E PAPEL | E16: LINHAS DE PONTUAÇÃO POR SPRINT, ISSUE, ALUNO E PAPEL | F16: LINHAS DE PONTUAÇÃO POR SPRINT, ISSUE, ALUNO E PAPEL | G16: LINHAS DE PONTUAÇÃO POR SPRINT, ISSUE, ALUNO E PAPEL | H16: LINHAS DE PONTUAÇÃO POR SPRINT, ISSUE, ALUNO E PAPEL | I16: LINHAS DE PONTUAÇÃO POR SPRINT, ISSUE, ALUNO E PAPEL | J16: LINHAS DE PONTUAÇÃO POR SPRINT, ISSUE, ALUNO E PAPEL | K16: LINHAS DE PONTUAÇÃO POR SPRINT, ISSUE, ALUNO E PAPEL | L16: LINHAS DE PONTUAÇÃO POR SPRINT, ISSUE, ALUNO E PAPEL | M16: LINHAS DE PONTUAÇÃO POR SPRINT, ISSUE, ALUNO E PAPEL | N16: LINHAS DE PONTUAÇÃO POR SPRINT, ISSUE, ALUNO E PAPEL | O16: LINHAS DE PONTUAÇÃO POR SPRINT, ISSUE, ALUNO E PAPEL | P16: LINHAS DE PONTUAÇÃO POR SPRINT, ISSUE, ALUNO E PAPEL | Q16: LINHAS DE PONTUAÇÃO POR SPRINT, ISSUE, ALUNO E PAPEL | R16: LINHAS DE PONTUAÇÃO POR SPRINT, ISSUE, ALUNO E PAPEL | S16: LINHAS DE PONTUAÇÃO POR SPRINT, ISSUE, ALUNO E PAPEL | T16: LINHAS DE PONTUAÇÃO POR SPRINT, ISSUE, ALUNO E PAPEL | U16: LINHAS DE PONTUAÇÃO POR SPRINT, ISSUE, ALUNO E PAPEL | V16: LINHAS DE PONTUAÇÃO POR SPRINT, ISSUE, ALUNO E PAPEL | W16: LINHAS DE PONTUAÇÃO POR SPRINT, ISSUE, ALUNO E PAPEL | X16: LINHAS DE PONTUAÇÃO POR SPRINT, ISSUE, ALUNO E PAPEL | Y16: LINHAS DE PONTUAÇÃO POR SPRINT, ISSUE, ALUNO E PAPEL | Z16: LINHAS DE PONTUAÇÃO POR SPRINT, ISSUE, ALUNO E PAPEL
A17: Sprint | B17: Issue | C17: Tarefa | D17: Aluno | E17: Papel | F17: Orçamento da tarefa | G17: Origem da parcela | H17: PMI | I17: Referência da transferência | J17: PC | K17: PR | L17: PMR | M17: Categoria de qualidade aprovada | N17: Q | O17: Fundamento e evidência | P17: Classificação atribuída por | Q17: PQ | R17: Prazo aplicável | S17: Data e hora de conclusão | T17: Atraso imputável em horas | U17: Penalização por atraso | V17: A | W17: Perda por qualidade | X17: PEO não arredondado | Y17: Perda por atraso | Z17: PEO
A18: S01 | B18: I001 | C18: Elaborar Proposta de Sistema | D18: Gonçalo Magalhães Ribeiro | E18: Executor | F18: 50 | G18: Atribuição inicial | H18: =IF($A18="","",IF($G18="Secretariado",10,IF($G18="Transferência recebida",0,IF($E18="Executor",$F18*60%,IF($E18="Revisor",$F18*30%,IF($E18="Auditor",$F18*10%,"")))))) -> 30 | I18: Não Aplicável | J18: 0 | K18: 0 | L18: =IF($A18="","",$H18-$J18+$K18) -> 30 | M18: Aceite sem correções obrigatórias | N18: =IF($A18="","",IF($M18="","",IF($E18="Executor",IFERROR(VLOOKUP($M18,'Listas de apoio'!$G$5:$H$9,2,FALSE),""),IF($E18="Revisor",IFERROR(VLOOKUP($M18,'Listas de apoio'!$J$5:$K$8,2,FALSE),""),IF($E18="Auditor",IFERROR(VLOOKUP($M18,'Listas de apoio'!$M$5:$N$7,2,FALSE),""),IF($E18="Secretário",IFERROR(VLOOKUP($M18,'Listas de apoio'!$P$5:$Q$7,2,FALSE),""),"")))))) -> 1 | O18: O modelo ficou utilizável sem necessidade de correções; | P18: Ivan Cristiano Silva Mendes | Q18: =IF(OR($A18="",NOT(ISNUMBER($L18)),NOT(ISNUMBER($N18))),"",$L18*$N18) -> 30 | R18: 46293 | S18: 46287.438 | T18: =IF(OR($A18="",$R18="",$S18=""),"",MAX(0,($S18-$R18)*24)) -> 0 | U18: Sem atraso | V18: =IF($A18="","",IF($U18="","",IFERROR(VLOOKUP($U18,'Listas de apoio'!$S$5:$T$10,2,FALSE),""))) -> 0 | W18: =IF(OR($A18="",NOT(ISNUMBER($L18)),NOT(ISNUMBER($Q18))),"",$L18-$Q18) -> 0 | X18: =IF(OR($A18="",NOT(ISNUMBER($Q18)),NOT(ISNUMBER($V18))),"",$Q18*(1-$V18)) -> 30 | Y18: =IF(OR($A18="",NOT(ISNUMBER($Q18)),NOT(ISNUMBER($X18))),"",$Q18-$X18) -> 0 | Z18: =IF(NOT(ISNUMBER($X18)),"",ROUND($X18,2)) -> 30
A19: S01 | B19: I001 | C19: Elaborar Proposta de Sistema | D19: Ivan Cristiano Silva Mendes | E19: Revisor | F19: 50 | G19: Atribuição inicial | H19: =IF($A19="","",IF($G19="Secretariado",10,IF($G19="Transferência recebida",0,IF($E19="Executor",$F19*60%,IF($E19="Revisor",$F19*30%,IF($E19="Auditor",$F19*10%,"")))))) -> 15 | I19: Não Aplicável | J19: 0 | K19: 0 | L19: =IF($A19="","",$H19-$J19+$K19) -> 15 | M19: Revisão completa, correta e sustentada por evidências | N19: =IF($A19="","",IF($M19="","",IF($E19="Executor",IFERROR(VLOOKUP($M19,'Listas de apoio'!$G$5:$H$9,2,FALSE),""),IF($E19="Revisor",IFERROR(VLOOKUP($M19,'Listas de apoio'!$J$5:$K$8,2,FALSE),""),IF($E19="Auditor",IFERROR(VLOOKUP($M19,'Listas de apoio'!$M$5:$N$7,2,FALSE),""),IF($E19="Secretário",IFERROR(VLOOKUP($M19,'Listas de apoio'!$P$5:$Q$7,2,FALSE),""),"")))))) -> 1 | O19: Revisão completa, com verificações e evidências suficientes para sustentar a aceitação. | P19: Ivan Cristiano Silva Mendes | Q19: =IF(OR($A19="",NOT(ISNUMBER($L19)),NOT(ISNUMBER($N19))),"",$L19*$N19) -> 15 | R19: 46293 | S19: 46287.438 | T19: =IF(OR($A19="",$R19="",$S19=""),"",MAX(0,($S19-$R19)*24)) -> 0 | U19: Sem atraso | V19: =IF($A19="","",IF($U19="","",IFERROR(VLOOKUP($U19,'Listas de apoio'!$S$5:$T$10,2,FALSE),""))) -> 0 | W19: =IF(OR($A19="",NOT(ISNUMBER($L19)),NOT(ISNUMBER($Q19))),"",$L19-$Q19) -> 0 | X19: =IF(OR($A19="",NOT(ISNUMBER($Q19)),NOT(ISNUMBER($V19))),"",$Q19*(1-$V19)) -> 15 | Y19: =IF(OR($A19="",NOT(ISNUMBER($Q19)),NOT(ISNUMBER($X19))),"",$Q19-$X19) -> 0 | Z19: =IF(NOT(ISNUMBER($X19)),"",ROUND($X19,2)) -> 15
A20: S01 | B20: I001 | C20: Elaborar Proposta de Sistema | D20: Ivan Cristiano Silva Mendes | E20: Auditor | F20: 50 | G20: Atribuição inicial | H20: =IF($A20="","",IF($G20="Secretariado",10,IF($G20="Transferência recebida",0,IF($E20="Executor",$F20*60%,IF($E20="Revisor",$F20*30%,IF($E20="Auditor",$F20*10%,"")))))) -> 5 | I20: Não Aplicável | J20: 0 | K20: 0 | L20: =IF($A20="","",$H20-$J20+$K20) -> 5 | M20: Auditoria completa antes do Sprint Review, incluindo a confirmação final | N20: =IF($A20="","",IF($M20="","",IF($E20="Executor",IFERROR(VLOOKUP($M20,'Listas de apoio'!$G$5:$H$9,2,FALSE),""),IF($E20="Revisor",IFERROR(VLOOKUP($M20,'Listas de apoio'!$J$5:$K$8,2,FALSE),""),IF($E20="Auditor",IFERROR(VLOOKUP($M20,'Listas de apoio'!$M$5:$N$7,2,FALSE),""),IF($E20="Secretário",IFERROR(VLOOKUP($M20,'Listas de apoio'!$P$5:$Q$7,2,FALSE),""),"")))))) -> 1 | O20: Auditoria concluída antes do Sprint Review, incluindo a confirmação final das evidências. | P20: Não Aplicável - O auditor não participa da própria classificação. | Q20: =IF(OR($A20="",NOT(ISNUMBER($L20)),NOT(ISNUMBER($N20))),"",$L20*$N20) -> 5 | R20: 46293 | S20: 46287.438 | T20: =IF(OR($A20="",$R20="",$S20=""),"",MAX(0,($S20-$R20)*24)) -> 0 | U20: Sem atraso | V20: =IF($A20="","",IF($U20="","",IFERROR(VLOOKUP($U20,'Listas de apoio'!$S$5:$T$10,2,FALSE),""))) -> 0 | W20: =IF(OR($A20="",NOT(ISNUMBER($L20)),NOT(ISNUMBER($Q20))),"",$L20-$Q20) -> 0 | X20: =IF(OR($A20="",NOT(ISNUMBER($Q20)),NOT(ISNUMBER($V20))),"",$Q20*(1-$V20)) -> 5 | Y20: =IF(OR($A20="",NOT(ISNUMBER($Q20)),NOT(ISNUMBER($X20))),"",$Q20-$X20) -> 0 | Z20: =IF(NOT(ISNUMBER($X20)),"",ROUND($X20,2)) -> 5
A21: S01 | B21: I002 | C21: Elaborar Declaração de Âmbito | D21: André Filipe Moreira Mesquita | E21: Executor | F21: 50 | G21: Atribuição inicial | H21: =IF($A21="","",IF($G21="Secretariado",10,IF($G21="Transferência recebida",0,IF($E21="Executor",$F21*60%,IF($E21="Revisor",$F21*30%,IF($E21="Auditor",$F21*10%,"")))))) -> 30 | I21: Não Aplicável | J21: 0 | K21: 0 | L21: =IF($A21="","",$H21-$J21+$K21) -> 30 | M21: Aceite sem correções obrigatórias | N21: =IF($A21="","",IF($M21="","",IF($E21="Executor",IFERROR(VLOOKUP($M21,'Listas de apoio'!$G$5:$H$9,2,FALSE),""),IF($E21="Revisor",IFERROR(VLOOKUP($M21,'Listas de apoio'!$J$5:$K$8,2,FALSE),""),IF($E21="Auditor",IFERROR(VLOOKUP($M21,'Listas de apoio'!$M$5:$N$7,2,FALSE),""),IF($E21="Secretário",IFERROR(VLOOKUP($M21,'Listas de apoio'!$P$5:$Q$7,2,FALSE),""),"")))))) -> 1 | O21: O modelo ficou utilizável sem necessidade de correções; | P21: Ivan Cristiano Silva Mendes | Q21: =IF(OR($A21="",NOT(ISNUMBER($L21)),NOT(ISNUMBER($N21))),"",$L21*$N21) -> 30 | R21: 46293 | S21: 46287.69 | T21: =IF(OR($A21="",$R21="",$S21=""),"",MAX(0,($S21-$R21)*24)) -> 0 | U21: Sem atraso | V21: =IF($A21="","",IF($U21="","",IFERROR(VLOOKUP($U21,'Listas de apoio'!$S$5:$T$10,2,FALSE),""))) -> 0 | W21: =IF(OR($A21="",NOT(ISNUMBER($L21)),NOT(ISNUMBER($Q21))),"",$L21-$Q21) -> 0 | X21: =IF(OR($A21="",NOT(ISNUMBER($Q21)),NOT(ISNUMBER($V21))),"",$Q21*(1-$V21)) -> 30 | Y21: =IF(OR($A21="",NOT(ISNUMBER($Q21)),NOT(ISNUMBER($X21))),"",$Q21-$X21) -> 0 | Z21: =IF(NOT(ISNUMBER($X21)),"",ROUND($X21,2)) -> 30
A22: S01 | B22: I002 | C22: Elaborar Declaração de Âmbito | D22: Ivan Cristiano Silva Mendes | E22: Revisor | F22: 50 | G22: Atribuição inicial | H22: =IF($A22="","",IF($G22="Secretariado",10,IF($G22="Transferência recebida",0,IF($E22="Executor",$F22*60%,IF($E22="Revisor",$F22*30%,IF($E22="Auditor",$F22*10%,"")))))) -> 15 | I22: Não Aplicável | J22: 0 | K22: 0 | L22: =IF($A22="","",$H22-$J22+$K22) -> 15 | M22: Revisão completa, correta e sustentada por evidências | N22: =IF($A22="","",IF($M22="","",IF($E22="Executor",IFERROR(VLOOKUP($M22,'Listas de apoio'!$G$5:$H$9,2,FALSE),""),IF($E22="Revisor",IFERROR(VLOOKUP($M22,'Listas de apoio'!$J$5:$K$8,2,FALSE),""),IF($E22="Auditor",IFERROR(VLOOKUP($M22,'Listas de apoio'!$M$5:$N$7,2,FALSE),""),IF($E22="Secretário",IFERROR(VLOOKUP($M22,'Listas de apoio'!$P$5:$Q$7,2,FALSE),""),"")))))) -> 1 | O22: Revisão completa, com verificações e evidências suficientes para sustentar a aceitação. | P22: Ivan Cristiano Silva Mendes | Q22: =IF(OR($A22="",NOT(ISNUMBER($L22)),NOT(ISNUMBER($N22))),"",$L22*$N22) -> 15 | R22: 46293 | S22: 46287.69 | T22: =IF(OR($A22="",$R22="",$S22=""),"",MAX(0,($S22-$R22)*24)) -> 0 | U22: Sem atraso | V22: =IF($A22="","",IF($U22="","",IFERROR(VLOOKUP($U22,'Listas de apoio'!$S$5:$T$10,2,FALSE),""))) -> 0 | W22: =IF(OR($A22="",NOT(ISNUMBER($L22)),NOT(ISNUMBER($Q22))),"",$L22-$Q22) -> 0 | X22: =IF(OR($A22="",NOT(ISNUMBER($Q22)),NOT(ISNUMBER($V22))),"",$Q22*(1-$V22)) -> 15 | Y22: =IF(OR($A22="",NOT(ISNUMBER($Q22)),NOT(ISNUMBER($X22))),"",$Q22-$X22) -> 0 | Z22: =IF(NOT(ISNUMBER($X22)),"",ROUND($X22,2)) -> 15
A23: S01 | B23: I002 | C23: Elaborar Declaração de Âmbito | D23: Ivan Cristiano Silva Mendes | E23: Auditor | F23: 50 | G23: Atribuição inicial | H23: =IF($A23="","",IF($G23="Secretariado",10,IF($G23="Transferência recebida",0,IF($E23="Executor",$F23*60%,IF($E23="Revisor",$F23*30%,IF($E23="Auditor",$F23*10%,"")))))) -> 5 | I23: Não Aplicável | J23: 0 | K23: 0 | L23: =IF($A23="","",$H23-$J23+$K23) -> 5 | M23: Auditoria completa antes do Sprint Review, incluindo a confirmação final | N23: =IF($A23="","",IF($M23="","",IF($E23="Executor",IFERROR(VLOOKUP($M23,'Listas de apoio'!$G$5:$H$9,2,FALSE),""),IF($E23="Revisor",IFERROR(VLOOKUP($M23,'Listas de apoio'!$J$5:$K$8,2,FALSE),""),IF($E23="Auditor",IFERROR(VLOOKUP($M23,'Listas de apoio'!$M$5:$N$7,2,FALSE),""),IF($E23="Secretário",IFERROR(VLOOKUP($M23,'Listas de apoio'!$P$5:$Q$7,2,FALSE),""),"")))))) -> 1 | O23: Auditoria concluída antes do Sprint Review, incluindo a confirmação final das evidências. | P23: Não Aplicável - O auditor não participa da própria classificação. | Q23: =IF(OR($A23="",NOT(ISNUMBER($L23)),NOT(ISNUMBER($N23))),"",$L23*$N23) -> 5 | R23: 46293 | S23: 46287.69 | T23: =IF(OR($A23="",$R23="",$S23=""),"",MAX(0,($S23-$R23)*24)) -> 0 | U23: Sem atraso | V23: =IF($A23="","",IF($U23="","",IFERROR(VLOOKUP($U23,'Listas de apoio'!$S$5:$T$10,2,FALSE),""))) -> 0 | W23: =IF(OR($A23="",NOT(ISNUMBER($L23)),NOT(ISNUMBER($Q23))),"",$L23-$Q23) -> 0 | X23: =IF(OR($A23="",NOT(ISNUMBER($Q23)),NOT(ISNUMBER($V23))),"",$Q23*(1-$V23)) -> 5 | Y23: =IF(OR($A23="",NOT(ISNUMBER($Q23)),NOT(ISNUMBER($X23))),"",$Q23-$X23) -> 0 | Z23: =IF(NOT(ISNUMBER($X23)),"",ROUND($X23,2)) -> 5
A24: S01 | B24: I003 | C24: Preparar Checklist de Controlo de Artefactos (CCA) | D24: Ivan Cristiano Silva Mendes | E24: Executor | F24: 30 | G24: Atribuição inicial | H24: =IF($A24="","",IF($G24="Secretariado",10,IF($G24="Transferência recebida",0,IF($E24="Executor",$F24*60%,IF($E24="Revisor",$F24*30%,IF($E24="Auditor",$F24*10%,"")))))) -> 18 | I24: Não Aplicável | J24: 0 | K24: 0 | L24: =IF($A24="","",$H24-$J24+$K24) -> 18 | M24: Aceite sem correções obrigatórias | N24: =IF($A24="","",IF($M24="","",IF($E24="Executor",IFERROR(VLOOKUP($M24,'Listas de apoio'!$G$5:$H$9,2,FALSE),""),IF($E24="Revisor",IFERROR(VLOOKUP($M24,'Listas de apoio'!$J$5:$K$8,2,FALSE),""),IF($E24="Auditor",IFERROR(VLOOKUP($M24,'Listas de apoio'!$M$5:$N$7,2,FALSE),""),IF($E24="Secretário",IFERROR(VLOOKUP($M24,'Listas de apoio'!$P$5:$Q$7,2,FALSE),""),"")))))) -> 1 | O24: O modelo ficou utilizável sem necessidade de correções; | P24: Gonçalo Magalhães Ribeiro | Q24: =IF(OR($A24="",NOT(ISNUMBER($L24)),NOT(ISNUMBER($N24))),"",$L24*$N24) -> 18 | R24: 46293 | S24: 46289.781 | T24: =IF(OR($A24="",$R24="",$S24=""),"",MAX(0,($S24-$R24)*24)) -> 0 | U24: Sem atraso | V24: =IF($A24="","",IF($U24="","",IFERROR(VLOOKUP($U24,'Listas de apoio'!$S$5:$T$10,2,FALSE),""))) -> 0 | W24: =IF(OR($A24="",NOT(ISNUMBER($L24)),NOT(ISNUMBER($Q24))),"",$L24-$Q24) -> 0 | X24: =IF(OR($A24="",NOT(ISNUMBER($Q24)),NOT(ISNUMBER($V24))),"",$Q24*(1-$V24)) -> 18 | Y24: =IF(OR($A24="",NOT(ISNUMBER($Q24)),NOT(ISNUMBER($X24))),"",$Q24-$X24) -> 0 | Z24: =IF(NOT(ISNUMBER($X24)),"",ROUND($X24,2)) -> 18
A25: S01 | B25: I003 | C25: Preparar Checklist de Controlo de Artefactos (CCA) | D25: Gonçalo Magalhães Ribeiro | E25: Revisor | F25: 30 | G25: Atribuição inicial | H25: =IF($A25="","",IF($G25="Secretariado",10,IF($G25="Transferência recebida",0,IF($E25="Executor",$F25*60%,IF($E25="Revisor",$F25*30%,IF($E25="Auditor",$F25*10%,"")))))) -> 9 | I25: Não Aplicável | J25: 0 | K25: 0 | L25: =IF($A25="","",$H25-$J25+$K25) -> 9 | M25: Revisão completa, correta e sustentada por evidências | N25: =IF($A25="","",IF($M25="","",IF($E25="Executor",IFERROR(VLOOKUP($M25,'Listas de apoio'!$G$5:$H$9,2,FALSE),""),IF($E25="Revisor",IFERROR(VLOOKUP($M25,'Listas de apoio'!$J$5:$K$8,2,FALSE),""),IF($E25="Auditor",IFERROR(VLOOKUP($M25,'Listas de apoio'!$M$5:$N$7,2,FALSE),""),IF($E25="Secretário",IFERROR(VLOOKUP($M25,'Listas de apoio'!$P$5:$Q$7,2,FALSE),""),"")))))) -> 1 | O25: Revisão completa, com verificações e evidências suficientes para sustentar a aceitação. | P25: Gonçalo Dinis Magalhães Teixeira | Q25: =IF(OR($A25="",NOT(ISNUMBER($L25)),NOT(ISNUMBER($N25))),"",$L25*$N25) -> 9 | R25: 46293 | S25: 46289.781 | T25: =IF(OR($A25="",$R25="",$S25=""),"",MAX(0,($S25-$R25)*24)) -> 0 | U25: Sem atraso | V25: =IF($A25="","",IF($U25="","",IFERROR(VLOOKUP($U25,'Listas de apoio'!$S$5:$T$10,2,FALSE),""))) -> 0 | W25: =IF(OR($A25="",NOT(ISNUMBER($L25)),NOT(ISNUMBER($Q25))),"",$L25-$Q25) -> 0 | X25: =IF(OR($A25="",NOT(ISNUMBER($Q25)),NOT(ISNUMBER($V25))),"",$Q25*(1-$V25)) -> 9 | Y25: =IF(OR($A25="",NOT(ISNUMBER($Q25)),NOT(ISNUMBER($X25))),"",$Q25-$X25) -> 0 | Z25: =IF(NOT(ISNUMBER($X25)),"",ROUND($X25,2)) -> 9
A26: S01 | B26: I003 | C26: Preparar Checklist de Controlo de Artefactos (CCA) | D26: Gonçalo Dinis Magalhães Teixeira | E26: Auditor | F26: 30 | G26: Atribuição inicial | H26: =IF($A26="","",IF($G26="Secretariado",10,IF($G26="Transferência recebida",0,IF($E26="Executor",$F26*60%,IF($E26="Revisor",$F26*30%,IF($E26="Auditor",$F26*10%,"")))))) -> 3 | I26: Não Aplicável | J26: 0 | K26: 0 | L26: =IF($A26="","",$H26-$J26+$K26) -> 3 | M26: Auditoria completa antes do Sprint Review, incluindo a confirmação final | N26: =IF($A26="","",IF($M26="","",IF($E26="Executor",IFERROR(VLOOKUP($M26,'Listas de apoio'!$G$5:$H$9,2,FALSE),""),IF($E26="Revisor",IFERROR(VLOOKUP($M26,'Listas de apoio'!$J$5:$K$8,2,FALSE),""),IF($E26="Auditor",IFERROR(VLOOKUP($M26,'Listas de apoio'!$M$5:$N$7,2,FALSE),""),IF($E26="Secretário",IFERROR(VLOOKUP($M26,'Listas de apoio'!$P$5:$Q$7,2,FALSE),""),"")))))) -> 1 | O26: Auditoria concluída antes do Sprint Review, incluindo a confirmação final das evidências. | P26: Não Aplicável - O auditor não participa da própria classificação. | Q26: =IF(OR($A26="",NOT(ISNUMBER($L26)),NOT(ISNUMBER($N26))),"",$L26*$N26) -> 3 | R26: 46293 | S26: 46289.781 | T26: =IF(OR($A26="",$R26="",$S26=""),"",MAX(0,($S26-$R26)*24)) -> 0 | U26: Sem atraso | V26: =IF($A26="","",IF($U26="","",IFERROR(VLOOKUP($U26,'Listas de apoio'!$S$5:$T$10,2,FALSE),""))) -> 0 | W26: =IF(OR($A26="",NOT(ISNUMBER($L26)),NOT(ISNUMBER($Q26))),"",$L26-$Q26) -> 0 | X26: =IF(OR($A26="",NOT(ISNUMBER($Q26)),NOT(ISNUMBER($V26))),"",$Q26*(1-$V26)) -> 3 | Y26: =IF(OR($A26="",NOT(ISNUMBER($Q26)),NOT(ISNUMBER($X26))),"",$Q26-$X26) -> 0 | Z26: =IF(NOT(ISNUMBER($X26)),"",ROUND($X26,2)) -> 3
A27: S01 | B27: I004 | C27: Obter e arquivar homologação da PS, DA e CCA | D27: Ivan Cristiano Silva Mendes | E27: Executor | F27: 10 | G27: Atribuição inicial | H27: =IF($A27="","",IF($G27="Secretariado",10,IF($G27="Transferência recebida",0,IF($E27="Executor",$F27*60%,IF($E27="Revisor",$F27*30%,IF($E27="Auditor",$F27*10%,"")))))) -> 6 | I27: Não Aplicável | J27: 0 | K27: 0 | L27: =IF($A27="","",$H27-$J27+$K27) -> 6 | M27: Aceite sem correções obrigatórias | N27: =IF($A27="","",IF($M27="","",IF($E27="Executor",IFERROR(VLOOKUP($M27,'Listas de apoio'!$G$5:$H$9,2,FALSE),""),IF($E27="Revisor",IFERROR(VLOOKUP($M27,'Listas de apoio'!$J$5:$K$8,2,FALSE),""),IF($E27="Auditor",IFERROR(VLOOKUP($M27,'Listas de apoio'!$M$5:$N$7,2,FALSE),""),IF($E27="Secretário",IFERROR(VLOOKUP($M27,'Listas de apoio'!$P$5:$Q$7,2,FALSE),""),"")))))) -> 1 | O27: O modelo ficou utilizável sem necessidade de correções; | P27: André Filipe Moreira Mesquita | Q27: =IF(OR($A27="",NOT(ISNUMBER($L27)),NOT(ISNUMBER($N27))),"",$L27*$N27) -> 6 | R27: 46293 | S27: 46290.48 | T27: =IF(OR($A27="",$R27="",$S27=""),"",MAX(0,($S27-$R27)*24)) -> 0 | U27: Sem atraso | V27: =IF($A27="","",IF($U27="","",IFERROR(VLOOKUP($U27,'Listas de apoio'!$S$5:$T$10,2,FALSE),""))) -> 0 | W27: =IF(OR($A27="",NOT(ISNUMBER($L27)),NOT(ISNUMBER($Q27))),"",$L27-$Q27) -> 0 | X27: =IF(OR($A27="",NOT(ISNUMBER($Q27)),NOT(ISNUMBER($V27))),"",$Q27*(1-$V27)) -> 6 | Y27: =IF(OR($A27="",NOT(ISNUMBER($Q27)),NOT(ISNUMBER($X27))),"",$Q27-$X27) -> 0 | Z27: =IF(NOT(ISNUMBER($X27)),"",ROUND($X27,2)) -> 6
A28: S01 | B28: I004 | C28: Obter e arquivar homologação da PS, DA e CCA | D28: André Filipe Moreira Mesquita | E28: Revisor | F28: 10 | G28: Atribuição inicial | H28: =IF($A28="","",IF($G28="Secretariado",10,IF($G28="Transferência recebida",0,IF($E28="Executor",$F28*60%,IF($E28="Revisor",$F28*30%,IF($E28="Auditor",$F28*10%,"")))))) -> 3 | I28: Não Aplicável | J28: 0 | K28: 0 | L28: =IF($A28="","",$H28-$J28+$K28) -> 3 | M28: Revisão completa, correta e sustentada por evidências | N28: =IF($A28="","",IF($M28="","",IF($E28="Executor",IFERROR(VLOOKUP($M28,'Listas de apoio'!$G$5:$H$9,2,FALSE),""),IF($E28="Revisor",IFERROR(VLOOKUP($M28,'Listas de apoio'!$J$5:$K$8,2,FALSE),""),IF($E28="Auditor",IFERROR(VLOOKUP($M28,'Listas de apoio'!$M$5:$N$7,2,FALSE),""),IF($E28="Secretário",IFERROR(VLOOKUP($M28,'Listas de apoio'!$P$5:$Q$7,2,FALSE),""),"")))))) -> 1 | O28: Revisão completa, com verificações e evidências suficientes para sustentar a aceitação. | P28: Gonçalo Magalhães Ribeiro | Q28: =IF(OR($A28="",NOT(ISNUMBER($L28)),NOT(ISNUMBER($N28))),"",$L28*$N28) -> 3 | R28: 46293 | S28: 46290.48 | T28: =IF(OR($A28="",$R28="",$S28=""),"",MAX(0,($S28-$R28)*24)) -> 0 | U28: Sem atraso | V28: =IF($A28="","",IF($U28="","",IFERROR(VLOOKUP($U28,'Listas de apoio'!$S$5:$T$10,2,FALSE),""))) -> 0 | W28: =IF(OR($A28="",NOT(ISNUMBER($L28)),NOT(ISNUMBER($Q28))),"",$L28-$Q28) -> 0 | X28: =IF(OR($A28="",NOT(ISNUMBER($Q28)),NOT(ISNUMBER($V28))),"",$Q28*(1-$V28)) -> 3 | Y28: =IF(OR($A28="",NOT(ISNUMBER($Q28)),NOT(ISNUMBER($X28))),"",$Q28-$X28) -> 0 | Z28: =IF(NOT(ISNUMBER($X28)),"",ROUND($X28,2)) -> 3
A29: S01 | B29: I004 | C29: Obter e arquivar homologação da PS, DA e CCA | D29: Gonçalo Magalhães Ribeiro | E29: Auditor | F29: 10 | G29: Atribuição inicial | H29: =IF($A29="","",IF($G29="Secretariado",10,IF($G29="Transferência recebida",0,IF($E29="Executor",$F29*60%,IF($E29="Revisor",$F29*30%,IF($E29="Auditor",$F29*10%,"")))))) -> 1 | I29: Não Aplicável | J29: 0 | K29: 0 | L29: =IF($A29="","",$H29-$J29+$K29) -> 1 | M29: Auditoria completa antes do Sprint Review, incluindo a confirmação final | N29: =IF($A29="","",IF($M29="","",IF($E29="Executor",IFERROR(VLOOKUP($M29,'Listas de apoio'!$G$5:$H$9,2,FALSE),""),IF($E29="Revisor",IFERROR(VLOOKUP($M29,'Listas de apoio'!$J$5:$K$8,2,FALSE),""),IF($E29="Auditor",IFERROR(VLOOKUP($M29,'Listas de apoio'!$M$5:$N$7,2,FALSE),""),IF($E29="Secretário",IFERROR(VLOOKUP($M29,'Listas de apoio'!$P$5:$Q$7,2,FALSE),""),"")))))) -> 1 | O29: Auditoria concluída antes do Sprint Review, incluindo a confirmação final das evidências. | P29: Não Aplicável - O auditor não participa da própria classificação. | Q29: =IF(OR($A29="",NOT(ISNUMBER($L29)),NOT(ISNUMBER($N29))),"",$L29*$N29) -> 1 | R29: 46293 | S29: 46290.48 | T29: =IF(OR($A29="",$R29="",$S29=""),"",MAX(0,($S29-$R29)*24)) -> 0 | U29: Sem atraso | V29: =IF($A29="","",IF($U29="","",IFERROR(VLOOKUP($U29,'Listas de apoio'!$S$5:$T$10,2,FALSE),""))) -> 0 | W29: =IF(OR($A29="",NOT(ISNUMBER($L29)),NOT(ISNUMBER($Q29))),"",$L29-$Q29) -> 0 | X29: =IF(OR($A29="",NOT(ISNUMBER($Q29)),NOT(ISNUMBER($V29))),"",$Q29*(1-$V29)) -> 1 | Y29: =IF(OR($A29="",NOT(ISNUMBER($Q29)),NOT(ISNUMBER($X29))),"",$Q29-$X29) -> 0 | Z29: =IF(NOT(ISNUMBER($X29)),"",ROUND($X29,2)) -> 1
... A88: S02 | B88: Não aplicável | C88: Secretário de Sprint 02 | D88: Gonçalo Magalhães Ribeiro | E88: Secretário | F88: 10 | G88: Secretariado | H88: =IF($A88="","",IF($G88="Secretariado",10,IF($G88="Transferência recebida",0,IF($E88="Executor",$F88*60%,IF($E88="Revisor",$F88*30%,IF($E88="Auditor",$F88*10%,"")))))) -> 10 | I88: Não Aplicável | J88: 0 | K88: 0 | L88: =IF($A88="","",$H88-$J88+$K88) -> 10 | M88: Trabalho completo e correto | N88: =IF($A88="","",IF($M88="","",IF($E88="Executor",IFERROR(VLOOKUP($M88,'Listas de apoio'!$G$5:$H$9,2,FALSE),""),IF($E88="Revisor",IFERROR(VLOOKUP($M88,'Listas de apoio'!$J$5:$K$8,2,FALSE),""),IF($E88="Auditor",IFERROR(VLOOKUP($M88,'Listas de apoio'!$M$5:$N$7,2,FALSE),""),IF($E88="Secretário",IFERROR(VLOOKUP($M88,'Listas de apoio'!$P$5:$Q$7,2,FALSE),""),"")))))) -> 1 | O88: Secretariado concluído; Trabalho completo e correto; | P88: André Filipe Moreira Mesquita; Gonçalo Magalhães Ribeiro; Ivan Cristiano Silva Mendes | Q88: =IF(OR($A88="",NOT(ISNUMBER($L88)),NOT(ISNUMBER($N88))),"",$L88*$N88) -> 10 | R88: 46303.708 | S88: 46302.979 | T88: =IF(OR($A88="",$R88="",$S88=""),"",MAX(0,($S88-$R88)*24)) -> 0 | U88: Sem atraso | V88: =IF($A88="","",IF($U88="","",IFERROR(VLOOKUP($U88,'Listas de apoio'!$S$5:$T$10,2,FALSE),""))) -> 0 | W88: =IF(OR($A88="",NOT(ISNUMBER($L88)),NOT(ISNUMBER($Q88))),"",$L88-$Q88) -> 0 | X88: =IF(OR($A88="",NOT(ISNUMBER($Q88)),NOT(ISNUMBER($V88))),"",$Q88*(1-$V88)) -> 10 | Y88: =IF(OR($A88="",NOT(ISNUMBER($Q88)),NOT(ISNUMBER($X88))),"",$Q88-$X88) -> 0 | Z88: =IF(NOT(ISNUMBER($X88)),"",ROUND($X88,2)) -> 10

Sheet Validação
A1: VALIDAÇÃO DO MAPA DE PONTUAÇÃO INDIVIDUAL | B1: VALIDAÇÃO DO MAPA DE PONTUAÇÃO INDIVIDUAL | C1: VALIDAÇÃO DO MAPA DE PONTUAÇÃO INDIVIDUAL | D1: VALIDAÇÃO DO MAPA DE PONTUAÇÃO INDIVIDUAL
A2: Esta folha deteta incoerências básicas. Um resultado «OK» não substitui a apreciação e aprovação formal dos resultados do Sprint no Sprint Review, nem a aprovação dos valores finais acumulados no fecho do Momento de Avaliação, nem a verificação do docente. | B2: Esta folha deteta incoerências básicas. Um resultado «OK» não substitui a apreciação, votação e aprovação formal no Sprint Review nem a verificação do docente. | C2: Esta folha deteta incoerências básicas. Um resultado «OK» não substitui a apreciação, votação e aprovação formal no Sprint Review nem a verificação do docente. | D2: Esta folha deteta incoerências básicas. Um resultado «OK» não substitui a apreciação, votação e aprovação formal no Sprint Review nem a verificação do docente.
A4: Verificação | B4: Resultado | C4: Estado | D4: Interpretação
A5: Linhas de pontuação registadas | B5: =COUNTIF('Detalhe da Pontuação'!A18:A88,"<>") -> 71 | C5: Informação | D5: Número de linhas preenchidas no detalhe, incluindo as linhas de Secretariado e as parcelas recebidas por transferência.
A6: Sprints registados nas fontes documentais | B6: =COUNTA('Detalhe da Pontuação'!A6:A14) -> 2 | C6: Informação | D6: Número de Sprints para os quais foram identificadas as versões vigentes do Sprint Backlog.
A7: Total de Pontos Efetivamente Obtidos do grupo | B7: =SUM('Detalhe da Pontuação'!Z18:Z88) -> 800 | C7: Informação | D7: Soma de todos os PEO antes do cálculo dos índices e das notas individuais.
A8: Sprints sem identificação simultânea do ficheiro editável (XLS/XLSX) e do PDF assinado | B8: =COUNTIFS('Detalhe da Pontuação'!A6:A14,"<>",'Detalhe da Pontuação'!B6:B14,"")+COUNTIFS('Detalhe da Pontuação'!A6:A14,"<>",'Detalhe da Pontuação'!I6:I14,"") -> 0 | C8: =IF(ABS(B8)<=0.005,"OK","Rever") -> OK | D8: Deve ser 0. Cada Sprint deve identificar a última versão cumulativa do Sprint Backlog no formato editável utilizado, XLS ou XLSX, e o PDF assinado que a congelou.
A9: Campos obrigatórios vazios nas linhas de pontuação | B9: =COUNTIFS('Detalhe da Pontuação'!A18:A88,"<>",'Detalhe da Pontuação'!D18:D88,"")+COUNTIFS('Detalhe da Pontuação'!A18:A88,"<>",'Detalhe da Pontuação'!E18:E88,"")+COUNTIFS('Detalhe da Pontuação'!A18:A88,"<>",'Detalhe da Pontuação'!F18:F88,"")+COUNTIFS('Detalhe da Pontuação'!A18:A88,"<>",'Detalhe da Pontuação'!G18:G88,"")+COUNTIFS('Detalhe da Pontuação'!A18:A88,"<>",'Detalhe da Pontuação'!M18:M88,"")+COUNTIFS('Detalhe da Pontuação'!A18:A88,"<>",'Detalhe da Pontuação'!O18:O88,"")+COUNTIFS('Detalhe da Pontuação'!A18:A88,"<>",'Detalhe da Pontuação'!P18:P88,"")+COUNTIFS('Detalhe da Pontuação'!A18:A88,"<>",'Detalhe da Pontuação'!U18:U88,"") -> 0 | C9: =IF(ABS(B9)<=0.005,"OK","Rever") -> OK | D9: Deve ser 0. O resultado conta células obrigatórias vazias, não linhas.
A10: Linhas sem Issue ou tarefa, exceto Secretariado | B10: =COUNTIFS('Detalhe da Pontuação'!A18:A88,"<>",'Detalhe da Pontuação'!E18:E88,"<>Secretário",'Detalhe da Pontuação'!B18:B88,"")+COUNTIFS('Detalhe da Pontuação'!A18:A88,"<>",'Detalhe da Pontuação'!E18:E88,"<>Secretário",'Detalhe da Pontuação'!C18:C88,"") -> 0 | C10: =IF(ABS(B10)<=0.005,"OK","Rever") -> OK | D10: Deve ser 0. Apenas a linha do Secretário pode usar «—» na Issue; as restantes linhas identificam Issue e tarefa.
A11: Orçamentos vazios, nulos ou negativos | B11: =COUNTIFS('Detalhe da Pontuação'!A18:A88,"<>",'Detalhe da Pontuação'!F18:F88,"<=0") -> 0 | C11: =IF(ABS(B11)<=0.005,"OK","Rever") -> OK | D11: Deve ser 0. O orçamento é o valor total aprovado para a tarefa; no Secretariado é sempre 10 pontos.
A12: Linhas em que a PMI não corresponde ao planeamento inicial | B12: =SUM('Listas de apoio'!W5:W75) -> 0 | C12: =IF(ABS(B12)<=0.005,"OK","Rever") -> OK | D12: Deve ser 0. A PMI é 60%, 30% ou 10% do orçamento para os papéis iniciais, 0 para uma parcela recebida e 10 para o Secretariado.
A13: Transferências sem referência ao registo do Sprint Backlog | B13: =COUNTIFS('Detalhe da Pontuação'!A18:A88,"<>",'Detalhe da Pontuação'!G18:G88,"Transferência recebida",'Detalhe da Pontuação'!I18:I88,"")+COUNTIFS('Detalhe da Pontuação'!A18:A88,"<>",'Detalhe da Pontuação'!J18:J88,">0",'Detalhe da Pontuação'!I18:I88,"") -> 0 | C13: =IF(ABS(B13)<=0.005,"OK","Rever") -> OK | D13: Deve ser 0. Os pontos cedidos e recebidos têm de remeter para o registo formal da folha Transferências do Sprint Backlog vigente.
A14: Diferença entre o total de pontos cedidos e recebidos | B14: =ABS(SUM('Detalhe da Pontuação'!J18:J88)-SUM('Detalhe da Pontuação'!K18:K88)) -> 0 | C14: =IF(ABS(B14)<=0.005,"OK","Rever") -> OK | D14: Deve ser 0,00. Cada ponto cedido por um aluno deve aparecer como ponto recebido por outro aluno.
A15: Linhas em que a PMR não corresponde a PMI - PC + PR | B15: =SUM('Listas de apoio'!X5:X75) -> 0 | C15: =IF(ABS(B15)<=0.005,"OK","Rever") -> OK | D15: Deve ser 0. A Parcela Máxima Resultante é calculada por PMR = PMI - PC + PR.
A16: Linhas com PMR negativa | B16: =COUNTIFS('Detalhe da Pontuação'!A18:A88,"<>",'Detalhe da Pontuação'!L18:L88,"<0") -> 0 | C16: =IF(ABS(B16)<=0.005,"OK","Rever") -> OK | D16: Deve ser 0. Um aluno não pode ceder mais pontos do que os disponíveis na sua parcela.
A17: Categorias de qualidade incompatíveis com o papel | B17: =COUNTIFS('Detalhe da Pontuação'!A18:A88,"<>",'Detalhe da Pontuação'!M18:M88,"<>")-COUNT('Detalhe da Pontuação'!N18:N88) -> 0 | C17: =IF(ABS(B17)<=0.005,"OK","Rever") -> OK | D17: Deve ser 0. Cada papel utiliza exclusivamente a respetiva escala oficial de qualidade; uma categoria incompatível impede o cálculo de Q.
A18: Linhas em que o fator de qualidade Q não corresponde à categoria de qualidade aprovada | B18: =SUM('Listas de apoio'!AG5:AG75) -> 0 | C18: =IF(ABS(B18)<=0.005,"OK","Rever") -> OK | D18: Deve ser 0. Em cada linha, o fator Q deve corresponder à percentagem prevista na escala oficial do papel para a categoria de qualidade selecionada.
A19: Linhas em que PQ não corresponde a PMR × Q | B19: =SUM('Listas de apoio'!Y5:Y75) -> 0 | C19: =IF(ABS(B19)<=0.005,"OK","Rever") -> OK | D19: Deve ser 0. A Parcela de Qualidade é calculada por PQ = PMR × Q.
A20: Linhas em que as horas de atraso não correspondem às datas | B20: =SUM('Listas de apoio'!Z5:Z75) -> 0 | C20: =IF(ABS(B20)<=0.005,"OK","Rever") -> OK | D20: Deve ser 0. As horas de atraso são calculadas a partir do Prazo aplicável e da Data e hora de conclusão.
A21: Níveis da escala de atraso incompatíveis com as horas calculadas | B21: =SUM('Listas de apoio'!AE5:AE75) -> 0 | C21: =IF(ABS(B21)<=0.005,"OK","Rever") -> OK | D21: Deve ser 0. A opção selecionada deve corresponder às horas calculadas. A categoria de 100% também abrange conclusões posteriores ao Sprint Review e, nesse caso, exige confirmação humana.
A22: Linhas em que o fator A não corresponde ao nível selecionado | B22: =COUNTIFS('Detalhe da Pontuação'!A18:A88,"<>",'Detalhe da Pontuação'!U18:U88,"<>")-COUNT('Detalhe da Pontuação'!V18:V88) -> 0 | C22: =IF(ABS(B22)<=0.005,"OK","Rever") -> OK | D22: Deve ser 0. O fator A é preenchido automaticamente através da escala oficial de penalização por atraso.
A23: Linhas em que a perda de pontos por qualidade não corresponde a PMR − PQ | B23: =SUM('Listas de apoio'!AA5:AA75) -> 0 | C23: =IF(ABS(B23)<=0.005,"OK","Rever") -> OK | D23: Deve ser 0. Em cada linha, a perda por qualidade deve corresponder à diferença entre a Parcela Máxima Resultante (PMR) e a Parcela de Qualidade (PQ).
A24: Linhas em que o PEO antes do arredondamento não corresponde a PQ × (1 − A) | B24: =SUM('Listas de apoio'!AB5:AB75) -> 0 | C24: =IF(ABS(B24)<=0.005,"OK","Rever") -> OK | D24: Deve ser 0. Em cada linha, o PEO antes do arredondamento deve resultar da aplicação do fator de atraso à Parcela de Qualidade: PEO = PQ × (1 − A).
A25: Linhas em que a perda de pontos por atraso não corresponde a PQ − PEO não arredondado | B25: =SUM('Listas de apoio'!AC5:AC75) -> 0 | C25: =IF(ABS(B25)<=0.005,"OK","Rever") -> OK | D25: Deve ser 0. Em cada linha, a perda por atraso deve corresponder à diferença entre a Parcela de Qualidade (PQ) e o PEO antes do arredondamento.
A26: Linhas em que o PEO final não corresponde ao arredondamento do PEO não arredondado | B26: =SUM('Listas de apoio'!AD5:AD75) -> 0 | C26: =IF(ABS(B26)<=0.005,"OK","Rever") -> OK | D26: Deve ser 0. Em cada linha, o PEO final deve corresponder ao PEO não arredondado arredondado a duas casas decimais. É este valor que é somado no cálculo de P_i.
A27: Linhas em que o PEO excede a PMR | B27: {=SUMPRODUCT(--('Detalhe da Pontuação'!A18:A88<>""),--('Detalhe da Pontuação'!Z18:Z88>'Detalhe da Pontuação'!L18:L88+0.005))} -> 0 | C27: =IF(ABS(B27)<=0.005,"OK","Rever") -> OK | D27: Deve ser 0. A qualidade e o atraso nunca podem aumentar a parcela máxima resultante.
A28: Linhas de Secretariado cujo orçamento ou PMI não é 10 | B28: =COUNTIFS('Detalhe da Pontuação'!E18:E88,"Secretário",'Detalhe da Pontuação'!F18:F88,"<>10")+COUNTIFS('Detalhe da Pontuação'!E18:E88,"Secretário",'Detalhe da Pontuação'!H18:H88,"<>10") -> 0 | C28: =IF(ABS(B28)<=0.005,"OK","Rever") -> OK | D28: Deve ser 0. Cada Sprint atribui ao Secretariado um máximo inicial de 10 pontos; o PEO pode ser inferior devido a qualidade ou atraso.
A29: Diferença entre o Orçamento Total do Grupo — B_T e a soma das PMI | B29: =ABS('Mapa de Pontuação Individual'!B9-SUM('Detalhe da Pontuação'!H18:H88)) -> 0 | C29: =IF(ABS(B29)<=0.005,"OK","Rever") -> OK | D29: Deve ser 0,00. B_T inclui os orçamentos das tarefas uma única vez e 10 pontos de Secretariado por Sprint; a soma das PMI reconstrói esse total.
A30: Diferença entre o total de PEO do grupo e a soma dos totais individuais — P_i | B30: =ABS('Mapa de Pontuação Individual'!B10-SUM('Mapa de Pontuação Individual'!F14:F17)) -> 0 | C30: =IF(ABS(B30)<=0.005,"OK","Rever") -> OK | D30: Deve ser 0,00. O total dos PEO do grupo deve corresponder à soma dos P_i dos alunos.
A31: Alunos cujo Índice Bruto — IB_i não corresponde a (20 × n × P_i) / B_T | B31: =IF(ABS('Mapa de Pontuação Individual'!G14-(20*'Mapa de Pontuação Individual'!$B$7*'Mapa de Pontuação Individual'!F14/'Mapa de Pontuação Individual'!$B$9))>0.005,1,0)+IF(ABS('Mapa de Pontuação Individual'!G15-(20*'Mapa de Pontuação Individual'!$B$7*'Mapa de Pontuação Individual'!F15/'Mapa de Pontuação Individual'!$B$9))>0.005,1,0)+IF(ABS('Mapa de Pontuação Individual'!G16-(20*'Mapa de Pontuação Individual'!$B$7*'Mapa de Pontuação Individual'!F16/'Mapa de Pontuação Individual'!$B$9))>0.005,1,0)+IF(ABS('Mapa de Pontuação Individual'!G17-(20*'Mapa de Pontuação Individual'!$B$7*'Mapa de Pontuação Individual'!F17/'Mapa de Pontuação Individual'!$B$9))>0.005,1,0) -> 0 | C31: =IF(ABS(B31)<=0.005,"OK","Rever") -> OK | D31: Deve ser 0. O índice bruto conserva o resultado anterior à aplicação do limite de 20 valores.
A32: Alunos cuja Nota Individual — NI_i não corresponde a min(20; IB_i) | B32: =IF(ABS('Mapa de Pontuação Individual'!H14-MIN(20,'Mapa de Pontuação Individual'!G14))>0.005,1,0)+IF(ABS('Mapa de Pontuação Individual'!H15-MIN(20,'Mapa de Pontuação Individual'!G15))>0.005,1,0)+IF(ABS('Mapa de Pontuação Individual'!H16-MIN(20,'Mapa de Pontuação Individual'!G16))>0.005,1,0)+IF(ABS('Mapa de Pontuação Individual'!H17-MIN(20,'Mapa de Pontuação Individual'!G17))>0.005,1,0) -> 0 | C32: =IF(ABS(B32)<=0.005,"OK","Rever") -> OK | D32: Deve ser 0. A Nota Individual é NI_i = min(20; IB_i).
A33: Número de alunos diferente de 4 sem referência de autorização | B33: =IF(AND('Mapa de Pontuação Individual'!B7<>4,OR('Mapa de Pontuação Individual'!B8="",'Mapa de Pontuação Individual'!B8="Não aplicável — n = 4")),1,0) -> 0 | C33: =IF(ABS(B33)<=0.005,"OK","Rever") -> OK | D33: Deve ser 0. Um grupo com n diferente de 4 exige autorização do docente e a respetiva referência documental.

Sheet Instruções
A1: INSTRUÇÕES DE PREENCHIMENTO | B1: INSTRUÇÕES DE PREENCHIMENTO | C1: INSTRUÇÕES DE PREENCHIMENTO | D1: INSTRUÇÕES DE PREENCHIMENTO
A2: Leia estas regras antes de substituir os exemplos. O ficheiro deve permitir reconstruir todos os cálculos aprovados e não substitui a ata do Sprint Review nem os restantes documentos oficiais. | B2: Leia estas regras antes de substituir os exemplos. O ficheiro deve permitir reconstruir todos os cálculos aprovados e não substitui a ata do Sprint Review nem os restantes documentos oficiais. | C2: Leia estas regras antes de substituir os exemplos. O ficheiro deve permitir reconstruir todos os cálculos aprovados e não substitui a ata do Sprint Review nem os restantes documentos oficiais. | D2: Leia estas regras antes de substituir os exemplos. O ficheiro deve permitir reconstruir todos os cálculos aprovados e não substitui a ata do Sprint Review nem os restantes documentos oficiais.
A3: N.º | B3: Tema | C3: Regra essencial | D3: Aplicação prática
A4: 1 | B4: Finalidade | C4: Este mapa é cumulativo por Momento de Avaliação e é preparado como suporte aos Sprint Reviews e, no final do Momento de Avaliação, à reunião formal autónoma de fecho. Reúne o detalhe necessário para calcular os Pontos Efetivamente Obtidos e os valores acumulados P_i, IB_i e NI_i. | D4: Em cada Sprint Review, complete as categorias aprovadas, os atrasos imputáveis, os fundamentos e os PEO. A ata do Sprint Review resume esses resultados e identifica o ficheiro editável em XLS ou XLSX e o respetivo PDF assinado. No fecho do Momento de Avaliação, a reunião formal autónoma aprecia e aprova os valores finais n, B_T, P_i, IB_i e NI_i.
A5: 2 | B5: Fonte do planeamento | C5: A PMI e os responsáveis iniciais vêm do Sprint Backlog aprovado no Sprint Planning. Use sempre a última versão cumulativa formalmente aprovada antes do Sprint Review. | D5: Se não houve transferências, será normalmente a versão aprovada no Sprint Planning. Se houve transferências, use a última versão resultante da reunião formal mais recente.
