Workbook
Name ConfirmacoesDoR: 'Listas de apoio'!$I$5:$I$7
Name DecisoesRefinement: 'Listas de apoio'!$M$5:$M$7
Name EstadosTarefa: 'Listas de apoio'!$K$5:$K$10
Name Milestones: 'Listas de apoio'!$E$5:$E$8
Name Orcamentos: 'Listas de apoio'!$G$5:$G$12
Name Prioridades: 'Listas de apoio'!$C$5:$C$9
Name TiposTarefa: 'Listas de apoio'!$A$5:$A$18

Sheet Backlog de Projeto
A1: BACKLOG DE PROJETO
A2: IDENTIFICAÇÃO E PLANEAMENTO | J2: ORÇAMENTO E REPARTIÇÃO | N2: CRITÉRIOS, QUALIDADE E DESTINO | V2: CONTROLO E DECISÃO
A3: Issue | B3: Tarefa | C3: Descrição | D3: Objetivo | E3: Tipo | F3: Resultado esperado | G3: Prioridade | H3: Milestone de Entrega prevista | I3: Sprint previsional | J3: Orçamento da tarefa | K3: Pontos do Executor | L3: Pontos do Revisor | M3: Pontos do Auditor | N3: Critérios de aceitação | O3: Evidências do Executor | P3: Verificações do Revisor | Q3: Checklist do Auditor | R3: Dependências | S3: Definition of Done aplicável | T3: Normas, modelos e referências | U3: Pasta de destino | V3: Definition of Ready confirmada | W3: Estado | X3: Decisão do Backlog Refinement | Y3: Data da decisão | Z3: Ata da decisão | AA3: Histórico e observações
A4: I001 | B4: Elaborar Proposta de Sistema | C4: Preparar a Proposta de Sistema do projeto Gestão de Clínica Veterinária, identificando problema, utilizadores, atores e funcionalidades principais. | D4: Definir formalmente o sistema a desenvolver e estabelecer a base para a Declaração de Âmbito e restantes artefactos técnicos. | E4: Documentação | F4: m1-proposta-sistema-v03.pdf | G4: 1 — Crítica | H4: m1 | I4: S01 | J4: 50 | K4: =IF(ISNUMBER(J4),J4*60%,IF(J4="","Por preencher",J4)) -> 30 | L4: =IF(ISNUMBER(J4),J4*30%,IF(J4="","Por preencher",J4)) -> 15 | M4: =IF(ISNUMBER(J4),J4*10%,IF(J4="","Por preencher",J4)) -> 5 | N4: Documento segue o template oficial; identifica sistema, atores e funcionalidades F001 e seguintes; inclui declaração de originalidade; conteúdo coerente e pronto para homologação. | O4: m1-proposta-sistema-v03.pdf; versões de trabalho; histórico de alterações e evidência de submissão para homologação. | P4: Verificar utilização do template, completude, coerência das funcionalidades, originalidade, nomenclatura, versão e consistência com o tema aprovado. | Q4: Confirmar que a revisão foi realizada, que a versão final corresponde à evidência, que o ficheiro está na pasta correta e que não existem campos obrigatórios em falta. | R4: Tema do projeto discutido com o docente. | S4: DoD G08 v01: resultado produzido e acessível; critérios de aceitação cumpridos; revisão e auditoria concluídas; versão final aprovada, corretamente nomeada e arquivada na pasta prevista. | T4: Regulamento de Funcionamento da UC v19; template oficial da Proposta de Sistema. | U4: /projeto/04-artefactos-tecnicos/04.01-proposta-de-sistema-e-declaracao-de-ambito | V4: Sim | W4: Done | X4: Aprovada como Ready | Y4: 46283 | Z4: /projeto/01-artefactos-de-gestao/01.03-reunioes-de-grupo/m1-20260918-backlog-refinement-ata-v01.pdf | AA4: 2026-09-30 — Regularização documental: esta linha reconstitui trabalho efetivamente realizado durante a M1 com base nos artefactos existentes. O registo foi preparado posteriormente para completar a rastreabilidade do processo e não altera o conteúdo técnico entregue. 2026-10-20 — A versão m1 v03 mantém-se histórica; a evolução homologada v04 é registada na rebaseline M3. 2026-10-27 — Retificação da entrada de 2026-10-20 (proposta para o Backlog Refinement do Sprint 05): as versões v04 da Proposta de Sistema e da Declaração de Âmbito ficaram sem efeito. As versões homologadas pelo docente em 2026-10-21 são a Proposta de Sistema v05 (m3-proposta-sistema-v05, reposição integral da v03, sem alteração ao produto) e a Declaração de Âmbito v05 (m3-declaracao-ambito-v05, transição de F005 e F007 para o não-âmbito), com a Checklist de Controlo de Artefactos v07 (evidência: 04.02-homologacao-ps-da-cca/m3-resposta-email-homologacao-ps-da-cca-v03.pdf). O trabalho correspondente é registado em I150.
A5: I002 | B5: Elaborar Declaração de Âmbito | C5: Preparar a Declaração de Âmbito mantendo as funcionalidades da Proposta de Sistema e definindo o trabalho previsto no backend, frontend web e frontend mobile, exclusões e limites. | D5: Delimitar de forma verificável o âmbito do projeto e impedir divergências sobre o que deverá ser implementado nas milestones seguintes. | E5: Documentação | F5: m1-declaracao-ambito-v03.pdf | G5: 1 — Crítica | H5: m1 | I5: S01 | J5: 50 | K5: =IF(ISNUMBER(J5),J5*60%,IF(J5="","Por preencher",J5)) -> 30 | L5: =IF(ISNUMBER(J5),J5*30%,IF(J5="","Por preencher",J5)) -> 15 | M5: =IF(ISNUMBER(J5),J5*10%,IF(J5="","Por preencher",J5)) -> 5 | N5: Mantém todas as funcionalidades da PS pela mesma ordem; identifica backend, web e mobile; explicita elementos fora do âmbito e respetivas justificações; é coerente com a PS. | O5: m1-declaracao-ambito-v03.pdf; versões de trabalho; comparação com a PS; evidência de submissão para homologação. | P5: Comparar funcionalidade a funcionalidade com a PS; verificar limites, exclusões, coerência entre componentes, nomenclatura e completude. | Q5: Confirmar cobertura da revisão, correspondência PS↔DA, versão final, pasta de destino e inexistência de alterações não revistas. | R5: I001 — Proposta de Sistema. | S5: DoD G08 v01: resultado produzido e acessível; critérios de aceitação cumpridos; revisão e auditoria concluídas; versão final aprovada, corretamente nomeada e arquivada na pasta prevista. | T5: Regulamento de Funcionamento da UC v19; template oficial da Declaração de Âmbito; Proposta de Sistema. | U5: /projeto/04-artefactos-tecnicos/04.01-proposta-de-sistema-e-declaracao-de-ambito | V5: Sim | W5: Done | X5: Aprovada como Ready | Y5: 46283 | Z5: /projeto/01-artefactos-de-gestao/01.03-reunioes-de-grupo/m1-20260918-backlog-refinement-ata-v01.pdf | AA5: 2026-09-30 — Regularização documental: esta linha reconstitui trabalho efetivamente realizado durante a M1 com base nos artefactos existentes. O registo foi preparado posteriormente para completar a rastreabilidade do processo e não altera o conteúdo técnico entregue. 2026-10-20 — A versão m1 v03 mantém-se histórica; a evolução homologada v04 é registada na rebaseline M3. 2026-10-27 — Retificação da entrada de 2026-10-20 (proposta para o Backlog Refinement do Sprint 05): as versões v04 da Proposta de Sistema e da Declaração de Âmbito ficaram sem efeito. As versões homologadas pelo docente em 2026-10-21 são a Proposta de Sistema v05 (m3-proposta-sistema-v05, reposição integral da v03, sem alteração ao produto) e a Declaração de Âmbito v05 (m3-declaracao-ambito-v05, transição de F005 e F007 para o não-âmbito), com a Checklist de Controlo de Artefactos v07 (evidência: 04.02-homologacao-ps-da-cca/m3-resposta-email-homologacao-ps-da-cca-v03.pdf). O trabalho correspondente é registado em I150.
A6: I003 | B6: Preparar Checklist de Controlo de Artefactos (CCA) | C6: Preencher e manter a CCA cumulativa com os compromissos técnicos e de qualidade do produto assumidos pelo grupo, respetivas milestones, justificações, pastas e estado. | D6: Formalizar e controlar os artefactos que o grupo se compromete a entregar ao longo do projeto. | E6: Qualidade de processo | F6: m1-checklist-controlo-artefactos-v03.xlsx e m1-checklist-controlo-artefactos-v03.pdf | G6: 1 — Crítica | H6: m1 | I6: S01 | J6: 30 | K6: =IF(ISNUMBER(J6),J6*60%,IF(J6="","Por preencher",J6)) -> 18 | L6: =IF(ISNUMBER(J6),J6*30%,IF(J6="","Por preencher",J6)) -> 9 | M6: =IF(ISNUMBER(J6),J6*10%,IF(J6="","Por preencher",J6)) -> 3 | N6: CCA contém os compromissos aprovados; códigos, milestones, justificações e pastas são coerentes; versão editável e PDF congelado correspondem entre si. | O6: m1-checklist-controlo-artefactos-v03.xlsx; m1-checklist-controlo-artefactos-v03.pdf; histórico de alterações. | P6: Conferir códigos, artefactos, milestones, justificações, pastas e estados; comparar integralmente XLSX e PDF. | Q6: Confirmar revisão completa, coerência XLSX↔PDF, versão correta, assinatura aplicável e armazenamento na pasta regulamentar. | R6: I001; I002; decisões do grupo sobre compromissos adicionais. | S6: DoD G08 v01: resultado produzido e acessível; critérios de aceitação cumpridos; revisão e auditoria concluídas; versão final aprovada, corretamente nomeada e arquivada na pasta prevista. | T6: Regulamento de Funcionamento da UC v19; template oficial da CCA; PS e DA. | U6: /projeto/02-artefactos-de-qualidade-de-processo/02.03-checklist-de-controlo-de-artefactos | V6: Sim | W6: Done | X6: Aprovada como Ready | Y6: 46283 | Z6: /projeto/01-artefactos-de-gestao/01.03-reunioes-de-grupo/m1-20260918-backlog-refinement-ata-v01.pdf | AA6: 2026-09-30 — Regularização documental: esta linha reconstitui trabalho efetivamente realizado durante a M1 com base nos artefactos existentes. O registo foi preparado posteriormente para completar a rastreabilidade do processo e não altera o conteúdo técnico entregue. 2026-10-20 — A CCA histórica mantém-se; a atualização cumulativa da M3 é planeada separadamente.
A7: I004 | B7: Obter e arquivar homologação da PS, DA e CCA | C7: Submeter as versões identificadas da PS, DA e CCA ao docente, obter a homologação expressa por e-mail e preservar a evidência em PDF. | D7: Garantir a validação formal do volume de trabalho e conservar a evidência obrigatória da homologação. | E7: Administração ou logística | F7: m1-resposta-email-homologacao-ps-da-cca-v04.pdf | G7: 1 — Crítica | H7: m1 | I7: S01 | J7: 10 | K7: =IF(ISNUMBER(J7),J7*60%,IF(J7="","Por preencher",J7)) -> 6 | L7: =IF(ISNUMBER(J7),J7*30%,IF(J7="","Por preencher",J7)) -> 3 | M7: =IF(ISNUMBER(J7),J7*10%,IF(J7="","Por preencher",J7)) -> 1 | N7: Pedido identifica inequivocamente as versões de PS, DA e CCA; todos os elementos estão em CC; existe resposta expressa de homologação; e-mail é preservado em PDF. | O7: E-mail enviado com versões identificadas; resposta de homologação; m1-resposta-email-homologacao-ps-da-cca-v04.pdf | P7: Confirmar versões referidas no pedido e na resposta, destinatários/CC, existência de homologação expressa e correspondência com os ficheiros finais. | Q7: Confirmar autenticidade e legibilidade da evidência, correspondência das versões e arquivo no caminho regulamentar. | R7: I001; I002; I003. | S7: DoD G08 v01: resultado produzido e acessível; critérios de aceitação cumpridos; revisão e auditoria concluídas; versão final aprovada, corretamente nomeada e arquivada na pasta prevista. | T7: Regulamento de Funcionamento da UC v19 — homologação obrigatória da PS, DA e CCA. | U7: /projeto/04-artefactos-tecnicos/04.02-homologacao-ps-da-cca | V7: Sim | W7: Done | X7: Aprovada como Ready | Y7: 46283 | Z7: /projeto/01-artefactos-de-gestao/01.03-reunioes-de-grupo/m1-20260918-backlog-refinement-ata-v01.pdf | AA7: 2026-09-30 — Regularização documental: esta linha reconstitui trabalho efetivamente realizado durante a M1 com base nos artefactos existentes. O registo foi preparado posteriormente para completar a rastreabilidade do processo e não altera o conteúdo técnico entregue.
A8: I012 | B8: Especificação de Requisitos | C8: Elaborar a especificação dos requisitos funcionais e não funcionais do sistema de Gestão de Clínica Veterinária, derivados da Proposta de Sistema e da Declaração de Âmbito homologadas, identificando cada requisito de forma única e verificável. | D8: Definir formalmente o comportamento, regras, restrições e características de qualidade do sistema, constituindo a base para os casos de uso, arquitetura, modelos, implementação e testes. | E8: Requisitos | F8: m2-especificacao-requisitos-v01.md | G8: 1 — Crítica | H8: m2 | I8: S02 | J8: 50 | K8: =IF(ISNUMBER(J8),J8*60%,IF(J8="","Por preencher",J8)) -> 30 | L8: =IF(ISNUMBER(J8),J8*30%,IF(J8="","Por preencher",J8)) -> 15 | M8: =IF(ISNUMBER(J8),J8*10%,IF(J8="","Por preencher",J8)) -> 5 | N8: Todos os requisitos abrangidos pela PS e DA estão especificados; cada requisito possui identificador único, título e redação verificável; requisitos funcionais e não funcionais estão distinguidos; não existem requisitos contraditórios com o âmbito homologado; os requisitos cumprem os critérios de qualidade definidos pelo G08 e permitem rastreabilidade posterior na RTM. | O8: m2-especificacao-requisitos-v01.md; histórico de versões/commits; identificação das fontes PS e DA; versão final arquivada na pasta prevista. | P8: Comparar os requisitos com a PS e DA; verificar cobertura das funcionalidades e restrições; confirmar IDs únicos, clareza, completude, consistência, singularidade, verificabilidade e ausência de requisitos fora do âmbito. | Q8: Confirmar independência dos papéis; verificar que a revisão cobre os critérios definidos; confirmar que eventuais defeitos foram tratados; verificar versão final, nomenclatura, rastreabilidade e localização do ficheiro. | R8: I001 — Proposta de Sistema; I002 — Declaração de Âmbito; I009 — Critérios de Qualidade dos Requisitos. | S8: DoD G08 v01: resultado acessível; critérios de aceitação cumpridos; evidências produzidas; revisão e auditoria concluídas; versão final aceite e confirmada; aprovação posterior no Sprint Review. | T8: Regulamento de Funcionamento da UC v19; Proposta de Sistema v03; Declaração de Âmbito v03; Critérios de Qualidade dos Requisitos v01; Definition of Ready v01; Definition of Done v01. | U8: /projeto/04-artefactos-tecnicos/04.03-requisitos-e-rtm | V8: Sim | W8: Done | X8: Aprovada como Ready | Y8: 46296 | Z8: /projeto/01-artefactos-de-gestao/01.03-reunioes-de-grupo/m2-s02-backlog-refinement-ata-v01.pdf | AA8: 2026-10-06 — Tarefa acrescentada ao Backlog durante a preparação da M2; aguarda análise em Backlog Refinement. 2026-10-19 18:56 — Atualização do registo: aprovada como Ready no Backlog Refinement de 2026-10-01 (ata m2-s02-backlog-refinement-ata-v01, secção 4) e passou a Done no Sprint Review de 2026-10-08 (ata m2-s02-20261008-sprint-review-ata-v01, secção 6.6). A entrada de 2026-10-06 sobre aguardar análise fica ultrapassada. 2026-10-20 — A v01 mantém-se histórica; a Especificação de Requisitos v02 é registada na rebaseline M3. 2026-10-27 — Clarificação (proposta para o Backlog Refinement do Sprint 05): as referências à Proposta de Sistema v03 e à Declaração de Âmbito v03 dizem respeito à v01 histórica e mantêm-se. A Especificação de Requisitos v02 da rebaseline M3 tem como referência a Proposta de Sistema v05 e a Declaração de Âmbito v05, homologadas em 2026-10-21. 2026-10-27 — Correção da referência à ata (proposta para o Backlog Refinement do Sprint 05): o ficheiro arquivado chama-se m2-s02-backlog-refinement-ata-v01.pdf; o nome anterior não correspondia a nenhum ficheiro.
A9: I013 | B9: Checklist de Aprovação dos Requisitos | C9: Preencher a Checklist de Aprovação dos Requisitos utilizando o template oficial, avaliando individualmente todos os requisitos funcionais e não funcionais especificados face aos critérios de qualidade definidos pelo Grupo G08. | D9: Demonstrar de forma objetiva e rastreável que cada requisito foi verificado e aprovado segundo os critérios de qualidade definidos pelo grupo. | E9: Qualidade de produto | F9: m2-checklist-aprovacao-requisitos-v01.xlsx | G9: 1 — Crítica | H9: m2 | I9: S02 | J9: 30 | K9: =IF(ISNUMBER(J9),J9*60%,IF(J9="","Por preencher",J9)) -> 18 | L9: =IF(ISNUMBER(J9),J9*30%,IF(J9="","Por preencher",J9)) -> 9 | M9: =IF(ISNUMBER(J9),J9*10%,IF(J9="","Por preencher",J9)) -> 3 | N9: É utilizado o template oficial; existe uma linha por cada requisito da Especificação de Requisitos; cada linha contém o ID e o título correspondentes; existe uma coluna independente por cada critério de qualidade definido pelo grupo; cada critério contém exclusivamente "Cumpre", "Não cumpre" ou "Não aplicável", em caso de não cumprimento ou não aplicável deve indicar-se a causa; o Resultado Final contém exclusivamente "Aprovado" ou "Não aprovado"; todos os requisitos considerados aprovados possuem Resultado Final "Aprovado". | O9: m2-checklist-aprovacao-requisitos-v01.xlsx preenchida; Especificação de Requisitos utilizada como fonte; m1-criterios-qualidade-requisitos-v01.md; histórico de alterações da checklist. | P9: Confirmar correspondência entre todas as linhas da checklist e os requisitos da Especificação de Requisitos; verificar aplicação dos 11 critérios de qualidade; confirmar que "Não cumpre" e "Não aplicável" possuem justificação objetiva; verificar coerência do Resultado Final de cada requisito. | Q9: Confirmar que todos os requisitos foram abrangidos; verificar independência e completude da revisão; confirmar utilização correta do template e dos valores permitidos; verificar correspondência entre requisito, critérios e Resultado Final; confirmar versão, nomenclatura e pasta de destino. | R9: I009 — Critérios de Qualidade dos Requisitos; I012 — Especificação de Requisitos. | S9: DoD G08 v01: resultado produzido e acessível; critérios de aceitação cumpridos; evidências arquivadas; revisão e auditoria concluídas; versão final aceite e confirmada; aprovação no Sprint Review. | T9: Regulamento de Funcionamento da UC v19; m1-criterios-qualidade-requisitos-v01.md; m2-especificacao-requisitos-v01.md; template oficial da Checklist de Aprovação dos Requisitos; Plano de Qualidade do Processo G08; Definition of Done G08 v01. | U9: /projeto/04-artefactos-tecnicos/04.03-requisitos-e-rtm | V9: Sim | W9: Done | X9: Aprovada como Ready | Y9: 46296 | Z9: /projeto/01-artefactos-de-gestao/01.03-reunioes-de-grupo/m2-s02-backlog-refinement-ata-v01.pdf | AA9: 2026-10-06 — Tarefa acrescentada ao Backlog durante a preparação da M2; aguarda análise em Backlog Refinement. 2026-10-19 18:56 — Atualização do registo: aprovada como Ready no Backlog Refinement de 2026-10-01 (ata m2-s02-backlog-refinement-ata-v01, secção 4) e passou a Done no Sprint Review de 2026-10-08 (ata m2-s02-20261008-sprint-review-ata-v01, secção 6.6). A entrada de 2026-10-06 sobre aguardar análise fica ultrapassada. 2026-10-20 — A v01 mantém-se histórica; a Checklist de Aprovação v02 é registada na rebaseline M3. 2026-10-27 — Correção da referência à ata (proposta para o Backlog Refinement do Sprint 05): o ficheiro arquivado chama-se m2-s02-backlog-refinement-ata-v01.pdf; o nome anterior não correspondia a nenhum ficheiro.
A10: I025 | B10: Desenvolver Backend | C10: Contentor do desenvolvimento do backend/API REST para as funcionalidades ativas F001, F002, F003, F004 e F006. O backend deve evoluir da base técnica criada em S03 para a stack corrente do grupo — C# 14, .NET 10, ASP.NET Core 10 e Entity Framework Core 10 — mantendo a arquitetura em camadas e excluindo totalmente gestão financeira e internamento/hospitalização. | D10: Disponibilizar um backend funcional, documentado e coerente com a baseline v02 e com a stack técnica corrente, cobrindo apenas F001, F002, F003, F004 e F006 e servindo de base aos frontends da M4. | E10: Desenvolvimento | F10: Backend funcional e documentado para o âmbito v02 da M3, integrado no repositório e coerente com Requisitos v02, Casos de Uso v02, Modelo de Dados v02, Arquitetura v02 e API v02. | G10: 1 — Crítica | H10: m3 | I10: Não definido | J10: Não aprovado | K10: =IF(ISNUMBER(J10),J10*60%,IF(J10="","Por preencher",J10)) -> Não aprovado | L10: =IF(ISNUMBER(J10),J10*30%,IF(J10="","Por preencher",J10)) -> Não aprovado | M10: =IF(ISNUMBER(J10),J10*10%,IF(J10="","Por preencher",J10)) -> Não aprovado | N10: Contentor: sem critérios próprios. Fica concluído quando todas as tarefas filhas indicadas na descrição estiverem em Done e o resultado agregado descrito em «Resultado esperado» estiver completo e coerente. | O10: Não aplicável — as evidências são produzidas nas tarefas filhas. | P10: Não aplicável — a revisão é feita nas tarefas filhas. | Q10: Não aplicável — a auditoria é feita nas tarefas filhas. Confirmar apenas, no fecho, que nenhuma filha ficou por concluir. | R10: I012, I015, I016, I019, I018, I020 e I026. Articulação com testes, pipeline e documentação da M3. | S10: Contentor, sem DoD própria: fica Done quando todas as tarefas filhas estiverem Done. Cada filha cumpre a DoD G08 v01 (resultado produzido e acessível; critérios de aceitação cumpridos; revisão e auditoria concluídas; versão final aprovada, corretamente nomeada e arquivada na pasta prevista). O contentor não é executado, revisto nem auditado como tarefa autónoma. | T10: Regulamento de Funcionamento da UC v19, secção 19 (04.12-backend/m3-v01); Especificação de Requisitos v02 (I012); Casos de Uso v02 (I015); Modelo de Dados v02 (I016); Arquitetura v02 (I019); Documentação de API v02 (I018); Modelo de Classes Backend v02 (I020). | U10: /projeto/04-artefactos-tecnicos/04.12-backend/m3-v01 | V10: Não | W10: Pendente | X10: Não analisada | AA10: 2026-10-14 23:05 — Proposta de refinamento preparada como versão de trabalho. Esta Issue original passa a contentor (épico) e deixa de ser executada diretamente: o trabalho foi dividido nas tarefas I058, I059, I063, I064, I065, I066, I067, I068, I069, I070, I071, I072, I073, I074, I075, I076, I077, I078, I079, I080, I081, I082, I083, I084, I085. Não tem pontos próprios, para que os pontos não sejam contados em duplicado. Ainda não analisada em Backlog Refinement; a divisão e as decisões estão por ratificar. 2026-10-19 18:56 — Removidas a data e a ata de decisão: esta Issue-contentor não recebeu decisão de Ready no Backlog Refinement de 2026-10-12, por não ser executada diretamente; a v01 citava um nome de ata inexistente (m3-20261012…). A divisão desta Issue em tarefas executáveis foi aprovada no Backlog Refinement de 2026-10-12 (ata m3-s03-20261012-backlog-refinement-ata-v01, secção 6, deliberação 2).
A11: I026 | B11: Preparar migrations, dados iniciais e reposição da base de dados | C11: Contentor da preparação da persistência e dos artefactos de base de dados da baseline v02. As EF Core 10 Migrations constituem a fonte versionada de implementação do esquema SQL Server 2025; dados iniciais, reposição por ambiente e eventuais scripts SQL derivados devem ser coerentes com essas migrations e não criar uma segunda fonte de verdade. | D11: Garantir que qualquer elemento consegue criar, migrar, popular e repor uma instância isolada da base de dados a partir das EF Core Migrations, sem manter um esquema SQL concorrente. | E11: Desenvolvimento | F11: Persistência Entity Framework Core 10.0, migrations, dados fictícios de demonstração e procedimento de reposição coerentes com o Modelo de Dados v02, com scripts SQL derivados das migrations quando exigidos para entrega. | G11: 1 — Crítica | H11: m3 | I11: Não definido | J11: Não aprovado | K11: =IF(ISNUMBER(J11),J11*60%,IF(J11="","Por preencher",J11)) -> Não aprovado | L11: =IF(ISNUMBER(J11),J11*30%,IF(J11="","Por preencher",J11)) -> Não aprovado | M11: =IF(ISNUMBER(J11),J11*10%,IF(J11="","Por preencher",J11)) -> Não aprovado | N11: Contentor: sem critérios próprios. Fica concluído quando todas as tarefas filhas indicadas na descrição estiverem em Done e o resultado agregado descrito em «Resultado esperado» estiver completo e coerente. | O11: Não aplicável — as evidências são produzidas nas tarefas filhas. | P11: Não aplicável — a revisão é feita nas tarefas filhas. | Q11: Não aplicável — a auditoria é feita nas tarefas filhas. Confirmar apenas, no fecho, que nenhuma filha ficou por concluir. | R11: I016 — Modelo de Dados v02; I019 — Documentação da Arquitetura v02; I020 — Modelo de Classes Backend v02. | S11: Contentor, sem DoD própria: fica Done quando todas as tarefas filhas estiverem Done. Cada filha cumpre a DoD G08 v01 (resultado produzido e acessível; critérios de aceitação cumpridos; revisão e auditoria concluídas; versão final aprovada, corretamente nomeada e arquivada na pasta prevista). O contentor não é executado, revisto nem auditado como tarefa autónoma. | T11: Regulamento de Funcionamento da UC v19, secção 19 (04.13) e secção 20.2; Modelo de Dados v02 (I016); Arquitetura v02 (I019); Modelo de Classes Backend v02 (I020); documentação oficial do Entity Framework Core 10. | U11: /projeto/04-artefactos-tecnicos/04.13-scripts-de-base-de-dados/m3-v01 | V11: Não | W11: Pendente | X11: Não analisada | AA11: 2026-10-14 23:05 — Proposta de refinamento preparada como versão de trabalho. Esta Issue original passa a contentor (épico) e deixa de ser executada diretamente: o trabalho foi dividido nas tarefas I060, I061, I062. Não tem pontos próprios, para que os pontos não sejam contados em duplicado. Ainda não analisada em Backlog Refinement; a divisão e as decisões estão por ratificar. 2026-10-19 18:56 — Removidas a data e a ata de decisão: esta Issue-contentor não recebeu decisão de Ready no Backlog Refinement de 2026-10-12, por não ser executada diretamente; a v01 citava um nome de ata inexistente (m3-20261012…). A divisão desta Issue em tarefas executáveis foi aprovada no Backlog Refinement de 2026-10-12 (ata m3-s03-20261012-backlog-refinement-ata-v01, secção 6, deliberação 2).
A12: I031 | B12: Implementar e Executar Testes de Integração do Backend | C12: Contentor da infraestrutura, implementação e execução dos testes de integração do backend para as áreas ativas F001, F002, F003, F004 e F006. Deve validar integração real entre API, autorização, persistência SQL Server, migrations, propriedade dos dados e regras de concorrência aplicáveis, produzindo no final evidência formal dos resultados. | D12: Comprovar automaticamente que os componentes do backend funcionam em conjunto, incluindo persistência, autorização por perfil/propriedade e regras de concorrência aplicáveis. | E12: Teste | F12: Código dos testes de integração no projeto de testes do backend (04.12-backend/m3-v01) e m3-resultados-testes-integracao-backend-v01.pdf. | G12: 1 — Crítica | H12: m3 | I12: Não definido | J12: Não aprovado | K12: =IF(ISNUMBER(J12),J12*60%,IF(J12="","Por preencher",J12)) -> Não aprovado | L12: =IF(ISNUMBER(J12),J12*30%,IF(J12="","Por preencher",J12)) -> Não aprovado | M12: =IF(ISNUMBER(J12),J12*10%,IF(J12="","Por preencher",J12)) -> Não aprovado | N12: Contentor: sem critérios próprios. Fica concluído quando todas as tarefas filhas indicadas na descrição estiverem em Done e o resultado agregado descrito em «Resultado esperado» estiver completo e coerente. | O12: Não aplicável — as evidências são produzidas nas tarefas filhas. | P12: Não aplicável — a revisão é feita nas tarefas filhas. | Q12: Não aplicável — a auditoria é feita nas tarefas filhas. Confirmar apenas, no fecho, que nenhuma filha ficou por concluir. | R12: I025, I026 e I030. | S12: Contentor, sem DoD própria: fica Done quando todas as tarefas filhas estiverem Done. Cada filha cumpre a DoD G08 v01 (resultado produzido e acessível; critérios de aceitação cumpridos; revisão e auditoria concluídas; versão final aprovada, corretamente nomeada e arquivada na pasta prevista). O contentor não é executado, revisto nem auditado como tarefa autónoma. | T12: Regulamento de Funcionamento da UC v19, secção 19 (03.01.03-testes-de-integracao); Especificação de Testes de Integração (I030); Documentação de API v02 (I018). | U12: /projeto/03-artefactos-de-qualidade-de-produto/03.01-backend/03.01.03-testes-de-integracao | V12: Não | W12: Pendente | X12: Não analisada | AA12: 2026-10-14 23:05 — Proposta de refinamento preparada como versão de trabalho. Esta Issue original passa a contentor (épico) e deixa de ser executada diretamente: o trabalho foi dividido nas tarefas I091, I092, I093, I094, I095, I096, I097. Não tem pontos próprios, para que os pontos não sejam contados em duplicado. Ainda não analisada em Backlog Refinement; a divisão e as decisões estão por ratificar. 2026-10-19 18:56 — Removidas a data e a ata de decisão: esta Issue-contentor não recebeu decisão de Ready no Backlog Refinement de 2026-10-12, por não ser executada diretamente; a v01 citava um nome de ata inexistente (m3-20261012…). A divisão desta Issue em tarefas executáveis foi aprovada no Backlog Refinement de 2026-10-12 (ata m3-s03-20261012-backlog-refinement-ata-v01, secção 6, deliberação 2).
A13: I035 | B13: Implementar a pipeline CI/CD do backend | C13: Contentor da pipeline CI/CD do backend em GitHub Actions, executada em runner ubuntu-latest. Deve incluir restore, compilação sem erros, formatação, testes unitários e de integração, cobertura mínima de 70%, análise estática, execução da Collection Postman quando integrada e restantes quality gates aplicáveis, bloqueando o Pull Request quando alguma verificação obrigatória falha. | D13: Garantir que cada alteração ao backend é verificada automaticamente e que nenhuma integração avança quando falha um quality gate obrigatório. | E13: DevOps / CI/CD | F13: Workflows de GitHub Actions da M3 versionados no repositório e arquivados em 04.16-ci-cd/m3-v01, com pipeline do backend funcional e quality gates aplicáveis. | G13: 1 — Crítica | H13: m3 | I13: Não definido | J13: Não aprovado | K13: =IF(ISNUMBER(J13),J13*60%,IF(J13="","Por preencher",J13)) -> Não aprovado | L13: =IF(ISNUMBER(J13),J13*30%,IF(J13="","Por preencher",J13)) -> Não aprovado | M13: =IF(ISNUMBER(J13),J13*10%,IF(J13="","Por preencher",J13)) -> Não aprovado | N13: Contentor: sem critérios próprios. Fica concluído quando todas as tarefas filhas indicadas na descrição estiverem em Done e o resultado agregado descrito em «Resultado esperado» estiver completo e coerente. | O13: Não aplicável — as evidências são produzidas nas tarefas filhas. | P13: Não aplicável — a revisão é feita nas tarefas filhas. | Q13: Não aplicável — a auditoria é feita nas tarefas filhas. Confirmar apenas, no fecho, que nenhuma filha ficou por concluir. | R13: I019 e estrutura do projeto (I025), com integração progressiva dos testes (I029 e I031) e da análise estática (I034). | S13: Contentor, sem DoD própria: fica Done quando todas as tarefas filhas estiverem Done. Cada filha cumpre a DoD G08 v01 (resultado produzido e acessível; critérios de aceitação cumpridos; revisão e auditoria concluídas; versão final aprovada, corretamente nomeada e arquivada na pasta prevista). O contentor não é executado, revisto nem auditado como tarefa autónoma. | T13: Regulamento de Funcionamento da UC v19, secção 19 (04.16-ci-cd) e secção 17; Regulamento Interno do Grupo G08 v02 (proposta); documentação oficial do GitHub Actions. | U13: /projeto/04-artefactos-tecnicos/04.16-ci-cd/m3-v01 | V13: Não | W13: Pendente | X13: Não analisada | AA13: 2026-10-14 23:05 — Proposta de refinamento preparada como versão de trabalho. Esta Issue original passa a contentor (épico) e deixa de ser executada diretamente: o trabalho foi dividido nas tarefas I102, I103, I104. Não tem pontos próprios, para que os pontos não sejam contados em duplicado. Ainda não analisada em Backlog Refinement; a divisão e as decisões estão por ratificar. 2026-10-19 18:56 — Removidas a data e a ata de decisão: esta Issue-contentor não recebeu decisão de Ready no Backlog Refinement de 2026-10-12, por não ser executada diretamente; a v01 citava um nome de ata inexistente (m3-20261012…). A divisão desta Issue em tarefas executáveis foi aprovada no Backlog Refinement de 2026-10-12 (ata m3-s03-20261012-backlog-refinement-ata-v01, secção 6, deliberação 2).
A14: I040 | B14: Desenvolver Frontend Web | C14: Contentor do desenvolvimento do Frontend Web para Administrador, Rececionista, Veterinário e Auxiliar Veterinário, usando TypeScript 6.0, React 19.3, Node.js 24 LTS, Vite 8.3 e npm 12. Abrange apenas F001, F002, F003, F004 e F006 e consome a API; gestão financeira e internamento ficam excluídos. | D14: Disponibilizar o Frontend Web funcional e integrado com o backend para todo o âmbito Web ativo da baseline v02. | E14: Desenvolvimento | F14: Código-fonte do frontend web em React 19.3/TypeScript 6.0, integrado com o backend e executável, arquivado em /projeto/04-artefactos-tecnicos/04.14-frontend-web/m4-v01. | G14: 1 — Crítica | H14: m4 | I14: Não definido | J14: Não aprovado | K14: =IF(ISNUMBER(J14),J14*60%,IF(J14="","Por preencher",J14)) -> Não aprovado | L14: =IF(ISNUMBER(J14),J14*30%,IF(J14="","Por preencher",J14)) -> Não aprovado | M14: =IF(ISNUMBER(J14),J14*10%,IF(J14="","Por preencher",J14)) -> Não aprovado | N14: Contentor: sem critérios próprios. Fica concluído quando todas as tarefas filhas indicadas na descrição estiverem em Done e o resultado agregado descrito em «Resultado esperado» estiver completo e coerente. | O14: Não aplicável — as evidências são produzidas nas tarefas filhas. | P14: Não aplicável — a revisão é feita nas tarefas filhas. | Q14: Não aplicável — a auditoria é feita nas tarefas filhas. Confirmar apenas, no fecho, que nenhuma filha ficou por concluir. | R14: I012, I015, I018, I017, I021 e backend M3 (I025). | S14: Contentor, sem DoD própria: fica Done quando todas as tarefas filhas estiverem Done. Cada filha cumpre a DoD G08 v01 (resultado produzido e acessível; critérios de aceitação cumpridos; revisão e auditoria concluídas; versão final aprovada, corretamente nomeada e arquivada na pasta prevista). O contentor não é executado, revisto nem auditado como tarefa autónoma. | T14: Regulamento de Funcionamento da UC v19, secção 19 (04.14-frontend-web/m4-v01); Regulamento Interno do Grupo G08 v02 (proposta); Protótipo v02 (I017); Modelo de Classes Frontend Web v02 (I021); Documentação de API v02 (I018); documentação oficial de React 19.3, TypeScript 6, Node.js 24 LTS e Vite 8.3. | U14: /projeto/04-artefactos-tecnicos/04.14-frontend-web/m4-v01 | V14: Não | W14: Pendente | X14: Não analisada | AA14: 2026-10-14 23:05 — Proposta de refinamento preparada como versão de trabalho. Esta Issue original passa a contentor (épico) e deixa de ser executada diretamente: o trabalho foi dividido nas tarefas I107, I108, I109, I110, I111, I112, I113, I114, I115, I116, I117, I118, I119. Não tem pontos próprios, para que os pontos não sejam contados em duplicado. Ainda não analisada em Backlog Refinement; a divisão e as decisões estão por ratificar.
A15: I041 | B15: Desenvolver Frontend Mobile | C15: Contentor do desenvolvimento da aplicação Android destinada exclusivamente ao perfil Cliente, usando Kotlin 2.2, Jetpack Compose, Material 3, Android SDK API 37 com minSdk 26, JDK 21, Gradle 9.6 e Android Gradle Plugin 9.4. A aplicação permite autenticação e consulta dos próprios animais, Consultas futuras, histórico administrativo e boletim de vacinação/desparasitação, sem financeiro, registo clínico ou internamento. | D15: Disponibilizar a aplicação Android funcional e integrada com o backend para todo o âmbito Mobile do Cliente previsto na baseline v02. | E15: Desenvolvimento | F15: Código-fonte do frontend mobile Android em Kotlin 2.2/Jetpack Compose, integrado com o backend e executável, arquivado em /projeto/04-artefactos-tecnicos/04.15-frontend-mobile/m4-v01. | G15: 1 — Crítica | H15: m4 | I15: Não definido | J15: Não aprovado | K15: =IF(ISNUMBER(J15),J15*60%,IF(J15="","Por preencher",J15)) -> Não aprovado | L15: =IF(ISNUMBER(J15),J15*30%,IF(J15="","Por preencher",J15)) -> Não aprovado | M15: =IF(ISNUMBER(J15),J15*10%,IF(J15="","Por preencher",J15)) -> Não aprovado | N15: Contentor: sem critérios próprios. Fica concluído quando todas as tarefas filhas indicadas na descrição estiverem em Done e o resultado agregado descrito em «Resultado esperado» estiver completo e coerente. | O15: Não aplicável — as evidências são produzidas nas tarefas filhas. | P15: Não aplicável — a revisão é feita nas tarefas filhas. | Q15: Não aplicável — a auditoria é feita nas tarefas filhas. Confirmar apenas, no fecho, que nenhuma filha ficou por concluir. | R15: I012, I015, I018, I017, I022 e backend M3 (I025). | S15: Contentor, sem DoD própria: fica Done quando todas as tarefas filhas estiverem Done. Cada filha cumpre a DoD G08 v01 (resultado produzido e acessível; critérios de aceitação cumpridos; revisão e auditoria concluídas; versão final aprovada, corretamente nomeada e arquivada na pasta prevista). O contentor não é executado, revisto nem auditado como tarefa autónoma. | T15: Regulamento de Funcionamento da UC v19, secção 19 (04.15-frontend-mobile/m4-v01); Regulamento Interno do Grupo G08 v02 (proposta); Protótipo v02 (I017); Modelo de Classes Frontend Mobile v02 (I022); Documentação de API v02 (I018); documentação oficial de Kotlin 2.2, Jetpack Compose, Material 3, Android API 37, JDK 21 e Gradle/AGP. | U15: /projeto/04-artefactos-tecnicos/04.15-frontend-mobile/m4-v01 | V15: Não | W15: Pendente | X15: Não analisada | AA15: 2026-10-14 23:05 — Proposta de refinamento preparada como versão de trabalho. Esta Issue original passa a contentor (épico) e deixa de ser executada diretamente: o trabalho foi dividido nas tarefas I120, I121, I122, I123, I124. Não tem pontos próprios, para que os pontos não sejam contados em duplicado. Ainda não analisada em Backlog Refinement; a divisão e as decisões estão por ratificar.
A16: I042 | B16: Integrar Frontends com Backend | C16: Contentor da validação integrada dos Frontends Web e Mobile com o backend: configuração de URLs/CORS, autenticação e sessão, tratamento coerente de erros, autorização por perfil/propriedade e execução ponta a ponta dos fluxos ativos. Os defeitos de integração devem ser corrigidos ou registados com rastreabilidade. | D16: Garantir que Web e Mobile funcionam ponta a ponta com o backend e respeitam autenticação, autorização, propriedade e tratamento de erros definidos. | E16: Desenvolvimento | F16: Fluxos web e mobile validados contra o backend, defeitos de integração corrigidos ou registados e evidência de execução. | G16: 1 — Crítica | H16: m4 | I16: Não definido | J16: Não aprovado | K16: =IF(ISNUMBER(J16),J16*60%,IF(J16="","Por preencher",J16)) -> Não aprovado | L16: =IF(ISNUMBER(J16),J16*30%,IF(J16="","Por preencher",J16)) -> Não aprovado | M16: =IF(ISNUMBER(J16),J16*10%,IF(J16="","Por preencher",J16)) -> Não aprovado | N16: Contentor: sem critérios próprios. Fica concluído quando todas as tarefas filhas indicadas na descrição estiverem em Done e o resultado agregado descrito em «Resultado esperado» estiver completo e coerente. | O16: Não aplicável — as evidências são produzidas nas tarefas filhas. | P16: Não aplicável — a revisão é feita nas tarefas filhas. | Q16: Não aplicável — a auditoria é feita nas tarefas filhas. Confirmar apenas, no fecho, que nenhuma filha ficou por concluir. | R16: I040, I041 e backend da M3 (I025). | S16: Contentor, sem DoD própria: fica Done quando todas as tarefas filhas estiverem Done. Cada filha cumpre a DoD G08 v01 (resultado produzido e acessível; critérios de aceitação cumpridos; revisão e auditoria concluídas; versão final aprovada, corretamente nomeada e arquivada na pasta prevista). O contentor não é executado, revisto nem auditado como tarefa autónoma. | T16: Regulamento de Funcionamento da UC v19, secção 19 (04.14 e 04.15); Arquitetura v02 (I019); Documentação de API v02 (I018); bases dos frontends Web (I040) e Mobile (I041). | U16: /projeto/04-artefactos-tecnicos/04.14-frontend-web/m4-v01; /projeto/04-artefactos-tecnicos/04.15-frontend-mobile/m4-v01 | V16: Não | W16: Pendente | X16: Não analisada | AA16: 2026-10-14 23:05 — Proposta de refinamento preparada como versão de trabalho. Esta Issue original passa a contentor (épico) e deixa de ser executada diretamente: o trabalho foi dividido nas tarefas I125, I126, I127. Não tem pontos próprios, para que os pontos não sejam contados em duplicado. Ainda não analisada em Backlog Refinement; a divisão e as decisões estão por ratificar.
A17: I052 | B17: Atualizar Pipeline CI/CD para sistema completo | C17: Contentor da evolução da pipeline para o sistema completo em GitHub Actions, integrando backend, Frontend Web e Frontend Mobile. Deve aplicar os quality gates do Regulamento aos três componentes, produzir os artefactos previstos e bloquear integração/entrega perante qualquer incumprimento obrigatório. | D17: Garantir que backend, Frontend Web e aplicação Android são verificados automaticamente em cada alteração pelos quality gates aplicáveis. | E17: DevOps / CI/CD | F17: Configuração GitHub Actions atualizada para o sistema completo, arquivada em 04.16-ci-cd/m4-v02, e m4-descricao-pipeline-ci-cd-v02.md. | G17: 1 — Crítica | H17: m4 | I17: Não definido | J17: Não aprovado | K17: =IF(ISNUMBER(J17),J17*60%,IF(J17="","Por preencher",J17)) -> Não aprovado | L17: =IF(ISNUMBER(J17),J17*30%,IF(J17="","Por preencher",J17)) -> Não aprovado | M17: =IF(ISNUMBER(J17),J17*10%,IF(J17="","Por preencher",J17)) -> Não aprovado | N17: Contentor: sem critérios próprios. Fica concluído quando todas as tarefas filhas indicadas na descrição estiverem em Done e o resultado agregado descrito em «Resultado esperado» estiver completo e coerente. | O17: Não aplicável — as evidências são produzidas nas tarefas filhas. | P17: Não aplicável — a revisão é feita nas tarefas filhas. | Q17: Não aplicável — a auditoria é feita nas tarefas filhas. Confirmar apenas, no fecho, que nenhuma filha ficou por concluir. | R17: I035, I040, I041, I046 e I050. | S17: Contentor, sem DoD própria: fica Done quando todas as tarefas filhas estiverem Done. Cada filha cumpre a DoD G08 v01 (resultado produzido e acessível; critérios de aceitação cumpridos; revisão e auditoria concluídas; versão final aprovada, corretamente nomeada e arquivada na pasta prevista). O contentor não é executado, revisto nem auditado como tarefa autónoma. | T17: Regulamento de Funcionamento da UC v19, secção 19 (04.16-ci-cd/m4-v02) e secção 17; Regulamento Interno do Grupo G08 v02 (proposta); documentação oficial do GitHub Actions. | U17: /projeto/04-artefactos-tecnicos/04.16-ci-cd/m4-v02 | V17: Não | W17: Pendente | X17: Não analisada | AA17: 2026-10-14 23:05 — Proposta de refinamento preparada como versão de trabalho. Esta Issue original passa a contentor (épico) e deixa de ser executada diretamente: o trabalho foi dividido nas tarefas I142, I143, I144. Não tem pontos próprios, para que os pontos não sejam contados em duplicado. Ainda não analisada em Backlog Refinement; a divisão e as decisões estão por ratificar.
A18: I058 | B18: Criar a solução .NET 8 do backend e a infraestrutura transversal da API | C18: Criar a solução .NET 8 com os projetos Api, Application, Domain e Infrastructure e os projetos de teste xUnit (unitários e de integração), segundo a Documentação da Arquitetura (I019) e o Modelo de Classes do Backend (I020). Configurar injeção de dependências, configuração por ambiente (ficheiro e variáveis de ambiente), Swagger/OpenAPI com esquema Bearer, CORS para o frontend web, registo de logs e um middleware único de tratamento de erros que converte exceções de validação, autenticação, autorização, recurso inexistente, conflito e regra de negócio nos códigos 400, 401, 403, 404, 409 e 422 do contrato. Não inclui endpoints de negócio nem acesso a dados. | D18: Dar à equipa uma base reproduzível e comum, para que as restantes tarefas do backend avancem em paralelo, sem conflitos de estrutura nem respostas de erro inconsistentes. | E18: Desenvolvimento | F18: Solução .NET 8 compilável e executável, com middleware de erros e Swagger a funcionar e README técnico do projeto, no repositório do backend (arquivo final em /projeto/04-artefactos-tecnicos/04.12-backend/m3-v01). | G18: 1 — Crítica | H18: m3 | I18: S03 | J18: 50 | K18: =IF(ISNUMBER(J18),J18*60%,IF(J18="","Por preencher",J18)) -> 30 | L18: =IF(ISNUMBER(J18),J18*30%,IF(J18="","Por preencher",J18)) -> 15 | M18: =IF(ISNUMBER(J18),J18*10%,IF(J18="","Por preencher",J18)) -> 5 | N18: 1. `dotnet build` e `dotnet test` terminam sem erros num clone limpo, com SDK .NET 8; os projetos de teste existem e executam (ainda sem casos de negócio). 2. A estrutura de projetos e dependências cumpre I019/I020: o projeto Domain não referencia nenhum outro projeto e a Api só depende de Application e Infrastructure. 3. A cadeia de ligação, a chave JWT, a validade do token (8 h) e o CORS são lidos de ficheiro por ambiente e de variáveis de ambiente; não há segredos versionados e existe um ficheiro de exemplo sem valores reais. 4. O middleware devolve sempre JSON com o mesmo formato (código, mensagem e detalhe de validação) para 400, 401, 403, 404, 409 e 422, demonstrado com uma exceção de cada tipo. 5. O Swagger/OpenAPI está disponível em ambiente de desenvolvimento com autorização Bearer configurada. 6. Os logs registam pedido, resultado e erros sem escrever palavras-passe nem tokens. 7. O README explica pré-requisitos, como compilar, configurar e arrancar a API localmente. | O18: 1. Merge Request com a solução e o README técnico. 2. Registo da execução de `dotnet build` e `dotnet test` (consola ou log da pipeline). 3. Exemplos de respostas de erro para cada código tratado. 4. Lista das variáveis de configuração necessárias. | P18: 1. Clonar o repositório, compilar e arrancar a API num ambiente limpo, seguindo apenas o README. 2. Verificar as referências entre projetos e confirmar que Domain não depende de Infrastructure. 3. Pesquisar no histórico Git a presença de segredos (cadeias de ligação, chaves). 4. Provocar cada tipo de erro e confirmar formato e código HTTP; confirmar que os logs não expõem dados sensíveis. | Q18: Checklist de auditoria 02.05 completa: independência dos três papéis, relatório de revisão 02.04, prazos de 48 h e 24 h, pontos, versão final e pasta. Confirmar que a estrutura criada corresponde à arquitetura aprovada e que o README permite reproduzir o arranque sem ajuda do Executor. | R18: I019 — Documentação da Arquitetura; I020 — Modelo de Classes - Backend; I018 — Documentação de API. | S18: DoD G08 v01: resultado produzido e acessível; critérios de aceitação cumpridos; revisão e auditoria concluídas; versão final aprovada, corretamente nomeada e arquivada na pasta prevista. Em código: integrado no repositório por Merge Request aprovado pelo Revisor, conforme o regulamento interno do grupo; compila e passa na verificação local sem erros; sem segredos no repositório; divergências face à Documentação de API ou ao Modelo de Dados registadas e decididas. | T18: Documentação da Arquitetura m2 (I019); Modelo de Classes - Backend (I020); Documentação de API (I018); documentação oficial ASP.NET Core 8; Regulamento de Funcionamento da UC v19, secção 19 (04.12). | U18: /projeto/04-artefactos-tecnicos/04.12-backend/m3-v01 (código desenvolvido no repositório Git do grupo e arquivado nesta pasta na entrega da M3) | V18: Sim | W18: Done | X18: Aprovada como Ready | Y18: 46307 | Z18: /projeto/01-artefactos-de-gestao/01.03-reunioes-de-grupo/m3-s03-20261012-backlog-refinement-ata-v01.pdf | AA18: 2026-10-14 23:05 — Tarefa criada na proposta de refinamento (versão de trabalho), por divisão da Issue original I025 «Desenvolver Backend». Ainda não analisada em Backlog Refinement: orçamento, DoR e decisão por ratificar. 2026-10-19 18:56 — Reconciliação documental para a versão de trabalho v02 (a apreciar no Backlog Refinement de 2026-10-19; os PDFs já assinados não são alterados). O orçamento 50/30/15/5 e a decisão «Aprovada como Ready» foram aprovados no Backlog Refinement de 2026-10-12 (ata m3-s03-20261012-backlog-refinement-ata-v01, secção 4), que a v01 ainda registava como «Não analisada» / «Por verificar». Executada no Sprint 03: PR #150 (commit c923cd5 em develop; promovida para main pela PR #155, commit 6802187). Revisão e auditoria concluídas em 2026-10-17 (relatório de revisão e checklist de auditoria da I058); o Sprint Review de 2026-10-17 (ata m3-s03-20261017-sprint-review-ata-v01) aprovou a passagem a Done. Estado atualizado de Pendente para Done.
A19: I059 | B19: Implementar a camada de persistência com Entity Framework Core | C19: Antes de implementar a persistência funcional, migrar a solução backend criada em S03 de .NET 8 para .NET 10 e atualizar os pacotes compatíveis, preservando a arquitetura e o comportamento transversal já aprovado. Depois, implementar na Infrastructure o DbContext e os mapeamentos EF Core 10/Fluent API segundo o Modelo de Dados v02, incluindo relações, índices, restrições, enumerações, DeleteBehavior.Restrict e a coluna calculada da próxima administração. | D19: Disponibilizar uma persistência EF Core 10 coerente com o Modelo de Dados v02 e com a Arquitetura v02, após migração controlada da base técnica para .NET 10. | E19: Desenvolvimento | F19: Camada Infrastructure com DbContext, entidades e mapeamentos Entity Framework Core 10.0 coerentes com o Modelo de Dados v02, integrada no repositório do backend (arquivo final em /projeto/04-artefactos-tecnicos/04.12-backend/m3-v01). | G19: 1 — Crítica | H19: m3 | I19: S04 | J19: 50 | K19: =IF(ISNUMBER(J19),J19*60%,IF(J19="","Por preencher",J19)) -> 30 | L19: =IF(ISNUMBER(J19),J19*30%,IF(J19="","Por preencher",J19)) -> 15 | M19: =IF(ISNUMBER(J19),J19*10%,IF(J19="","Por preencher",J19)) -> 5 | N19: O mapeamento EF cobre as 19 tabelas ativas do Modelo de Dados v02; PK/FK, cardinalidades, CHECK, UNIQUE, índices e DeleteBehavior.Restrict estão coerentes; Cliente.UtilizadorId é opcional e único quando preenchido; não existem entidades/tabelas de F005/F007; migrations executam sem divergências. | O19: 1. Merge Request com entidades, mapeamentos e repositórios. 2. Resultado da comparação modelo EF ↔ esquema (ou lista de diferenças e decisão). 3. Registo da criação da base de dados numa instância vazia. | P19: 1. Rever o mapeamento Entity Framework Core contra o Modelo de Dados v02, confirmando entidades, PK/FK, cardinalidades, restrições, índices e DeleteBehavior aplicáveis. 2. Criar a base através das migrations numa instância limpa e comparar o esquema resultante com o modelo, incluindo Cliente opcionalmente associado a Utilizador, Consulta, horários, registo clínico e profilaxia. 3. Confirmar que não existem entidades/tabelas de F005/F007 nem SQL construído de forma insegura. | Q19: Checklist de auditoria 02.05 completa: independência dos três papéis, relatório de revisão 02.04, prazos de 48 h e 24 h, pontos, versão final e pasta. Confirmar que o mapeamento não altera o Modelo de Dados aprovado sem decisão registada e que as dependências com I060 estão cumpridas. | R19: I058; I016; I019; I020. | S19: DoD G08 v01: resultado produzido e acessível; critérios de aceitação cumpridos; revisão e auditoria concluídas; versão final aprovada, corretamente nomeada e arquivada na pasta prevista. Em código: integrado no repositório por Merge Request aprovado pelo Revisor, conforme o regulamento interno do grupo; compila e passa na verificação local sem erros; sem segredos no repositório; divergências face à Documentação de API ou ao Modelo de Dados registadas e decididas. | T19: Modelo de Dados v02 (I016); Arquitetura v02 (I019); Modelo de Classes Backend v02 (I020); Regulamento Interno do Grupo G08 v02 (proposta); documentação oficial do Entity Framework Core 10; Regulamento de Funcionamento da UC v19, secção 19 (04.12). | U19: /projeto/04-artefactos-tecnicos/04.12-backend/m3-v01 (código desenvolvido no repositório Git do grupo e arquivado nesta pasta na entrega da M3) | V19: Sim | W19: Done | X19: Aprovada como Ready | Y19: 46314 | Z19: /projeto/01-artefactos-de-gestao/01.03-reunioes-de-grupo/m3-s04-20261019-backlog-refinement-ata-v01.pdf | AA19: 2026-10-14 23:05 — Tarefa criada na proposta de refinamento (versão de trabalho), por divisão da Issue original I025 «Desenvolver Backend». Ainda não analisada em Backlog Refinement: orçamento, DoR e decisão por ratificar. 2026-10-21 15:30 — Versão de trabalho v03: registada a decisão do Backlog Refinement de 2026-10-19 (Aprovada como Ready; DoR = Sim; orçamento 50; ata m3-20261019-s04-ata-backlog-refinement-v01.pdf, secção 4 e deliberação 3). A redação desta Issue foi atualizada em 2026-10-20 na rebaseline M3 (retirada de F005/F007 do âmbito, requisitos RF, API v02). O Sprint Planning S04 (2026-10-20 a 2026-10-21) manteve o texto aprovado em 2026-10-19; a alteração de redação será apreciada no Backlog Refinement do Sprint 05. 2026-10-27 — Correção da referência à ata (proposta para o Backlog Refinement do Sprint 05): o ficheiro arquivado chama-se m3-s04-20261019-backlog-refinement-ata-v01.pdf; o nome anterior não correspondia a nenhum ficheiro. 2026-10-27 — Sprint Review do Sprint 04: tarefa aceite e estado alterado para Done (m3-s04-20261027-sprint-review-ata-v01.pdf).
A20: I060 | B20: Escrever o script de criação do esquema da base de dados | C20: Escrever o script T-SQL de criação da base de dados clinica-veterinaria a partir do Modelo de Dados (I016): tabelas, chaves primárias e estrangeiras, tipos, restrições CHECK e UNIQUE, valores por omissão e índices de pesquisa (clientes, animais, consultas por veterinário e data, contas por cliente). O script deve ser reexecutável (verifica a existência antes de criar) e dividido em ficheiros numerados por ordem de execução. | D20: Obter um esquema físico fiel ao modelo aprovado, criado de forma automática e repetível, que sirva de referência à persistência EF Core e aos ambientes individuais. | E20: Desenvolvimento | F20: Scripts SQL numerados de criação do esquema em /projeto/04-artefactos-tecnicos/04.13-scripts-de-base-de-dados/m3-v01, executáveis numa instância SQL Server vazia. | G20: 1 — Crítica | H20: m3 | I20: S03 | J20: 50 | K20: =IF(ISNUMBER(J20),J20*60%,IF(J20="","Por preencher",J20)) -> 30 | L20: =IF(ISNUMBER(J20),J20*30%,IF(J20="","Por preencher",J20)) -> 15 | M20: =IF(ISNUMBER(J20),J20*10%,IF(J20="","Por preencher",J20)) -> 5 | N20: 1. Os scripts correm do início ao fim numa instância SQL Server vazia, sem erros, por ordem numérica. 2. Todas as tabelas, colunas, chaves, relações e cardinalidades do Modelo de Dados (I016) estão criadas e coincidem em nomes e tipos. 3. Existem restrições UNIQUE para e-mail de utilizador, NIF e e-mail de cliente e CHECK para valores positivos (peso, valores monetários, intervalo em dias). 4. Os scripts são reexecutáveis: uma segunda execução não falha nem duplica objetos. 5. Cada ficheiro tem cabeçalho com finalidade, ordem de execução e pré-requisitos; não há dados pessoais reais nem palavras-passe. | O20: 1. Ficheiros SQL no repositório (e na pasta de scripts). 2. Registo da execução numa base vazia e numa segunda execução. 3. Quadro de correspondência tabela do modelo ↔ tabela criada. | P20: 1. Executar os scripts numa instância limpa, duas vezes, e comparar objetos criados com o Modelo de Dados. 2. Confirmar chaves estrangeiras, UNIQUE e CHECK com inserções válidas e inválidas. 3. Verificar que não há dados reais nem segredos nos scripts. | Q20: Checklist de auditoria 02.05 completa: independência dos três papéis, relatório de revisão 02.04, prazos de 48 h e 24 h, pontos, versão final e pasta. Confirmar que o esquema criado cobre todas as entidades do modelo e que a ordem dos ficheiros permite execução automática pela pipeline. | R20: I016 — Modelo de Dados (Base de dados clinica-veterinaria); I019 — Documentação da Arquitetura. | S20: DoD G08 v01: resultado produzido e acessível; critérios de aceitação cumpridos; revisão e auditoria concluídas; versão final aprovada, corretamente nomeada e arquivada na pasta prevista. Em código: integrado no repositório por Merge Request aprovado pelo Revisor, conforme o regulamento interno do grupo; compila e passa na verificação local sem erros; sem segredos no repositório; divergências face à Documentação de API ou ao Modelo de Dados registadas e decididas. | T20: Modelo de Dados m2 (I016); Documentação da Arquitetura (I019); Regulamento de Funcionamento da UC v19, secção 19 (04.13-scripts-de-base-de-dados). | U20: /projeto/04-artefactos-tecnicos/04.13-scripts-de-base-de-dados/m3-v01 | V20: Sim | W20: Done | X20: Aprovada como Ready | Y20: 46307 | Z20: /projeto/01-artefactos-de-gestao/01.03-reunioes-de-grupo/m3-s03-20261012-backlog-refinement-ata-v01.pdf | AA20: 2026-10-14 23:05 — Tarefa criada na proposta de refinamento (versão de trabalho), por divisão da Issue original I026 «Implementar Scripts de Bases de Dados». Ainda não analisada em Backlog Refinement: orçamento, DoR e decisão por ratificar. 2026-10-19 18:56 — Reconciliação documental para a versão de trabalho v02 (a apreciar no Backlog Refinement de 2026-10-19; os PDFs já assinados não são alterados). O orçamento 50/30/15/5 e a decisão «Aprovada como Ready» foram aprovados no Backlog Refinement de 2026-10-12 (ata m3-s03-20261012-backlog-refinement-ata-v01, secção 4), que a v01 ainda registava como «Não analisada» / «Por verificar». Executada no Sprint 03: PR #152 (commit 2329042; main f300c52) e evidências de execução na PR #153 (commit 1a43c22; main 052f366). Revisão e auditoria concluídas em 2026-10-17 (relatório de revisão e checklist de auditoria da I060); o Sprint Review de 2026-10-17 (ata m3-s03-20261017-sprint-review-ata-v01) aprovou a passagem a Done. Estado atualizado de Pendente para Done.
