Workbook

Sheet Mapa de Pontuação Individual
A1: MAPA DE PONTUAÇÃO INDIVIDUAL
A2: RESUMO CALCULADO — este mapa sustenta os resultados apreciados nos Sprint Reviews e os valores acumulados utilizados no fecho do Momento de Avaliação. Preencha os campos amarelos e a folha «Detalhe da Pontuação»; não altere as células azuis.
A4: IDENTIFICAÇÃO DO MOMENTO DE AVALIAÇÃO
A5: Momento de Avaliação | B5: m3
A6: Sprints abrangidos | B6: Sprint 03
A7: Número de alunos considerado — n | B7: =COUNTA('Listas de apoio'!A5:A12) -> 4
A8: Referência da autorização para n diferente de 4 | B8: Não aplicável — n = 4
A9: Orçamento Total do Grupo — B_T | B9: =SUM('Detalhe da Pontuação'!H18:H88) -> 140
A10: Total de Pontos Efetivamente Obtidos do grupo | B10: =SUM('Detalhe da Pontuação'!Z18:Z88) -> 101
A12: RESUMO POR ALUNO
A13: Aluno | B13: PEO Executor | C13: PEO Revisor | D13: PEO Auditor | E13: PEO Secretário | F13: P_i | G13: IB_i | H13: NI_i
A14: ='Listas de apoio'!A5 -> André Filipe Moreira Mesquita | B14: =IF($A14="","",SUMIFS('Detalhe da Pontuação'!$Z$18:$Z$88,'Detalhe da Pontuação'!$D$18:$D$88,$A14,'Detalhe da Pontuação'!$E$18:$E$88,"Executor")) -> 0 | C14: =IF($A14="","",SUMIFS('Detalhe da Pontuação'!$Z$18:$Z$88,'Detalhe da Pontuação'!$D$18:$D$88,$A14,'Detalhe da Pontuação'!$E$18:$E$88,"Revisor")) -> 24 | D14: =IF($A14="","",SUMIFS('Detalhe da Pontuação'!$Z$18:$Z$88,'Detalhe da Pontuação'!$D$18:$D$88,$A14,'Detalhe da Pontuação'!$E$18:$E$88,"Auditor")) -> 0 | E14: =IF($A14="","",SUMIFS('Detalhe da Pontuação'!$Z$18:$Z$88,'Detalhe da Pontuação'!$D$18:$D$88,$A14,'Detalhe da Pontuação'!$E$18:$E$88,"Secretário")) -> 10 | F14: =IF($A14="","",SUM($B14:$E14)) -> 34 | G14: =IF(OR($A14="",$B$9=0),"",20*$B$7*$F14/$B$9) -> 19.428571 | H14: =IF(NOT(ISNUMBER($G14)),"",MIN(20,$G14)) -> 19.428571
A15: ='Listas de apoio'!A6 -> Gonçalo Dinis Magalhães Teixeira | B15: =IF($A15="","",SUMIFS('Detalhe da Pontuação'!$Z$18:$Z$88,'Detalhe da Pontuação'!$D$18:$D$88,$A15,'Detalhe da Pontuação'!$E$18:$E$88,"Executor")) -> 15 | C15: =IF($A15="","",SUMIFS('Detalhe da Pontuação'!$Z$18:$Z$88,'Detalhe da Pontuação'!$D$18:$D$88,$A15,'Detalhe da Pontuação'!$E$18:$E$88,"Revisor")) -> 0 | D15: =IF($A15="","",SUMIFS('Detalhe da Pontuação'!$Z$18:$Z$88,'Detalhe da Pontuação'!$D$18:$D$88,$A15,'Detalhe da Pontuação'!$E$18:$E$88,"Auditor")) -> 5 | E15: =IF($A15="","",SUMIFS('Detalhe da Pontuação'!$Z$18:$Z$88,'Detalhe da Pontuação'!$D$18:$D$88,$A15,'Detalhe da Pontuação'!$E$18:$E$88,"Secretário")) -> 0 | F15: =IF($A15="","",SUM($B15:$E15)) -> 20 | G15: =IF(OR($A15="",$B$9=0),"",20*$B$7*$F15/$B$9) -> 11.428571 | H15: =IF(NOT(ISNUMBER($G15)),"",MIN(20,$G15)) -> 11.428571
A16: ='Listas de apoio'!A7 -> Gonçalo Magalhães Ribeiro | B16: =IF($A16="","",SUMIFS('Detalhe da Pontuação'!$Z$18:$Z$88,'Detalhe da Pontuação'!$D$18:$D$88,$A16,'Detalhe da Pontuação'!$E$18:$E$88,"Executor")) -> 15 | C16: =IF($A16="","",SUMIFS('Detalhe da Pontuação'!$Z$18:$Z$88,'Detalhe da Pontuação'!$D$18:$D$88,$A16,'Detalhe da Pontuação'!$E$18:$E$88,"Revisor")) -> 0 | D16: =IF($A16="","",SUMIFS('Detalhe da Pontuação'!$Z$18:$Z$88,'Detalhe da Pontuação'!$D$18:$D$88,$A16,'Detalhe da Pontuação'!$E$18:$E$88,"Auditor")) -> 8 | E16: =IF($A16="","",SUMIFS('Detalhe da Pontuação'!$Z$18:$Z$88,'Detalhe da Pontuação'!$D$18:$D$88,$A16,'Detalhe da Pontuação'!$E$18:$E$88,"Secretário")) -> 0 | F16: =IF($A16="","",SUM($B16:$E16)) -> 23 | G16: =IF(OR($A16="",$B$9=0),"",20*$B$7*$F16/$B$9) -> 13.142857 | H16: =IF(NOT(ISNUMBER($G16)),"",MIN(20,$G16)) -> 13.142857
A17: ='Listas de apoio'!A8 -> Ivan Cristiano Silva Mendes | B17: =IF($A17="","",SUMIFS('Detalhe da Pontuação'!$Z$18:$Z$88,'Detalhe da Pontuação'!$D$18:$D$88,$A17,'Detalhe da Pontuação'!$E$18:$E$88,"Executor")) -> 9 | C17: =IF($A17="","",SUMIFS('Detalhe da Pontuação'!$Z$18:$Z$88,'Detalhe da Pontuação'!$D$18:$D$88,$A17,'Detalhe da Pontuação'!$E$18:$E$88,"Revisor")) -> 15 | D17: =IF($A17="","",SUMIFS('Detalhe da Pontuação'!$Z$18:$Z$88,'Detalhe da Pontuação'!$D$18:$D$88,$A17,'Detalhe da Pontuação'!$E$18:$E$88,"Auditor")) -> 0 | E17: =IF($A17="","",SUMIFS('Detalhe da Pontuação'!$Z$18:$Z$88,'Detalhe da Pontuação'!$D$18:$D$88,$A17,'Detalhe da Pontuação'!$E$18:$E$88,"Secretário")) -> 0 | F17: =IF($A17="","",SUM($B17:$E17)) -> 24 | G17: =IF(OR($A17="",$B$9=0),"",20*$B$7*$F17/$B$9) -> 13.714286 | H17: =IF(NOT(ISNUMBER($G17)),"",MIN(20,$G17)) -> 13.714286
A18: Grupo | B18: =SUM(B14:B17) -> 39 | C18: =SUM(C14:C17) -> 39 | D18: =SUM(D14:D17) -> 13 | E18: =SUM(E14:E17) -> 10 | F18: =SUM(F14:F17) -> 101
A20: FÓRMULAS APLICADAS
A21: Fórmula | B21: Resultado calculado | C21: Leitura do exemplo
A22: P_i = Σ PEO_i | B22: =F14 -> 34 | C22: P_A no Momento de Avaliação
A23: IB_i = (20 × n × P_i) / B_T | B23: =G14 -> 19.428571 | C23: IB_A antes do limite máximo
A24: NI_i = min(20; IB_i) | B24: =H14 -> 19.428571 | C24: NI_A depois da aplicação do limite máximo
A26: RESULTADOS POR SPRINT
A27: Sprint | B27: =$A$14 -> André Filipe Moreira Mesquita | C27: =$A$15 -> Gonçalo Dinis Magalhães Teixeira | D27: =$A$16 -> Gonçalo Magalhães Ribeiro | E27: =$A$17 -> Ivan Cristiano Silva Mendes | F27: Total do Sprint
A28: =IF('Detalhe da Pontuação'!A6="","",'Detalhe da Pontuação'!A6) -> S03 | B28: =IF($A28="","",SUMIFS('Detalhe da Pontuação'!$Z$18:$Z$88,'Detalhe da Pontuação'!$A$18:$A$88,$A28,'Detalhe da Pontuação'!$D$18:$D$88,B$27)) -> 34 | C28: =IF($A28="","",SUMIFS('Detalhe da Pontuação'!$Z$18:$Z$88,'Detalhe da Pontuação'!$A$18:$A$88,$A28,'Detalhe da Pontuação'!$D$18:$D$88,C$27)) -> 20 | D28: =IF($A28="","",SUMIFS('Detalhe da Pontuação'!$Z$18:$Z$88,'Detalhe da Pontuação'!$A$18:$A$88,$A28,'Detalhe da Pontuação'!$D$18:$D$88,D$27)) -> 23 | E28: =IF($A28="","",SUMIFS('Detalhe da Pontuação'!$Z$18:$Z$88,'Detalhe da Pontuação'!$A$18:$A$88,$A28,'Detalhe da Pontuação'!$D$18:$D$88,E$27)) -> 24 | F28: =IF($A28="","",SUM(B28:E28)) -> 101
A29: =IF('Detalhe da Pontuação'!A7="","",'Detalhe da Pontuação'!A7) | B29: =IF($A29="","",SUMIFS('Detalhe da Pontuação'!$Z$18:$Z$88,'Detalhe da Pontuação'!$A$18:$A$88,$A29,'Detalhe da Pontuação'!$D$18:$D$88,B$27)) | C29: =IF($A29="","",SUMIFS('Detalhe da Pontuação'!$Z$18:$Z$88,'Detalhe da Pontuação'!$A$18:$A$88,$A29,'Detalhe da Pontuação'!$D$18:$D$88,C$27)) | D29: =IF($A29="","",SUMIFS('Detalhe da Pontuação'!$Z$18:$Z$88,'Detalhe da Pontuação'!$A$18:$A$88,$A29,'Detalhe da Pontuação'!$D$18:$D$88,D$27)) | E29: =IF($A29="","",SUMIFS('Detalhe da Pontuação'!$Z$18:$Z$88,'Detalhe da Pontuação'!$A$18:$A$88,$A29,'Detalhe da Pontuação'!$D$18:$D$88,E$27)) | F29: =IF($A29="","",SUM(B29:E29))
A30: =IF('Detalhe da Pontuação'!A8="","",'Detalhe da Pontuação'!A8) | B30: =IF($A30="","",SUMIFS('Detalhe da Pontuação'!$Z$18:$Z$88,'Detalhe da Pontuação'!$A$18:$A$88,$A30,'Detalhe da Pontuação'!$D$18:$D$88,B$27)) | C30: =IF($A30="","",SUMIFS('Detalhe da Pontuação'!$Z$18:$Z$88,'Detalhe da Pontuação'!$A$18:$A$88,$A30,'Detalhe da Pontuação'!$D$18:$D$88,C$27)) | D30: =IF($A30="","",SUMIFS('Detalhe da Pontuação'!$Z$18:$Z$88,'Detalhe da Pontuação'!$A$18:$A$88,$A30,'Detalhe da Pontuação'!$D$18:$D$88,D$27)) | E30: =IF($A30="","",SUMIFS('Detalhe da Pontuação'!$Z$18:$Z$88,'Detalhe da Pontuação'!$A$18:$A$88,$A30,'Detalhe da Pontuação'!$D$18:$D$88,E$27)) | F30: =IF($A30="","",SUM(B30:E30))
A31: =IF('Detalhe da Pontuação'!A9="","",'Detalhe da Pontuação'!A9) | B31: =IF($A31="","",SUMIFS('Detalhe da Pontuação'!$Z$18:$Z$88,'Detalhe da Pontuação'!$A$18:$A$88,$A31,'Detalhe da Pontuação'!$D$18:$D$88,B$27)) | C31: =IF($A31="","",SUMIFS('Detalhe da Pontuação'!$Z$18:$Z$88,'Detalhe da Pontuação'!$A$18:$A$88,$A31,'Detalhe da Pontuação'!$D$18:$D$88,C$27)) | D31: =IF($A31="","",SUMIFS('Detalhe da Pontuação'!$Z$18:$Z$88,'Detalhe da Pontuação'!$A$18:$A$88,$A31,'Detalhe da Pontuação'!$D$18:$D$88,D$27)) | E31: =IF($A31="","",SUMIFS('Detalhe da Pontuação'!$Z$18:$Z$88,'Detalhe da Pontuação'!$A$18:$A$88,$A31,'Detalhe da Pontuação'!$D$18:$D$88,E$27)) | F31: =IF($A31="","",SUM(B31:E31))
A32: =IF('Detalhe da Pontuação'!A10="","",'Detalhe da Pontuação'!A10) | B32: =IF($A32="","",SUMIFS('Detalhe da Pontuação'!$Z$18:$Z$88,'Detalhe da Pontuação'!$A$18:$A$88,$A32,'Detalhe da Pontuação'!$D$18:$D$88,B$27)) | C32: =IF($A32="","",SUMIFS('Detalhe da Pontuação'!$Z$18:$Z$88,'Detalhe da Pontuação'!$A$18:$A$88,$A32,'Detalhe da Pontuação'!$D$18:$D$88,C$27)) | D32: =IF($A32="","",SUMIFS('Detalhe da Pontuação'!$Z$18:$Z$88,'Detalhe da Pontuação'!$A$18:$A$88,$A32,'Detalhe da Pontuação'!$D$18:$D$88,D$27)) | E32: =IF($A32="","",SUMIFS('Detalhe da Pontuação'!$Z$18:$Z$88,'Detalhe da Pontuação'!$A$18:$A$88,$A32,'Detalhe da Pontuação'!$D$18:$D$88,E$27)) | F32: =IF($A32="","",SUM(B32:E32))
A33: =IF('Detalhe da Pontuação'!A11="","",'Detalhe da Pontuação'!A11) | B33: =IF($A33="","",SUMIFS('Detalhe da Pontuação'!$Z$18:$Z$88,'Detalhe da Pontuação'!$A$18:$A$88,$A33,'Detalhe da Pontuação'!$D$18:$D$88,B$27)) | C33: =IF($A33="","",SUMIFS('Detalhe da Pontuação'!$Z$18:$Z$88,'Detalhe da Pontuação'!$A$18:$A$88,$A33,'Detalhe da Pontuação'!$D$18:$D$88,C$27)) | D33: =IF($A33="","",SUMIFS('Detalhe da Pontuação'!$Z$18:$Z$88,'Detalhe da Pontuação'!$A$18:$A$88,$A33,'Detalhe da Pontuação'!$D$18:$D$88,D$27)) | E33: =IF($A33="","",SUMIFS('Detalhe da Pontuação'!$Z$18:$Z$88,'Detalhe da Pontuação'!$A$18:$A$88,$A33,'Detalhe da Pontuação'!$D$18:$D$88,E$27)) | F33: =IF($A33="","",SUM(B33:E33))
A34: =IF('Detalhe da Pontuação'!A12="","",'Detalhe da Pontuação'!A12) | B34: =IF($A34="","",SUMIFS('Detalhe da Pontuação'!$Z$18:$Z$88,'Detalhe da Pontuação'!$A$18:$A$88,$A34,'Detalhe da Pontuação'!$D$18:$D$88,B$27)) | C34: =IF($A34="","",SUMIFS('Detalhe da Pontuação'!$Z$18:$Z$88,'Detalhe da Pontuação'!$A$18:$A$88,$A34,'Detalhe da Pontuação'!$D$18:$D$88,C$27)) | D34: =IF($A34="","",SUMIFS('Detalhe da Pontuação'!$Z$18:$Z$88,'Detalhe da Pontuação'!$A$18:$A$88,$A34,'Detalhe da Pontuação'!$D$18:$D$88,D$27)) | E34: =IF($A34="","",SUMIFS('Detalhe da Pontuação'!$Z$18:$Z$88,'Detalhe da Pontuação'!$A$18:$A$88,$A34,'Detalhe da Pontuação'!$D$18:$D$88,E$27)) | F34: =IF($A34="","",SUM(B34:E34))
A35: =IF('Detalhe da Pontuação'!A13="","",'Detalhe da Pontuação'!A13) | B35: =IF($A35="","",SUMIFS('Detalhe da Pontuação'!$Z$18:$Z$88,'Detalhe da Pontuação'!$A$18:$A$88,$A35,'Detalhe da Pontuação'!$D$18:$D$88,B$27)) | C35: =IF($A35="","",SUMIFS('Detalhe da Pontuação'!$Z$18:$Z$88,'Detalhe da Pontuação'!$A$18:$A$88,$A35,'Detalhe da Pontuação'!$D$18:$D$88,C$27)) | D35: =IF($A35="","",SUMIFS('Detalhe da Pontuação'!$Z$18:$Z$88,'Detalhe da Pontuação'!$A$18:$A$88,$A35,'Detalhe da Pontuação'!$D$18:$D$88,D$27)) | E35: =IF($A35="","",SUMIFS('Detalhe da Pontuação'!$Z$18:$Z$88,'Detalhe da Pontuação'!$A$18:$A$88,$A35,'Detalhe da Pontuação'!$D$18:$D$88,E$27)) | F35: =IF($A35="","",SUM(B35:E35))
A36: =IF('Detalhe da Pontuação'!A14="","",'Detalhe da Pontuação'!A14) | B36: =IF($A36="","",SUMIFS('Detalhe da Pontuação'!$Z$18:$Z$88,'Detalhe da Pontuação'!$A$18:$A$88,$A36,'Detalhe da Pontuação'!$D$18:$D$88,B$27)) | C36: =IF($A36="","",SUMIFS('Detalhe da Pontuação'!$Z$18:$Z$88,'Detalhe da Pontuação'!$A$18:$A$88,$A36,'Detalhe da Pontuação'!$D$18:$D$88,C$27)) | D36: =IF($A36="","",SUMIFS('Detalhe da Pontuação'!$Z$18:$Z$88,'Detalhe da Pontuação'!$A$18:$A$88,$A36,'Detalhe da Pontuação'!$D$18:$D$88,D$27)) | E36: =IF($A36="","",SUMIFS('Detalhe da Pontuação'!$Z$18:$Z$88,'Detalhe da Pontuação'!$A$18:$A$88,$A36,'Detalhe da Pontuação'!$D$18:$D$88,E$27)) | F36: =IF($A36="","",SUM(B36:E36))
A37: Total do Momento de Avaliação | B37: =SUM(B28:B36) -> 34 | C37: =SUM(C28:C36) -> 20 | D37: =SUM(D28:D36) -> 23 | E37: =SUM(E28:E36) -> 24 | F37: =SUM(F28:F36) -> 101

Sheet Detalhe da Pontuação
A1: DETALHE DA PONTUAÇÃO
A2: PREENCHIMENTO PRINCIPAL — prepare este mapa como suporte ao Sprint Review. Use a última versão cumulativa do Sprint Backlog formalmente aprovada antes da reunião, incluindo todas as transferências ocorridas. Os campos amarelos são editáveis; os campos azuis são calculados.
A4: SPRINTS E FONTES DOCUMENTAIS
A5: Sprint | B5: Sprint Backlog vigente — versão editável (XLS/XLSX) | I5: Sprint Backlog vigente — PDF assinado
A6: S03 | B6: /projeto/01-artefactos-de-gestao/01.04-backlog-de-projeto/m3-s03-sprint-backlog-v01.xlsx | I6: /projeto/01-artefactos-de-gestao/01.04-backlog-de-projeto/m3-s03-sprint-backlog-v01.pdf
A16: LINHAS DE PONTUAÇÃO POR SPRINT, ISSUE, ALUNO E PAPEL
A17: Sprint | B17: Issue | C17: Tarefa | D17: Aluno | E17: Papel | F17: Orçamento da tarefa | G17: Origem da parcela | H17: PMI | I17: Referência da transferência | J17: PC | K17: PR | L17: PMR | M17: Categoria de qualidade aprovada | N17: Q | O17: Fundamento e evidência | P17: Classificação atribuída por | Q17: PQ | R17: Prazo aplicável | S17: Data e hora de conclusão | T17: Atraso imputável em horas | U17: Penalização por atraso | V17: A | W17: Perda por qualidade | X17: PEO não arredondado | Y17: Perda por atraso | Z17: PEO
A18: S03 | B18: I058 | C18: Criar a solução .NET 8 do backend e a infraestrutura transversal da API | D18: Gonçalo Dinis Magalhães Teixeira | E18: Executor | F18: 50 | G18: Atribuição inicial | H18: =IF($A18="","",IF($G18="Secretariado",10,IF($G18="Transferência recebida",0,IF($E18="Executor",$F18*60%,IF($E18="Revisor",$F18*30%,IF($E18="Auditor",$F18*10%,"")))))) -> 30 | I18: Não Aplicável | J18: 0 | K18: 0 | L18: =IF($A18="","",$H18-$J18+$K18) -> 30 | M18: Aceite sem correções obrigatórias | N18: =IF($A18="","",IF($M18="","",IF($E18="Executor",IFERROR(VLOOKUP($M18,'Listas de apoio'!$G$5:$H$9,2,FALSE()),""),IF($E18="Revisor",IFERROR(VLOOKUP($M18,'Listas de apoio'!$J$5:$K$8,2,FALSE()),""),IF($E18="Auditor",IFERROR(VLOOKUP($M18,'Listas de apoio'!$M$5:$N$7,2,FALSE()),""),IF($E18="Secretário",IFERROR(VLOOKUP($M18,'Listas de apoio'!$P$5:$Q$7,2,FALSE()),""),"")))))) -> 1 | O18: Relatório de revisão m3-s03-i058-20261017-relatorio-revisao-v01: sem defeitos obrigatórios; critérios de aceitação 1 a 6 e README cumpridos (PR #150, commit e774f2a, integrado em develop como c923cd5). Melhorias M1–M4 não obrigatórias. | P18: André Filipe Moreira Mesquita | Q18: =IF(OR($A18="",NOT(ISNUMBER($L18)),NOT(ISNUMBER($N18))),"",$L18*$N18) -> 30 | R18: 46310.396 | S18: 46311.799 | T18: =IF(OR($A18="",$R18="",$S18=""),"",MAX(0,($S18-$R18)*24)) -> 33.666667 | U18: Mais de 24 e até 48 horas, inclusive | V18: =IF($A18="","",IF($U18="","",IFERROR(VLOOKUP($U18,'Listas de apoio'!$S$5:$T$10,2,FALSE()),""))) -> 0.5 | W18: =IF(OR($A18="",NOT(ISNUMBER($L18)),NOT(ISNUMBER($Q18))),"",$L18-$Q18) -> 0 | X18: =IF(OR($A18="",NOT(ISNUMBER($Q18)),NOT(ISNUMBER($V18))),"",$Q18*(1-$V18)) -> 15 | Y18: =IF(OR($A18="",NOT(ISNUMBER($Q18)),NOT(ISNUMBER($X18))),"",$Q18-$X18) -> 15 | Z18: =IF(NOT(ISNUMBER($X18)),"",ROUND($X18,2)) -> 15
A19: S03 | B19: I058 | C19: Criar a solução .NET 8 do backend e a infraestrutura transversal da API | D19: André Filipe Moreira Mesquita | E19: Revisor | F19: 50 | G19: Atribuição inicial | H19: =IF($A19="","",IF($G19="Secretariado",10,IF($G19="Transferência recebida",0,IF($E19="Executor",$F19*60%,IF($E19="Revisor",$F19*30%,IF($E19="Auditor",$F19*10%,"")))))) -> 15 | I19: Não Aplicável | J19: 0 | K19: 0 | L19: =IF($A19="","",$H19-$J19+$K19) -> 15 | M19: Revisão completa, correta e sustentada por evidências | N19: =IF($A19="","",IF($M19="","",IF($E19="Executor",IFERROR(VLOOKUP($M19,'Listas de apoio'!$G$5:$H$9,2,FALSE()),""),IF($E19="Revisor",IFERROR(VLOOKUP($M19,'Listas de apoio'!$J$5:$K$8,2,FALSE()),""),IF($E19="Auditor",IFERROR(VLOOKUP($M19,'Listas de apoio'!$M$5:$N$7,2,FALSE()),""),IF($E19="Secretário",IFERROR(VLOOKUP($M19,'Listas de apoio'!$P$5:$Q$7,2,FALSE()),""),"")))))) -> 1 | O19: Checklist de auditoria m3-s03-i058-20261017-checklist-auditoria-v01: revisão completa, com 14 verificações sustentadas por evidências do repositório (estrutura, referências, configuração, middleware, README e histórico Git). Desvio de processo registado: merge da PR #150 pelo Revisor antes da autorização do Auditor. Aprovação da PR #150 a 2026-10-16 19:12; relatório de revisão assinado a 2026-10-17 18:21. | P19: Gonçalo Magalhães Ribeiro | Q19: =IF(OR($A19="",NOT(ISNUMBER($L19)),NOT(ISNUMBER($N19))),"",$L19*$N19) -> 15 | R19: 46312.799 | S19: 46312.765 | T19: =IF(OR($A19="",$R19="",$S19=""),"",MAX(0,($S19-$R19)*24)) -> 0 | U19: Sem atraso | V19: =IF($A19="","",IF($U19="","",IFERROR(VLOOKUP($U19,'Listas de apoio'!$S$5:$T$10,2,FALSE()),""))) -> 0 | W19: =IF(OR($A19="",NOT(ISNUMBER($L19)),NOT(ISNUMBER($Q19))),"",$L19-$Q19) -> 0 | X19: =IF(OR($A19="",NOT(ISNUMBER($Q19)),NOT(ISNUMBER($V19))),"",$Q19*(1-$V19)) -> 15 | Y19: =IF(OR($A19="",NOT(ISNUMBER($Q19)),NOT(ISNUMBER($X19))),"",$Q19-$X19) -> 0 | Z19: =IF(NOT(ISNUMBER($X19)),"",ROUND($X19,2)) -> 15
A20: S03 | B20: I058 | C20: Criar a solução .NET 8 do backend e a infraestrutura transversal da API | D20: Gonçalo Magalhães Ribeiro | E20: Auditor | F20: 50 | G20: Atribuição inicial | H20: =IF($A20="","",IF($G20="Secretariado",10,IF($G20="Transferência recebida",0,IF($E20="Executor",$F20*60%,IF($E20="Revisor",$F20*30%,IF($E20="Auditor",$F20*10%,"")))))) -> 5 | I20: Não Aplicável | J20: 0 | K20: 0 | L20: =IF($A20="","",$H20-$J20+$K20) -> 5 | M20: Auditoria completa antes do Sprint Review, incluindo a confirmação final | N20: =IF($A20="","",IF($M20="","",IF($E20="Executor",IFERROR(VLOOKUP($M20,'Listas de apoio'!$G$5:$H$9,2,FALSE()),""),IF($E20="Revisor",IFERROR(VLOOKUP($M20,'Listas de apoio'!$J$5:$K$8,2,FALSE()),""),IF($E20="Auditor",IFERROR(VLOOKUP($M20,'Listas de apoio'!$M$5:$N$7,2,FALSE()),""),IF($E20="Secretário",IFERROR(VLOOKUP($M20,'Listas de apoio'!$P$5:$Q$7,2,FALSE()),""),"")))))) -> 1 | O20: Checklist m3-s03-i058-20261017-checklist-auditoria-v01: auditoria inicial (pontos 1 a 9) e confirmação final (pontos 10 a 12) concluídas, com os desvios de processo registados. Checklist assinada a 2026-10-17 18:21, depois da sessão do Sprint Review das 09:30, por os relatórios e checklists formais só terem sido conhecidos como obrigatórios nesse dia; o grupo considera a auditoria completa. | P20: André Filipe Moreira Mesquita; Gonçalo Dinis Magalhães Teixeira; Ivan Cristiano Silva Mendes | Q20: =IF(OR($A20="",NOT(ISNUMBER($L20)),NOT(ISNUMBER($N20))),"",$L20*$N20) -> 5 | R20: 46313.431 | S20: 46312.765 | T20: =IF(OR($A20="",$R20="",$S20=""),"",MAX(0,($S20-$R20)*24)) -> 0 | U20: Sem atraso | V20: =IF($A20="","",IF($U20="","",IFERROR(VLOOKUP($U20,'Listas de apoio'!$S$5:$T$10,2,FALSE()),""))) -> 0 | W20: =IF(OR($A20="",NOT(ISNUMBER($L20)),NOT(ISNUMBER($Q20))),"",$L20-$Q20) -> 0 | X20: =IF(OR($A20="",NOT(ISNUMBER($Q20)),NOT(ISNUMBER($V20))),"",$Q20*(1-$V20)) -> 5 | Y20: =IF(OR($A20="",NOT(ISNUMBER($Q20)),NOT(ISNUMBER($X20))),"",$Q20-$X20) -> 0 | Z20: =IF(NOT(ISNUMBER($X20)),"",ROUND($X20,2)) -> 5
A21: S03 | B21: I060 | C21: Escrever o script de criação do esquema da base de dados | D21: Gonçalo Magalhães Ribeiro | E21: Executor | F21: 50 | G21: Atribuição inicial | H21: =IF($A21="","",IF($G21="Secretariado",10,IF($G21="Transferência recebida",0,IF($E21="Executor",$F21*60%,IF($E21="Revisor",$F21*30%,IF($E21="Auditor",$F21*10%,"")))))) -> 30 | I21: Não Aplicável | J21: 0 | K21: 0 | L21: =IF($A21="","",$H21-$J21+$K21) -> 30 | M21: Aceite sem correções obrigatórias | N21: =IF($A21="","",IF($M21="","",IF($E21="Executor",IFERROR(VLOOKUP($M21,'Listas de apoio'!$G$5:$H$9,2,FALSE()),""),IF($E21="Revisor",IFERROR(VLOOKUP($M21,'Listas de apoio'!$J$5:$K$8,2,FALSE()),""),IF($E21="Auditor",IFERROR(VLOOKUP($M21,'Listas de apoio'!$M$5:$N$7,2,FALSE()),""),IF($E21="Secretário",IFERROR(VLOOKUP($M21,'Listas de apoio'!$P$5:$Q$7,2,FALSE()),""),"")))))) -> 1 | O21: Relatório de revisão m3-s03-i060-20261017-relatorio-revisao-v01: sem defeitos obrigatórios; 22 tabelas, 36 FK, 7 UNIQUE e 23 CHECK verificados, 372 verificações sem divergências e 56/56 testes de restrições (PR #152, commit 2329042, integrado em main como f300c52). Melhorias M1–M4 não obrigatórias. | P21: Ivan Cristiano Silva Mendes | Q21: =IF(OR($A21="",NOT(ISNUMBER($L21)),NOT(ISNUMBER($N21))),"",$L21*$N21) -> 30 | R21: 46310.396 | S21: 46311.974 | T21: =IF(OR($A21="",$R21="",$S21=""),"",MAX(0,($S21-$R21)*24)) -> 37.866667 | U21: Mais de 24 e até 48 horas, inclusive | V21: =IF($A21="","",IF($U21="","",IFERROR(VLOOKUP($U21,'Listas de apoio'!$S$5:$T$10,2,FALSE()),""))) -> 0.5 | W21: =IF(OR($A21="",NOT(ISNUMBER($L21)),NOT(ISNUMBER($Q21))),"",$L21-$Q21) -> 0 | X21: =IF(OR($A21="",NOT(ISNUMBER($Q21)),NOT(ISNUMBER($V21))),"",$Q21*(1-$V21)) -> 15 | Y21: =IF(OR($A21="",NOT(ISNUMBER($Q21)),NOT(ISNUMBER($X21))),"",$Q21-$X21) -> 15 | Z21: =IF(NOT(ISNUMBER($X21)),"",ROUND($X21,2)) -> 15
A22: S03 | B22: I060 | C22: Escrever o script de criação do esquema da base de dados | D22: Ivan Cristiano Silva Mendes | E22: Revisor | F22: 50 | G22: Atribuição inicial | H22: =IF($A22="","",IF($G22="Secretariado",10,IF($G22="Transferência recebida",0,IF($E22="Executor",$F22*60%,IF($E22="Revisor",$F22*30%,IF($E22="Auditor",$F22*10%,"")))))) -> 15 | I22: Não Aplicável | J22: 0 | K22: 0 | L22: =IF($A22="","",$H22-$J22+$K22) -> 15 | M22: Revisão completa, correta e sustentada por evidências | N22: =IF($A22="","",IF($M22="","",IF($E22="Executor",IFERROR(VLOOKUP($M22,'Listas de apoio'!$G$5:$H$9,2,FALSE()),""),IF($E22="Revisor",IFERROR(VLOOKUP($M22,'Listas de apoio'!$J$5:$K$8,2,FALSE()),""),IF($E22="Auditor",IFERROR(VLOOKUP($M22,'Listas de apoio'!$M$5:$N$7,2,FALSE()),""),IF($E22="Secretário",IFERROR(VLOOKUP($M22,'Listas de apoio'!$P$5:$Q$7,2,FALSE()),""),"")))))) -> 1 | O22: Checklist de auditoria m3-s03-i060-20261017-checklist-auditoria-v01: revisão completa, com 13 verificações e registos de execução transcritos no Anexo A com SHA-256. Desvio de processo registado: merge da PR #152 antes da autorização do Auditor. Relatório de revisão assinado a 2026-10-17 18:21. | P22: Gonçalo Dinis Magalhães Teixeira | Q22: =IF(OR($A22="",NOT(ISNUMBER($L22)),NOT(ISNUMBER($N22))),"",$L22*$N22) -> 15 | R22: 46312.974 | S22: 46312.765 | T22: =IF(OR($A22="",$R22="",$S22=""),"",MAX(0,($S22-$R22)*24)) -> 0 | U22: Sem atraso | V22: =IF($A22="","",IF($U22="","",IFERROR(VLOOKUP($U22,'Listas de apoio'!$S$5:$T$10,2,FALSE()),""))) -> 0 | W22: =IF(OR($A22="",NOT(ISNUMBER($L22)),NOT(ISNUMBER($Q22))),"",$L22-$Q22) -> 0 | X22: =IF(OR($A22="",NOT(ISNUMBER($Q22)),NOT(ISNUMBER($V22))),"",$Q22*(1-$V22)) -> 15 | Y22: =IF(OR($A22="",NOT(ISNUMBER($Q22)),NOT(ISNUMBER($X22))),"",$Q22-$X22) -> 0 | Z22: =IF(NOT(ISNUMBER($X22)),"",ROUND($X22,2)) -> 15
A23: S03 | B23: I060 | C23: Escrever o script de criação do esquema da base de dados | D23: Gonçalo Dinis Magalhães Teixeira | E23: Auditor | F23: 50 | G23: Atribuição inicial | H23: =IF($A23="","",IF($G23="Secretariado",10,IF($G23="Transferência recebida",0,IF($E23="Executor",$F23*60%,IF($E23="Revisor",$F23*30%,IF($E23="Auditor",$F23*10%,"")))))) -> 5 | I23: Não Aplicável | J23: 0 | K23: 0 | L23: =IF($A23="","",$H23-$J23+$K23) -> 5 | M23: Auditoria completa antes do Sprint Review, incluindo a confirmação final | N23: =IF($A23="","",IF($M23="","",IF($E23="Executor",IFERROR(VLOOKUP($M23,'Listas de apoio'!$G$5:$H$9,2,FALSE()),""),IF($E23="Revisor",IFERROR(VLOOKUP($M23,'Listas de apoio'!$J$5:$K$8,2,FALSE()),""),IF($E23="Auditor",IFERROR(VLOOKUP($M23,'Listas de apoio'!$M$5:$N$7,2,FALSE()),""),IF($E23="Secretário",IFERROR(VLOOKUP($M23,'Listas de apoio'!$P$5:$Q$7,2,FALSE()),""),"")))))) -> 1 | O23: Checklist m3-s03-i060-20261017-checklist-auditoria-v01: auditoria inicial (pontos 1 a 10) e confirmação final (pontos 11 a 13) concluídas, com os desvios de processo registados. Checklist assinada a 2026-10-17 18:21, depois da sessão do Sprint Review das 09:30, por os relatórios e checklists formais só terem sido conhecidos como obrigatórios nesse dia; o grupo considera a auditoria completa. | P23: André Filipe Moreira Mesquita; Gonçalo Magalhães Ribeiro; Ivan Cristiano Silva Mendes | Q23: =IF(OR($A23="",NOT(ISNUMBER($L23)),NOT(ISNUMBER($N23))),"",$L23*$N23) -> 5 | R23: 46313.431 | S23: 46312.765 | T23: =IF(OR($A23="",$R23="",$S23=""),"",MAX(0,($S23-$R23)*24)) -> 0 | U23: Sem atraso | V23: =IF($A23="","",IF($U23="","",IFERROR(VLOOKUP($U23,'Listas de apoio'!$S$5:$T$10,2,FALSE()),""))) -> 0 | W23: =IF(OR($A23="",NOT(ISNUMBER($L23)),NOT(ISNUMBER($Q23))),"",$L23-$Q23) -> 0 | X23: =IF(OR($A23="",NOT(ISNUMBER($Q23)),NOT(ISNUMBER($V23))),"",$Q23*(1-$V23)) -> 5 | Y23: =IF(OR($A23="",NOT(ISNUMBER($Q23)),NOT(ISNUMBER($X23))),"",$Q23-$X23) -> 0 | Z23: =IF(NOT(ISNUMBER($X23)),"",ROUND($X23,2)) -> 5
A24: S03 | B24: I027 | C24: Elaborar o Plano de Testes do Backend | D24: Ivan Cristiano Silva Mendes | E24: Executor | F24: 30 | G24: Atribuição inicial | H24: =IF($A24="","",IF($G24="Secretariado",10,IF($G24="Transferência recebida",0,IF($E24="Executor",$F24*60%,IF($E24="Revisor",$F24*30%,IF($E24="Auditor",$F24*10%,"")))))) -> 18 | I24: Não Aplicável | J24: 0 | K24: 0 | L24: =IF($A24="","",$H24-$J24+$K24) -> 18 | M24: Aceite sem correções obrigatórias | N24: =IF($A24="","",IF($M24="","",IF($E24="Executor",IFERROR(VLOOKUP($M24,'Listas de apoio'!$G$5:$H$9,2,FALSE()),""),IF($E24="Revisor",IFERROR(VLOOKUP($M24,'Listas de apoio'!$J$5:$K$8,2,FALSE()),""),IF($E24="Auditor",IFERROR(VLOOKUP($M24,'Listas de apoio'!$M$5:$N$7,2,FALSE()),""),IF($E24="Secretário",IFERROR(VLOOKUP($M24,'Listas de apoio'!$P$5:$Q$7,2,FALSE()),""),"")))))) -> 1 | O24: Relatório de revisão m3-s03-i027-20261017-relatorio-revisao-v01: sem defeitos obrigatórios; 51/51 endpoints e RF001–RF052 rastreados face à Documentação de API; critérios de aceitação 1 a 6 cumpridos (PR #151, commit c1c3a94, integrado como ed8f880). Melhorias M1–M3 não obrigatórias. | P24: André Filipe Moreira Mesquita | Q24: =IF(OR($A24="",NOT(ISNUMBER($L24)),NOT(ISNUMBER($N24))),"",$L24*$N24) -> 18 | R24: 46310.396 | S24: 46311.931 | T24: =IF(OR($A24="",$R24="",$S24=""),"",MAX(0,($S24-$R24)*24)) -> 36.85 | U24: Mais de 24 e até 48 horas, inclusive | V24: =IF($A24="","",IF($U24="","",IFERROR(VLOOKUP($U24,'Listas de apoio'!$S$5:$T$10,2,FALSE()),""))) -> 0.5 | W24: =IF(OR($A24="",NOT(ISNUMBER($L24)),NOT(ISNUMBER($Q24))),"",$L24-$Q24) -> 0 | X24: =IF(OR($A24="",NOT(ISNUMBER($Q24)),NOT(ISNUMBER($V24))),"",$Q24*(1-$V24)) -> 9 | Y24: =IF(OR($A24="",NOT(ISNUMBER($Q24)),NOT(ISNUMBER($X24))),"",$Q24-$X24) -> 9 | Z24: =IF(NOT(ISNUMBER($X24)),"",ROUND($X24,2)) -> 9
A25: S03 | B25: I027 | C25: Elaborar o Plano de Testes do Backend | D25: André Filipe Moreira Mesquita | E25: Revisor | F25: 30 | G25: Atribuição inicial | H25: =IF($A25="","",IF($G25="Secretariado",10,IF($G25="Transferência recebida",0,IF($E25="Executor",$F25*60%,IF($E25="Revisor",$F25*30%,IF($E25="Auditor",$F25*10%,"")))))) -> 9 | I25: Não Aplicável | J25: 0 | K25: 0 | L25: =IF($A25="","",$H25-$J25+$K25) -> 9 | M25: Revisão completa, correta e sustentada por evidências | N25: =IF($A25="","",IF($M25="","",IF($E25="Executor",IFERROR(VLOOKUP($M25,'Listas de apoio'!$G$5:$H$9,2,FALSE()),""),IF($E25="Revisor",IFERROR(VLOOKUP($M25,'Listas de apoio'!$J$5:$K$8,2,FALSE()),""),IF($E25="Auditor",IFERROR(VLOOKUP($M25,'Listas de apoio'!$M$5:$N$7,2,FALSE()),""),IF($E25="Secretário",IFERROR(VLOOKUP($M25,'Listas de apoio'!$P$5:$Q$7,2,FALSE()),""),"")))))) -> 1 | O25: Checklist de auditoria m3-s03-i027-20261017-checklist-auditoria-v01: revisão completa, com 14 verificações, incluindo a comparação por script da matriz com a Documentação de API e o hash do ficheiro integrado. Relatório de revisão assinado a 2026-10-17 18:21. | P25: Gonçalo Magalhães Ribeiro | Q25: =IF(OR($A25="",NOT(ISNUMBER($L25)),NOT(ISNUMBER($N25))),"",$L25*$N25) -> 9 | R25: 46312.931 | S25: 46312.765 | T25: =IF(OR($A25="",$R25="",$S25=""),"",MAX(0,($S25-$R25)*24)) -> 0 | U25: Sem atraso | V25: =IF($A25="","",IF($U25="","",IFERROR(VLOOKUP($U25,'Listas de apoio'!$S$5:$T$10,2,FALSE()),""))) -> 0 | W25: =IF(OR($A25="",NOT(ISNUMBER($L25)),NOT(ISNUMBER($Q25))),"",$L25-$Q25) -> 0 | X25: =IF(OR($A25="",NOT(ISNUMBER($Q25)),NOT(ISNUMBER($V25))),"",$Q25*(1-$V25)) -> 9 | Y25: =IF(OR($A25="",NOT(ISNUMBER($Q25)),NOT(ISNUMBER($X25))),"",$Q25-$X25) -> 0 | Z25: =IF(NOT(ISNUMBER($X25)),"",ROUND($X25,2)) -> 9
A26: S03 | B26: I027 | C26: Elaborar o Plano de Testes do Backend | D26: Gonçalo Magalhães Ribeiro | E26: Auditor | F26: 30 | G26: Atribuição inicial | H26: =IF($A26="","",IF($G26="Secretariado",10,IF($G26="Transferência recebida",0,IF($E26="Executor",$F26*60%,IF($E26="Revisor",$F26*30%,IF($E26="Auditor",$F26*10%,"")))))) -> 3 | I26: Não Aplicável | J26: 0 | K26: 0 | L26: =IF($A26="","",$H26-$J26+$K26) -> 3 | M26: Auditoria completa antes do Sprint Review, incluindo a confirmação final | N26: =IF($A26="","",IF($M26="","",IF($E26="Executor",IFERROR(VLOOKUP($M26,'Listas de apoio'!$G$5:$H$9,2,FALSE()),""),IF($E26="Revisor",IFERROR(VLOOKUP($M26,'Listas de apoio'!$J$5:$K$8,2,FALSE()),""),IF($E26="Auditor",IFERROR(VLOOKUP($M26,'Listas de apoio'!$M$5:$N$7,2,FALSE()),""),IF($E26="Secretário",IFERROR(VLOOKUP($M26,'Listas de apoio'!$P$5:$Q$7,2,FALSE()),""),"")))))) -> 1 | O26: Checklist m3-s03-i027-20261017-checklist-auditoria-v01: auditoria inicial (pontos 1 a 9) e confirmação final (pontos 10 a 12) concluídas, com os desvios de processo registados. Checklist assinada a 2026-10-17 18:21, depois da sessão do Sprint Review das 09:30, por os relatórios e checklists formais só terem sido conhecidos como obrigatórios nesse dia; o grupo considera a auditoria completa. | P26: André Filipe Moreira Mesquita; Gonçalo Dinis Magalhães Teixeira; Ivan Cristiano Silva Mendes | Q26: =IF(OR($A26="",NOT(ISNUMBER($L26)),NOT(ISNUMBER($N26))),"",$L26*$N26) -> 3 | R26: 46313.431 | S26: 46312.765 | T26: =IF(OR($A26="",$R26="",$S26=""),"",MAX(0,($S26-$R26)*24)) -> 0 | U26: Sem atraso | V26: =IF($A26="","",IF($U26="","",IFERROR(VLOOKUP($U26,'Listas de apoio'!$S$5:$T$10,2,FALSE()),""))) -> 0 | W26: =IF(OR($A26="",NOT(ISNUMBER($L26)),NOT(ISNUMBER($Q26))),"",$L26-$Q26) -> 0 | X26: =IF(OR($A26="",NOT(ISNUMBER($Q26)),NOT(ISNUMBER($V26))),"",$Q26*(1-$V26)) -> 3 | Y26: =IF(OR($A26="",NOT(ISNUMBER($Q26)),NOT(ISNUMBER($X26))),"",$Q26-$X26) -> 0 | Z26: =IF(NOT(ISNUMBER($X26)),"",ROUND($X26,2)) -> 3
A27: S03 | B27: Não aplicável | C27: Secretário de Sprint 03 | D27: André Filipe Moreira Mesquita | E27: Secretário | F27: 10 | G27: Secretariado | H27: =IF($A27="","",IF($G27="Secretariado",10,IF($G27="Transferência recebida",0,IF($E27="Executor",$F27*60%,IF($E27="Revisor",$F27*30%,IF($E27="Auditor",$F27*10%,"")))))) -> 10 | I27: Não Aplicável | J27: 0 | K27: 0 | L27: =IF($A27="","",$H27-$J27+$K27) -> 10 | M27: Trabalho completo e correto | N27: =IF($A27="","",IF($M27="","",IF($E27="Executor",IFERROR(VLOOKUP($M27,'Listas de apoio'!$G$5:$H$9,2,FALSE()),""),IF($E27="Revisor",IFERROR(VLOOKUP($M27,'Listas de apoio'!$J$5:$K$8,2,FALSE()),""),IF($E27="Auditor",IFERROR(VLOOKUP($M27,'Listas de apoio'!$M$5:$N$7,2,FALSE()),""),IF($E27="Secretário",IFERROR(VLOOKUP($M27,'Listas de apoio'!$P$5:$Q$7,2,FALSE()),""),"")))))) -> 1 | O27: Convocatória do Sprint Review do Sprint 03 emitida a 2026-10-16 18:00, com 15 horas de antecedência face às 24 horas indicadas na convocatória, para a reunião de 2026-10-17 09:30. Os alunos com direito de voto deliberaram não aplicar penalização por atraso (ata do Sprint Review, deliberação 3); o prazo aplicável regista essa decisão. Restantes deveres de secretariado cumpridos. | P27: Gonçalo Dinis Magalhães Teixeira; Gonçalo Magalhães Ribeiro; Ivan Cristiano Silva Mendes | Q27: =IF(OR($A27="",NOT(ISNUMBER($L27)),NOT(ISNUMBER($N27))),"",$L27*$N27) -> 10 | R27: 46311.75 | S27: 46311.75 | T27: =IF(OR($A27="",$R27="",$S27=""),"",MAX(0,($S27-$R27)*24)) -> 0 | U27: Sem atraso | V27: =IF($A27="","",IF($U27="","",IFERROR(VLOOKUP($U27,'Listas de apoio'!$S$5:$T$10,2,FALSE()),""))) -> 0 | W27: =IF(OR($A27="",NOT(ISNUMBER($L27)),NOT(ISNUMBER($Q27))),"",$L27-$Q27) -> 0 | X27: =IF(OR($A27="",NOT(ISNUMBER($Q27)),NOT(ISNUMBER($V27))),"",$Q27*(1-$V27)) -> 10 | Y27: =IF(OR($A27="",NOT(ISNUMBER($Q27)),NOT(ISNUMBER($X27))),"",$Q27-$X27) -> 0 | Z27: =IF(NOT(ISNUMBER($X27)),"",ROUND($X27,2)) -> 10
H28: =IF($A28="","",IF($G28="Secretariado",10,IF($G28="Transferência recebida",0,IF($E28="Executor",$F28*60%,IF($E28="Revisor",$F28*30%,IF($E28="Auditor",$F28*10%,"")))))) | L28: =IF($A28="","",$H28-$J28+$K28) | N28: =IF($A28="","",IF($M28="","",IF($E28="Executor",IFERROR(VLOOKUP($M28,'Listas de apoio'!$G$5:$H$9,2,FALSE()),""),IF($E28="Revisor",IFERROR(VLOOKUP($M28,'Listas de apoio'!$J$5:$K$8,2,FALSE()),""),IF($E28="Auditor",IFERROR(VLOOKUP($M28,'Listas de apoio'!$M$5:$N$7,2,FALSE()),""),IF($E28="Secretário",IFERROR(VLOOKUP($M28,'Listas de apoio'!$P$5:$Q$7,2,FALSE()),""),"")))))) | Q28: =IF(OR($A28="",NOT(ISNUMBER($L28)),NOT(ISNUMBER($N28))),"",$L28*$N28) | T28: =IF(OR($A28="",$R28="",$S28=""),"",MAX(0,($S28-$R28)*24)) | V28: =IF($A28="","",IF($U28="","",IFERROR(VLOOKUP($U28,'Listas de apoio'!$S$5:$T$10,2,FALSE()),""))) | W28: =IF(OR($A28="",NOT(ISNUMBER($L28)),NOT(ISNUMBER($Q28))),"",$L28-$Q28) | X28: =IF(OR($A28="",NOT(ISNUMBER($Q28)),NOT(ISNUMBER($V28))),"",$Q28*(1-$V28)) | Y28: =IF(OR($A28="",NOT(ISNUMBER($Q28)),NOT(ISNUMBER($X28))),"",$Q28-$X28) | Z28: =IF(NOT(ISNUMBER($X28)),"",ROUND($X28,2))
H29: =IF($A29="","",IF($G29="Secretariado",10,IF($G29="Transferência recebida",0,IF($E29="Executor",$F29*60%,IF($E29="Revisor",$F29*30%,IF($E29="Auditor",$F29*10%,"")))))) | L29: =IF($A29="","",$H29-$J29+$K29) | N29: =IF($A29="","",IF($M29="","",IF($E29="Executor",IFERROR(VLOOKUP($M29,'Listas de apoio'!$G$5:$H$9,2,FALSE()),""),IF($E29="Revisor",IFERROR(VLOOKUP($M29,'Listas de apoio'!$J$5:$K$8,2,FALSE()),""),IF($E29="Auditor",IFERROR(VLOOKUP($M29,'Listas de apoio'!$M$5:$N$7,2,FALSE()),""),IF($E29="Secretário",IFERROR(VLOOKUP($M29,'Listas de apoio'!$P$5:$Q$7,2,FALSE()),""),"")))))) | Q29: =IF(OR($A29="",NOT(ISNUMBER($L29)),NOT(ISNUMBER($N29))),"",$L29*$N29) | T29: =IF(OR($A29="",$R29="",$S29=""),"",MAX(0,($S29-$R29)*24)) | V29: =IF($A29="","",IF($U29="","",IFERROR(VLOOKUP($U29,'Listas de apoio'!$S$5:$T$10,2,FALSE()),""))) | W29: =IF(OR($A29="",NOT(ISNUMBER($L29)),NOT(ISNUMBER($Q29))),"",$L29-$Q29) | X29: =IF(OR($A29="",NOT(ISNUMBER($Q29)),NOT(ISNUMBER($V29))),"",$Q29*(1-$V29)) | Y29: =IF(OR($A29="",NOT(ISNUMBER($Q29)),NOT(ISNUMBER($X29))),"",$Q29-$X29) | Z29: =IF(NOT(ISNUMBER($X29)),"",ROUND($X29,2))
H30: =IF($A30="","",IF($G30="Secretariado",10,IF($G30="Transferência recebida",0,IF($E30="Executor",$F30*60%,IF($E30="Revisor",$F30*30%,IF($E30="Auditor",$F30*10%,"")))))) | L30: =IF($A30="","",$H30-$J30+$K30) | N30: =IF($A30="","",IF($M30="","",IF($E30="Executor",IFERROR(VLOOKUP($M30,'Listas de apoio'!$G$5:$H$9,2,FALSE()),""),IF($E30="Revisor",IFERROR(VLOOKUP($M30,'Listas de apoio'!$J$5:$K$8,2,FALSE()),""),IF($E30="Auditor",IFERROR(VLOOKUP($M30,'Listas de apoio'!$M$5:$N$7,2,FALSE()),""),IF($E30="Secretário",IFERROR(VLOOKUP($M30,'Listas de apoio'!$P$5:$Q$7,2,FALSE()),""),"")))))) | Q30: =IF(OR($A30="",NOT(ISNUMBER($L30)),NOT(ISNUMBER($N30))),"",$L30*$N30) | T30: =IF(OR($A30="",$R30="",$S30=""),"",MAX(0,($S30-$R30)*24)) | V30: =IF($A30="","",IF($U30="","",IFERROR(VLOOKUP($U30,'Listas de apoio'!$S$5:$T$10,2,FALSE()),""))) | W30: =IF(OR($A30="",NOT(ISNUMBER($L30)),NOT(ISNUMBER($Q30))),"",$L30-$Q30) | X30: =IF(OR($A30="",NOT(ISNUMBER($Q30)),NOT(ISNUMBER($V30))),"",$Q30*(1-$V30)) | Y30: =IF(OR($A30="",NOT(ISNUMBER($Q30)),NOT(ISNUMBER($X30))),"",$Q30-$X30) | Z30: =IF(NOT(ISNUMBER($X30)),"",ROUND($X30,2))
H31: =IF($A31="","",IF($G31="Secretariado",10,IF($G31="Transferência recebida",0,IF($E31="Executor",$F31*60%,IF($E31="Revisor",$F31*30%,IF($E31="Auditor",$F31*10%,"")))))) | L31: =IF($A31="","",$H31-$J31+$K31) | N31: =IF($A31="","",IF($M31="","",IF($E31="Executor",IFERROR(VLOOKUP($M31,'Listas de apoio'!$G$5:$H$9,2,FALSE()),""),IF($E31="Revisor",IFERROR(VLOOKUP($M31,'Listas de apoio'!$J$5:$K$8,2,FALSE()),""),IF($E31="Auditor",IFERROR(VLOOKUP($M31,'Listas de apoio'!$M$5:$N$7,2,FALSE()),""),IF($E31="Secretário",IFERROR(VLOOKUP($M31,'Listas de apoio'!$P$5:$Q$7,2,FALSE()),""),"")))))) | Q31: =IF(OR($A31="",NOT(ISNUMBER($L31)),NOT(ISNUMBER($N31))),"",$L31*$N31) | T31: =IF(OR($A31="",$R31="",$S31=""),"",MAX(0,($S31-$R31)*24)) | V31: =IF($A31="","",IF($U31="","",IFERROR(VLOOKUP($U31,'Listas de apoio'!$S$5:$T$10,2,FALSE()),""))) | W31: =IF(OR($A31="",NOT(ISNUMBER($L31)),NOT(ISNUMBER($Q31))),"",$L31-$Q31) | X31: =IF(OR($A31="",NOT(ISNUMBER($Q31)),NOT(ISNUMBER($V31))),"",$Q31*(1-$V31)) | Y31: =IF(OR($A31="",NOT(ISNUMBER($Q31)),NOT(ISNUMBER($X31))),"",$Q31-$X31) | Z31: =IF(NOT(ISNUMBER($X31)),"",ROUND($X31,2))
H32: =IF($A32="","",IF($G32="Secretariado",10,IF($G32="Transferência recebida",0,IF($E32="Executor",$F32*60%,IF($E32="Revisor",$F32*30%,IF($E32="Auditor",$F32*10%,"")))))) | L32: =IF($A32="","",$H32-$J32+$K32) | N32: =IF($A32="","",IF($M32="","",IF($E32="Executor",IFERROR(VLOOKUP($M32,'Listas de apoio'!$G$5:$H$9,2,FALSE()),""),IF($E32="Revisor",IFERROR(VLOOKUP($M32,'Listas de apoio'!$J$5:$K$8,2,FALSE()),""),IF($E32="Auditor",IFERROR(VLOOKUP($M32,'Listas de apoio'!$M$5:$N$7,2,FALSE()),""),IF($E32="Secretário",IFERROR(VLOOKUP($M32,'Listas de apoio'!$P$5:$Q$7,2,FALSE()),""),"")))))) | Q32: =IF(OR($A32="",NOT(ISNUMBER($L32)),NOT(ISNUMBER($N32))),"",$L32*$N32) | T32: =IF(OR($A32="",$R32="",$S32=""),"",MAX(0,($S32-$R32)*24)) | V32: =IF($A32="","",IF($U32="","",IFERROR(VLOOKUP($U32,'Listas de apoio'!$S$5:$T$10,2,FALSE()),""))) | W32: =IF(OR($A32="",NOT(ISNUMBER($L32)),NOT(ISNUMBER($Q32))),"",$L32-$Q32) | X32: =IF(OR($A32="",NOT(ISNUMBER($Q32)),NOT(ISNUMBER($V32))),"",$Q32*(1-$V32)) | Y32: =IF(OR($A32="",NOT(ISNUMBER($Q32)),NOT(ISNUMBER($X32))),"",$Q32-$X32) | Z32: =IF(NOT(ISNUMBER($X32)),"",ROUND($X32,2))
H33: =IF($A33="","",IF($G33="Secretariado",10,IF($G33="Transferência recebida",0,IF($E33="Executor",$F33*60%,IF($E33="Revisor",$F33*30%,IF($E33="Auditor",$F33*10%,"")))))) | L33: =IF($A33="","",$H33-$J33+$K33) | N33: =IF($A33="","",IF($M33="","",IF($E33="Executor",IFERROR(VLOOKUP($M33,'Listas de apoio'!$G$5:$H$9,2,FALSE()),""),IF($E33="Revisor",IFERROR(VLOOKUP($M33,'Listas de apoio'!$J$5:$K$8,2,FALSE()),""),IF($E33="Auditor",IFERROR(VLOOKUP($M33,'Listas de apoio'!$M$5:$N$7,2,FALSE()),""),IF($E33="Secretário",IFERROR(VLOOKUP($M33,'Listas de apoio'!$P$5:$Q$7,2,FALSE()),""),"")))))) | Q33: =IF(OR($A33="",NOT(ISNUMBER($L33)),NOT(ISNUMBER($N33))),"",$L33*$N33) | T33: =IF(OR($A33="",$R33="",$S33=""),"",MAX(0,($S33-$R33)*24)) | V33: =IF($A33="","",IF($U33="","",IFERROR(VLOOKUP($U33,'Listas de apoio'!$S$5:$T$10,2,FALSE()),""))) | W33: =IF(OR($A33="",NOT(ISNUMBER($L33)),NOT(ISNUMBER($Q33))),"",$L33-$Q33) | X33: =IF(OR($A33="",NOT(ISNUMBER($Q33)),NOT(ISNUMBER($V33))),"",$Q33*(1-$V33)) | Y33: =IF(OR($A33="",NOT(ISNUMBER($Q33)),NOT(ISNUMBER($X33))),"",$Q33-$X33) | Z33: =IF(NOT(ISNUMBER($X33)),"",ROUND($X33,2))
H34: =IF($A34="","",IF($G34="Secretariado",10,IF($G34="Transferência recebida",0,IF($E34="Executor",$F34*60%,IF($E34="Revisor",$F34*30%,IF($E34="Auditor",$F34*10%,"")))))) | L34: =IF($A34="","",$H34-$J34+$K34) | N34: =IF($A34="","",IF($M34="","",IF($E34="Executor",IFERROR(VLOOKUP($M34,'Listas de apoio'!$G$5:$H$9,2,FALSE()),""),IF($E34="Revisor",IFERROR(VLOOKUP($M34,'Listas de apoio'!$J$5:$K$8,2,FALSE()),""),IF($E34="Auditor",IFERROR(VLOOKUP($M34,'Listas de apoio'!$M$5:$N$7,2,FALSE()),""),IF($E34="Secretário",IFERROR(VLOOKUP($M34,'Listas de apoio'!$P$5:$Q$7,2,FALSE()),""),"")))))) | Q34: =IF(OR($A34="",NOT(ISNUMBER($L34)),NOT(ISNUMBER($N34))),"",$L34*$N34) | T34: =IF(OR($A34="",$R34="",$S34=""),"",MAX(0,($S34-$R34)*24)) | V34: =IF($A34="","",IF($U34="","",IFERROR(VLOOKUP($U34,'Listas de apoio'!$S$5:$T$10,2,FALSE()),""))) | W34: =IF(OR($A34="",NOT(ISNUMBER($L34)),NOT(ISNUMBER($Q34))),"",$L34-$Q34) | X34: =IF(OR($A34="",NOT(ISNUMBER($Q34)),NOT(ISNUMBER($V34))),"",$Q34*(1-$V34)) | Y34: =IF(OR($A34="",NOT(ISNUMBER($Q34)),NOT(ISNUMBER($X34))),"",$Q34-$X34) | Z34: =IF(NOT(ISNUMBER($X34)),"",ROUND($X34,2))
H35: =IF($A35="","",IF($G35="Secretariado",10,IF($G35="Transferência recebida",0,IF($E35="Executor",$F35*60%,IF($E35="Revisor",$F35*30%,IF($E35="Auditor",$F35*10%,"")))))) | L35: =IF($A35="","",$H35-$J35+$K35) | N35: =IF($A35="","",IF($M35="","",IF($E35="Executor",IFERROR(VLOOKUP($M35,'Listas de apoio'!$G$5:$H$9,2,FALSE()),""),IF($E35="Revisor",IFERROR(VLOOKUP($M35,'Listas de apoio'!$J$5:$K$8,2,FALSE()),""),IF($E35="Auditor",IFERROR(VLOOKUP($M35,'Listas de apoio'!$M$5:$N$7,2,FALSE()),""),IF($E35="Secretário",IFERROR(VLOOKUP($M35,'Listas de apoio'!$P$5:$Q$7,2,FALSE()),""),"")))))) | Q35: =IF(OR($A35="",NOT(ISNUMBER($L35)),NOT(ISNUMBER($N35))),"",$L35*$N35) | T35: =IF(OR($A35="",$R35="",$S35=""),"",MAX(0,($S35-$R35)*24)) | V35: =IF($A35="","",IF($U35="","",IFERROR(VLOOKUP($U35,'Listas de apoio'!$S$5:$T$10,2,FALSE()),""))) | W35: =IF(OR($A35="",NOT(ISNUMBER($L35)),NOT(ISNUMBER($Q35))),"",$L35-$Q35) | X35: =IF(OR($A35="",NOT(ISNUMBER($Q35)),NOT(ISNUMBER($V35))),"",$Q35*(1-$V35)) | Y35: =IF(OR($A35="",NOT(ISNUMBER($Q35)),NOT(ISNUMBER($X35))),"",$Q35-$X35) | Z35: =IF(NOT(ISNUMBER($X35)),"",ROUND($X35,2))
H36: =IF($A36="","",IF($G36="Secretariado",10,IF($G36="Transferência recebida",0,IF($E36="Executor",$F36*60%,IF($E36="Revisor",$F36*30%,IF($E36="Auditor",$F36*10%,"")))))) | L36: =IF($A36="","",$H36-$J36+$K36) | N36: =IF($A36="","",IF($M36="","",IF($E36="Executor",IFERROR(VLOOKUP($M36,'Listas de apoio'!$G$5:$H$9,2,FALSE()),""),IF($E36="Revisor",IFERROR(VLOOKUP($M36,'Listas de apoio'!$J$5:$K$8,2,FALSE()),""),IF($E36="Auditor",IFERROR(VLOOKUP($M36,'Listas de apoio'!$M$5:$N$7,2,FALSE()),""),IF($E36="Secretário",IFERROR(VLOOKUP($M36,'Listas de apoio'!$P$5:$Q$7,2,FALSE()),""),"")))))) | Q36: =IF(OR($A36="",NOT(ISNUMBER($L36)),NOT(ISNUMBER($N36))),"",$L36*$N36) | T36: =IF(OR($A36="",$R36="",$S36=""),"",MAX(0,($S36-$R36)*24)) | V36: =IF($A36="","",IF($U36="","",IFERROR(VLOOKUP($U36,'Listas de apoio'!$S$5:$T$10,2,FALSE()),""))) | W36: =IF(OR($A36="",NOT(ISNUMBER($L36)),NOT(ISNUMBER($Q36))),"",$L36-$Q36) | X36: =IF(OR($A36="",NOT(ISNUMBER($Q36)),NOT(ISNUMBER($V36))),"",$Q36*(1-$V36)) | Y36: =IF(OR($A36="",NOT(ISNUMBER($Q36)),NOT(ISNUMBER($X36))),"",$Q36-$X36) | Z36: =IF(NOT(ISNUMBER($X36)),"",ROUND($X36,2))
H37: =IF($A37="","",IF($G37="Secretariado",10,IF($G37="Transferência recebida",0,IF($E37="Executor",$F37*60%,IF($E37="Revisor",$F37*30%,IF($E37="Auditor",$F37*10%,"")))))) | L37: =IF($A37="","",$H37-$J37+$K37) | N37: =IF($A37="","",IF($M37="","",IF($E37="Executor",IFERROR(VLOOKUP($M37,'Listas de apoio'!$G$5:$H$9,2,FALSE()),""),IF($E37="Revisor",IFERROR(VLOOKUP($M37,'Listas de apoio'!$J$5:$K$8,2,FALSE()),""),IF($E37="Auditor",IFERROR(VLOOKUP($M37,'Listas de apoio'!$M$5:$N$7,2,FALSE()),""),IF($E37="Secretário",IFERROR(VLOOKUP($M37,'Listas de apoio'!$P$5:$Q$7,2,FALSE()),""),"")))))) | Q37: =IF(OR($A37="",NOT(ISNUMBER($L37)),NOT(ISNUMBER($N37))),"",$L37*$N37) | T37: =IF(OR($A37="",$R37="",$S37=""),"",MAX(0,($S37-$R37)*24)) | V37: =IF($A37="","",IF($U37="","",IFERROR(VLOOKUP($U37,'Listas de apoio'!$S$5:$T$10,2,FALSE()),""))) | W37: =IF(OR($A37="",NOT(ISNUMBER($L37)),NOT(ISNUMBER($Q37))),"",$L37-$Q37) | X37: =IF(OR($A37="",NOT(ISNUMBER($Q37)),NOT(ISNUMBER($V37))),"",$Q37*(1-$V37)) | Y37: =IF(OR($A37="",NOT(ISNUMBER($Q37)),NOT(ISNUMBER($X37))),"",$Q37-$X37) | Z37: =IF(NOT(ISNUMBER($X37)),"",ROUND($X37,2))
H38: =IF($A38="","",IF($G38="Secretariado",10,IF($G38="Transferência recebida",0,IF($E38="Executor",$F38*60%,IF($E38="Revisor",$F38*30%,IF($E38="Auditor",$F38*10%,"")))))) | L38: =IF($A38="","",$H38-$J38+$K38) | N38: =IF($A38="","",IF($M38="","",IF($E38="Executor",IFERROR(VLOOKUP($M38,'Listas de apoio'!$G$5:$H$9,2,FALSE()),""),IF($E38="Revisor",IFERROR(VLOOKUP($M38,'Listas de apoio'!$J$5:$K$8,2,FALSE()),""),IF($E38="Auditor",IFERROR(VLOOKUP($M38,'Listas de apoio'!$M$5:$N$7,2,FALSE()),""),IF($E38="Secretário",IFERROR(VLOOKUP($M38,'Listas de apoio'!$P$5:$Q$7,2,FALSE()),""),"")))))) | Q38: =IF(OR($A38="",NOT(ISNUMBER($L38)),NOT(ISNUMBER($N38))),"",$L38*$N38) | T38: =IF(OR($A38="",$R38="",$S38=""),"",MAX(0,($S38-$R38)*24)) | V38: =IF($A38="","",IF($U38="","",IFERROR(VLOOKUP($U38,'Listas de apoio'!$S$5:$T$10,2,FALSE()),""))) | W38: =IF(OR($A38="",NOT(ISNUMBER($L38)),NOT(ISNUMBER($Q38))),"",$L38-$Q38) | X38: =IF(OR($A38="",NOT(ISNUMBER($Q38)),NOT(ISNUMBER($V38))),"",$Q38*(1-$V38)) | Y38: =IF(OR($A38="",NOT(ISNUMBER($Q38)),NOT(ISNUMBER($X38))),"",$Q38-$X38) | Z38: =IF(NOT(ISNUMBER($X38)),"",ROUND($X38,2))
H39: =IF($A39="","",IF($G39="Secretariado",10,IF($G39="Transferência recebida",0,IF($E39="Executor",$F39*60%,IF($E39="Revisor",$F39*30%,IF($E39="Auditor",$F39*10%,"")))))) | L39: =IF($A39="","",$H39-$J39+$K39) | N39: =IF($A39="","",IF($M39="","",IF($E39="Executor",IFERROR(VLOOKUP($M39,'Listas de apoio'!$G$5:$H$9,2,FALSE()),""),IF($E39="Revisor",IFERROR(VLOOKUP($M39,'Listas de apoio'!$J$5:$K$8,2,FALSE()),""),IF($E39="Auditor",IFERROR(VLOOKUP($M39,'Listas de apoio'!$M$5:$N$7,2,FALSE()),""),IF($E39="Secretário",IFERROR(VLOOKUP($M39,'Listas de apoio'!$P$5:$Q$7,2,FALSE()),""),"")))))) | Q39: =IF(OR($A39="",NOT(ISNUMBER($L39)),NOT(ISNUMBER($N39))),"",$L39*$N39) | T39: =IF(OR($A39="",$R39="",$S39=""),"",MAX(0,($S39-$R39)*24)) | V39: =IF($A39="","",IF($U39="","",IFERROR(VLOOKUP($U39,'Listas de apoio'!$S$5:$T$10,2,FALSE()),""))) | W39: =IF(OR($A39="",NOT(ISNUMBER($L39)),NOT(ISNUMBER($Q39))),"",$L39-$Q39) | X39: =IF(OR($A39="",NOT(ISNUMBER($Q39)),NOT(ISNUMBER($V39))),"",$Q39*(1-$V39)) | Y39: =IF(OR($A39="",NOT(ISNUMBER($Q39)),NOT(ISNUMBER($X39))),"",$Q39-$X39) | Z39: =IF(NOT(ISNUMBER($X39)),"",ROUND($X39,2))
... H88: =IF($A88="","",IF($G88="Secretariado",10,IF($G88="Transferência recebida",0,IF($E88="Executor",$F88*60%,IF($E88="Revisor",$F88*30%,IF($E88="Auditor",$F88*10%,"")))))) | L88: =IF($A88="","",$H88-$J88+$K88) | N88: =IF($A88="","",IF($M88="","",IF($E88="Executor",IFERROR(VLOOKUP($M88,'Listas de apoio'!$G$5:$H$9,2,FALSE()),""),IF($E88="Revisor",IFERROR(VLOOKUP($M88,'Listas de apoio'!$J$5:$K$8,2,FALSE()),""),IF($E88="Auditor",IFERROR(VLOOKUP($M88,'Listas de apoio'!$M$5:$N$7,2,FALSE()),""),IF($E88="Secretário",IFERROR(VLOOKUP($M88,'Listas de apoio'!$P$5:$Q$7,2,FALSE()),""),"")))))) | Q88: =IF(OR($A88="",NOT(ISNUMBER($L88)),NOT(ISNUMBER($N88))),"",$L88*$N88) | T88: =IF(OR($A88="",$R88="",$S88=""),"",MAX(0,($S88-$R88)*24)) | V88: =IF($A88="","",IF($U88="","",IFERROR(VLOOKUP($U88,'Listas de apoio'!$S$5:$T$10,2,FALSE()),""))) | W88: =IF(OR($A88="",NOT(ISNUMBER($L88)),NOT(ISNUMBER($Q88))),"",$L88-$Q88) | X88: =IF(OR($A88="",NOT(ISNUMBER($Q88)),NOT(ISNUMBER($V88))),"",$Q88*(1-$V88)) | Y88: =IF(OR($A88="",NOT(ISNUMBER($Q88)),NOT(ISNUMBER($X88))),"",$Q88-$X88) | Z88: =IF(NOT(ISNUMBER($X88)),"",ROUND($X88,2))

Sheet Validação
A1: VALIDAÇÃO DO MAPA DE PONTUAÇÃO INDIVIDUAL
A2: Esta folha deteta incoerências básicas. Um resultado «OK» não substitui a apreciação e aprovação formal dos resultados do Sprint no Sprint Review, nem a aprovação dos valores finais acumulados no fecho do Momento de Avaliação, nem a verificação do docente.
A4: Verificação | B4: Resultado | C4: Estado | D4: Interpretação
A5: Linhas de pontuação registadas | B5: =COUNTIF('Detalhe da Pontuação'!A18:A88,"<>") -> 10 | C5: Informação | D5: Número de linhas preenchidas no detalhe, incluindo as linhas de Secretariado e as parcelas recebidas por transferência.
A6: Sprints registados nas fontes documentais | B6: =COUNTA('Detalhe da Pontuação'!A6:A14) -> 1 | C6: Informação | D6: Número de Sprints para os quais foram identificadas as versões vigentes do Sprint Backlog.
A7: Total de Pontos Efetivamente Obtidos do grupo | B7: =SUM('Detalhe da Pontuação'!Z18:Z88) -> 101 | C7: Informação | D7: Soma de todos os PEO antes do cálculo dos índices e das notas individuais.
A8: Sprints sem identificação simultânea do ficheiro editável (XLS/XLSX) e do PDF assinado | B8: =COUNTIFS('Detalhe da Pontuação'!A6:A14,"<>",'Detalhe da Pontuação'!B6:B14,"")+COUNTIFS('Detalhe da Pontuação'!A6:A14,"<>",'Detalhe da Pontuação'!I6:I14,"") -> 0 | C8: =IF(ABS(B8)<=0.005,"OK","Rever") -> OK | D8: Deve ser 0. Cada Sprint deve identificar a última versão cumulativa do Sprint Backlog no formato editável utilizado, XLS ou XLSX, e o PDF assinado que a congelou.
A9: Campos obrigatórios vazios nas linhas de pontuação | B9: =COUNTIFS('Detalhe da Pontuação'!A18:A88,"<>",'Detalhe da Pontuação'!D18:D88,"")+COUNTIFS('Detalhe da Pontuação'!A18:A88,"<>",'Detalhe da Pontuação'!E18:E88,"")+COUNTIFS('Detalhe da Pontuação'!A18:A88,"<>",'Detalhe da Pontuação'!F18:F88,"")+COUNTIFS('Detalhe da Pontuação'!A18:A88,"<>",'Detalhe da Pontuação'!G18:G88,"")+COUNTIFS('Detalhe da Pontuação'!A18:A88,"<>",'Detalhe da Pontuação'!M18:M88,"")+COUNTIFS('Detalhe da Pontuação'!A18:A88,"<>",'Detalhe da Pontuação'!O18:O88,"")+COUNTIFS('Detalhe da Pontuação'!A18:A88,"<>",'Detalhe da Pontuação'!P18:P88,"")+COUNTIFS('Detalhe da Pontuação'!A18:A88,"<>",'Detalhe da Pontuação'!U18:U88,"") -> 0 | C9: =IF(ABS(B9)<=0.005,"OK","Rever") -> OK | D9: Deve ser 0. O resultado conta células obrigatórias vazias, não linhas.
A10: Linhas sem Issue ou tarefa, exceto Secretariado | B10: =COUNTIFS('Detalhe da Pontuação'!A18:A88,"<>",'Detalhe da Pontuação'!E18:E88,"<>Secretário",'Detalhe da Pontuação'!B18:B88,"")+COUNTIFS('Detalhe da Pontuação'!A18:A88,"<>",'Detalhe da Pontuação'!E18:E88,"<>Secretário",'Detalhe da Pontuação'!C18:C88,"") -> 0 | C10: =IF(ABS(B10)<=0.005,"OK","Rever") -> OK | D10: Deve ser 0. Apenas a linha do Secretário pode usar «—» na Issue; as restantes linhas identificam Issue e tarefa.
A11: Orçamentos vazios, nulos ou negativos | B11: =COUNTIFS('Detalhe da Pontuação'!A18:A88,"<>",'Detalhe da Pontuação'!F18:F88,"<=0") -> 0 | C11: =IF(ABS(B11)<=0.005,"OK","Rever") -> OK | D11: Deve ser 0. O orçamento é o valor total aprovado para a tarefa; no Secretariado é sempre 10 pontos.
A12: Linhas em que a PMI não corresponde ao planeamento inicial | B12: =SUM('Listas de apoio'!W5:W75) -> 0 | C12: =IF(ABS(B12)<=0.005,"OK","Rever") -> OK | D12: Deve ser 0. A PMI é 60%, 30% ou 10% do orçamento para os papéis iniciais, 0 para uma parcela recebida e 10 para o Secretariado.
A13: Transferências sem referência ao registo do Sprint Backlog | B13: =COUNTIFS('Detalhe da Pontuação'!A18:A88,"<>",'Detalhe da Pontuação'!G18:G88,"Transferência recebida",'Detalhe da Pontuação'!I18:I88,"")+COUNTIFS('Detalhe da Pontuação'!A18:A88,"<>",'Detalhe da Pontuação'!J18:J88,">0",'Detalhe da Pontuação'!I18:I88,"") -> 0 | C13: =IF(ABS(B13)<=0.005,"OK","Rever") -> OK | D13: Deve ser 0. Os pontos cedidos e recebidos têm de remeter para o registo formal da folha Transferências do Sprint Backlog vigente.
A14: Diferença entre o total de pontos cedidos e recebidos | B14: =ABS(SUM('Detalhe da Pontuação'!J18:J88)-SUM('Detalhe da Pontuação'!K18:K88)) -> 0 | C14: =IF(ABS(B14)<=0.005,"OK","Rever") -> OK | D14: Deve ser 0,00. Cada ponto cedido por um aluno deve aparecer como ponto recebido por outro aluno.
A15: Linhas em que a PMR não corresponde a PMI - PC + PR | B15: =SUM('Listas de apoio'!X5:X75) -> 0 | C15: =IF(ABS(B15)<=0.005,"OK","Rever") -> OK | D15: Deve ser 0. A Parcela Máxima Resultante é calculada por PMR = PMI - PC + PR.
A16: Linhas com PMR negativa | B16: =COUNTIFS('Detalhe da Pontuação'!A18:A88,"<>",'Detalhe da Pontuação'!L18:L88,"<0") -> 0 | C16: =IF(ABS(B16)<=0.005,"OK","Rever") -> OK | D16: Deve ser 0. Um aluno não pode ceder mais pontos do que os disponíveis na sua parcela.
A17: Categorias de qualidade incompatíveis com o papel | B17: =COUNTIFS('Detalhe da Pontuação'!A18:A88,"<>",'Detalhe da Pontuação'!M18:M88,"<>")-COUNT('Detalhe da Pontuação'!N18:N88) -> 0 | C17: =IF(ABS(B17)<=0.005,"OK","Rever") -> OK | D17: Deve ser 0. Cada papel utiliza exclusivamente a respetiva escala oficial de qualidade; uma categoria incompatível impede o cálculo de Q.
A18: Linhas em que o fator de qualidade Q não corresponde à categoria de qualidade aprovada | B18: =SUM('Listas de apoio'!AG5:AG75) -> 0 | C18: =IF(ABS(B18)<=0.005,"OK","Rever") -> OK | D18: Deve ser 0. Em cada linha, o fator Q deve corresponder à percentagem prevista na escala oficial do papel para a categoria de qualidade selecionada.
A19: Linhas em que PQ não corresponde a PMR × Q | B19: =SUM('Listas de apoio'!Y5:Y75) -> 0 | C19: =IF(ABS(B19)<=0.005,"OK","Rever") -> OK | D19: Deve ser 0. A Parcela de Qualidade é calculada por PQ = PMR × Q.
A20: Linhas em que as horas de atraso não correspondem às datas | B20: =SUM('Listas de apoio'!Z5:Z75) -> 0 | C20: =IF(ABS(B20)<=0.005,"OK","Rever") -> OK | D20: Deve ser 0. As horas de atraso são calculadas a partir do Prazo aplicável e da Data e hora de conclusão.
A21: Níveis da escala de atraso incompatíveis com as horas calculadas | B21: =SUM('Listas de apoio'!AE5:AE75) -> 0 | C21: =IF(ABS(B21)<=0.005,"OK","Rever") -> OK | D21: Deve ser 0. A opção selecionada deve corresponder às horas calculadas. A categoria de 100% também abrange conclusões posteriores ao Sprint Review e, nesse caso, exige confirmação humana.
A22: Linhas em que o fator A não corresponde ao nível selecionado | B22: =COUNTIFS('Detalhe da Pontuação'!A18:A88,"<>",'Detalhe da Pontuação'!U18:U88,"<>")-COUNT('Detalhe da Pontuação'!V18:V88) -> 0 | C22: =IF(ABS(B22)<=0.005,"OK","Rever") -> OK | D22: Deve ser 0. O fator A é preenchido automaticamente através da escala oficial de penalização por atraso.
A23: Linhas em que a perda de pontos por qualidade não corresponde a PMR − PQ | B23: =SUM('Listas de apoio'!AA5:AA75) -> 0 | C23: =IF(ABS(B23)<=0.005,"OK","Rever") -> OK | D23: Deve ser 0. Em cada linha, a perda por qualidade deve corresponder à diferença entre a Parcela Máxima Resultante (PMR) e a Parcela de Qualidade (PQ).
A24: Linhas em que o PEO antes do arredondamento não corresponde a PQ × (1 − A) | B24: =SUM('Listas de apoio'!AB5:AB75) -> 0 | C24: =IF(ABS(B24)<=0.005,"OK","Rever") -> OK | D24: Deve ser 0. Em cada linha, o PEO antes do arredondamento deve resultar da aplicação do fator de atraso à Parcela de Qualidade: PEO = PQ × (1 − A).
A25: Linhas em que a perda de pontos por atraso não corresponde a PQ − PEO não arredondado | B25: =SUM('Listas de apoio'!AC5:AC75) -> 0 | C25: =IF(ABS(B25)<=0.005,"OK","Rever") -> OK | D25: Deve ser 0. Em cada linha, a perda por atraso deve corresponder à diferença entre a Parcela de Qualidade (PQ) e o PEO antes do arredondamento.
A26: Linhas em que o PEO final não corresponde ao arredondamento do PEO não arredondado | B26: =SUM('Listas de apoio'!AD5:AD75) -> 0 | C26: =IF(ABS(B26)<=0.005,"OK","Rever") -> OK | D26: Deve ser 0. Em cada linha, o PEO final deve corresponder ao PEO não arredondado arredondado a duas casas decimais. É este valor que é somado no cálculo de P_i.
A27: Linhas em que o PEO excede a PMR | B27: {=SUMPRODUCT(('Detalhe da Pontuação'!A18:A88<>"")*IFERROR(('Detalhe da Pontuação'!Z18:Z88>'Detalhe da Pontuação'!L18:L88+0.005)*1,0))} -> 0 | C27: =IF(ABS(B27)<=0.005,"OK","Rever") -> OK | D27: Deve ser 0. A qualidade e o atraso nunca podem aumentar a parcela máxima resultante.
A28: Linhas de Secretariado cujo orçamento ou PMI não é 10 | B28: =COUNTIFS('Detalhe da Pontuação'!E18:E88,"Secretário",'Detalhe da Pontuação'!F18:F88,"<>10")+COUNTIFS('Detalhe da Pontuação'!E18:E88,"Secretário",'Detalhe da Pontuação'!H18:H88,"<>10") -> 0 | C28: =IF(ABS(B28)<=0.005,"OK","Rever") -> OK | D28: Deve ser 0. Cada Sprint atribui ao Secretariado um máximo inicial de 10 pontos; o PEO pode ser inferior devido a qualidade ou atraso.
A29: Diferença entre o Orçamento Total do Grupo — B_T e a soma das PMI | B29: =ABS('Mapa de Pontuação Individual'!B9-SUM('Detalhe da Pontuação'!H18:H88)) -> 0 | C29: =IF(ABS(B29)<=0.005,"OK","Rever") -> OK | D29: Deve ser 0,00. B_T inclui os orçamentos das tarefas uma única vez e 10 pontos de Secretariado por Sprint; a soma das PMI reconstrói esse total.
A30: Diferença entre o total de PEO do grupo e a soma dos totais individuais — P_i | B30: =ABS('Mapa de Pontuação Individual'!B10-SUM('Mapa de Pontuação Individual'!F14:F17)) -> 0 | C30: =IF(ABS(B30)<=0.005,"OK","Rever") -> OK | D30: Deve ser 0,00. O total dos PEO do grupo deve corresponder à soma dos P_i dos alunos.
A31: Alunos cujo Índice Bruto — IB_i não corresponde a (20 × n × P_i) / B_T | B31: =IF(ABS('Mapa de Pontuação Individual'!G14-(20*'Mapa de Pontuação Individual'!$B$7*'Mapa de Pontuação Individual'!F14/'Mapa de Pontuação Individual'!$B$9))>0.005,1,0)+IF(ABS('Mapa de Pontuação Individual'!G15-(20*'Mapa de Pontuação Individual'!$B$7*'Mapa de Pontuação Individual'!F15/'Mapa de Pontuação Individual'!$B$9))>0.005,1,0)+IF(ABS('Mapa de Pontuação Individual'!G16-(20*'Mapa de Pontuação Individual'!$B$7*'Mapa de Pontuação Individual'!F16/'Mapa de Pontuação Individual'!$B$9))>0.005,1,0)+IF(ABS('Mapa de Pontuação Individual'!G17-(20*'Mapa de Pontuação Individual'!$B$7*'Mapa de Pontuação Individual'!F17/'Mapa de Pontuação Individual'!$B$9))>0.005,1,0) -> 0 | C31: =IF(ABS(B31)<=0.005,"OK","Rever") -> OK | D31: Deve ser 0. O índice bruto conserva o resultado anterior à aplicação do limite de 20 valores.
A32: Alunos cuja Nota Individual — NI_i não corresponde a min(20; IB_i) | B32: =IF(ABS('Mapa de Pontuação Individual'!H14-MIN(20,'Mapa de Pontuação Individual'!G14))>0.005,1,0)+IF(ABS('Mapa de Pontuação Individual'!H15-MIN(20,'Mapa de Pontuação Individual'!G15))>0.005,1,0)+IF(ABS('Mapa de Pontuação Individual'!H16-MIN(20,'Mapa de Pontuação Individual'!G16))>0.005,1,0)+IF(ABS('Mapa de Pontuação Individual'!H17-MIN(20,'Mapa de Pontuação Individual'!G17))>0.005,1,0) -> 0 | C32: =IF(ABS(B32)<=0.005,"OK","Rever") -> OK | D32: Deve ser 0. A Nota Individual é NI_i = min(20; IB_i).
A33: Número de alunos diferente de 4 sem referência de autorização | B33: =IF(AND('Mapa de Pontuação Individual'!B7<>4,OR('Mapa de Pontuação Individual'!B8="",'Mapa de Pontuação Individual'!B8="Não aplicável — n = 4")),1,0) -> 0 | C33: =IF(ABS(B33)<=0.005,"OK","Rever") -> OK | D33: Deve ser 0. Um grupo com n diferente de 4 exige autorização do docente e a respetiva referência documental.

Sheet Instruções
A1: INSTRUÇÕES DE PREENCHIMENTO
A2: Leia estas regras antes de substituir os exemplos. O ficheiro deve permitir reconstruir todos os cálculos aprovados e não substitui a ata do Sprint Review nem os restantes documentos oficiais.
A3: N.º | B3: Tema | C3: Regra essencial | D3: Aplicação prática
A4: 1 | B4: Finalidade | C4: Este mapa é cumulativo por Momento de Avaliação e é preparado como suporte aos Sprint Reviews e, no final do Momento de Avaliação, à reunião formal autónoma de fecho. Reúne o detalhe necessário para calcular os Pontos Efetivamente Obtidos e os valores acumulados P_i, IB_i e NI_i. | D4: Em cada Sprint Review, complete as categorias aprovadas, os atrasos imputáveis, os fundamentos e os PEO. A ata do Sprint Review resume esses resultados e identifica o ficheiro editável em XLS ou XLSX e o respetivo PDF assinado. No fecho do Momento de Avaliação, a reunião formal autónoma aprecia e aprova os valores finais n, B_T, P_i, IB_i e NI_i.
A5: 2 | B5: Fonte do planeamento | C5: A PMI e os responsáveis iniciais vêm do Sprint Backlog aprovado no Sprint Planning. Use sempre a última versão cumulativa formalmente aprovada antes do Sprint Review. | D5: Se não houve transferências, será normalmente a versão aprovada no Sprint Planning. Se houve transferências, use a última versão resultante da reunião formal mais recente.
A6: 3 | B6: Fonte normativa | C6: No bloco Sprints e fontes documentais, identifique o ficheiro editável vigente, em formato XLS ou XLSX, e o PDF assinado que congelou essa versão. O PDF assinado é a fonte normativa; o ficheiro editável permite consultar dados e fórmulas. | D6: Não use apenas uma ligação para uma Issue ou uma versão editável que não tenha sido congelada e assinada.
A7: 4 | B7: Transferências | C7: Os PC e PR vêm da folha Transferências do Sprint Backlog vigente. Uma transferência não altera a PMI nem apaga a atribuição inicial. | D7: Na linha do cedente, registe PC. Na linha do destinatário, use Origem da parcela = Transferência recebida, PMI = 0 e registe PR. Ambas as linhas remetem para o mesmo identificador de transferência.
A8: 5 | B8: PMR | C8: A Parcela Máxima Resultante é calculada por PMR = PMI - PC + PR. | D8: A soma dos pontos cedidos no mapa deve ser igual à soma dos pontos recebidos. A PMR nunca pode ser negativa.
