Workbook
Name AlunosRotacao: 'Listas de apoio'!$A$5:$A$8
Name Confirmacoes: 'Listas de apoio'!$I$5:$I$7
Name MilestonesRotacao: 'Listas de apoio'!$C$5:$C$8
Name ModelosLideranca: 'Listas de apoio'!$K$5:$K$6
Name PapeisRotacao: 'Listas de apoio'!$M$5:$M$7
Name SituacoesSprint: 'Listas de apoio'!$G$5:$G$6
Name SprintsRotacao: 'Listas de apoio'!$E$5:$E$24

Sheet Grelha de Rotação de Papéis
A1: GRELHA DE ROTAÇÃO DE PAPÉIS | B1: GRELHA DE ROTAÇÃO DE PAPÉIS | C1: GRELHA DE ROTAÇÃO DE PAPÉIS | D1: GRELHA DE ROTAÇÃO DE PAPÉIS | E1: GRELHA DE ROTAÇÃO DE PAPÉIS | F1: GRELHA DE ROTAÇÃO DE PAPÉIS | G1: GRELHA DE ROTAÇÃO DE PAPÉIS | H1: GRELHA DE ROTAÇÃO DE PAPÉIS | I1: GRELHA DE ROTAÇÃO DE PAPÉIS
A2: DOCUMENTO CUMULATIVO DE TODO O PROJETO — entregue uma versão atualizada em cada Milestone de Entrega. Os resumos são calculados a partir da folha «Registo da Rotação» e distinguem atribuições iniciais de desempenhos efetivamente confirmados. | B2: DOCUMENTO CUMULATIVO DE TODO O PROJETO — entregue uma versão atualizada em cada Milestone de Entrega. Os resumos são calculados a partir da folha «Registo da Rotação» e distinguem atribuições iniciais de desempenhos efetivamente confirmados. | C2: DOCUMENTO CUMULATIVO DE TODO O PROJETO — entregue uma versão atualizada em cada Milestone de Entrega. Os resumos são calculados a partir da folha «Registo da Rotação» e distinguem atribuições iniciais de desempenhos efetivamente confirmados. | D2: DOCUMENTO CUMULATIVO DE TODO O PROJETO — entregue uma versão atualizada em cada Milestone de Entrega. Os resumos são calculados a partir da folha «Registo da Rotação» e distinguem atribuições iniciais de desempenhos efetivamente confirmados. | E2: DOCUMENTO CUMULATIVO DE TODO O PROJETO — entregue uma versão atualizada em cada Milestone de Entrega. Os resumos são calculados a partir da folha «Registo da Rotação» e distinguem atribuições iniciais de desempenhos efetivamente confirmados. | F2: DOCUMENTO CUMULATIVO DE TODO O PROJETO — entregue uma versão atualizada em cada Milestone de Entrega. Os resumos são calculados a partir da folha «Registo da Rotação» e distinguem atribuições iniciais de desempenhos efetivamente confirmados. | G2: DOCUMENTO CUMULATIVO DE TODO O PROJETO — entregue uma versão atualizada em cada Milestone de Entrega. Os resumos são calculados a partir da folha «Registo da Rotação» e distinguem atribuições iniciais de desempenhos efetivamente confirmados. | H2: DOCUMENTO CUMULATIVO DE TODO O PROJETO — entregue uma versão atualizada em cada Milestone de Entrega. Os resumos são calculados a partir da folha «Registo da Rotação» e distinguem atribuições iniciais de desempenhos efetivamente confirmados. | I2: DOCUMENTO CUMULATIVO DE TODO O PROJETO — entregue uma versão atualizada em cada Milestone de Entrega. Os resumos são calculados a partir da folha «Registo da Rotação» e distinguem atribuições iniciais de desempenhos efetivamente confirmados.
A4: IDENTIFICAÇÃO | B4: IDENTIFICAÇÃO | C4: IDENTIFICAÇÃO | D4: IDENTIFICAÇÃO | E4: IDENTIFICAÇÃO | F4: IDENTIFICAÇÃO | G4: IDENTIFICAÇÃO | H4: IDENTIFICAÇÃO | I4: IDENTIFICAÇÃO
A5: Número de alunos considerado — n | B5: 4
A6: Referência da autorização para n diferente de 4 | B6: Não aplicável — n = 4
A7: Modelo de liderança | B7: Permanente
A8: Líder permanente | B8: Ivan Cristiano Silva Mendes
A10: RESUMO ACUMULADO POR ALUNO | B10: RESUMO ACUMULADO POR ALUNO | C10: RESUMO ACUMULADO POR ALUNO | D10: RESUMO ACUMULADO POR ALUNO | E10: RESUMO ACUMULADO POR ALUNO | F10: RESUMO ACUMULADO POR ALUNO | G10: RESUMO ACUMULADO POR ALUNO | H10: RESUMO ACUMULADO POR ALUNO | I10: RESUMO ACUMULADO POR ALUNO
A11: Aluno | B11: Executor — atribuições iniciais | C11: Executor — desempenhos confirmados | D11: Revisor — atribuições iniciais | E11: Revisor — desempenhos confirmados | F11: Auditor — atribuições iniciais | G11: Auditor — desempenhos confirmados | H11: Secretário — designações | I11: Secretariado confirmado
A12: =IF('Listas de apoio'!A5="","",'Listas de apoio'!A5) -> André Filipe Moreira Mesquita | B12: =IF(A12="","",COUNTIF('Registo da Rotação'!$F$54:$F$162,A12)) -> 2 | C12: =IF(A12="","",COUNTIFS('Registo da Rotação'!$F$54:$F$162,A12,'Registo da Rotação'!$I$54:$I$162,"Sim")+COUNTIFS('Registo da Rotação'!$D$168:$D$217,"Executor",'Registo da Rotação'!$F$168:$F$217,A12,'Registo da Rotação'!$H$168:$H$217,"Sim")) -> 2 | D12: =IF(A12="","",COUNTIF('Registo da Rotação'!$G$54:$G$162,A12)) -> 3 | E12: =IF(A12="","",COUNTIFS('Registo da Rotação'!$G$54:$G$162,A12,'Registo da Rotação'!$J$54:$J$162,"Sim")+COUNTIFS('Registo da Rotação'!$D$168:$D$217,"Revisor",'Registo da Rotação'!$F$168:$F$217,A12,'Registo da Rotação'!$H$168:$H$217,"Sim")) -> 3 | F12: =IF(A12="","",COUNTIF('Registo da Rotação'!$H$54:$H$162,A12)) -> 1 | G12: =IF(A12="","",COUNTIFS('Registo da Rotação'!$H$54:$H$162,A12,'Registo da Rotação'!$K$54:$K$162,"Sim")+COUNTIFS('Registo da Rotação'!$D$168:$D$217,"Auditor",'Registo da Rotação'!$F$168:$F$217,A12,'Registo da Rotação'!$H$168:$H$217,"Sim")) -> 1 | H12: =IF(A12="","",COUNTIF('Registo da Rotação'!$F$6:$F$25,A12)) -> 0 | I12: =IF(A12="","",COUNTIFS('Registo da Rotação'!$F$6:$F$25,A12,'Registo da Rotação'!$G$6:$G$25,"Sim")) -> 0
A13: =IF('Listas de apoio'!A6="","",'Listas de apoio'!A6) -> Gonçalo Dinis Magalhães Teixeira | B13: =IF(A13="","",COUNTIF('Registo da Rotação'!$F$54:$F$162,A13)) -> 2 | C13: =IF(A13="","",COUNTIFS('Registo da Rotação'!$F$54:$F$162,A13,'Registo da Rotação'!$I$54:$I$162,"Sim")+COUNTIFS('Registo da Rotação'!$D$168:$D$217,"Executor",'Registo da Rotação'!$F$168:$F$217,A13,'Registo da Rotação'!$H$168:$H$217,"Sim")) -> 2 | D13: =IF(A13="","",COUNTIF('Registo da Rotação'!$G$54:$G$162,A13)) -> 0 | E13: =IF(A13="","",COUNTIFS('Registo da Rotação'!$G$54:$G$162,A13,'Registo da Rotação'!$J$54:$J$162,"Sim")+COUNTIFS('Registo da Rotação'!$D$168:$D$217,"Revisor",'Registo da Rotação'!$F$168:$F$217,A13,'Registo da Rotação'!$H$168:$H$217,"Sim")) -> 0 | F13: =IF(A13="","",COUNTIF('Registo da Rotação'!$H$54:$H$162,A13)) -> 2 | G13: =IF(A13="","",COUNTIFS('Registo da Rotação'!$H$54:$H$162,A13,'Registo da Rotação'!$K$54:$K$162,"Sim")+COUNTIFS('Registo da Rotação'!$D$168:$D$217,"Auditor",'Registo da Rotação'!$F$168:$F$217,A13,'Registo da Rotação'!$H$168:$H$217,"Sim")) -> 2 | H13: =IF(A13="","",COUNTIF('Registo da Rotação'!$F$6:$F$25,A13)) -> 1 | I13: =IF(A13="","",COUNTIFS('Registo da Rotação'!$F$6:$F$25,A13,'Registo da Rotação'!$G$6:$G$25,"Sim")) -> 1
A14: =IF('Listas de apoio'!A7="","",'Listas de apoio'!A7) -> Gonçalo Magalhães Ribeiro | B14: =IF(A14="","",COUNTIF('Registo da Rotação'!$F$54:$F$162,A14)) -> 2 | C14: =IF(A14="","",COUNTIFS('Registo da Rotação'!$F$54:$F$162,A14,'Registo da Rotação'!$I$54:$I$162,"Sim")+COUNTIFS('Registo da Rotação'!$D$168:$D$217,"Executor",'Registo da Rotação'!$F$168:$F$217,A14,'Registo da Rotação'!$H$168:$H$217,"Sim")) -> 2 | D14: =IF(A14="","",COUNTIF('Registo da Rotação'!$G$54:$G$162,A14)) -> 2 | E14: =IF(A14="","",COUNTIFS('Registo da Rotação'!$G$54:$G$162,A14,'Registo da Rotação'!$J$54:$J$162,"Sim")+COUNTIFS('Registo da Rotação'!$D$168:$D$217,"Revisor",'Registo da Rotação'!$F$168:$F$217,A14,'Registo da Rotação'!$H$168:$H$217,"Sim")) -> 2 | F14: =IF(A14="","",COUNTIF('Registo da Rotação'!$H$54:$H$162,A14)) -> 2 | G14: =IF(A14="","",COUNTIFS('Registo da Rotação'!$H$54:$H$162,A14,'Registo da Rotação'!$K$54:$K$162,"Sim")+COUNTIFS('Registo da Rotação'!$D$168:$D$217,"Auditor",'Registo da Rotação'!$F$168:$F$217,A14,'Registo da Rotação'!$H$168:$H$217,"Sim")) -> 2 | H14: =IF(A14="","",COUNTIF('Registo da Rotação'!$F$6:$F$25,A14)) -> 0 | I14: =IF(A14="","",COUNTIFS('Registo da Rotação'!$F$6:$F$25,A14,'Registo da Rotação'!$G$6:$G$25,"Sim")) -> 0
A15: =IF('Listas de apoio'!A8="","",'Listas de apoio'!A8) -> Ivan Cristiano Silva Mendes | B15: =IF(A15="","",COUNTIF('Registo da Rotação'!$F$54:$F$162,A15)) -> 4 | C15: =IF(A15="","",COUNTIFS('Registo da Rotação'!$F$54:$F$162,A15,'Registo da Rotação'!$I$54:$I$162,"Sim")+COUNTIFS('Registo da Rotação'!$D$168:$D$217,"Executor",'Registo da Rotação'!$F$168:$F$217,A15,'Registo da Rotação'!$H$168:$H$217,"Sim")) -> 4 | D15: =IF(A15="","",COUNTIF('Registo da Rotação'!$G$54:$G$162,A15)) -> 5 | E15: =IF(A15="","",COUNTIFS('Registo da Rotação'!$G$54:$G$162,A15,'Registo da Rotação'!$J$54:$J$162,"Sim")+COUNTIFS('Registo da Rotação'!$D$168:$D$217,"Revisor",'Registo da Rotação'!$F$168:$F$217,A15,'Registo da Rotação'!$H$168:$H$217,"Sim")) -> 5 | F15: =IF(A15="","",COUNTIF('Registo da Rotação'!$H$54:$H$162,A15)) -> 5 | G15: =IF(A15="","",COUNTIFS('Registo da Rotação'!$H$54:$H$162,A15,'Registo da Rotação'!$K$54:$K$162,"Sim")+COUNTIFS('Registo da Rotação'!$D$168:$D$217,"Auditor",'Registo da Rotação'!$F$168:$F$217,A15,'Registo da Rotação'!$H$168:$H$217,"Sim")) -> 5 | H15: =IF(A15="","",COUNTIF('Registo da Rotação'!$F$6:$F$25,A15)) -> 0 | I15: =IF(A15="","",COUNTIFS('Registo da Rotação'!$F$6:$F$25,A15,'Registo da Rotação'!$G$6:$G$25,"Sim")) -> 0
A17: DISTRIBUIÇÃO GLOBAL DOS DESEMPENHOS CONFIRMADOS | B17: DISTRIBUIÇÃO GLOBAL DOS DESEMPENHOS CONFIRMADOS | C17: DISTRIBUIÇÃO GLOBAL DOS DESEMPENHOS CONFIRMADOS | D17: DISTRIBUIÇÃO GLOBAL DOS DESEMPENHOS CONFIRMADOS | E17: DISTRIBUIÇÃO GLOBAL DOS DESEMPENHOS CONFIRMADOS
A18: Papel | B18: Menor número por aluno | C18: Maior número por aluno | D18: Diferença | E18: Interpretação
A19: Executor | B19: =MIN(C12:C15) -> 2 | C19: =MAX(C12:C15) -> 4 | D19: =C19-B19 -> 2 | E19: =IF(D19=0,"Distribuição igual",IF(D19=1,"Distribuição aproximada","Analisar distribuição")) -> Analisar distribuição
A20: Revisor | B20: =MIN(E12:E15) -> 0 | C20: =MAX(E12:E15) -> 5 | D20: =C20-B20 -> 5 | E20: =IF(D20=0,"Distribuição igual",IF(D20=1,"Distribuição aproximada","Analisar distribuição")) -> Analisar distribuição
A21: Auditor | B21: =MIN(G12:G15) -> 1 | C21: =MAX(G12:G15) -> 5 | D21: =C21-B21 -> 4 | E21: =IF(D21=0,"Distribuição igual",IF(D21=1,"Distribuição aproximada","Analisar distribuição")) -> Analisar distribuição
A22: Secretário | B22: =MIN(I12:I15) -> 0 | C22: =MAX(I12:I15) -> 1 | D22: =C22-B22 -> 1 | E22: =IF(D22=0,"Distribuição igual",IF(D22=1,"Distribuição aproximada","Analisar distribuição")) -> Distribuição aproximada
A24: RESUMO POR MILESTONE DE ENTREGA | B24: RESUMO POR MILESTONE DE ENTREGA | C24: RESUMO POR MILESTONE DE ENTREGA | D24: RESUMO POR MILESTONE DE ENTREGA | E24: RESUMO POR MILESTONE DE ENTREGA | F24: RESUMO POR MILESTONE DE ENTREGA | G24: RESUMO POR MILESTONE DE ENTREGA
A25: Milestone de Entrega | B25: Aluno | C25: Executor confirmado | D25: Revisor confirmado | E25: Auditor confirmado | F25: Secretariado confirmado | G25: Cobertura dos três papéis
A26: ='Listas de apoio'!C5 -> m1 | B26: =IF('Listas de apoio'!A5="","",'Listas de apoio'!A5) -> André Filipe Moreira Mesquita | C26: =IF(B26="","",COUNTIFS('Registo da Rotação'!$B$54:$B$162,A26,'Registo da Rotação'!$F$54:$F$162,B26,'Registo da Rotação'!$I$54:$I$162,"Sim")+COUNTIFS('Registo da Rotação'!$A$168:$A$217,A26,'Registo da Rotação'!$D$168:$D$217,"Executor",'Registo da Rotação'!$F$168:$F$217,B26,'Registo da Rotação'!$H$168:$H$217,"Sim")) -> 2 | D26: =IF(B26="","",COUNTIFS('Registo da Rotação'!$B$54:$B$162,A26,'Registo da Rotação'!$G$54:$G$162,B26,'Registo da Rotação'!$J$54:$J$162,"Sim")+COUNTIFS('Registo da Rotação'!$A$168:$A$217,A26,'Registo da Rotação'!$D$168:$D$217,"Revisor",'Registo da Rotação'!$F$168:$F$217,B26,'Registo da Rotação'!$H$168:$H$217,"Sim")) -> 3 | E26: =IF(B26="","",COUNTIFS('Registo da Rotação'!$B$54:$B$162,A26,'Registo da Rotação'!$H$54:$H$162,B26,'Registo da Rotação'!$K$54:$K$162,"Sim")+COUNTIFS('Registo da Rotação'!$A$168:$A$217,A26,'Registo da Rotação'!$D$168:$D$217,"Auditor",'Registo da Rotação'!$F$168:$F$217,B26,'Registo da Rotação'!$H$168:$H$217,"Sim")) -> 1 | F26: =IF(B26="","",COUNTIFS('Registo da Rotação'!$A$6:$A$25,A26,'Registo da Rotação'!$F$6:$F$25,B26,'Registo da Rotação'!$G$6:$G$25,"Sim")) -> 0 | G26: =IF(B26="","",IF(COUNTIFS('Registo da Rotação'!$A$6:$A$25,A26,'Registo da Rotação'!$D$6:$D$25,"Em curso")>0,"Em avaliação",IF(COUNTIFS('Registo da Rotação'!$A$6:$A$25,A26,'Registo da Rotação'!$D$6:$D$25,"Concluído")=0,"Sem sprints concluídos",IF(COUNTIF('Registo da Rotação'!$B$54:$B$162,A26)<$B$5,"Não aplicável — tarefas insuficientes",IF(AND(C26>0,D26>0,E26>0),"Cumprida","Por cumprir"))))) -> Cumprida
A27: ='Listas de apoio'!C5 -> m1 | B27: =IF('Listas de apoio'!A6="","",'Listas de apoio'!A6) -> Gonçalo Dinis Magalhães Teixeira | C27: =IF(B27="","",COUNTIFS('Registo da Rotação'!$B$54:$B$162,A27,'Registo da Rotação'!$F$54:$F$162,B27,'Registo da Rotação'!$I$54:$I$162,"Sim")+COUNTIFS('Registo da Rotação'!$A$168:$A$217,A27,'Registo da Rotação'!$D$168:$D$217,"Executor",'Registo da Rotação'!$F$168:$F$217,B27,'Registo da Rotação'!$H$168:$H$217,"Sim")) -> 2 | D27: =IF(B27="","",COUNTIFS('Registo da Rotação'!$B$54:$B$162,A27,'Registo da Rotação'!$G$54:$G$162,B27,'Registo da Rotação'!$J$54:$J$162,"Sim")+COUNTIFS('Registo da Rotação'!$A$168:$A$217,A27,'Registo da Rotação'!$D$168:$D$217,"Revisor",'Registo da Rotação'!$F$168:$F$217,B27,'Registo da Rotação'!$H$168:$H$217,"Sim")) -> 0 | E27: =IF(B27="","",COUNTIFS('Registo da Rotação'!$B$54:$B$162,A27,'Registo da Rotação'!$H$54:$H$162,B27,'Registo da Rotação'!$K$54:$K$162,"Sim")+COUNTIFS('Registo da Rotação'!$A$168:$A$217,A27,'Registo da Rotação'!$D$168:$D$217,"Auditor",'Registo da Rotação'!$F$168:$F$217,B27,'Registo da Rotação'!$H$168:$H$217,"Sim")) -> 2 | F27: =IF(B27="","",COUNTIFS('Registo da Rotação'!$A$6:$A$25,A27,'Registo da Rotação'!$F$6:$F$25,B27,'Registo da Rotação'!$G$6:$G$25,"Sim")) -> 1 | G27: =IF(B27="","",IF(COUNTIFS('Registo da Rotação'!$A$6:$A$25,A27,'Registo da Rotação'!$D$6:$D$25,"Em curso")>0,"Em avaliação",IF(COUNTIFS('Registo da Rotação'!$A$6:$A$25,A27,'Registo da Rotação'!$D$6:$D$25,"Concluído")=0,"Sem sprints concluídos",IF(COUNTIF('Registo da Rotação'!$B$54:$B$162,A27)<$B$5,"Não aplicável — tarefas insuficientes",IF(AND(C27>0,D27>0,E27>0),"Cumprida","Por cumprir"))))) -> Por cumprir
A28: ='Listas de apoio'!C5 -> m1 | B28: =IF('Listas de apoio'!A7="","",'Listas de apoio'!A7) -> Gonçalo Magalhães Ribeiro | C28: =IF(B28="","",COUNTIFS('Registo da Rotação'!$B$54:$B$162,A28,'Registo da Rotação'!$F$54:$F$162,B28,'Registo da Rotação'!$I$54:$I$162,"Sim")+COUNTIFS('Registo da Rotação'!$A$168:$A$217,A28,'Registo da Rotação'!$D$168:$D$217,"Executor",'Registo da Rotação'!$F$168:$F$217,B28,'Registo da Rotação'!$H$168:$H$217,"Sim")) -> 2 | D28: =IF(B28="","",COUNTIFS('Registo da Rotação'!$B$54:$B$162,A28,'Registo da Rotação'!$G$54:$G$162,B28,'Registo da Rotação'!$J$54:$J$162,"Sim")+COUNTIFS('Registo da Rotação'!$A$168:$A$217,A28,'Registo da Rotação'!$D$168:$D$217,"Revisor",'Registo da Rotação'!$F$168:$F$217,B28,'Registo da Rotação'!$H$168:$H$217,"Sim")) -> 2 | E28: =IF(B28="","",COUNTIFS('Registo da Rotação'!$B$54:$B$162,A28,'Registo da Rotação'!$H$54:$H$162,B28,'Registo da Rotação'!$K$54:$K$162,"Sim")+COUNTIFS('Registo da Rotação'!$A$168:$A$217,A28,'Registo da Rotação'!$D$168:$D$217,"Auditor",'Registo da Rotação'!$F$168:$F$217,B28,'Registo da Rotação'!$H$168:$H$217,"Sim")) -> 2 | F28: =IF(B28="","",COUNTIFS('Registo da Rotação'!$A$6:$A$25,A28,'Registo da Rotação'!$F$6:$F$25,B28,'Registo da Rotação'!$G$6:$G$25,"Sim")) -> 0 | G28: =IF(B28="","",IF(COUNTIFS('Registo da Rotação'!$A$6:$A$25,A28,'Registo da Rotação'!$D$6:$D$25,"Em curso")>0,"Em avaliação",IF(COUNTIFS('Registo da Rotação'!$A$6:$A$25,A28,'Registo da Rotação'!$D$6:$D$25,"Concluído")=0,"Sem sprints concluídos",IF(COUNTIF('Registo da Rotação'!$B$54:$B$162,A28)<$B$5,"Não aplicável — tarefas insuficientes",IF(AND(C28>0,D28>0,E28>0),"Cumprida","Por cumprir"))))) -> Cumprida
A29: ='Listas de apoio'!C5 -> m1 | B29: =IF('Listas de apoio'!A8="","",'Listas de apoio'!A8) -> Ivan Cristiano Silva Mendes | C29: =IF(B29="","",COUNTIFS('Registo da Rotação'!$B$54:$B$162,A29,'Registo da Rotação'!$F$54:$F$162,B29,'Registo da Rotação'!$I$54:$I$162,"Sim")+COUNTIFS('Registo da Rotação'!$A$168:$A$217,A29,'Registo da Rotação'!$D$168:$D$217,"Executor",'Registo da Rotação'!$F$168:$F$217,B29,'Registo da Rotação'!$H$168:$H$217,"Sim")) -> 4 | D29: =IF(B29="","",COUNTIFS('Registo da Rotação'!$B$54:$B$162,A29,'Registo da Rotação'!$G$54:$G$162,B29,'Registo da Rotação'!$J$54:$J$162,"Sim")+COUNTIFS('Registo da Rotação'!$A$168:$A$217,A29,'Registo da Rotação'!$D$168:$D$217,"Revisor",'Registo da Rotação'!$F$168:$F$217,B29,'Registo da Rotação'!$H$168:$H$217,"Sim")) -> 5 | E29: =IF(B29="","",COUNTIFS('Registo da Rotação'!$B$54:$B$162,A29,'Registo da Rotação'!$H$54:$H$162,B29,'Registo da Rotação'!$K$54:$K$162,"Sim")+COUNTIFS('Registo da Rotação'!$A$168:$A$217,A29,'Registo da Rotação'!$D$168:$D$217,"Auditor",'Registo da Rotação'!$F$168:$F$217,B29,'Registo da Rotação'!$H$168:$H$217,"Sim")) -> 5 | F29: =IF(B29="","",COUNTIFS('Registo da Rotação'!$A$6:$A$25,A29,'Registo da Rotação'!$F$6:$F$25,B29,'Registo da Rotação'!$G$6:$G$25,"Sim")) -> 0 | G29: =IF(B29="","",IF(COUNTIFS('Registo da Rotação'!$A$6:$A$25,A29,'Registo da Rotação'!$D$6:$D$25,"Em curso")>0,"Em avaliação",IF(COUNTIFS('Registo da Rotação'!$A$6:$A$25,A29,'Registo da Rotação'!$D$6:$D$25,"Concluído")=0,"Sem sprints concluídos",IF(COUNTIF('Registo da Rotação'!$B$54:$B$162,A29)<$B$5,"Não aplicável — tarefas insuficientes",IF(AND(C29>0,D29>0,E29>0),"Cumprida","Por cumprir"))))) -> Cumprida
A30: ='Listas de apoio'!C6 -> m2 | B30: =IF('Listas de apoio'!A5="","",'Listas de apoio'!A5) -> André Filipe Moreira Mesquita | C30: =IF(B30="","",COUNTIFS('Registo da Rotação'!$B$54:$B$162,A30,'Registo da Rotação'!$F$54:$F$162,B30,'Registo da Rotação'!$I$54:$I$162,"Sim")+COUNTIFS('Registo da Rotação'!$A$168:$A$217,A30,'Registo da Rotação'!$D$168:$D$217,"Executor",'Registo da Rotação'!$F$168:$F$217,B30,'Registo da Rotação'!$H$168:$H$217,"Sim")) -> 0 | D30: =IF(B30="","",COUNTIFS('Registo da Rotação'!$B$54:$B$162,A30,'Registo da Rotação'!$G$54:$G$162,B30,'Registo da Rotação'!$J$54:$J$162,"Sim")+COUNTIFS('Registo da Rotação'!$A$168:$A$217,A30,'Registo da Rotação'!$D$168:$D$217,"Revisor",'Registo da Rotação'!$F$168:$F$217,B30,'Registo da Rotação'!$H$168:$H$217,"Sim")) -> 0 | E30: =IF(B30="","",COUNTIFS('Registo da Rotação'!$B$54:$B$162,A30,'Registo da Rotação'!$H$54:$H$162,B30,'Registo da Rotação'!$K$54:$K$162,"Sim")+COUNTIFS('Registo da Rotação'!$A$168:$A$217,A30,'Registo da Rotação'!$D$168:$D$217,"Auditor",'Registo da Rotação'!$F$168:$F$217,B30,'Registo da Rotação'!$H$168:$H$217,"Sim")) -> 0 | F30: =IF(B30="","",COUNTIFS('Registo da Rotação'!$A$6:$A$25,A30,'Registo da Rotação'!$F$6:$F$25,B30,'Registo da Rotação'!$G$6:$G$25,"Sim")) -> 0 | G30: =IF(B30="","",IF(COUNTIFS('Registo da Rotação'!$A$6:$A$25,A30,'Registo da Rotação'!$D$6:$D$25,"Em curso")>0,"Em avaliação",IF(COUNTIFS('Registo da Rotação'!$A$6:$A$25,A30,'Registo da Rotação'!$D$6:$D$25,"Concluído")=0,"Sem sprints concluídos",IF(COUNTIF('Registo da Rotação'!$B$54:$B$162,A30)<$B$5,"Não aplicável — tarefas insuficientes",IF(AND(C30>0,D30>0,E30>0),"Cumprida","Por cumprir"))))) -> Sem sprints concluídos
A31: ='Listas de apoio'!C6 -> m2 | B31: =IF('Listas de apoio'!A6="","",'Listas de apoio'!A6) -> Gonçalo Dinis Magalhães Teixeira | C31: =IF(B31="","",COUNTIFS('Registo da Rotação'!$B$54:$B$162,A31,'Registo da Rotação'!$F$54:$F$162,B31,'Registo da Rotação'!$I$54:$I$162,"Sim")+COUNTIFS('Registo da Rotação'!$A$168:$A$217,A31,'Registo da Rotação'!$D$168:$D$217,"Executor",'Registo da Rotação'!$F$168:$F$217,B31,'Registo da Rotação'!$H$168:$H$217,"Sim")) -> 0 | D31: =IF(B31="","",COUNTIFS('Registo da Rotação'!$B$54:$B$162,A31,'Registo da Rotação'!$G$54:$G$162,B31,'Registo da Rotação'!$J$54:$J$162,"Sim")+COUNTIFS('Registo da Rotação'!$A$168:$A$217,A31,'Registo da Rotação'!$D$168:$D$217,"Revisor",'Registo da Rotação'!$F$168:$F$217,B31,'Registo da Rotação'!$H$168:$H$217,"Sim")) -> 0 | E31: =IF(B31="","",COUNTIFS('Registo da Rotação'!$B$54:$B$162,A31,'Registo da Rotação'!$H$54:$H$162,B31,'Registo da Rotação'!$K$54:$K$162,"Sim")+COUNTIFS('Registo da Rotação'!$A$168:$A$217,A31,'Registo da Rotação'!$D$168:$D$217,"Auditor",'Registo da Rotação'!$F$168:$F$217,B31,'Registo da Rotação'!$H$168:$H$217,"Sim")) -> 0 | F31: =IF(B31="","",COUNTIFS('Registo da Rotação'!$A$6:$A$25,A31,'Registo da Rotação'!$F$6:$F$25,B31,'Registo da Rotação'!$G$6:$G$25,"Sim")) -> 0 | G31: =IF(B31="","",IF(COUNTIFS('Registo da Rotação'!$A$6:$A$25,A31,'Registo da Rotação'!$D$6:$D$25,"Em curso")>0,"Em avaliação",IF(COUNTIFS('Registo da Rotação'!$A$6:$A$25,A31,'Registo da Rotação'!$D$6:$D$25,"Concluído")=0,"Sem sprints concluídos",IF(COUNTIF('Registo da Rotação'!$B$54:$B$162,A31)<$B$5,"Não aplicável — tarefas insuficientes",IF(AND(C31>0,D31>0,E31>0),"Cumprida","Por cumprir"))))) -> Sem sprints concluídos
A32: ='Listas de apoio'!C6 -> m2 | B32: =IF('Listas de apoio'!A7="","",'Listas de apoio'!A7) -> Gonçalo Magalhães Ribeiro | C32: =IF(B32="","",COUNTIFS('Registo da Rotação'!$B$54:$B$162,A32,'Registo da Rotação'!$F$54:$F$162,B32,'Registo da Rotação'!$I$54:$I$162,"Sim")+COUNTIFS('Registo da Rotação'!$A$168:$A$217,A32,'Registo da Rotação'!$D$168:$D$217,"Executor",'Registo da Rotação'!$F$168:$F$217,B32,'Registo da Rotação'!$H$168:$H$217,"Sim")) -> 0 | D32: =IF(B32="","",COUNTIFS('Registo da Rotação'!$B$54:$B$162,A32,'Registo da Rotação'!$G$54:$G$162,B32,'Registo da Rotação'!$J$54:$J$162,"Sim")+COUNTIFS('Registo da Rotação'!$A$168:$A$217,A32,'Registo da Rotação'!$D$168:$D$217,"Revisor",'Registo da Rotação'!$F$168:$F$217,B32,'Registo da Rotação'!$H$168:$H$217,"Sim")) -> 0 | E32: =IF(B32="","",COUNTIFS('Registo da Rotação'!$B$54:$B$162,A32,'Registo da Rotação'!$H$54:$H$162,B32,'Registo da Rotação'!$K$54:$K$162,"Sim")+COUNTIFS('Registo da Rotação'!$A$168:$A$217,A32,'Registo da Rotação'!$D$168:$D$217,"Auditor",'Registo da Rotação'!$F$168:$F$217,B32,'Registo da Rotação'!$H$168:$H$217,"Sim")) -> 0 | F32: =IF(B32="","",COUNTIFS('Registo da Rotação'!$A$6:$A$25,A32,'Registo da Rotação'!$F$6:$F$25,B32,'Registo da Rotação'!$G$6:$G$25,"Sim")) -> 0 | G32: =IF(B32="","",IF(COUNTIFS('Registo da Rotação'!$A$6:$A$25,A32,'Registo da Rotação'!$D$6:$D$25,"Em curso")>0,"Em avaliação",IF(COUNTIFS('Registo da Rotação'!$A$6:$A$25,A32,'Registo da Rotação'!$D$6:$D$25,"Concluído")=0,"Sem sprints concluídos",IF(COUNTIF('Registo da Rotação'!$B$54:$B$162,A32)<$B$5,"Não aplicável — tarefas insuficientes",IF(AND(C32>0,D32>0,E32>0),"Cumprida","Por cumprir"))))) -> Sem sprints concluídos
A33: ='Listas de apoio'!C6 -> m2 | B33: =IF('Listas de apoio'!A8="","",'Listas de apoio'!A8) -> Ivan Cristiano Silva Mendes | C33: =IF(B33="","",COUNTIFS('Registo da Rotação'!$B$54:$B$162,A33,'Registo da Rotação'!$F$54:$F$162,B33,'Registo da Rotação'!$I$54:$I$162,"Sim")+COUNTIFS('Registo da Rotação'!$A$168:$A$217,A33,'Registo da Rotação'!$D$168:$D$217,"Executor",'Registo da Rotação'!$F$168:$F$217,B33,'Registo da Rotação'!$H$168:$H$217,"Sim")) -> 0 | D33: =IF(B33="","",COUNTIFS('Registo da Rotação'!$B$54:$B$162,A33,'Registo da Rotação'!$G$54:$G$162,B33,'Registo da Rotação'!$J$54:$J$162,"Sim")+COUNTIFS('Registo da Rotação'!$A$168:$A$217,A33,'Registo da Rotação'!$D$168:$D$217,"Revisor",'Registo da Rotação'!$F$168:$F$217,B33,'Registo da Rotação'!$H$168:$H$217,"Sim")) -> 0 | E33: =IF(B33="","",COUNTIFS('Registo da Rotação'!$B$54:$B$162,A33,'Registo da Rotação'!$H$54:$H$162,B33,'Registo da Rotação'!$K$54:$K$162,"Sim")+COUNTIFS('Registo da Rotação'!$A$168:$A$217,A33,'Registo da Rotação'!$D$168:$D$217,"Auditor",'Registo da Rotação'!$F$168:$F$217,B33,'Registo da Rotação'!$H$168:$H$217,"Sim")) -> 0 | F33: =IF(B33="","",COUNTIFS('Registo da Rotação'!$A$6:$A$25,A33,'Registo da Rotação'!$F$6:$F$25,B33,'Registo da Rotação'!$G$6:$G$25,"Sim")) -> 0 | G33: =IF(B33="","",IF(COUNTIFS('Registo da Rotação'!$A$6:$A$25,A33,'Registo da Rotação'!$D$6:$D$25,"Em curso")>0,"Em avaliação",IF(COUNTIFS('Registo da Rotação'!$A$6:$A$25,A33,'Registo da Rotação'!$D$6:$D$25,"Concluído")=0,"Sem sprints concluídos",IF(COUNTIF('Registo da Rotação'!$B$54:$B$162,A33)<$B$5,"Não aplicável — tarefas insuficientes",IF(AND(C33>0,D33>0,E33>0),"Cumprida","Por cumprir"))))) -> Sem sprints concluídos
A34: ='Listas de apoio'!C7 -> m3 | B34: =IF('Listas de apoio'!A5="","",'Listas de apoio'!A5) -> André Filipe Moreira Mesquita | C34: =IF(B34="","",COUNTIFS('Registo da Rotação'!$B$54:$B$162,A34,'Registo da Rotação'!$F$54:$F$162,B34,'Registo da Rotação'!$I$54:$I$162,"Sim")+COUNTIFS('Registo da Rotação'!$A$168:$A$217,A34,'Registo da Rotação'!$D$168:$D$217,"Executor",'Registo da Rotação'!$F$168:$F$217,B34,'Registo da Rotação'!$H$168:$H$217,"Sim")) -> 0 | D34: =IF(B34="","",COUNTIFS('Registo da Rotação'!$B$54:$B$162,A34,'Registo da Rotação'!$G$54:$G$162,B34,'Registo da Rotação'!$J$54:$J$162,"Sim")+COUNTIFS('Registo da Rotação'!$A$168:$A$217,A34,'Registo da Rotação'!$D$168:$D$217,"Revisor",'Registo da Rotação'!$F$168:$F$217,B34,'Registo da Rotação'!$H$168:$H$217,"Sim")) -> 0 | E34: =IF(B34="","",COUNTIFS('Registo da Rotação'!$B$54:$B$162,A34,'Registo da Rotação'!$H$54:$H$162,B34,'Registo da Rotação'!$K$54:$K$162,"Sim")+COUNTIFS('Registo da Rotação'!$A$168:$A$217,A34,'Registo da Rotação'!$D$168:$D$217,"Auditor",'Registo da Rotação'!$F$168:$F$217,B34,'Registo da Rotação'!$H$168:$H$217,"Sim")) -> 0 | F34: =IF(B34="","",COUNTIFS('Registo da Rotação'!$A$6:$A$25,A34,'Registo da Rotação'!$F$6:$F$25,B34,'Registo da Rotação'!$G$6:$G$25,"Sim")) -> 0 | G34: =IF(B34="","",IF(COUNTIFS('Registo da Rotação'!$A$6:$A$25,A34,'Registo da Rotação'!$D$6:$D$25,"Em curso")>0,"Em avaliação",IF(COUNTIFS('Registo da Rotação'!$A$6:$A$25,A34,'Registo da Rotação'!$D$6:$D$25,"Concluído")=0,"Sem sprints concluídos",IF(COUNTIF('Registo da Rotação'!$B$54:$B$162,A34)<$B$5,"Não aplicável — tarefas insuficientes",IF(AND(C34>0,D34>0,E34>0),"Cumprida","Por cumprir"))))) -> Sem sprints concluídos
A35: ='Listas de apoio'!C7 -> m3 | B35: =IF('Listas de apoio'!A6="","",'Listas de apoio'!A6) -> Gonçalo Dinis Magalhães Teixeira | C35: =IF(B35="","",COUNTIFS('Registo da Rotação'!$B$54:$B$162,A35,'Registo da Rotação'!$F$54:$F$162,B35,'Registo da Rotação'!$I$54:$I$162,"Sim")+COUNTIFS('Registo da Rotação'!$A$168:$A$217,A35,'Registo da Rotação'!$D$168:$D$217,"Executor",'Registo da Rotação'!$F$168:$F$217,B35,'Registo da Rotação'!$H$168:$H$217,"Sim")) -> 0 | D35: =IF(B35="","",COUNTIFS('Registo da Rotação'!$B$54:$B$162,A35,'Registo da Rotação'!$G$54:$G$162,B35,'Registo da Rotação'!$J$54:$J$162,"Sim")+COUNTIFS('Registo da Rotação'!$A$168:$A$217,A35,'Registo da Rotação'!$D$168:$D$217,"Revisor",'Registo da Rotação'!$F$168:$F$217,B35,'Registo da Rotação'!$H$168:$H$217,"Sim")) -> 0 | E35: =IF(B35="","",COUNTIFS('Registo da Rotação'!$B$54:$B$162,A35,'Registo da Rotação'!$H$54:$H$162,B35,'Registo da Rotação'!$K$54:$K$162,"Sim")+COUNTIFS('Registo da Rotação'!$A$168:$A$217,A35,'Registo da Rotação'!$D$168:$D$217,"Auditor",'Registo da Rotação'!$F$168:$F$217,B35,'Registo da Rotação'!$H$168:$H$217,"Sim")) -> 0 | F35: =IF(B35="","",COUNTIFS('Registo da Rotação'!$A$6:$A$25,A35,'Registo da Rotação'!$F$6:$F$25,B35,'Registo da Rotação'!$G$6:$G$25,"Sim")) -> 0 | G35: =IF(B35="","",IF(COUNTIFS('Registo da Rotação'!$A$6:$A$25,A35,'Registo da Rotação'!$D$6:$D$25,"Em curso")>0,"Em avaliação",IF(COUNTIFS('Registo da Rotação'!$A$6:$A$25,A35,'Registo da Rotação'!$D$6:$D$25,"Concluído")=0,"Sem sprints concluídos",IF(COUNTIF('Registo da Rotação'!$B$54:$B$162,A35)<$B$5,"Não aplicável — tarefas insuficientes",IF(AND(C35>0,D35>0,E35>0),"Cumprida","Por cumprir"))))) -> Sem sprints concluídos
A36: ='Listas de apoio'!C7 -> m3 | B36: =IF('Listas de apoio'!A7="","",'Listas de apoio'!A7) -> Gonçalo Magalhães Ribeiro | C36: =IF(B36="","",COUNTIFS('Registo da Rotação'!$B$54:$B$162,A36,'Registo da Rotação'!$F$54:$F$162,B36,'Registo da Rotação'!$I$54:$I$162,"Sim")+COUNTIFS('Registo da Rotação'!$A$168:$A$217,A36,'Registo da Rotação'!$D$168:$D$217,"Executor",'Registo da Rotação'!$F$168:$F$217,B36,'Registo da Rotação'!$H$168:$H$217,"Sim")) -> 0 | D36: =IF(B36="","",COUNTIFS('Registo da Rotação'!$B$54:$B$162,A36,'Registo da Rotação'!$G$54:$G$162,B36,'Registo da Rotação'!$J$54:$J$162,"Sim")+COUNTIFS('Registo da Rotação'!$A$168:$A$217,A36,'Registo da Rotação'!$D$168:$D$217,"Revisor",'Registo da Rotação'!$F$168:$F$217,B36,'Registo da Rotação'!$H$168:$H$217,"Sim")) -> 0 | E36: =IF(B36="","",COUNTIFS('Registo da Rotação'!$B$54:$B$162,A36,'Registo da Rotação'!$H$54:$H$162,B36,'Registo da Rotação'!$K$54:$K$162,"Sim")+COUNTIFS('Registo da Rotação'!$A$168:$A$217,A36,'Registo da Rotação'!$D$168:$D$217,"Auditor",'Registo da Rotação'!$F$168:$F$217,B36,'Registo da Rotação'!$H$168:$H$217,"Sim")) -> 0 | F36: =IF(B36="","",COUNTIFS('Registo da Rotação'!$A$6:$A$25,A36,'Registo da Rotação'!$F$6:$F$25,B36,'Registo da Rotação'!$G$6:$G$25,"Sim")) -> 0 | G36: =IF(B36="","",IF(COUNTIFS('Registo da Rotação'!$A$6:$A$25,A36,'Registo da Rotação'!$D$6:$D$25,"Em curso")>0,"Em avaliação",IF(COUNTIFS('Registo da Rotação'!$A$6:$A$25,A36,'Registo da Rotação'!$D$6:$D$25,"Concluído")=0,"Sem sprints concluídos",IF(COUNTIF('Registo da Rotação'!$B$54:$B$162,A36)<$B$5,"Não aplicável — tarefas insuficientes",IF(AND(C36>0,D36>0,E36>0),"Cumprida","Por cumprir"))))) -> Sem sprints concluídos
A37: ='Listas de apoio'!C7 -> m3 | B37: =IF('Listas de apoio'!A8="","",'Listas de apoio'!A8) -> Ivan Cristiano Silva Mendes | C37: =IF(B37="","",COUNTIFS('Registo da Rotação'!$B$54:$B$162,A37,'Registo da Rotação'!$F$54:$F$162,B37,'Registo da Rotação'!$I$54:$I$162,"Sim")+COUNTIFS('Registo da Rotação'!$A$168:$A$217,A37,'Registo da Rotação'!$D$168:$D$217,"Executor",'Registo da Rotação'!$F$168:$F$217,B37,'Registo da Rotação'!$H$168:$H$217,"Sim")) -> 0 | D37: =IF(B37="","",COUNTIFS('Registo da Rotação'!$B$54:$B$162,A37,'Registo da Rotação'!$G$54:$G$162,B37,'Registo da Rotação'!$J$54:$J$162,"Sim")+COUNTIFS('Registo da Rotação'!$A$168:$A$217,A37,'Registo da Rotação'!$D$168:$D$217,"Revisor",'Registo da Rotação'!$F$168:$F$217,B37,'Registo da Rotação'!$H$168:$H$217,"Sim")) -> 0 | E37: =IF(B37="","",COUNTIFS('Registo da Rotação'!$B$54:$B$162,A37,'Registo da Rotação'!$H$54:$H$162,B37,'Registo da Rotação'!$K$54:$K$162,"Sim")+COUNTIFS('Registo da Rotação'!$A$168:$A$217,A37,'Registo da Rotação'!$D$168:$D$217,"Auditor",'Registo da Rotação'!$F$168:$F$217,B37,'Registo da Rotação'!$H$168:$H$217,"Sim")) -> 0 | F37: =IF(B37="","",COUNTIFS('Registo da Rotação'!$A$6:$A$25,A37,'Registo da Rotação'!$F$6:$F$25,B37,'Registo da Rotação'!$G$6:$G$25,"Sim")) -> 0 | G37: =IF(B37="","",IF(COUNTIFS('Registo da Rotação'!$A$6:$A$25,A37,'Registo da Rotação'!$D$6:$D$25,"Em curso")>0,"Em avaliação",IF(COUNTIFS('Registo da Rotação'!$A$6:$A$25,A37,'Registo da Rotação'!$D$6:$D$25,"Concluído")=0,"Sem sprints concluídos",IF(COUNTIF('Registo da Rotação'!$B$54:$B$162,A37)<$B$5,"Não aplicável — tarefas insuficientes",IF(AND(C37>0,D37>0,E37>0),"Cumprida","Por cumprir"))))) -> Sem sprints concluídos
A38: ='Listas de apoio'!C8 -> m4 | B38: =IF('Listas de apoio'!A5="","",'Listas de apoio'!A5) -> André Filipe Moreira Mesquita | C38: =IF(B38="","",COUNTIFS('Registo da Rotação'!$B$54:$B$162,A38,'Registo da Rotação'!$F$54:$F$162,B38,'Registo da Rotação'!$I$54:$I$162,"Sim")+COUNTIFS('Registo da Rotação'!$A$168:$A$217,A38,'Registo da Rotação'!$D$168:$D$217,"Executor",'Registo da Rotação'!$F$168:$F$217,B38,'Registo da Rotação'!$H$168:$H$217,"Sim")) -> 0 | D38: =IF(B38="","",COUNTIFS('Registo da Rotação'!$B$54:$B$162,A38,'Registo da Rotação'!$G$54:$G$162,B38,'Registo da Rotação'!$J$54:$J$162,"Sim")+COUNTIFS('Registo da Rotação'!$A$168:$A$217,A38,'Registo da Rotação'!$D$168:$D$217,"Revisor",'Registo da Rotação'!$F$168:$F$217,B38,'Registo da Rotação'!$H$168:$H$217,"Sim")) -> 0 | E38: =IF(B38="","",COUNTIFS('Registo da Rotação'!$B$54:$B$162,A38,'Registo da Rotação'!$H$54:$H$162,B38,'Registo da Rotação'!$K$54:$K$162,"Sim")+COUNTIFS('Registo da Rotação'!$A$168:$A$217,A38,'Registo da Rotação'!$D$168:$D$217,"Auditor",'Registo da Rotação'!$F$168:$F$217,B38,'Registo da Rotação'!$H$168:$H$217,"Sim")) -> 0 | F38: =IF(B38="","",COUNTIFS('Registo da Rotação'!$A$6:$A$25,A38,'Registo da Rotação'!$F$6:$F$25,B38,'Registo da Rotação'!$G$6:$G$25,"Sim")) -> 0 | G38: =IF(B38="","",IF(COUNTIFS('Registo da Rotação'!$A$6:$A$25,A38,'Registo da Rotação'!$D$6:$D$25,"Em curso")>0,"Em avaliação",IF(COUNTIFS('Registo da Rotação'!$A$6:$A$25,A38,'Registo da Rotação'!$D$6:$D$25,"Concluído")=0,"Sem sprints concluídos",IF(COUNTIF('Registo da Rotação'!$B$54:$B$162,A38)<$B$5,"Não aplicável — tarefas insuficientes",IF(AND(C38>0,D38>0,E38>0),"Cumprida","Por cumprir"))))) -> Sem sprints concluídos
A39: ='Listas de apoio'!C8 -> m4 | B39: =IF('Listas de apoio'!A6="","",'Listas de apoio'!A6) -> Gonçalo Dinis Magalhães Teixeira | C39: =IF(B39="","",COUNTIFS('Registo da Rotação'!$B$54:$B$162,A39,'Registo da Rotação'!$F$54:$F$162,B39,'Registo da Rotação'!$I$54:$I$162,"Sim")+COUNTIFS('Registo da Rotação'!$A$168:$A$217,A39,'Registo da Rotação'!$D$168:$D$217,"Executor",'Registo da Rotação'!$F$168:$F$217,B39,'Registo da Rotação'!$H$168:$H$217,"Sim")) -> 0 | D39: =IF(B39="","",COUNTIFS('Registo da Rotação'!$B$54:$B$162,A39,'Registo da Rotação'!$G$54:$G$162,B39,'Registo da Rotação'!$J$54:$J$162,"Sim")+COUNTIFS('Registo da Rotação'!$A$168:$A$217,A39,'Registo da Rotação'!$D$168:$D$217,"Revisor",'Registo da Rotação'!$F$168:$F$217,B39,'Registo da Rotação'!$H$168:$H$217,"Sim")) -> 0 | E39: =IF(B39="","",COUNTIFS('Registo da Rotação'!$B$54:$B$162,A39,'Registo da Rotação'!$H$54:$H$162,B39,'Registo da Rotação'!$K$54:$K$162,"Sim")+COUNTIFS('Registo da Rotação'!$A$168:$A$217,A39,'Registo da Rotação'!$D$168:$D$217,"Auditor",'Registo da Rotação'!$F$168:$F$217,B39,'Registo da Rotação'!$H$168:$H$217,"Sim")) -> 0 | F39: =IF(B39="","",COUNTIFS('Registo da Rotação'!$A$6:$A$25,A39,'Registo da Rotação'!$F$6:$F$25,B39,'Registo da Rotação'!$G$6:$G$25,"Sim")) -> 0 | G39: =IF(B39="","",IF(COUNTIFS('Registo da Rotação'!$A$6:$A$25,A39,'Registo da Rotação'!$D$6:$D$25,"Em curso")>0,"Em avaliação",IF(COUNTIFS('Registo da Rotação'!$A$6:$A$25,A39,'Registo da Rotação'!$D$6:$D$25,"Concluído")=0,"Sem sprints concluídos",IF(COUNTIF('Registo da Rotação'!$B$54:$B$162,A39)<$B$5,"Não aplicável — tarefas insuficientes",IF(AND(C39>0,D39>0,E39>0),"Cumprida","Por cumprir"))))) -> Sem sprints concluídos
A40: ='Listas de apoio'!C8 -> m4 | B40: =IF('Listas de apoio'!A7="","",'Listas de apoio'!A7) -> Gonçalo Magalhães Ribeiro | C40: =IF(B40="","",COUNTIFS('Registo da Rotação'!$B$54:$B$162,A40,'Registo da Rotação'!$F$54:$F$162,B40,'Registo da Rotação'!$I$54:$I$162,"Sim")+COUNTIFS('Registo da Rotação'!$A$168:$A$217,A40,'Registo da Rotação'!$D$168:$D$217,"Executor",'Registo da Rotação'!$F$168:$F$217,B40,'Registo da Rotação'!$H$168:$H$217,"Sim")) -> 0 | D40: =IF(B40="","",COUNTIFS('Registo da Rotação'!$B$54:$B$162,A40,'Registo da Rotação'!$G$54:$G$162,B40,'Registo da Rotação'!$J$54:$J$162,"Sim")+COUNTIFS('Registo da Rotação'!$A$168:$A$217,A40,'Registo da Rotação'!$D$168:$D$217,"Revisor",'Registo da Rotação'!$F$168:$F$217,B40,'Registo da Rotação'!$H$168:$H$217,"Sim")) -> 0 | E40: =IF(B40="","",COUNTIFS('Registo da Rotação'!$B$54:$B$162,A40,'Registo da Rotação'!$H$54:$H$162,B40,'Registo da Rotação'!$K$54:$K$162,"Sim")+COUNTIFS('Registo da Rotação'!$A$168:$A$217,A40,'Registo da Rotação'!$D$168:$D$217,"Auditor",'Registo da Rotação'!$F$168:$F$217,B40,'Registo da Rotação'!$H$168:$H$217,"Sim")) -> 0 | F40: =IF(B40="","",COUNTIFS('Registo da Rotação'!$A$6:$A$25,A40,'Registo da Rotação'!$F$6:$F$25,B40,'Registo da Rotação'!$G$6:$G$25,"Sim")) -> 0 | G40: =IF(B40="","",IF(COUNTIFS('Registo da Rotação'!$A$6:$A$25,A40,'Registo da Rotação'!$D$6:$D$25,"Em curso")>0,"Em avaliação",IF(COUNTIFS('Registo da Rotação'!$A$6:$A$25,A40,'Registo da Rotação'!$D$6:$D$25,"Concluído")=0,"Sem sprints concluídos",IF(COUNTIF('Registo da Rotação'!$B$54:$B$162,A40)<$B$5,"Não aplicável — tarefas insuficientes",IF(AND(C40>0,D40>0,E40>0),"Cumprida","Por cumprir"))))) -> Sem sprints concluídos
A41: ='Listas de apoio'!C8 -> m4 | B41: =IF('Listas de apoio'!A8="","",'Listas de apoio'!A8) -> Ivan Cristiano Silva Mendes | C41: =IF(B41="","",COUNTIFS('Registo da Rotação'!$B$54:$B$162,A41,'Registo da Rotação'!$F$54:$F$162,B41,'Registo da Rotação'!$I$54:$I$162,"Sim")+COUNTIFS('Registo da Rotação'!$A$168:$A$217,A41,'Registo da Rotação'!$D$168:$D$217,"Executor",'Registo da Rotação'!$F$168:$F$217,B41,'Registo da Rotação'!$H$168:$H$217,"Sim")) -> 0 | D41: =IF(B41="","",COUNTIFS('Registo da Rotação'!$B$54:$B$162,A41,'Registo da Rotação'!$G$54:$G$162,B41,'Registo da Rotação'!$J$54:$J$162,"Sim")+COUNTIFS('Registo da Rotação'!$A$168:$A$217,A41,'Registo da Rotação'!$D$168:$D$217,"Revisor",'Registo da Rotação'!$F$168:$F$217,B41,'Registo da Rotação'!$H$168:$H$217,"Sim")) -> 0 | E41: =IF(B41="","",COUNTIFS('Registo da Rotação'!$B$54:$B$162,A41,'Registo da Rotação'!$H$54:$H$162,B41,'Registo da Rotação'!$K$54:$K$162,"Sim")+COUNTIFS('Registo da Rotação'!$A$168:$A$217,A41,'Registo da Rotação'!$D$168:$D$217,"Auditor",'Registo da Rotação'!$F$168:$F$217,B41,'Registo da Rotação'!$H$168:$H$217,"Sim")) -> 0 | F41: =IF(B41="","",COUNTIFS('Registo da Rotação'!$A$6:$A$25,A41,'Registo da Rotação'!$F$6:$F$25,B41,'Registo da Rotação'!$G$6:$G$25,"Sim")) -> 0 | G41: =IF(B41="","",IF(COUNTIFS('Registo da Rotação'!$A$6:$A$25,A41,'Registo da Rotação'!$D$6:$D$25,"Em curso")>0,"Em avaliação",IF(COUNTIFS('Registo da Rotação'!$A$6:$A$25,A41,'Registo da Rotação'!$D$6:$D$25,"Concluído")=0,"Sem sprints concluídos",IF(COUNTIF('Registo da Rotação'!$B$54:$B$162,A41)<$B$5,"Não aplicável — tarefas insuficientes",IF(AND(C41>0,D41>0,E41>0),"Cumprida","Por cumprir"))))) -> Sem sprints concluídos

Sheet Registo da Rotação
A1: REGISTO DA ROTAÇÃO | B1: REGISTO DA ROTAÇÃO | C1: REGISTO DA ROTAÇÃO | D1: REGISTO DA ROTAÇÃO | E1: REGISTO DA ROTAÇÃO | F1: REGISTO DA ROTAÇÃO | G1: REGISTO DA ROTAÇÃO | H1: REGISTO DA ROTAÇÃO | I1: REGISTO DA ROTAÇÃO | J1: REGISTO DA ROTAÇÃO | K1: REGISTO DA ROTAÇÃO | L1: REGISTO DA ROTAÇÃO | M1: REGISTO DA ROTAÇÃO | N1: REGISTO DA ROTAÇÃO | O1: REGISTO DA ROTAÇÃO | P1: REGISTO DA ROTAÇÃO | Q1: REGISTO DA ROTAÇÃO | R1: REGISTO DA ROTAÇÃO
A2: PREENCHIMENTO PRINCIPAL — substitua todos os exemplos. Registe as atribuições iniciais a partir do Sprint Backlog vigente e confirme o desempenho através do Mapa de Pontuação Individual apreciado no Sprint Review. Células amarelas são editáveis; células azuis são calculadas. | B2: PREENCHIMENTO PRINCIPAL — substitua todos os exemplos. Registe as atribuições iniciais a partir do Sprint Backlog vigente e confirme o desempenho através do Mapa de Pontuação Individual apreciado no Sprint Review. Células amarelas são editáveis; células azuis são calculadas. | C2: PREENCHIMENTO PRINCIPAL — substitua todos os exemplos. Registe as atribuições iniciais a partir do Sprint Backlog vigente e confirme o desempenho através do Mapa de Pontuação Individual apreciado no Sprint Review. Células amarelas são editáveis; células azuis são calculadas. | D2: PREENCHIMENTO PRINCIPAL — substitua todos os exemplos. Registe as atribuições iniciais a partir do Sprint Backlog vigente e confirme o desempenho através do Mapa de Pontuação Individual apreciado no Sprint Review. Células amarelas são editáveis; células azuis são calculadas. | E2: PREENCHIMENTO PRINCIPAL — substitua todos os exemplos. Registe as atribuições iniciais a partir do Sprint Backlog vigente e confirme o desempenho através do Mapa de Pontuação Individual apreciado no Sprint Review. Células amarelas são editáveis; células azuis são calculadas. | F2: PREENCHIMENTO PRINCIPAL — substitua todos os exemplos. Registe as atribuições iniciais a partir do Sprint Backlog vigente e confirme o desempenho através do Mapa de Pontuação Individual apreciado no Sprint Review. Células amarelas são editáveis; células azuis são calculadas. | G2: PREENCHIMENTO PRINCIPAL — substitua todos os exemplos. Registe as atribuições iniciais a partir do Sprint Backlog vigente e confirme o desempenho através do Mapa de Pontuação Individual apreciado no Sprint Review. Células amarelas são editáveis; células azuis são calculadas. | H2: PREENCHIMENTO PRINCIPAL — substitua todos os exemplos. Registe as atribuições iniciais a partir do Sprint Backlog vigente e confirme o desempenho através do Mapa de Pontuação Individual apreciado no Sprint Review. Células amarelas são editáveis; células azuis são calculadas. | I2: PREENCHIMENTO PRINCIPAL — substitua todos os exemplos. Registe as atribuições iniciais a partir do Sprint Backlog vigente e confirme o desempenho através do Mapa de Pontuação Individual apreciado no Sprint Review. Células amarelas são editáveis; células azuis são calculadas. | J2: PREENCHIMENTO PRINCIPAL — substitua todos os exemplos. Registe as atribuições iniciais a partir do Sprint Backlog vigente e confirme o desempenho através do Mapa de Pontuação Individual apreciado no Sprint Review. Células amarelas são editáveis; células azuis são calculadas. | K2: PREENCHIMENTO PRINCIPAL — substitua todos os exemplos. Registe as atribuições iniciais a partir do Sprint Backlog vigente e confirme o desempenho através do Mapa de Pontuação Individual apreciado no Sprint Review. Células amarelas são editáveis; células azuis são calculadas. | L2: PREENCHIMENTO PRINCIPAL — substitua todos os exemplos. Registe as atribuições iniciais a partir do Sprint Backlog vigente e confirme o desempenho através do Mapa de Pontuação Individual apreciado no Sprint Review. Células amarelas são editáveis; células azuis são calculadas. | M2: PREENCHIMENTO PRINCIPAL — substitua todos os exemplos. Registe as atribuições iniciais a partir do Sprint Backlog vigente e confirme o desempenho através do Mapa de Pontuação Individual apreciado no Sprint Review. Células amarelas são editáveis; células azuis são calculadas. | N2: PREENCHIMENTO PRINCIPAL — substitua todos os exemplos. Registe as atribuições iniciais a partir do Sprint Backlog vigente e confirme o desempenho através do Mapa de Pontuação Individual apreciado no Sprint Review. Células amarelas são editáveis; células azuis são calculadas. | O2: PREENCHIMENTO PRINCIPAL — substitua todos os exemplos. Registe as atribuições iniciais a partir do Sprint Backlog vigente e confirme o desempenho através do Mapa de Pontuação Individual apreciado no Sprint Review. Células amarelas são editáveis; células azuis são calculadas. | P2: PREENCHIMENTO PRINCIPAL — substitua todos os exemplos. Registe as atribuições iniciais a partir do Sprint Backlog vigente e confirme o desempenho através do Mapa de Pontuação Individual apreciado no Sprint Review. Células amarelas são editáveis; células azuis são calculadas. | Q2: PREENCHIMENTO PRINCIPAL — substitua todos os exemplos. Registe as atribuições iniciais a partir do Sprint Backlog vigente e confirme o desempenho através do Mapa de Pontuação Individual apreciado no Sprint Review. Células amarelas são editáveis; células azuis são calculadas. | R2: PREENCHIMENTO PRINCIPAL — substitua todos os exemplos. Registe as atribuições iniciais a partir do Sprint Backlog vigente e confirme o desempenho através do Mapa de Pontuação Individual apreciado no Sprint Review. Células amarelas são editáveis; células azuis são calculadas.
A4: SPRINTS, LIDERANÇA E SECRETARIADO | B4: SPRINTS, LIDERANÇA E SECRETARIADO | C4: SPRINTS, LIDERANÇA E SECRETARIADO | D4: SPRINTS, LIDERANÇA E SECRETARIADO | E4: SPRINTS, LIDERANÇA E SECRETARIADO | F4: SPRINTS, LIDERANÇA E SECRETARIADO | G4: SPRINTS, LIDERANÇA E SECRETARIADO
A5: Milestone de Entrega | B5: Ordem do Sprint | C5: Sprint | D5: Situação | E5: Líder | F5: Secretário designado | G5: Secretariado efetivamente desempenhado
A6: m1 | B6: 1 | C6: S01 | D6: Concluído | E6: Ivan Cristiano Silva Mendes | F6: Gonçalo Dinis Magalhães Teixeira | G6: Sim
A27: FONTES DOCUMENTAIS POR SPRINT | B27: FONTES DOCUMENTAIS POR SPRINT | C27: FONTES DOCUMENTAIS POR SPRINT | D27: FONTES DOCUMENTAIS POR SPRINT | E27: FONTES DOCUMENTAIS POR SPRINT | F27: FONTES DOCUMENTAIS POR SPRINT | G27: FONTES DOCUMENTAIS POR SPRINT | H27: FONTES DOCUMENTAIS POR SPRINT | I27: FONTES DOCUMENTAIS POR SPRINT | J27: FONTES DOCUMENTAIS POR SPRINT | K27: FONTES DOCUMENTAIS POR SPRINT | L27: FONTES DOCUMENTAIS POR SPRINT | M27: FONTES DOCUMENTAIS POR SPRINT | N27: FONTES DOCUMENTAIS POR SPRINT | O27: FONTES DOCUMENTAIS POR SPRINT | P27: FONTES DOCUMENTAIS POR SPRINT | Q27: FONTES DOCUMENTAIS POR SPRINT | R27: FONTES DOCUMENTAIS POR SPRINT
A28: Sprint | B28: Situação | C28: Sprint Backlog vigente — versão editável (XLS/XLSX) | G28: Sprint Backlog vigente — PDF assinado | K28: Mapa de Pontuação Individual — versão editável (XLS/XLSX) | O28: Mapa de Pontuação Individual — PDF assinado
A29: S01 | C29: /projeto/01-artefactos-de-gestao/01.04-backlog-de-projeto/m1-s01-sprint-backlog-v01.xlsx | G29: /projeto/01-artefactos-de-gestao/01.04-backlog-de-projeto/m1-s01-sprint-backlog-v01.pdf | K29: /projeto/01-artefactos-de-gestao/01.06-avaliacao-interna-do-grupo/m1-s01-mapa-pontuacao-individual-v01.xlsx | O29: /projeto/01-artefactos-de-gestao/01.06-avaliacao-interna-do-grupo/m1-s01-mapa-pontuacao-individual-v01.pdf
B32: =IF(A32="","",IFERROR(VLOOKUP(A32,$C$6:$D$25,2,FALSE),"Sprint não registado"))
B33: =IF(A33="","",IFERROR(VLOOKUP(A33,$C$6:$D$25,2,FALSE),"Sprint não registado"))
B34: =IF(A34="","",IFERROR(VLOOKUP(A34,$C$6:$D$25,2,FALSE),"Sprint não registado"))
B35: =IF(A35="","",IFERROR(VLOOKUP(A35,$C$6:$D$25,2,FALSE),"Sprint não registado"))
B36: =IF(A36="","",IFERROR(VLOOKUP(A36,$C$6:$D$25,2,FALSE),"Sprint não registado"))
B37: =IF(A37="","",IFERROR(VLOOKUP(A37,$C$6:$D$25,2,FALSE),"Sprint não registado"))
B38: =IF(A38="","",IFERROR(VLOOKUP(A38,$C$6:$D$25,2,FALSE),"Sprint não registado"))
B39: =IF(A39="","",IFERROR(VLOOKUP(A39,$C$6:$D$25,2,FALSE),"Sprint não registado"))
B40: =IF(A40="","",IFERROR(VLOOKUP(A40,$C$6:$D$25,2,FALSE),"Sprint não registado"))
B41: =IF(A41="","",IFERROR(VLOOKUP(A41,$C$6:$D$25,2,FALSE),"Sprint não registado"))
B42: =IF(A42="","",IFERROR(VLOOKUP(A42,$C$6:$D$25,2,FALSE),"Sprint não registado"))
B43: =IF(A43="","",IFERROR(VLOOKUP(A43,$C$6:$D$25,2,FALSE),"Sprint não registado"))
... B48: =IF(A48="","",IFERROR(VLOOKUP(A48,$C$6:$D$25,2,FALSE),"Sprint não registado"))
A51: ATRIBUIÇÕES INICIAIS DAS TAREFAS | B51: ATRIBUIÇÕES INICIAIS DAS TAREFAS | C51: ATRIBUIÇÕES INICIAIS DAS TAREFAS | D51: ATRIBUIÇÕES INICIAIS DAS TAREFAS | E51: ATRIBUIÇÕES INICIAIS DAS TAREFAS | F51: ATRIBUIÇÕES INICIAIS DAS TAREFAS | G51: ATRIBUIÇÕES INICIAIS DAS TAREFAS | H51: ATRIBUIÇÕES INICIAIS DAS TAREFAS | I51: ATRIBUIÇÕES INICIAIS DAS TAREFAS | J51: ATRIBUIÇÕES INICIAIS DAS TAREFAS | K51: ATRIBUIÇÕES INICIAIS DAS TAREFAS
A52: Registe cada tarefa uma única vez, pela ordem cronológica da atribuição formal. A sequência permite verificar as combinações usadas para o mesmo Executor. As confirmações só ficam definitivas depois do Sprint Review. | B52: Registe cada tarefa uma única vez, pela ordem cronológica da atribuição formal. A sequência permite verificar as combinações usadas para o mesmo Executor. As confirmações só ficam definitivas depois do Sprint Review. | C52: Registe cada tarefa uma única vez, pela ordem cronológica da atribuição formal. A sequência permite verificar as combinações usadas para o mesmo Executor. As confirmações só ficam definitivas depois do Sprint Review. | D52: Registe cada tarefa uma única vez, pela ordem cronológica da atribuição formal. A sequência permite verificar as combinações usadas para o mesmo Executor. As confirmações só ficam definitivas depois do Sprint Review. | E52: Registe cada tarefa uma única vez, pela ordem cronológica da atribuição formal. A sequência permite verificar as combinações usadas para o mesmo Executor. As confirmações só ficam definitivas depois do Sprint Review. | F52: Registe cada tarefa uma única vez, pela ordem cronológica da atribuição formal. A sequência permite verificar as combinações usadas para o mesmo Executor. As confirmações só ficam definitivas depois do Sprint Review. | G52: Registe cada tarefa uma única vez, pela ordem cronológica da atribuição formal. A sequência permite verificar as combinações usadas para o mesmo Executor. As confirmações só ficam definitivas depois do Sprint Review. | H52: Registe cada tarefa uma única vez, pela ordem cronológica da atribuição formal. A sequência permite verificar as combinações usadas para o mesmo Executor. As confirmações só ficam definitivas depois do Sprint Review. | I52: Registe cada tarefa uma única vez, pela ordem cronológica da atribuição formal. A sequência permite verificar as combinações usadas para o mesmo Executor. As confirmações só ficam definitivas depois do Sprint Review. | J52: Registe cada tarefa uma única vez, pela ordem cronológica da atribuição formal. A sequência permite verificar as combinações usadas para o mesmo Executor. As confirmações só ficam definitivas depois do Sprint Review. | K52: Registe cada tarefa uma única vez, pela ordem cronológica da atribuição formal. A sequência permite verificar as combinações usadas para o mesmo Executor. As confirmações só ficam definitivas depois do Sprint Review.
A53: Sequência | B53: Milestone de Entrega | C53: Sprint | D53: Issue | E53: Tarefa | F53: Executor inicial | G53: Revisor inicial | H53: Auditor inicial | I53: Execução confirmada | J53: Revisão confirmada | K53: Auditoria confirmada
A54: 1 | B54: m1 | C54: S01 | D54: I001 | E54: Elaborar Proposta de Sistema | F54: Gonçalo Magalhães Ribeiro | G54: Ivan Cristiano Silva Mendes | H54: Ivan Cristiano Silva Mendes | I54: Sim | J54: Sim | K54: Sim
A55: 2 | B55: m1 | C55: S01 | D55: I002 | E55: Elaborar Declaraçao de Âmbito | F55: André Filipe Moreira Mesquita | G55: Ivan Cristiano Silva Mendes | H55: Ivan Cristiano Silva Mendes | I55: Sim | J55: Sim | K55: Sim
A56: 3 | B56: m1 | C56: S01 | D56: I003 | E56: Preparar CCA | F56: Ivan Cristiano Silva Mendes | G56: Gonçalo Magalhães Ribeiro | H56: Gonçalo Dinis Magalhães Teixeira | I56: Sim | J56: Sim | K56: Sim
A57: 4 | B57: m1 | C57: S01 | D57: I004 | E57: Obter e arquivar homologação PS/DA/CCA | F57: Ivan Cristiano Silva Mendes | G57: André Filipe Moreira Mesquita | H57: Gonçalo Magalhães Ribeiro | I57: Sim | J57: Sim | K57: Sim
A58: 5 | B58: m1 | C58: S01 | D58: I005 | E58: Elaborar Regulamento Interno | F58: Ivan Cristiano Silva Mendes | G58: Gonçalo Magalhães Ribeiro | H58: André Filipe Moreira Mesquita | I58: Sim | J58: Sim | K58: Sim
A59: 6 | B59: m1 | C59: S01 | D59: I006 | E59: Elaborar Plano de Qualidade | F59: André Filipe Moreira Mesquita | G59: Ivan Cristiano Silva Mendes | H59: Ivan Cristiano Silva Mendes | I59: Sim | J59: Sim | K59: Sim
A60: 7 | B60: m1 | C60: S01 | D60: I007 | E60: Elaborar Definition of Ready | F60: Gonçalo Dinis Magalhães Teixeira | G60: Ivan Cristiano Silva Mendes | H60: Ivan Cristiano Silva Mendes | I60: Sim | J60: Sim | K60: Sim
A61: 8 | B61: m1 | C61: S01 | D61: I008 | E61: Elaborar Definition of Done | F61: Gonçalo Dinis Magalhães Teixeira | G61: Ivan Cristiano Silva Mendes | H61: Ivan Cristiano Silva Mendes | I61: Sim | J61: Sim | K61: Sim
A62: 9 | B62: m1 | C62: S01 | D62: I009 | E62: Definir Critérios de Qualidade dos Requisitos | F62: Gonçalo Magalhães Ribeiro | G62: André Filipe Moreira Mesquita | H62: Gonçalo Dinis Magalhães Teixeira | I62: Sim | J62: Sim | K62: Sim
A63: 10 | B63: m1 | C63: S01 | D63: I010 | E63: Preparar Grelha de Rotação de Papéis | F63: Ivan Cristiano Silva Mendes | G63: André Filipe Moreira Mesquita | H63: Gonçalo Magalhães Ribeiro | I63: Sim | J63: Sim | K63: Sim
A165: PARTICIPAÇÕES RESULTANTES DE TRANSFERÊNCIAS
A166: Uma transferência não altera a atribuição inicial. O novo responsável só conta como tendo desempenhado o papel quando existir confirmação sustentada pelas evidências e pelo Mapa de Pontuação Individual aprovado.
A167: Milestone de Entrega | B167: Sprint | C167: Issue | D167: Papel transferido | E167: Cedente | F167: Novo responsável | G167: Referência da transferência | H167: Desempenho confirmado

Sheet Validação
A1: VALIDAÇÃO DA GRELHA DE ROTAÇÃO DE PAPÉIS | B1: VALIDAÇÃO DA GRELHA DE ROTAÇÃO DE PAPÉIS | C1: VALIDAÇÃO DA GRELHA DE ROTAÇÃO DE PAPÉIS | D1: VALIDAÇÃO DA GRELHA DE ROTAÇÃO DE PAPÉIS
A2: Esta folha deteta faltas e incoerências básicas. Um resultado «OK» não substitui a verificação das evidências, a aprovação formal das reuniões nem a apreciação do docente. | B2: Esta folha deteta faltas e incoerências básicas. Um resultado «OK» não substitui a verificação das evidências, a aprovação formal das reuniões nem a apreciação do docente. | C2: Esta folha deteta faltas e incoerências básicas. Um resultado «OK» não substitui a verificação das evidências, a aprovação formal das reuniões nem a apreciação do docente. | D2: Esta folha deteta faltas e incoerências básicas. Um resultado «OK» não substitui a verificação das evidências, a aprovação formal das reuniões nem a apreciação do docente.
A4: Verificação | B4: Resultado | C4: Estado | D4: Interpretação
A5: Sprints registados | B5: =COUNTIF('Registo da Rotação'!$C$6:$C$25,"<>") -> 1 | C5: Informação | D5: Número de Sprints incluídos no registo cumulativo.
A6: Tarefas com atribuições iniciais | B6: =COUNTIF('Registo da Rotação'!$D$54:$D$162,"<>") -> 10 | C6: Informação | D6: Número de tarefas transcritas dos Sprint Backlogs vigentes.
A7: Transferências registadas | B7: =COUNTIF('Registo da Rotação'!$C$168:$C$217,"<>") -> 0 | C7: Informação | D7: Número de participações adicionais resultantes de transferências formais.
A8: Campos obrigatórios vazios no quadro dos Sprints | B8: =SUMPRODUCT(--('Registo da Rotação'!$C$6:$C$25<>""),--(('Registo da Rotação'!$A$6:$A$25="")+('Registo da Rotação'!$B$6:$B$25="")+('Registo da Rotação'!$D$6:$D$25="")+('Registo da Rotação'!$E$6:$E$25="")+('Registo da Rotação'!$F$6:$F$25="")+('Registo da Rotação'!$G$6:$G$25="")>0)) -> 0 | C8: =IF(B8=0,"OK","Rever") -> OK | D8: Deve ser 0. Cada Sprint identifica milestone, ordem, situação, Líder, Secretário e confirmação do Secretariado.
A9: Sprints ou números de ordem repetidos | B9: =SUM('Listas de apoio'!AG5:AG24) -> 0 | C9: =IF(B9=0,"OK","Rever") -> OK | D9: Deve ser 0. Cada Sprint e cada número de ordem aparecem uma única vez.
A10: Sprints sem linha correspondente nas fontes documentais | B10: =SUM('Listas de apoio'!AE5:AE24) -> 0 | C10: =IF(B10=0,"OK","Rever") -> OK | D10: Deve ser 0. Cada Sprint registado deve possuir uma linha no quadro das fontes documentais.
A11: Fontes documentais associadas a Sprints que não constam do registo | B11: =COUNTIF('Registo da Rotação'!$B$29:$B$48,"Sprint não registado") -> 0 | C11: =IF(B11=0,"OK","Rever") -> OK | D11: Deve ser 0. Cada linha do quadro «Fontes documentais por Sprint» tem de identificar um Sprint previamente registado no quadro «Sprints, liderança e Secretariado». Um valor superior a 0 indica que existe pelo menos uma fonte documental associada a um Sprint que não foi registado.
A12: Sprints sem o Sprint Backlog editável (XLS/XLSX) e PDF assinado | B12: =SUMPRODUCT(--('Registo da Rotação'!$A$29:$A$48<>""),--((('Registo da Rotação'!$C$29:$C$48="")+('Registo da Rotação'!$G$29:$G$48=""))>0)) -> 0 | C12: =IF(B12=0,"OK","Rever") -> OK | D12: Deve ser 0. O Sprint Backlog vigente é obrigatório mesmo enquanto o Sprint está em curso.
A13: Sprints concluídos sem o Mapa de Pontuação Individual editável (XLS/XLSX) e PDF assinado | B13: =SUMPRODUCT(--('Registo da Rotação'!$A$29:$A$48<>""),--('Registo da Rotação'!$B$29:$B$48="Concluído"),--((('Registo da Rotação'!$K$29:$K$48="")+('Registo da Rotação'!$O$29:$O$48=""))>0)) -> 0 | C13: =IF(B13=0,"OK","Rever") -> OK | D13: Deve ser 0. Num Sprint concluído, o Mapa de Pontuação Individual comprova os desempenhos apreciados no Sprint Review.
A14: Referências ao Mapa de Pontuação Individual indicadas como Ainda não aplicável | B14: =COUNTIF('Registo da Rotação'!$K$29:$K$48,"Ainda não aplicável")+COUNTIF('Registo da Rotação'!$O$29:$O$48,"Ainda não aplicável") -> 0 | C14: Informação | D14: Pode ser superior a 0 apenas em Sprints ainda em curso. Esta indicação chama a atenção para fontes que terão de ser completadas depois do Sprint Review.
A15: Sprints concluídos que ainda apresentam fontes como Ainda não aplicável | B15: =SUM('Listas de apoio'!AF5:AF24) -> 0 | C15: =IF(B15=0,"OK","Rever") -> OK | D15: Deve ser 0. Depois do Sprint Review, substitua Ainda não aplicável pelos caminhos do ficheiro editável em formato XLS ou XLSX e do respetivo PDF assinado.
A16: Campos obrigatórios vazios nas atribuições iniciais | B16: =SUM('Listas de apoio'!O5:O104) -> 0 | C16: =IF(B16=0,"OK","Rever") -> OK | D16: Deve ser 0. Cada tarefa deve conter sequência, milestone, Sprint, Issue, designação, três responsáveis e três confirmações.
A17: Tarefas associadas a um Sprint não registado | B17: =SUM('Listas de apoio'!P5:P104) -> 0 | C17: =IF(B17=0,"OK","Rever") -> OK | D17: Deve ser 0. O Sprint de cada tarefa deve existir no primeiro quadro da folha Registo da Rotação.
A18: Tarefas em que o mesmo aluno acumula mais de um papel | B18: =SUM('Listas de apoio'!Q5:Q104) -> 5 | C18: =IF(B18=0,"OK","Rever") -> Rever | D18: Deve ser 0. Executor, Revisor e Auditor devem ser alunos diferentes na mesma tarefa.
A19: Desempenhos ainda não avaliados em Sprints concluídos | B19: =SUM('Listas de apoio'!R5:R104)+SUM('Listas de apoio'!AB5:AB54)+SUM('Listas de apoio'!AH5:AH24) -> 0 | C19: =IF(B19=0,"OK","Rever") -> OK | D19: Deve ser 0. Quando o Sprint fica concluído, as tarefas, transferências e o Secretariado deixam de apresentar Ainda não avaliado.
A20: Repetição imediata do mesmo Revisor e Auditor em tarefas do mesmo Executor | B20: =SUM('Listas de apoio'!S5:S104) -> 2 | C20: =IF(B20=0,"OK","Rever") -> Rever | D20: Deve ser 0. Considere separadamente a sequência de tarefas atribuídas a cada Executor. Em duas atribuições consecutivas do mesmo Executor, o par formado pelo Revisor e pelo Auditor não pode ser exatamente o mesmo. Um valor superior a 0 indica pelo menos uma repetição imediata dessa combinação.
A21: Reutilização da mesma combinação antes da participação dos restantes alunos | B21: =SUM('Listas de apoio'!T5:T104) -> 5 | C21: =IF(B21=0,"OK","Rever") -> Rever | D21: Deve ser 0. Analise separadamente cada Executor. Se uma combinação de Revisor e Auditor já tiver sido usada com esse Executor, só pode ser repetida depois de todos os outros alunos elegíveis que não integram essa combinação terem participado entretanto como Revisor ou Auditor em tarefas desse Executor.
A22: Sequências ou Issues repetidas no mesmo Sprint | B22: =SUM('Listas de apoio'!U5:U104) -> 0 | C22: =IF(B22=0,"OK","Rever") -> OK | D22: Deve ser 0. A sequência é única no projeto e cada Issue aparece uma única vez por Sprint nesta grelha.
A23: Campos obrigatórios vazios nas transferências | B23: =SUM('Listas de apoio'!W5:W54) -> 0 | C23: =IF(B23=0,"OK","Rever") -> OK | D23: Deve ser 0. Cada transferência identifica a origem, o destinatário, a referência formal e a confirmação do desempenho.
A24: Transferências em que o cedente e o novo responsável são a mesma pessoa | B24: =SUM('Listas de apoio'!X5:X54) -> 0 | C24: =IF(B24=0,"OK","Rever") -> OK | D24: Deve ser 0. Uma transferência exige dois alunos diferentes.
A25: Transferências associadas a Sprints não registados | B25: =SUM('Listas de apoio'!Y5:Y54) -> 0 | C25: =IF(B25=0,"OK","Rever") -> OK | D25: Deve ser 0. O Sprint da transferência deve existir no registo cumulativo.
A26: Transferências que criam acumulação incompatível de papéis | B26: =SUM('Listas de apoio'!Z5:Z54) -> 0 | C26: =IF(B26=0,"OK","Rever") -> OK | D26: Deve ser 0. O novo responsável não pode já desempenhar outro dos três papéis na mesma tarefa.
A27: Transferências cujo cedente não corresponde ao responsável inicial do papel | B27: =SUM('Listas de apoio'!AA5:AA54) -> 0 | C27: =IF(B27=0,"OK","Rever") -> OK | D27: Deve ser 0. O cedente deve corresponder ao responsável inicialmente atribuído ao papel indicado.
A28: Sprints em que o Líder e o Secretário coincidem ou o Secretariado continua pendente | B28: =SUM('Listas de apoio'!AH5:AH24) -> 0 | C28: =IF(B28=0,"OK","Rever") -> OK | D28: Deve ser 0. Líder e Secretário são alunos diferentes; num Sprint concluído, o Secretariado deve estar avaliado.
