Workbook
Name CatalogoCCA: 'Catálogo de referência'!A6:E60
Name EstadosCCA: 'Listas de apoio'!$E$5:$E$7
Name MilestonesCCA: 'Listas de apoio'!$A$5:$A$8
Name OrigensCCA: 'Listas de apoio'!$C$5:$C$6

Sheet CCA
A1: CHECKLIST DE CONTROLO DE ARTEFACTOS — CCA | B1: CHECKLIST DE CONTROLO DE ARTEFACTOS — CCA | C1: CHECKLIST DE CONTROLO DE ARTEFACTOS — CCA | D1: CHECKLIST DE CONTROLO DE ARTEFACTOS — CCA | E1: CHECKLIST DE CONTROLO DE ARTEFACTOS — CCA | F1: CHECKLIST DE CONTROLO DE ARTEFACTOS — CCA | G1: CHECKLIST DE CONTROLO DE ARTEFACTOS — CCA
A3: Próxima Milestone de Entrega | D3: m1 | F3: =IF(SUM('Listas de apoio'!$H$5:$R$154,'Listas de apoio'!$T$5:$V$154)=0,"Conforme","Rever") -> Conforme
A5: RESUMO POR MILESTONE | B5: RESUMO POR MILESTONE | C5: RESUMO POR MILESTONE | D5: RESUMO POR MILESTONE | E5: RESUMO POR MILESTONE | F5: RESUMO POR MILESTONE | G5: RESUMO POR MILESTONE
A6: Milestone | B6: Artefactos com compromisso assumido | C6: Previstos | D6: Prontos para entrega | E6: Entregues | F6: Situação
A7: m1 | B7: =COUNTIFS($D$16:$D$165,A7,$A$16:$A$165,"<>") -> 3 | C7: =COUNTIFS($D$16:$D$165,A7,$G$16:$G$165,"Previsto") -> 0 | D7: =COUNTIFS($D$16:$D$165,A7,$G$16:$G$165,"Pronto para entrega") -> 3 | E7: =COUNTIFS($D$16:$D$165,A7,$G$16:$G$165,"Entregue") -> 0 | F7: =IF(MATCH(A7,MilestonesCCA,0)<MATCH($D$3,MilestonesCCA,0),IF(B7=E7,"Entregue","Rever"),IF(MATCH(A7,MilestonesCCA,0)=MATCH($D$3,MilestonesCCA,0),IF(B7=D7+E7,"Conforme","Rever"),"Milestone futura")) -> Conforme
A8: m2 | B8: =COUNTIFS($D$16:$D$165,A8,$A$16:$A$165,"<>") -> 13 | C8: =COUNTIFS($D$16:$D$165,A8,$G$16:$G$165,"Previsto") -> 13 | D8: =COUNTIFS($D$16:$D$165,A8,$G$16:$G$165,"Pronto para entrega") -> 0 | E8: =COUNTIFS($D$16:$D$165,A8,$G$16:$G$165,"Entregue") -> 0 | F8: =IF(MATCH(A8,MilestonesCCA,0)<MATCH($D$3,MilestonesCCA,0),IF(B8=E8,"Entregue","Rever"),IF(MATCH(A8,MilestonesCCA,0)=MATCH($D$3,MilestonesCCA,0),IF(B8=D8+E8,"Conforme","Rever"),"Milestone futura")) -> Milestone futura
A9: m3 | B9: =COUNTIFS($D$16:$D$165,A9,$A$16:$A$165,"<>") -> 17 | C9: =COUNTIFS($D$16:$D$165,A9,$G$16:$G$165,"Previsto") -> 17 | D9: =COUNTIFS($D$16:$D$165,A9,$G$16:$G$165,"Pronto para entrega") -> 0 | E9: =COUNTIFS($D$16:$D$165,A9,$G$16:$G$165,"Entregue") -> 0 | F9: =IF(MATCH(A9,MilestonesCCA,0)<MATCH($D$3,MilestonesCCA,0),IF(B9=E9,"Entregue","Rever"),IF(MATCH(A9,MilestonesCCA,0)=MATCH($D$3,MilestonesCCA,0),IF(B9=D9+E9,"Conforme","Rever"),"Milestone futura")) -> Milestone futura
A10: m4 | B10: =COUNTIFS($D$16:$D$165,A10,$A$16:$A$165,"<>") -> 18 | C10: =COUNTIFS($D$16:$D$165,A10,$G$16:$G$165,"Previsto") -> 18 | D10: =COUNTIFS($D$16:$D$165,A10,$G$16:$G$165,"Pronto para entrega") -> 0 | E10: =COUNTIFS($D$16:$D$165,A10,$G$16:$G$165,"Entregue") -> 0 | F10: =IF(MATCH(A10,MilestonesCCA,0)<MATCH($D$3,MilestonesCCA,0),IF(B10=E10,"Entregue","Rever"),IF(MATCH(A10,MilestonesCCA,0)=MATCH($D$3,MilestonesCCA,0),IF(B10=D10+E10,"Conforme","Rever"),"Milestone futura")) -> Milestone futura
A11: Total | B11: =SUM(B7:B10) -> 51 | C11: =SUM(C7:C10) -> 48 | D11: =SUM(D7:D10) -> 3 | E11: =SUM(E7:E10) -> 0 | F11: —
A13: ARTEFACTOS COM COMPROMISSO ASSUMIDO | B13: ARTEFACTOS COM COMPROMISSO ASSUMIDO | C13: ARTEFACTOS COM COMPROMISSO ASSUMIDO | D13: ARTEFACTOS COM COMPROMISSO ASSUMIDO | E13: ARTEFACTOS COM COMPROMISSO ASSUMIDO | F13: ARTEFACTOS COM COMPROMISSO ASSUMIDO | G13: ARTEFACTOS COM COMPROMISSO ASSUMIDO
A14: Não elimine linhas existentes em versões anteriores. Acrescente uma nova linha por artefacto ou nova versão cuja entrega seja assumida. O estado Entregue só é usado depois da submissão efetiva no Moodle. | B14: Não elimine linhas existentes em versões anteriores. Acrescente uma nova linha por artefacto ou nova versão cuja entrega seja assumida. O estado Entregue só é usado depois da submissão efetiva no Moodle. | C14: Não elimine linhas existentes em versões anteriores. Acrescente uma nova linha por artefacto ou nova versão cuja entrega seja assumida. O estado Entregue só é usado depois da submissão efetiva no Moodle. | D14: Não elimine linhas existentes em versões anteriores. Acrescente uma nova linha por artefacto ou nova versão cuja entrega seja assumida. O estado Entregue só é usado depois da submissão efetiva no Moodle. | E14: Não elimine linhas existentes em versões anteriores. Acrescente uma nova linha por artefacto ou nova versão cuja entrega seja assumida. O estado Entregue só é usado depois da submissão efetiva no Moodle. | F14: Não elimine linhas existentes em versões anteriores. Acrescente uma nova linha por artefacto ou nova versão cuja entrega seja assumida. O estado Entregue só é usado depois da submissão efetiva no Moodle. | G14: Não elimine linhas existentes em versões anteriores. Acrescente uma nova linha por artefacto ou nova versão cuja entrega seja assumida. O estado Entregue só é usado depois da submissão efetiva no Moodle.
A15: Código | B15: Artefacto | C15: Origem da obrigação | D15: Milestone de Entrega | E15: Justificação | F15: Pasta de destino | G15: Estado
A16: OF-M1-001 | B16: Proposta de Sistema v1 | C16: Regulamento da UC | D16: m1 | E16: Apresenta a aplicação criada de raiz e descreve as suas funcionalidades principais. | F16: /projeto/04-artefactos-tecnicos/04.01-proposta-de-sistema-e-declaracao-de-ambito | G16: Pronto para entrega
A17: OF-M1-002 | B17: Declaração de Âmbito v1 | C17: Regulamento da UC | D17: m1 | E17: Fixa o Âmbito, o Não-Âmbito e o volume de trabalho assumido pelo grupo. | F17: /projeto/04-artefactos-tecnicos/04.01-proposta-de-sistema-e-declaracao-de-ambito | G17: Pronto para entrega
A18: OF-M1-003 | B18: Critérios de qualidade dos requisitos v1 | C18: Regulamento da UC | D18: m1 | E18: Define os critérios objetivos aplicáveis à elaboração e aprovação dos requisitos. | F18: /projeto/04-artefactos-tecnicos/04.03-requisitos-e-rtm | G18: Pronto para entrega
A19: OF-M2-001 | B19: Especificação de requisitos v1 | C19: Regulamento da UC | D19: m2 | E19: Especifica os requisitos funcionais e não funcionais abrangidos pelo projeto. | F19: /projeto/04-artefactos-tecnicos/04.03-requisitos-e-rtm | G19: Previsto
A20: OF-M2-002 | B20: Checklist de aprovação dos requisitos v1 | C20: Regulamento da UC | D20: m2 | E20: Demonstra a verificação e aprovação individual dos requisitos através dos critérios de qualidade definidos. | F20: /projeto/04-artefactos-tecnicos/04.03-requisitos-e-rtm | G20: Previsto
A21: OF-M2-003 | B21: Requirements Traceability Matrix v1 | C21: Regulamento da UC | D21: m2 | E21: Estabelece a rastreabilidade inicial entre âmbito, requisitos, casos de uso, arquitetura e testes previstos. | F21: /projeto/04-artefactos-tecnicos/04.03-requisitos-e-rtm | G21: Previsto
A22: OF-M2-004 | B22: Especificações dos casos de uso v1 | C22: Regulamento da UC | D22: m2 | E22: Documenta os atores, objetivos, fluxos, exceções e requisitos associados aos casos de uso relevantes. | F22: /projeto/04-artefactos-tecnicos/04.04-casos-de-uso | G22: Previsto
A23: OF-M2-005 | B23: Documentação da arquitetura v1 | C23: Regulamento da UC | D23: m2 | E23: Documenta componentes, responsabilidades, relações, tecnologias, interfaces, restrições e decisões da arquitetura. | F23: /projeto/04-artefactos-tecnicos/04.05-arquitetura | G23: Previsto
A24: OF-M2-006 | B24: Modelo de dados — clinica-veterinaria v1 | C24: Regulamento da UC | D24: m2 | E24: Documenta os modelos conceptual, lógico e físico e o dicionário de dados da base de dados clinica-veterinaria. | F24: /projeto/04-artefactos-tecnicos/04.06-modelos-de-dados | G24: Previsto
... A66: AD-005 | B66: Relatório de cobertura dos testes do frontend v1 | C66: Compromisso do grupo | D66: m4 | E66: O grupo considera a cobertura uma métrica tecnicamente adequada e decidiu incluí-la nos seus controlos de qualidade. | F66: /projeto/03-artefactos-de-qualidade-de-produto/03.02-frontend/03.02.05-cobertura-de-testes | G66: Previsto

Sheet Catálogo de referência
A1: CATÁLOGO DE REFERÊNCIA | B1: CATÁLOGO DE REFERÊNCIA | C1: CATÁLOGO DE REFERÊNCIA | D1: CATÁLOGO DE REFERÊNCIA | E1: CATÁLOGO DE REFERÊNCIA | F1: CATÁLOGO DE REFERÊNCIA
A2: REFERÊNCIA — não editar. Os artefactos obrigatórios são incluídos na CCA. Os artefactos condicionais só passam a compromisso quando o grupo os acrescenta à CCA. | B2: REFERÊNCIA — não editar. Os artefactos obrigatórios são incluídos na CCA. Os artefactos condicionais só passam a compromisso quando o grupo os acrescenta à CCA. | C2: REFERÊNCIA — não editar. Os artefactos obrigatórios são incluídos na CCA. Os artefactos condicionais só passam a compromisso quando o grupo os acrescenta à CCA. | D2: REFERÊNCIA — não editar. Os artefactos obrigatórios são incluídos na CCA. Os artefactos condicionais só passam a compromisso quando o grupo os acrescenta à CCA. | E2: REFERÊNCIA — não editar. Os artefactos obrigatórios são incluídos na CCA. Os artefactos condicionais só passam a compromisso quando o grupo os acrescenta à CCA. | F2: REFERÊNCIA — não editar. Os artefactos obrigatórios são incluídos na CCA. Os artefactos condicionais só passam a compromisso quando o grupo os acrescenta à CCA.
A4: ARTEFACTOS TÉCNICOS E DE QUALIDADE DO PRODUTO | B4: ARTEFACTOS TÉCNICOS E DE QUALIDADE DO PRODUTO | C4: ARTEFACTOS TÉCNICOS E DE QUALIDADE DO PRODUTO | D4: ARTEFACTOS TÉCNICOS E DE QUALIDADE DO PRODUTO | E4: ARTEFACTOS TÉCNICOS E DE QUALIDADE DO PRODUTO | F4: ARTEFACTOS TÉCNICOS E DE QUALIDADE DO PRODUTO
A5: Código de referência | B5: Artefacto de referência | C5: Natureza no Regulamento | D5: Milestone | E5: Pasta de destino | F5: Tratamento na CCA
A6: OF-M1-001 | B6: Proposta de Sistema v1 | C6: Obrigatório | D6: m1 | E6: /projeto/04-artefactos-tecnicos/04.01-proposta-de-sistema-e-declaracao-de-ambito | F6: Incluído automaticamente na CCA.
A7: OF-M1-002 | B7: Declaração de Âmbito v1 | C7: Obrigatório | D7: m1 | E7: /projeto/04-artefactos-tecnicos/04.01-proposta-de-sistema-e-declaracao-de-ambito | F7: Incluído automaticamente na CCA.
A8: OF-M1-003 | B8: Critérios de qualidade dos requisitos v1 | C8: Obrigatório | D8: m1 | E8: /projeto/04-artefactos-tecnicos/04.03-requisitos-e-rtm | F8: Incluído automaticamente na CCA.
A9: OF-M2-001 | B9: Especificação de requisitos v1 | C9: Obrigatório | D9: m2 | E9: /projeto/04-artefactos-tecnicos/04.03-requisitos-e-rtm | F9: Incluído automaticamente na CCA.
A10: OF-M2-002 | B10: Checklist de aprovação dos requisitos v1 | C10: Obrigatório | D10: m2 | E10: /projeto/04-artefactos-tecnicos/04.03-requisitos-e-rtm | F10: Incluído automaticamente na CCA.
A11: OF-M2-003 | B11: Requirements Traceability Matrix v1 | C11: Obrigatório | D11: m2 | E11: /projeto/04-artefactos-tecnicos/04.03-requisitos-e-rtm | F11: Incluído automaticamente na CCA.
A12: OF-M2-004 | B12: Especificações dos casos de uso v1 | C12: Obrigatório | D12: m2 | E12: /projeto/04-artefactos-tecnicos/04.04-casos-de-uso | F12: Incluído automaticamente na CCA.
A13: OF-M2-005 | B13: Documentação da arquitetura v1 | C13: Obrigatório | D13: m2 | E13: /projeto/04-artefactos-tecnicos/04.05-arquitetura | F13: Incluído automaticamente na CCA.
... A60: REF-GERAL-001 | B60: Documentação técnica complementar | C60: Condicional | D60: m1–m4 | E60: /projeto/04-artefactos-tecnicos/04.20-documentacao-complementar | F60: Acrescentar uma linha por estudo ou artefacto técnico assumido pelo grupo.

Sheet Validação
A1: VALIDAÇÃO | B1: VALIDAÇÃO | C1: VALIDAÇÃO | D1: VALIDAÇÃO
A2: Confirme que todas as verificações apresentam OK antes de congelar a CCA em PDF, recolher as assinaturas digitais dos alunos presentes que aprovam e assinam a ata da reunião autónoma de controlo final e preparar a entrega.
A4: Verificação | B4: Resultado | C4: Estado | D4: Interpretação
A5: Artefactos com compromisso assumido | B5: =COUNTIF(CCA!$A$16:$A$165,"<>") -> 51 | C5: Informação | D5: Número total de linhas preenchidas na CCA.
A6: Artefactos técnicos obrigatórios em falta | B6: =SUM('Listas de apoio'!$V$5:$V$154) -> 0 | C6: =IF(B6=0,"OK","Rever") -> OK | D6: Deve ser 0. Todos os artefactos técnicos e de qualidade do produto classificados como obrigatórios no catálogo devem constar da CCA.
A7: Códigos repetidos | B7: =SUM('Listas de apoio'!$T$5:$T$154) -> 0 | C7: =IF(B7=0,"OK","Rever") -> OK | D7: Deve ser 0. Cada compromisso de entrega deve possuir um código único.
A8: Linhas parcialmente preenchidas | B8: =SUM('Listas de apoio'!$H$5:$H$154) -> 0 | C8: =IF(B8=0,"OK","Rever") -> OK | D8: Deve ser 0. Uma linha iniciada deve conter os sete campos obrigatórios.
A9: Valores inválidos em Origem da obrigação | B9: =SUM('Listas de apoio'!$I$5:$I$154) -> 0 | C9: =IF(B9=0,"OK","Rever") -> OK | D9: Deve ser 0. Utilize apenas Regulamento da UC ou Compromisso do grupo.
A10: Valores inválidos em Milestone de Entrega | B10: =SUM('Listas de apoio'!$J$5:$J$154) -> 0 | C10: =IF(B10=0,"OK","Rever") -> OK | D10: Deve ser 0. Utilize apenas m1, m2, m3 ou m4.
A11: Valores inválidos em Estado | B11: =SUM('Listas de apoio'!$K$5:$K$154) -> 0 | C11: =IF(B11=0,"OK","Rever") -> OK | D11: Deve ser 0. Utilize apenas Previsto, Pronto para entrega ou Entregue.
A12: Código incompatível com a origem da obrigação | B12: =SUM('Listas de apoio'!$L$5:$L$154) -> 0 | C12: =IF(B12=0,"OK","Rever") -> OK | D12: Deve ser 0. Use OF- para obrigações regulamentares e AD- para compromissos acrescentados pelo grupo.
A13: Milestones de artefactos oficiais diferentes do catálogo | B13: =SUM('Listas de apoio'!$M$5:$M$154) -> 0 | C13: =IF(B13=0,"OK","Rever") -> OK | D13: Deve ser 0. A milestone regulamentar de um artefacto obrigatório não pode ser alterada.
A14: Pastas de artefactos oficiais diferentes do catálogo | B14: =SUM('Listas de apoio'!$N$5:$N$154) -> 0 | C14: =IF(B14=0,"OK","Rever") -> OK | D14: Deve ser 0. Os artefactos oficiais devem permanecer na pasta funcional definida na hierarquia.
A15: Compromissos acrescentados pelo grupo sem justificação suficiente | B15: =SUM('Listas de apoio'!$O$5:$O$154) -> 0 | C15: =IF(B15=0,"OK","Rever") -> OK | D15: Deve ser 0. Explique concretamente por que razão o grupo decidiu produzir cada artefacto adicional.
A16: Artefactos de milestones anteriores ainda não entregues | B16: =SUM('Listas de apoio'!$P$5:$P$154) -> 0 | C16: =IF(B16=0,"OK","Rever") -> OK | D16: Deve ser 0. Todos os artefactos das milestones anteriores devem estar marcados como Entregue.
A17: Artefactos ainda previstos para a próxima milestone | B17: =SUM('Listas de apoio'!$Q$5:$Q$154) -> 0 | C17: =IF(B17=0,"OK","Rever") -> OK | D17: Deve ser 0 antes da submissão. Um artefacto em estado Previsto ainda não está pronto para integrar o ZIP.
A18: Artefactos de milestones futuras marcados como entregues | B18: =SUM('Listas de apoio'!$R$5:$R$154) -> 0 | C18: =IF(B18=0,"OK","Rever") -> OK | D18: Deve ser 0. O trabalho pode ser preparado antecipadamente, mas só é entregue na milestone regulamentar correspondente.
A19: Designações ou caminhos ainda com marcadores genéricos | B19: =SUM('Listas de apoio'!$U$5:$U$154) -> 0 | C19: =IF(B19=0,"OK","Rever") -> OK | D19: Deve ser 0. Substitua marcadores como <módulo>, <interação> ou <nome-da-base-de-dados> por valores concretos.
A20: Comparação com a versão anterior da CCA | B20: Verificação manual | C20: Confirmar | D20: Compare com o ficheiro editável em formato XLS ou XLSX e o PDF assinado da milestone anterior. Nenhuma linha anteriormente assumida pode desaparecer nem a respetiva milestone ser adiada sem autorização prévia e escrita do docente.
A21: Congelamento e assinaturas da CCA | B21: Verificação manual | C21: Confirmar | D21: Em cada milestone, exporte a folha CCA para PDF, confirme que corresponde ao ficheiro editável em formato XLS ou XLSX e recolha as assinaturas digitais dos alunos presentes que aprovam e assinam a ata da reunião autónoma de controlo final.

Sheet Instruções
A1: INSTRUÇÕES | B1: INSTRUÇÕES | C1: INSTRUÇÕES | D1: INSTRUÇÕES
A2: Leia integralmente estas regras antes de substituir os exemplos. A CCA é cumulativa e, em cada milestone, deve ser conservada a versão editável efetivamente utilizada, em formato XLS ou XLSX, e o respetivo PDF assinado digitalmente pelos alunos presentes que aprovam e assinam a ata da reunião autónoma de controlo final.
A4: N.º | B4: Tópico | C4: Regra | D4: Exemplo ou observação
A5: 1 | B5: Finalidade | C5: A CCA fixa antecipadamente os artefactos técnicos e de qualidade do produto que o grupo fica obrigado a entregar. | D5: Não é um inventário de todos os ficheiros existentes em /projeto.
A6: 2 | B6: Âmbito | C6: Inclua os artefactos técnicos e de qualidade do produto obrigatórios, os artefactos técnicos ou de qualidade do produto condicionais que o grupo decida produzir e os artefactos técnicos ou de qualidade do produto adicionais cuja entrega o grupo assuma. | D6: Não inclua convocatórias, atas, anexos obrigatórios das reuniões, mapas de avaliação interna, grelha de rotação, templates, README ou e-mails.
A7: 3 | B7: Primeira versão | C7: Em m1, concretize os exemplos e antecipe os artefactos que serão necessários até m4. Todos os artefactos regulamentares obrigatórios permanecem na CCA. | D7: Substitua medstock, backend, módulos, interações e funcionalidades pelos valores reais do projeto.
A8: 4 | B8: Próxima Milestone de Entrega | C8: Selecione a milestone que o grupo está a preparar. A folha Validação utiliza este valor para distinguir entregas anteriores, a próxima entrega e entregas futuras. | D8: Antes de m1 use m1; depois da submissão de m1 passe para m2.
A9: 5 | B9: Origem da obrigação — Regulamento da UC | C9: Use Regulamento da UC quando a entrega já for obrigatória nos documentos oficiais. | D9: Estas linhas utilizam códigos iniciados por OF-.
A10: 6 | B10: Origem da obrigação — Compromisso do grupo | C10: Use Compromisso do grupo quando o artefacto era condicional ou não estava previsto, mas o grupo decidiu entregá-lo. | D10: Estas linhas utilizam códigos AD-001, AD-002, etc.
A11: 7 | B11: Efeito do compromisso | C11: Todos os artefactos inscritos na CCA passam a ser obrigatórios. Um artefacto condicional deixa de ser facultativo depois de incluído. | D11: Não utilize Não aplicável como estado.
A12: 8 | B12: Estado — Previsto | C12: Use Previsto enquanto o artefacto ainda não estiver concluído e validado. Este estado abrange também o período em que está a ser produzido. | D12: Não é necessário alterar a CCA apenas para indicar o início dos trabalhos.
A13: 9 | B13: Estado — Pronto para entrega | C13: Use Pronto para entrega apenas quando o artefacto estiver concluído, revisto, colocado na pasta correta e preparado para integrar o ZIP. | D13: A validação da próxima milestone exige que nenhuma linha permaneça em Previsto.
A14: 10 | B14: Estado — Entregue | C14: Use Entregue apenas depois de o artefacto integrar efetivamente o ZIP submetido no Moodle. | D14: Um artefacto de uma milestone futura não pode ser marcado como Entregue.
A15: 11 | B15: Responsabilidade | C15: A responsabilidade de entregar todos os artefactos é coletiva. A CCA não repete a atribuição individual existente no Backlog de Projeto, Sprint Backlog e atas. | D15: A ausência da coluna Executor é intencional.
A16: 12 | B16: Comprovação da entrega | C16: O cumprimento é confirmado pela presença física do artefacto na pasta indicada dentro de /projeto e pela respetiva ligação no README. | D16: Não são aceites ligações externas como substituto do ficheiro.
... A31: 27 | B31: Dados de exemplo | C31: Os dados representam um projeto MedStock na preparação de m2 e demonstram as três situações possíveis. | D31: Substitua integralmente os exemplos pelos compromissos reais do grupo.

Sheet Listas de apoio
A1: LISTAS DE APOIO | B1: LISTAS DE APOIO | C1: LISTAS DE APOIO | D1: LISTAS DE APOIO | E1: LISTAS DE APOIO | F1: LISTAS DE APOIO
A2: Estas listas suportam as opções, os cálculos e as verificações automáticas. Não altere as milestones, origens, estados ou colunas auxiliares.
A4: MILESTONES | C4: ORIGEM DA OBRIGAÇÃO | E4: ESTADOS | G4: Linha CCA | H4: Linha incompleta | I4: Origem inválida | J4: Milestone inválida | K4: Estado inválido | L4: Prefixo incoerente | M4: Milestone oficial alterada | N4: Pasta oficial alterada | O4: Adição sem justificação | P4: Milestone anterior não entregue | Q4: Próxima milestone ainda prevista | R4: Milestone futura entregue | T4: Código repetido | U4: Marcador genérico | V4: Obrigatório em falta
A5: m1 | C5: Regulamento da UC | E5: Previsto | G5: 17 | H5: =IF(COUNTA(CCA!A16:G16)=0,0,IF(COUNTA(CCA!A16:G16)<7,1,0)) -> 0 | I5: =IF(CCA!A16="",0,IF(COUNTIF(OrigensCCA,CCA!C16)=0,1,0)) -> 0 | J5: =IF(CCA!A16="",0,IF(COUNTIF(MilestonesCCA,CCA!D16)=0,1,0)) -> 0 | K5: =IF(CCA!A16="",0,IF(COUNTIF(EstadosCCA,CCA!G16)=0,1,0)) -> 0 | L5: =IF(CCA!A16="",0,IF(CCA!C16="Regulamento da UC",IF(LEFT(CCA!A16,3)="OF-",0,1),IF(CCA!C16="Compromisso do grupo",IF(LEFT(CCA!A16,3)="AD-",0,1),0))) -> 0 | M5: =IF(LEFT(CCA!A16,3)<>"OF-",0,IFERROR(IF(VLOOKUP(CCA!A16,CatalogoCCA,4,FALSE)=CCA!D16,0,1),0)) -> 0 | N5: =IF(LEFT(CCA!A16,3)<>"OF-",0,IFERROR(IF(VLOOKUP(CCA!A16,CatalogoCCA,5,FALSE)=CCA!F16,0,1),0)) -> 0 | O5: =IF(CCA!A16="",0,IF(CCA!C16="Compromisso do grupo",IF(LEN(TRIM(CCA!E16))<20,1,0),0)) -> 0 | P5: =IF(CCA!A16="",0,IFERROR(IF(MATCH(CCA!D16,MilestonesCCA,0)<MATCH(CCA!$D$3,MilestonesCCA,0),IF(CCA!G16<>"Entregue",1,0),0),0)) -> 0 | Q5: =IF(CCA!A16="",0,IFERROR(IF(MATCH(CCA!D16,MilestonesCCA,0)=MATCH(CCA!$D$3,MilestonesCCA,0),IF(CCA!G16="Previsto",1,0),0),0)) -> 0 | R5: =IF(CCA!A16="",0,IFERROR(IF(MATCH(CCA!D16,MilestonesCCA,0)>MATCH(CCA!$D$3,MilestonesCCA,0),IF(CCA!G16="Entregue",1,0),0),0)) -> 0 | T5: =IF(CCA!A16="",0,IF(COUNTIF(CCA!$A$16:$A$165,CCA!A16)>1,1,0)) -> 0 | U5: =IF(CCA!A16="",0,IF(OR(ISNUMBER(SEARCH("<",CCA!B16)),ISNUMBER(SEARCH(">",CCA!B16)),ISNUMBER(SEARCH("<",CCA!F16)),ISNUMBER(SEARCH(">",CCA!F16))),1,0)) -> 0 | V5: =IF('Catálogo de referência'!C6<>"Obrigatório",0,IF(COUNTIF(CCA!$A$16:$A$165,'Catálogo de referência'!A6)=0,1,0)) -> 0
A6: m2 | C6: Compromisso do grupo | E6: Pronto para entrega | G6: 18 | H6: =IF(COUNTA(CCA!A17:G17)=0,0,IF(COUNTA(CCA!A17:G17)<7,1,0)) -> 0 | I6: =IF(CCA!A17="",0,IF(COUNTIF(OrigensCCA,CCA!C17)=0,1,0)) -> 0 | J6: =IF(CCA!A17="",0,IF(COUNTIF(MilestonesCCA,CCA!D17)=0,1,0)) -> 0 | K6: =IF(CCA!A17="",0,IF(COUNTIF(EstadosCCA,CCA!G17)=0,1,0)) -> 0 | L6: =IF(CCA!A17="",0,IF(CCA!C17="Regulamento da UC",IF(LEFT(CCA!A17,3)="OF-",0,1),IF(CCA!C17="Compromisso do grupo",IF(LEFT(CCA!A17,3)="AD-",0,1),0))) -> 0 | M6: =IF(LEFT(CCA!A17,3)<>"OF-",0,IFERROR(IF(VLOOKUP(CCA!A17,CatalogoCCA,4,FALSE)=CCA!D17,0,1),0)) -> 0 | N6: =IF(LEFT(CCA!A17,3)<>"OF-",0,IFERROR(IF(VLOOKUP(CCA!A17,CatalogoCCA,5,FALSE)=CCA!F17,0,1),0)) -> 0 | O6: =IF(CCA!A17="",0,IF(CCA!C17="Compromisso do grupo",IF(LEN(TRIM(CCA!E17))<20,1,0),0)) -> 0 | P6: =IF(CCA!A17="",0,IFERROR(IF(MATCH(CCA!D17,MilestonesCCA,0)<MATCH(CCA!$D$3,MilestonesCCA,0),IF(CCA!G17<>"Entregue",1,0),0),0)) -> 0 | Q6: =IF(CCA!A17="",0,IFERROR(IF(MATCH(CCA!D17,MilestonesCCA,0)=MATCH(CCA!$D$3,MilestonesCCA,0),IF(CCA!G17="Previsto",1,0),0),0)) -> 0 | R6: =IF(CCA!A17="",0,IFERROR(IF(MATCH(CCA!D17,MilestonesCCA,0)>MATCH(CCA!$D$3,MilestonesCCA,0),IF(CCA!G17="Entregue",1,0),0),0)) -> 0 | T6: =IF(CCA!A17="",0,IF(COUNTIF(CCA!$A$16:$A$165,CCA!A17)>1,1,0)) -> 0 | U6: =IF(CCA!A17="",0,IF(OR(ISNUMBER(SEARCH("<",CCA!B17)),ISNUMBER(SEARCH(">",CCA!B17)),ISNUMBER(SEARCH("<",CCA!F17)),ISNUMBER(SEARCH(">",CCA!F17))),1,0)) -> 0 | V6: =IF('Catálogo de referência'!C7<>"Obrigatório",0,IF(COUNTIF(CCA!$A$16:$A$165,'Catálogo de referência'!A7)=0,1,0)) -> 0
A7: m3 | E7: Entregue | G7: 19 | H7: =IF(COUNTA(CCA!A18:G18)=0,0,IF(COUNTA(CCA!A18:G18)<7,1,0)) -> 0 | I7: =IF(CCA!A18="",0,IF(COUNTIF(OrigensCCA,CCA!C18)=0,1,0)) -> 0 | J7: =IF(CCA!A18="",0,IF(COUNTIF(MilestonesCCA,CCA!D18)=0,1,0)) -> 0 | K7: =IF(CCA!A18="",0,IF(COUNTIF(EstadosCCA,CCA!G18)=0,1,0)) -> 0 | L7: =IF(CCA!A18="",0,IF(CCA!C18="Regulamento da UC",IF(LEFT(CCA!A18,3)="OF-",0,1),IF(CCA!C18="Compromisso do grupo",IF(LEFT(CCA!A18,3)="AD-",0,1),0))) -> 0 | M7: =IF(LEFT(CCA!A18,3)<>"OF-",0,IFERROR(IF(VLOOKUP(CCA!A18,CatalogoCCA,4,FALSE)=CCA!D18,0,1),0)) -> 0 | N7: =IF(LEFT(CCA!A18,3)<>"OF-",0,IFERROR(IF(VLOOKUP(CCA!A18,CatalogoCCA,5,FALSE)=CCA!F18,0,1),0)) -> 0 | O7: =IF(CCA!A18="",0,IF(CCA!C18="Compromisso do grupo",IF(LEN(TRIM(CCA!E18))<20,1,0),0)) -> 0 | P7: =IF(CCA!A18="",0,IFERROR(IF(MATCH(CCA!D18,MilestonesCCA,0)<MATCH(CCA!$D$3,MilestonesCCA,0),IF(CCA!G18<>"Entregue",1,0),0),0)) -> 0 | Q7: =IF(CCA!A18="",0,IFERROR(IF(MATCH(CCA!D18,MilestonesCCA,0)=MATCH(CCA!$D$3,MilestonesCCA,0),IF(CCA!G18="Previsto",1,0),0),0)) -> 0 | R7: =IF(CCA!A18="",0,IFERROR(IF(MATCH(CCA!D18,MilestonesCCA,0)>MATCH(CCA!$D$3,MilestonesCCA,0),IF(CCA!G18="Entregue",1,0),0),0)) -> 0 | T7: =IF(CCA!A18="",0,IF(COUNTIF(CCA!$A$16:$A$165,CCA!A18)>1,1,0)) -> 0 | U7: =IF(CCA!A18="",0,IF(OR(ISNUMBER(SEARCH("<",CCA!B18)),ISNUMBER(SEARCH(">",CCA!B18)),ISNUMBER(SEARCH("<",CCA!F18)),ISNUMBER(SEARCH(">",CCA!F18))),1,0)) -> 0 | V7: =IF('Catálogo de referência'!C8<>"Obrigatório",0,IF(COUNTIF(CCA!$A$16:$A$165,'Catálogo de referência'!A8)=0,1,0)) -> 0
A8: m4 | G8: 20 | H8: =IF(COUNTA(CCA!A19:G19)=0,0,IF(COUNTA(CCA!A19:G19)<7,1,0)) -> 0 | I8: =IF(CCA!A19="",0,IF(COUNTIF(OrigensCCA,CCA!C19)=0,1,0)) -> 0 | J8: =IF(CCA!A19="",0,IF(COUNTIF(MilestonesCCA,CCA!D19)=0,1,0)) -> 0 | K8: =IF(CCA!A19="",0,IF(COUNTIF(EstadosCCA,CCA!G19)=0,1,0)) -> 0 | L8: =IF(CCA!A19="",0,IF(CCA!C19="Regulamento da UC",IF(LEFT(CCA!A19,3)="OF-",0,1),IF(CCA!C19="Compromisso do grupo",IF(LEFT(CCA!A19,3)="AD-",0,1),0))) -> 0 | M8: =IF(LEFT(CCA!A19,3)<>"OF-",0,IFERROR(IF(VLOOKUP(CCA!A19,CatalogoCCA,4,FALSE)=CCA!D19,0,1),0)) -> 0 | N8: =IF(LEFT(CCA!A19,3)<>"OF-",0,IFERROR(IF(VLOOKUP(CCA!A19,CatalogoCCA,5,FALSE)=CCA!F19,0,1),0)) -> 0 | O8: =IF(CCA!A19="",0,IF(CCA!C19="Compromisso do grupo",IF(LEN(TRIM(CCA!E19))<20,1,0),0)) -> 0 | P8: =IF(CCA!A19="",0,IFERROR(IF(MATCH(CCA!D19,MilestonesCCA,0)<MATCH(CCA!$D$3,MilestonesCCA,0),IF(CCA!G19<>"Entregue",1,0),0),0)) -> 0 | Q8: =IF(CCA!A19="",0,IFERROR(IF(MATCH(CCA!D19,MilestonesCCA,0)=MATCH(CCA!$D$3,MilestonesCCA,0),IF(CCA!G19="Previsto",1,0),0),0)) -> 0 | R8: =IF(CCA!A19="",0,IFERROR(IF(MATCH(CCA!D19,MilestonesCCA,0)>MATCH(CCA!$D$3,MilestonesCCA,0),IF(CCA!G19="Entregue",1,0),0),0)) -> 0 | T8: =IF(CCA!A19="",0,IF(COUNTIF(CCA!$A$16:$A$165,CCA!A19)>1,1,0)) -> 0 | U8: =IF(CCA!A19="",0,IF(OR(ISNUMBER(SEARCH("<",CCA!B19)),ISNUMBER(SEARCH(">",CCA!B19)),ISNUMBER(SEARCH("<",CCA!F19)),ISNUMBER(SEARCH(">",CCA!F19))),1,0)) -> 0 | V8: =IF('Catálogo de referência'!C9<>"Obrigatório",0,IF(COUNTIF(CCA!$A$16:$A$165,'Catálogo de referência'!A9)=0,1,0)) -> 0
G9: 21 | H9: =IF(COUNTA(CCA!A20:G20)=0,0,IF(COUNTA(CCA!A20:G20)<7,1,0)) -> 0 | I9: =IF(CCA!A20="",0,IF(COUNTIF(OrigensCCA,CCA!C20)=0,1,0)) -> 0 | J9: =IF(CCA!A20="",0,IF(COUNTIF(MilestonesCCA,CCA!D20)=0,1,0)) -> 0 | K9: =IF(CCA!A20="",0,IF(COUNTIF(EstadosCCA,CCA!G20)=0,1,0)) -> 0 | L9: =IF(CCA!A20="",0,IF(CCA!C20="Regulamento da UC",IF(LEFT(CCA!A20,3)="OF-",0,1),IF(CCA!C20="Compromisso do grupo",IF(LEFT(CCA!A20,3)="AD-",0,1),0))) -> 0 | M9: =IF(LEFT(CCA!A20,3)<>"OF-",0,IFERROR(IF(VLOOKUP(CCA!A20,CatalogoCCA,4,FALSE)=CCA!D20,0,1),0)) -> 0 | N9: =IF(LEFT(CCA!A20,3)<>"OF-",0,IFERROR(IF(VLOOKUP(CCA!A20,CatalogoCCA,5,FALSE)=CCA!F20,0,1),0)) -> 0 | O9: =IF(CCA!A20="",0,IF(CCA!C20="Compromisso do grupo",IF(LEN(TRIM(CCA!E20))<20,1,0),0)) -> 0 | P9: =IF(CCA!A20="",0,IFERROR(IF(MATCH(CCA!D20,MilestonesCCA,0)<MATCH(CCA!$D$3,MilestonesCCA,0),IF(CCA!G20<>"Entregue",1,0),0),0)) -> 0 | Q9: =IF(CCA!A20="",0,IFERROR(IF(MATCH(CCA!D20,MilestonesCCA,0)=MATCH(CCA!$D$3,MilestonesCCA,0),IF(CCA!G20="Previsto",1,0),0),0)) -> 0 | R9: =IF(CCA!A20="",0,IFERROR(IF(MATCH(CCA!D20,MilestonesCCA,0)>MATCH(CCA!$D$3,MilestonesCCA,0),IF(CCA!G20="Entregue",1,0),0),0)) -> 0 | T9: =IF(CCA!A20="",0,IF(COUNTIF(CCA!$A$16:$A$165,CCA!A20)>1,1,0)) -> 0 | U9: =IF(CCA!A20="",0,IF(OR(ISNUMBER(SEARCH("<",CCA!B20)),ISNUMBER(SEARCH(">",CCA!B20)),ISNUMBER(SEARCH("<",CCA!F20)),ISNUMBER(SEARCH(">",CCA!F20))),1,0)) -> 0 | V9: =IF('Catálogo de referência'!C10<>"Obrigatório",0,IF(COUNTIF(CCA!$A$16:$A$165,'Catálogo de referência'!A10)=0,1,0)) -> 0
G10: 22 | H10: =IF(COUNTA(CCA!A21:G21)=0,0,IF(COUNTA(CCA!A21:G21)<7,1,0)) -> 0 | I10: =IF(CCA!A21="",0,IF(COUNTIF(OrigensCCA,CCA!C21)=0,1,0)) -> 0 | J10: =IF(CCA!A21="",0,IF(COUNTIF(MilestonesCCA,CCA!D21)=0,1,0)) -> 0 | K10: =IF(CCA!A21="",0,IF(COUNTIF(EstadosCCA,CCA!G21)=0,1,0)) -> 0 | L10: =IF(CCA!A21="",0,IF(CCA!C21="Regulamento da UC",IF(LEFT(CCA!A21,3)="OF-",0,1),IF(CCA!C21="Compromisso do grupo",IF(LEFT(CCA!A21,3)="AD-",0,1),0))) -> 0 | M10: =IF(LEFT(CCA!A21,3)<>"OF-",0,IFERROR(IF(VLOOKUP(CCA!A21,CatalogoCCA,4,FALSE)=CCA!D21,0,1),0)) -> 0 | N10: =IF(LEFT(CCA!A21,3)<>"OF-",0,IFERROR(IF(VLOOKUP(CCA!A21,CatalogoCCA,5,FALSE)=CCA!F21,0,1),0)) -> 0 | O10: =IF(CCA!A21="",0,IF(CCA!C21="Compromisso do grupo",IF(LEN(TRIM(CCA!E21))<20,1,0),0)) -> 0 | P10: =IF(CCA!A21="",0,IFERROR(IF(MATCH(CCA!D21,MilestonesCCA,0)<MATCH(CCA!$D$3,MilestonesCCA,0),IF(CCA!G21<>"Entregue",1,0),0),0)) -> 0 | Q10: =IF(CCA!A21="",0,IFERROR(IF(MATCH(CCA!D21,MilestonesCCA,0)=MATCH(CCA!$D$3,MilestonesCCA,0),IF(CCA!G21="Previsto",1,0),0),0)) -> 0 | R10: =IF(CCA!A21="",0,IFERROR(IF(MATCH(CCA!D21,MilestonesCCA,0)>MATCH(CCA!$D$3,MilestonesCCA,0),IF(CCA!G21="Entregue",1,0),0),0)) -> 0 | T10: =IF(CCA!A21="",0,IF(COUNTIF(CCA!$A$16:$A$165,CCA!A21)>1,1,0)) -> 0 | U10: =IF(CCA!A21="",0,IF(OR(ISNUMBER(SEARCH("<",CCA!B21)),ISNUMBER(SEARCH(">",CCA!B21)),ISNUMBER(SEARCH("<",CCA!F21)),ISNUMBER(SEARCH(">",CCA!F21))),1,0)) -> 0 | V10: =IF('Catálogo de referência'!C11<>"Obrigatório",0,IF(COUNTIF(CCA!$A$16:$A$165,'Catálogo de referência'!A11)=0,1,0)) -> 0
G11: 23 | H11: =IF(COUNTA(CCA!A22:G22)=0,0,IF(COUNTA(CCA!A22:G22)<7,1,0)) -> 0 | I11: =IF(CCA!A22="",0,IF(COUNTIF(OrigensCCA,CCA!C22)=0,1,0)) -> 0 | J11: =IF(CCA!A22="",0,IF(COUNTIF(MilestonesCCA,CCA!D22)=0,1,0)) -> 0 | K11: =IF(CCA!A22="",0,IF(COUNTIF(EstadosCCA,CCA!G22)=0,1,0)) -> 0 | L11: =IF(CCA!A22="",0,IF(CCA!C22="Regulamento da UC",IF(LEFT(CCA!A22,3)="OF-",0,1),IF(CCA!C22="Compromisso do grupo",IF(LEFT(CCA!A22,3)="AD-",0,1),0))) -> 0 | M11: =IF(LEFT(CCA!A22,3)<>"OF-",0,IFERROR(IF(VLOOKUP(CCA!A22,CatalogoCCA,4,FALSE)=CCA!D22,0,1),0)) -> 0 | N11: =IF(LEFT(CCA!A22,3)<>"OF-",0,IFERROR(IF(VLOOKUP(CCA!A22,CatalogoCCA,5,FALSE)=CCA!F22,0,1),0)) -> 0 | O11: =IF(CCA!A22="",0,IF(CCA!C22="Compromisso do grupo",IF(LEN(TRIM(CCA!E22))<20,1,0),0)) -> 0 | P11: =IF(CCA!A22="",0,IFERROR(IF(MATCH(CCA!D22,MilestonesCCA,0)<MATCH(CCA!$D$3,MilestonesCCA,0),IF(CCA!G22<>"Entregue",1,0),0),0)) -> 0 | Q11: =IF(CCA!A22="",0,IFERROR(IF(MATCH(CCA!D22,MilestonesCCA,0)=MATCH(CCA!$D$3,MilestonesCCA,0),IF(CCA!G22="Previsto",1,0),0),0)) -> 0 | R11: =IF(CCA!A22="",0,IFERROR(IF(MATCH(CCA!D22,MilestonesCCA,0)>MATCH(CCA!$D$3,MilestonesCCA,0),IF(CCA!G22="Entregue",1,0),0),0)) -> 0 | T11: =IF(CCA!A22="",0,IF(COUNTIF(CCA!$A$16:$A$165,CCA!A22)>1,1,0)) -> 0 | U11: =IF(CCA!A22="",0,IF(OR(ISNUMBER(SEARCH("<",CCA!B22)),ISNUMBER(SEARCH(">",CCA!B22)),ISNUMBER(SEARCH("<",CCA!F22)),ISNUMBER(SEARCH(">",CCA!F22))),1,0)) -> 0 | V11: =IF('Catálogo de referência'!C12<>"Obrigatório",0,IF(COUNTIF(CCA!$A$16:$A$165,'Catálogo de referência'!A12)=0,1,0)) -> 0
G12: 24 | H12: =IF(COUNTA(CCA!A23:G23)=0,0,IF(COUNTA(CCA!A23:G23)<7,1,0)) -> 0 | I12: =IF(CCA!A23="",0,IF(COUNTIF(OrigensCCA,CCA!C23)=0,1,0)) -> 0 | J12: =IF(CCA!A23="",0,IF(COUNTIF(MilestonesCCA,CCA!D23)=0,1,0)) -> 0 | K12: =IF(CCA!A23="",0,IF(COUNTIF(EstadosCCA,CCA!G23)=0,1,0)) -> 0 | L12: =IF(CCA!A23="",0,IF(CCA!C23="Regulamento da UC",IF(LEFT(CCA!A23,3)="OF-",0,1),IF(CCA!C23="Compromisso do grupo",IF(LEFT(CCA!A23,3)="AD-",0,1),0))) -> 0 | M12: =IF(LEFT(CCA!A23,3)<>"OF-",0,IFERROR(IF(VLOOKUP(CCA!A23,CatalogoCCA,4,FALSE)=CCA!D23,0,1),0)) -> 0 | N12: =IF(LEFT(CCA!A23,3)<>"OF-",0,IFERROR(IF(VLOOKUP(CCA!A23,CatalogoCCA,5,FALSE)=CCA!F23,0,1),0)) -> 0 | O12: =IF(CCA!A23="",0,IF(CCA!C23="Compromisso do grupo",IF(LEN(TRIM(CCA!E23))<20,1,0),0)) -> 0 | P12: =IF(CCA!A23="",0,IFERROR(IF(MATCH(CCA!D23,MilestonesCCA,0)<MATCH(CCA!$D$3,MilestonesCCA,0),IF(CCA!G23<>"Entregue",1,0),0),0)) -> 0 | Q12: =IF(CCA!A23="",0,IFERROR(IF(MATCH(CCA!D23,MilestonesCCA,0)=MATCH(CCA!$D$3,MilestonesCCA,0),IF(CCA!G23="Previsto",1,0),0),0)) -> 0 | R12: =IF(CCA!A23="",0,IFERROR(IF(MATCH(CCA!D23,MilestonesCCA,0)>MATCH(CCA!$D$3,MilestonesCCA,0),IF(CCA!G23="Entregue",1,0),0),0)) -> 0 | T12: =IF(CCA!A23="",0,IF(COUNTIF(CCA!$A$16:$A$165,CCA!A23)>1,1,0)) -> 0 | U12: =IF(CCA!A23="",0,IF(OR(ISNUMBER(SEARCH("<",CCA!B23)),ISNUMBER(SEARCH(">",CCA!B23)),ISNUMBER(SEARCH("<",CCA!F23)),ISNUMBER(SEARCH(">",CCA!F23))),1,0)) -> 0 | V12: =IF('Catálogo de referência'!C13<>"Obrigatório",0,IF(COUNTIF(CCA!$A$16:$A$165,'Catálogo de referência'!A13)=0,1,0)) -> 0
G13: 25 | H13: =IF(COUNTA(CCA!A24:G24)=0,0,IF(COUNTA(CCA!A24:G24)<7,1,0)) -> 0 | I13: =IF(CCA!A24="",0,IF(COUNTIF(OrigensCCA,CCA!C24)=0,1,0)) -> 0 | J13: =IF(CCA!A24="",0,IF(COUNTIF(MilestonesCCA,CCA!D24)=0,1,0)) -> 0 | K13: =IF(CCA!A24="",0,IF(COUNTIF(EstadosCCA,CCA!G24)=0,1,0)) -> 0 | L13: =IF(CCA!A24="",0,IF(CCA!C24="Regulamento da UC",IF(LEFT(CCA!A24,3)="OF-",0,1),IF(CCA!C24="Compromisso do grupo",IF(LEFT(CCA!A24,3)="AD-",0,1),0))) -> 0 | M13: =IF(LEFT(CCA!A24,3)<>"OF-",0,IFERROR(IF(VLOOKUP(CCA!A24,CatalogoCCA,4,FALSE)=CCA!D24,0,1),0)) -> 0 | N13: =IF(LEFT(CCA!A24,3)<>"OF-",0,IFERROR(IF(VLOOKUP(CCA!A24,CatalogoCCA,5,FALSE)=CCA!F24,0,1),0)) -> 0 | O13: =IF(CCA!A24="",0,IF(CCA!C24="Compromisso do grupo",IF(LEN(TRIM(CCA!E24))<20,1,0),0)) -> 0 | P13: =IF(CCA!A24="",0,IFERROR(IF(MATCH(CCA!D24,MilestonesCCA,0)<MATCH(CCA!$D$3,MilestonesCCA,0),IF(CCA!G24<>"Entregue",1,0),0),0)) -> 0 | Q13: =IF(CCA!A24="",0,IFERROR(IF(MATCH(CCA!D24,MilestonesCCA,0)=MATCH(CCA!$D$3,MilestonesCCA,0),IF(CCA!G24="Previsto",1,0),0),0)) -> 0 | R13: =IF(CCA!A24="",0,IFERROR(IF(MATCH(CCA!D24,MilestonesCCA,0)>MATCH(CCA!$D$3,MilestonesCCA,0),IF(CCA!G24="Entregue",1,0),0),0)) -> 0 | T13: =IF(CCA!A24="",0,IF(COUNTIF(CCA!$A$16:$A$165,CCA!A24)>1,1,0)) -> 0 | U13: =IF(CCA!A24="",0,IF(OR(ISNUMBER(SEARCH("<",CCA!B24)),ISNUMBER(SEARCH(">",CCA!B24)),ISNUMBER(SEARCH("<",CCA!F24)),ISNUMBER(SEARCH(">",CCA!F24))),1,0)) -> 0 | V13: =IF('Catálogo de referência'!C14<>"Obrigatório",0,IF(COUNTIF(CCA!$A$16:$A$165,'Catálogo de referência'!A14)=0,1,0)) -> 0
G14: 26 | H14: =IF(COUNTA(CCA!A25:G25)=0,0,IF(COUNTA(CCA!A25:G25)<7,1,0)) -> 0 | I14: =IF(CCA!A25="",0,IF(COUNTIF(OrigensCCA,CCA!C25)=0,1,0)) -> 0 | J14: =IF(CCA!A25="",0,IF(COUNTIF(MilestonesCCA,CCA!D25)=0,1,0)) -> 0 | K14: =IF(CCA!A25="",0,IF(COUNTIF(EstadosCCA,CCA!G25)=0,1,0)) -> 0 | L14: =IF(CCA!A25="",0,IF(CCA!C25="Regulamento da UC",IF(LEFT(CCA!A25,3)="OF-",0,1),IF(CCA!C25="Compromisso do grupo",IF(LEFT(CCA!A25,3)="AD-",0,1),0))) -> 0 | M14: =IF(LEFT(CCA!A25,3)<>"OF-",0,IFERROR(IF(VLOOKUP(CCA!A25,CatalogoCCA,4,FALSE)=CCA!D25,0,1),0)) -> 0 | N14: =IF(LEFT(CCA!A25,3)<>"OF-",0,IFERROR(IF(VLOOKUP(CCA!A25,CatalogoCCA,5,FALSE)=CCA!F25,0,1),0)) -> 0 | O14: =IF(CCA!A25="",0,IF(CCA!C25="Compromisso do grupo",IF(LEN(TRIM(CCA!E25))<20,1,0),0)) -> 0 | P14: =IF(CCA!A25="",0,IFERROR(IF(MATCH(CCA!D25,MilestonesCCA,0)<MATCH(CCA!$D$3,MilestonesCCA,0),IF(CCA!G25<>"Entregue",1,0),0),0)) -> 0 | Q14: =IF(CCA!A25="",0,IFERROR(IF(MATCH(CCA!D25,MilestonesCCA,0)=MATCH(CCA!$D$3,MilestonesCCA,0),IF(CCA!G25="Previsto",1,0),0),0)) -> 0 | R14: =IF(CCA!A25="",0,IFERROR(IF(MATCH(CCA!D25,MilestonesCCA,0)>MATCH(CCA!$D$3,MilestonesCCA,0),IF(CCA!G25="Entregue",1,0),0),0)) -> 0 | T14: =IF(CCA!A25="",0,IF(COUNTIF(CCA!$A$16:$A$165,CCA!A25)>1,1,0)) -> 0 | U14: =IF(CCA!A25="",0,IF(OR(ISNUMBER(SEARCH("<",CCA!B25)),ISNUMBER(SEARCH(">",CCA!B25)),ISNUMBER(SEARCH("<",CCA!F25)),ISNUMBER(SEARCH(">",CCA!F25))),1,0)) -> 0 | V14: =IF('Catálogo de referência'!C15<>"Obrigatório",0,IF(COUNTIF(CCA!$A$16:$A$165,'Catálogo de referência'!A15)=0,1,0)) -> 0
G15: 27 | H15: =IF(COUNTA(CCA!A26:G26)=0,0,IF(COUNTA(CCA!A26:G26)<7,1,0)) -> 0 | I15: =IF(CCA!A26="",0,IF(COUNTIF(OrigensCCA,CCA!C26)=0,1,0)) -> 0 | J15: =IF(CCA!A26="",0,IF(COUNTIF(MilestonesCCA,CCA!D26)=0,1,0)) -> 0 | K15: =IF(CCA!A26="",0,IF(COUNTIF(EstadosCCA,CCA!G26)=0,1,0)) -> 0 | L15: =IF(CCA!A26="",0,IF(CCA!C26="Regulamento da UC",IF(LEFT(CCA!A26,3)="OF-",0,1),IF(CCA!C26="Compromisso do grupo",IF(LEFT(CCA!A26,3)="AD-",0,1),0))) -> 0 | M15: =IF(LEFT(CCA!A26,3)<>"OF-",0,IFERROR(IF(VLOOKUP(CCA!A26,CatalogoCCA,4,FALSE)=CCA!D26,0,1),0)) -> 0 | N15: =IF(LEFT(CCA!A26,3)<>"OF-",0,IFERROR(IF(VLOOKUP(CCA!A26,CatalogoCCA,5,FALSE)=CCA!F26,0,1),0)) -> 0 | O15: =IF(CCA!A26="",0,IF(CCA!C26="Compromisso do grupo",IF(LEN(TRIM(CCA!E26))<20,1,0),0)) -> 0 | P15: =IF(CCA!A26="",0,IFERROR(IF(MATCH(CCA!D26,MilestonesCCA,0)<MATCH(CCA!$D$3,MilestonesCCA,0),IF(CCA!G26<>"Entregue",1,0),0),0)) -> 0 | Q15: =IF(CCA!A26="",0,IFERROR(IF(MATCH(CCA!D26,MilestonesCCA,0)=MATCH(CCA!$D$3,MilestonesCCA,0),IF(CCA!G26="Previsto",1,0),0),0)) -> 0 | R15: =IF(CCA!A26="",0,IFERROR(IF(MATCH(CCA!D26,MilestonesCCA,0)>MATCH(CCA!$D$3,MilestonesCCA,0),IF(CCA!G26="Entregue",1,0),0),0)) -> 0 | T15: =IF(CCA!A26="",0,IF(COUNTIF(CCA!$A$16:$A$165,CCA!A26)>1,1,0)) -> 0 | U15: =IF(CCA!A26="",0,IF(OR(ISNUMBER(SEARCH("<",CCA!B26)),ISNUMBER(SEARCH(">",CCA!B26)),ISNUMBER(SEARCH("<",CCA!F26)),ISNUMBER(SEARCH(">",CCA!F26))),1,0)) -> 0 | V15: =IF('Catálogo de referência'!C16<>"Obrigatório",0,IF(COUNTIF(CCA!$A$16:$A$165,'Catálogo de referência'!A16)=0,1,0)) -> 0
G16: 28 | H16: =IF(COUNTA(CCA!A27:G27)=0,0,IF(COUNTA(CCA!A27:G27)<7,1,0)) -> 0 | I16: =IF(CCA!A27="",0,IF(COUNTIF(OrigensCCA,CCA!C27)=0,1,0)) -> 0 | J16: =IF(CCA!A27="",0,IF(COUNTIF(MilestonesCCA,CCA!D27)=0,1,0)) -> 0 | K16: =IF(CCA!A27="",0,IF(COUNTIF(EstadosCCA,CCA!G27)=0,1,0)) -> 0 | L16: =IF(CCA!A27="",0,IF(CCA!C27="Regulamento da UC",IF(LEFT(CCA!A27,3)="OF-",0,1),IF(CCA!C27="Compromisso do grupo",IF(LEFT(CCA!A27,3)="AD-",0,1),0))) -> 0 | M16: =IF(LEFT(CCA!A27,3)<>"OF-",0,IFERROR(IF(VLOOKUP(CCA!A27,CatalogoCCA,4,FALSE)=CCA!D27,0,1),0)) -> 0 | N16: =IF(LEFT(CCA!A27,3)<>"OF-",0,IFERROR(IF(VLOOKUP(CCA!A27,CatalogoCCA,5,FALSE)=CCA!F27,0,1),0)) -> 0 | O16: =IF(CCA!A27="",0,IF(CCA!C27="Compromisso do grupo",IF(LEN(TRIM(CCA!E27))<20,1,0),0)) -> 0 | P16: =IF(CCA!A27="",0,IFERROR(IF(MATCH(CCA!D27,MilestonesCCA,0)<MATCH(CCA!$D$3,MilestonesCCA,0),IF(CCA!G27<>"Entregue",1,0),0),0)) -> 0 | Q16: =IF(CCA!A27="",0,IFERROR(IF(MATCH(CCA!D27,MilestonesCCA,0)=MATCH(CCA!$D$3,MilestonesCCA,0),IF(CCA!G27="Previsto",1,0),0),0)) -> 0 | R16: =IF(CCA!A27="",0,IFERROR(IF(MATCH(CCA!D27,MilestonesCCA,0)>MATCH(CCA!$D$3,MilestonesCCA,0),IF(CCA!G27="Entregue",1,0),0),0)) -> 0 | T16: =IF(CCA!A27="",0,IF(COUNTIF(CCA!$A$16:$A$165,CCA!A27)>1,1,0)) -> 0 | U16: =IF(CCA!A27="",0,IF(OR(ISNUMBER(SEARCH("<",CCA!B27)),ISNUMBER(SEARCH(">",CCA!B27)),ISNUMBER(SEARCH("<",CCA!F27)),ISNUMBER(SEARCH(">",CCA!F27))),1,0)) -> 0 | V16: =IF('Catálogo de referência'!C17<>"Obrigatório",0,IF(COUNTIF(CCA!$A$16:$A$165,'Catálogo de referência'!A17)=0,1,0)) -> 0
G17: 29 | H17: =IF(COUNTA(CCA!A28:G28)=0,0,IF(COUNTA(CCA!A28:G28)<7,1,0)) -> 0 | I17: =IF(CCA!A28="",0,IF(COUNTIF(OrigensCCA,CCA!C28)=0,1,0)) -> 0 | J17: =IF(CCA!A28="",0,IF(COUNTIF(MilestonesCCA,CCA!D28)=0,1,0)) -> 0 | K17: =IF(CCA!A28="",0,IF(COUNTIF(EstadosCCA,CCA!G28)=0,1,0)) -> 0 | L17: =IF(CCA!A28="",0,IF(CCA!C28="Regulamento da UC",IF(LEFT(CCA!A28,3)="OF-",0,1),IF(CCA!C28="Compromisso do grupo",IF(LEFT(CCA!A28,3)="AD-",0,1),0))) -> 0 | M17: =IF(LEFT(CCA!A28,3)<>"OF-",0,IFERROR(IF(VLOOKUP(CCA!A28,CatalogoCCA,4,FALSE)=CCA!D28,0,1),0)) -> 0 | N17: =IF(LEFT(CCA!A28,3)<>"OF-",0,IFERROR(IF(VLOOKUP(CCA!A28,CatalogoCCA,5,FALSE)=CCA!F28,0,1),0)) -> 0 | O17: =IF(CCA!A28="",0,IF(CCA!C28="Compromisso do grupo",IF(LEN(TRIM(CCA!E28))<20,1,0),0)) -> 0 | P17: =IF(CCA!A28="",0,IFERROR(IF(MATCH(CCA!D28,MilestonesCCA,0)<MATCH(CCA!$D$3,MilestonesCCA,0),IF(CCA!G28<>"Entregue",1,0),0),0)) -> 0 | Q17: =IF(CCA!A28="",0,IFERROR(IF(MATCH(CCA!D28,MilestonesCCA,0)=MATCH(CCA!$D$3,MilestonesCCA,0),IF(CCA!G28="Previsto",1,0),0),0)) -> 0 | R17: =IF(CCA!A28="",0,IFERROR(IF(MATCH(CCA!D28,MilestonesCCA,0)>MATCH(CCA!$D$3,MilestonesCCA,0),IF(CCA!G28="Entregue",1,0),0),0)) -> 0 | T17: =IF(CCA!A28="",0,IF(COUNTIF(CCA!$A$16:$A$165,CCA!A28)>1,1,0)) -> 0 | U17: =IF(CCA!A28="",0,IF(OR(ISNUMBER(SEARCH("<",CCA!B28)),ISNUMBER(SEARCH(">",CCA!B28)),ISNUMBER(SEARCH("<",CCA!F28)),ISNUMBER(SEARCH(">",CCA!F28))),1,0)) -> 0 | V17: =IF('Catálogo de referência'!C18<>"Obrigatório",0,IF(COUNTIF(CCA!$A$16:$A$165,'Catálogo de referência'!A18)=0,1,0)) -> 0
G18: 30 | H18: =IF(COUNTA(CCA!A29:G29)=0,0,IF(COUNTA(CCA!A29:G29)<7,1,0)) -> 0 | I18: =IF(CCA!A29="",0,IF(COUNTIF(OrigensCCA,CCA!C29)=0,1,0)) -> 0 | J18: =IF(CCA!A29="",0,IF(COUNTIF(MilestonesCCA,CCA!D29)=0,1,0)) -> 0 | K18: =IF(CCA!A29="",0,IF(COUNTIF(EstadosCCA,CCA!G29)=0,1,0)) -> 0 | L18: =IF(CCA!A29="",0,IF(CCA!C29="Regulamento da UC",IF(LEFT(CCA!A29,3)="OF-",0,1),IF(CCA!C29="Compromisso do grupo",IF(LEFT(CCA!A29,3)="AD-",0,1),0))) -> 0 | M18: =IF(LEFT(CCA!A29,3)<>"OF-",0,IFERROR(IF(VLOOKUP(CCA!A29,CatalogoCCA,4,FALSE)=CCA!D29,0,1),0)) -> 0 | N18: =IF(LEFT(CCA!A29,3)<>"OF-",0,IFERROR(IF(VLOOKUP(CCA!A29,CatalogoCCA,5,FALSE)=CCA!F29,0,1),0)) -> 0 | O18: =IF(CCA!A29="",0,IF(CCA!C29="Compromisso do grupo",IF(LEN(TRIM(CCA!E29))<20,1,0),0)) -> 0 | P18: =IF(CCA!A29="",0,IFERROR(IF(MATCH(CCA!D29,MilestonesCCA,0)<MATCH(CCA!$D$3,MilestonesCCA,0),IF(CCA!G29<>"Entregue",1,0),0),0)) -> 0 | Q18: =IF(CCA!A29="",0,IFERROR(IF(MATCH(CCA!D29,MilestonesCCA,0)=MATCH(CCA!$D$3,MilestonesCCA,0),IF(CCA!G29="Previsto",1,0),0),0)) -> 0 | R18: =IF(CCA!A29="",0,IFERROR(IF(MATCH(CCA!D29,MilestonesCCA,0)>MATCH(CCA!$D$3,MilestonesCCA,0),IF(CCA!G29="Entregue",1,0),0),0)) -> 0 | T18: =IF(CCA!A29="",0,IF(COUNTIF(CCA!$A$16:$A$165,CCA!A29)>1,1,0)) -> 0 | U18: =IF(CCA!A29="",0,IF(OR(ISNUMBER(SEARCH("<",CCA!B29)),ISNUMBER(SEARCH(">",CCA!B29)),ISNUMBER(SEARCH("<",CCA!F29)),ISNUMBER(SEARCH(">",CCA!F29))),1,0)) -> 0 | V18: =IF('Catálogo de referência'!C19<>"Obrigatório",0,IF(COUNTIF(CCA!$A$16:$A$165,'Catálogo de referência'!A19)=0,1,0)) -> 0
G19: 31 | H19: =IF(COUNTA(CCA!A30:G30)=0,0,IF(COUNTA(CCA!A30:G30)<7,1,0)) -> 0 | I19: =IF(CCA!A30="",0,IF(COUNTIF(OrigensCCA,CCA!C30)=0,1,0)) -> 0 | J19: =IF(CCA!A30="",0,IF(COUNTIF(MilestonesCCA,CCA!D30)=0,1,0)) -> 0 | K19: =IF(CCA!A30="",0,IF(COUNTIF(EstadosCCA,CCA!G30)=0,1,0)) -> 0 | L19: =IF(CCA!A30="",0,IF(CCA!C30="Regulamento da UC",IF(LEFT(CCA!A30,3)="OF-",0,1),IF(CCA!C30="Compromisso do grupo",IF(LEFT(CCA!A30,3)="AD-",0,1),0))) -> 0 | M19: =IF(LEFT(CCA!A30,3)<>"OF-",0,IFERROR(IF(VLOOKUP(CCA!A30,CatalogoCCA,4,FALSE)=CCA!D30,0,1),0)) -> 0 | N19: =IF(LEFT(CCA!A30,3)<>"OF-",0,IFERROR(IF(VLOOKUP(CCA!A30,CatalogoCCA,5,FALSE)=CCA!F30,0,1),0)) -> 0 | O19: =IF(CCA!A30="",0,IF(CCA!C30="Compromisso do grupo",IF(LEN(TRIM(CCA!E30))<20,1,0),0)) -> 0 | P19: =IF(CCA!A30="",0,IFERROR(IF(MATCH(CCA!D30,MilestonesCCA,0)<MATCH(CCA!$D$3,MilestonesCCA,0),IF(CCA!G30<>"Entregue",1,0),0),0)) -> 0 | Q19: =IF(CCA!A30="",0,IFERROR(IF(MATCH(CCA!D30,MilestonesCCA,0)=MATCH(CCA!$D$3,MilestonesCCA,0),IF(CCA!G30="Previsto",1,0),0),0)) -> 0 | R19: =IF(CCA!A30="",0,IFERROR(IF(MATCH(CCA!D30,MilestonesCCA,0)>MATCH(CCA!$D$3,MilestonesCCA,0),IF(CCA!G30="Entregue",1,0),0),0)) -> 0 | T19: =IF(CCA!A30="",0,IF(COUNTIF(CCA!$A$16:$A$165,CCA!A30)>1,1,0)) -> 0 | U19: =IF(CCA!A30="",0,IF(OR(ISNUMBER(SEARCH("<",CCA!B30)),ISNUMBER(SEARCH(">",CCA!B30)),ISNUMBER(SEARCH("<",CCA!F30)),ISNUMBER(SEARCH(">",CCA!F30))),1,0)) -> 0 | V19: =IF('Catálogo de referência'!C20<>"Obrigatório",0,IF(COUNTIF(CCA!$A$16:$A$165,'Catálogo de referência'!A20)=0,1,0)) -> 0
G20: 32 | H20: =IF(COUNTA(CCA!A31:G31)=0,0,IF(COUNTA(CCA!A31:G31)<7,1,0)) -> 0 | I20: =IF(CCA!A31="",0,IF(COUNTIF(OrigensCCA,CCA!C31)=0,1,0)) -> 0 | J20: =IF(CCA!A31="",0,IF(COUNTIF(MilestonesCCA,CCA!D31)=0,1,0)) -> 0 | K20: =IF(CCA!A31="",0,IF(COUNTIF(EstadosCCA,CCA!G31)=0,1,0)) -> 0 | L20: =IF(CCA!A31="",0,IF(CCA!C31="Regulamento da UC",IF(LEFT(CCA!A31,3)="OF-",0,1),IF(CCA!C31="Compromisso do grupo",IF(LEFT(CCA!A31,3)="AD-",0,1),0))) -> 0 | M20: =IF(LEFT(CCA!A31,3)<>"OF-",0,IFERROR(IF(VLOOKUP(CCA!A31,CatalogoCCA,4,FALSE)=CCA!D31,0,1),0)) -> 0 | N20: =IF(LEFT(CCA!A31,3)<>"OF-",0,IFERROR(IF(VLOOKUP(CCA!A31,CatalogoCCA,5,FALSE)=CCA!F31,0,1),0)) -> 0 | O20: =IF(CCA!A31="",0,IF(CCA!C31="Compromisso do grupo",IF(LEN(TRIM(CCA!E31))<20,1,0),0)) -> 0 | P20: =IF(CCA!A31="",0,IFERROR(IF(MATCH(CCA!D31,MilestonesCCA,0)<MATCH(CCA!$D$3,MilestonesCCA,0),IF(CCA!G31<>"Entregue",1,0),0),0)) -> 0 | Q20: =IF(CCA!A31="",0,IFERROR(IF(MATCH(CCA!D31,MilestonesCCA,0)=MATCH(CCA!$D$3,MilestonesCCA,0),IF(CCA!G31="Previsto",1,0),0),0)) -> 0 | R20: =IF(CCA!A31="",0,IFERROR(IF(MATCH(CCA!D31,MilestonesCCA,0)>MATCH(CCA!$D$3,MilestonesCCA,0),IF(CCA!G31="Entregue",1,0),0),0)) -> 0 | T20: =IF(CCA!A31="",0,IF(COUNTIF(CCA!$A$16:$A$165,CCA!A31)>1,1,0)) -> 0 | U20: =IF(CCA!A31="",0,IF(OR(ISNUMBER(SEARCH("<",CCA!B31)),ISNUMBER(SEARCH(">",CCA!B31)),ISNUMBER(SEARCH("<",CCA!F31)),ISNUMBER(SEARCH(">",CCA!F31))),1,0)) -> 0 | V20: =IF('Catálogo de referência'!C21<>"Obrigatório",0,IF(COUNTIF(CCA!$A$16:$A$165,'Catálogo de referência'!A21)=0,1,0)) -> 0
... G59: 71 | H59: =IF(COUNTA(CCA!A70:G70)=0,0,IF(COUNTA(CCA!A70:G70)<7,1,0)) -> 0 | I59: =IF(CCA!A70="",0,IF(COUNTIF(OrigensCCA,CCA!C70)=0,1,0)) -> 0 | J59: =IF(CCA!A70="",0,IF(COUNTIF(MilestonesCCA,CCA!D70)=0,1,0)) -> 0 | K59: =IF(CCA!A70="",0,IF(COUNTIF(EstadosCCA,CCA!G70)=0,1,0)) -> 0 | L59: =IF(CCA!A70="",0,IF(CCA!C70="Regulamento da UC",IF(LEFT(CCA!A70,3)="OF-",0,1),IF(CCA!C70="Compromisso do grupo",IF(LEFT(CCA!A70,3)="AD-",0,1),0))) -> 0 | M59: =IF(LEFT(CCA!A70,3)<>"OF-",0,IFERROR(IF(VLOOKUP(CCA!A70,CatalogoCCA,4,FALSE)=CCA!D70,0,1),0)) -> 0 | N59: =IF(LEFT(CCA!A70,3)<>"OF-",0,IFERROR(IF(VLOOKUP(CCA!A70,CatalogoCCA,5,FALSE)=CCA!F70,0,1),0)) -> 0 | O59: =IF(CCA!A70="",0,IF(CCA!C70="Compromisso do grupo",IF(LEN(TRIM(CCA!E70))<20,1,0),0)) -> 0 | P59: =IF(CCA!A70="",0,IFERROR(IF(MATCH(CCA!D70,MilestonesCCA,0)<MATCH(CCA!$D$3,MilestonesCCA,0),IF(CCA!G70<>"Entregue",1,0),0),0)) -> 0 | Q59: =IF(CCA!A70="",0,IFERROR(IF(MATCH(CCA!D70,MilestonesCCA,0)=MATCH(CCA!$D$3,MilestonesCCA,0),IF(CCA!G70="Previsto",1,0),0),0)) -> 0 | R59: =IF(CCA!A70="",0,IFERROR(IF(MATCH(CCA!D70,MilestonesCCA,0)>MATCH(CCA!$D$3,MilestonesCCA,0),IF(CCA!G70="Entregue",1,0),0),0)) -> 0 | T59: =IF(CCA!A70="",0,IF(COUNTIF(CCA!$A$16:$A$165,CCA!A70)>1,1,0)) -> 0 | U59: =IF(CCA!A70="",0,IF(OR(ISNUMBER(SEARCH("<",CCA!B70)),ISNUMBER(SEARCH(">",CCA!B70)),ISNUMBER(SEARCH("<",CCA!F70)),ISNUMBER(SEARCH(">",CCA!F70))),1,0)) -> 0 | V59: =IF('Catálogo de referência'!C60<>"Obrigatório",0,IF(COUNTIF(CCA!$A$16:$A$165,'Catálogo de referência'!A60)=0,1,0)) -> 0
G60: 72 | H60: =IF(COUNTA(CCA!A71:G71)=0,0,IF(COUNTA(CCA!A71:G71)<7,1,0)) -> 0 | I60: =IF(CCA!A71="",0,IF(COUNTIF(OrigensCCA,CCA!C71)=0,1,0)) -> 0 | J60: =IF(CCA!A71="",0,IF(COUNTIF(MilestonesCCA,CCA!D71)=0,1,0)) -> 0 | K60: =IF(CCA!A71="",0,IF(COUNTIF(EstadosCCA,CCA!G71)=0,1,0)) -> 0 | L60: =IF(CCA!A71="",0,IF(CCA!C71="Regulamento da UC",IF(LEFT(CCA!A71,3)="OF-",0,1),IF(CCA!C71="Compromisso do grupo",IF(LEFT(CCA!A71,3)="AD-",0,1),0))) -> 0 | M60: =IF(LEFT(CCA!A71,3)<>"OF-",0,IFERROR(IF(VLOOKUP(CCA!A71,CatalogoCCA,4,FALSE)=CCA!D71,0,1),0)) -> 0 | N60: =IF(LEFT(CCA!A71,3)<>"OF-",0,IFERROR(IF(VLOOKUP(CCA!A71,CatalogoCCA,5,FALSE)=CCA!F71,0,1),0)) -> 0 | O60: =IF(CCA!A71="",0,IF(CCA!C71="Compromisso do grupo",IF(LEN(TRIM(CCA!E71))<20,1,0),0)) -> 0 | P60: =IF(CCA!A71="",0,IFERROR(IF(MATCH(CCA!D71,MilestonesCCA,0)<MATCH(CCA!$D$3,MilestonesCCA,0),IF(CCA!G71<>"Entregue",1,0),0),0)) -> 0 | Q60: =IF(CCA!A71="",0,IFERROR(IF(MATCH(CCA!D71,MilestonesCCA,0)=MATCH(CCA!$D$3,MilestonesCCA,0),IF(CCA!G71="Previsto",1,0),0),0)) -> 0 | R60: =IF(CCA!A71="",0,IFERROR(IF(MATCH(CCA!D71,MilestonesCCA,0)>MATCH(CCA!$D$3,MilestonesCCA,0),IF(CCA!G71="Entregue",1,0),0),0)) -> 0 | T60: =IF(CCA!A71="",0,IF(COUNTIF(CCA!$A$16:$A$165,CCA!A71)>1,1,0)) -> 0 | U60: =IF(CCA!A71="",0,IF(OR(ISNUMBER(SEARCH("<",CCA!B71)),ISNUMBER(SEARCH(">",CCA!B71)),ISNUMBER(SEARCH("<",CCA!F71)),ISNUMBER(SEARCH(">",CCA!F71))),1,0)) -> 0
G61: 73 | H61: =IF(COUNTA(CCA!A72:G72)=0,0,IF(COUNTA(CCA!A72:G72)<7,1,0)) -> 0 | I61: =IF(CCA!A72="",0,IF(COUNTIF(OrigensCCA,CCA!C72)=0,1,0)) -> 0 | J61: =IF(CCA!A72="",0,IF(COUNTIF(MilestonesCCA,CCA!D72)=0,1,0)) -> 0 | K61: =IF(CCA!A72="",0,IF(COUNTIF(EstadosCCA,CCA!G72)=0,1,0)) -> 0 | L61: =IF(CCA!A72="",0,IF(CCA!C72="Regulamento da UC",IF(LEFT(CCA!A72,3)="OF-",0,1),IF(CCA!C72="Compromisso do grupo",IF(LEFT(CCA!A72,3)="AD-",0,1),0))) -> 0 | M61: =IF(LEFT(CCA!A72,3)<>"OF-",0,IFERROR(IF(VLOOKUP(CCA!A72,CatalogoCCA,4,FALSE)=CCA!D72,0,1),0)) -> 0 | N61: =IF(LEFT(CCA!A72,3)<>"OF-",0,IFERROR(IF(VLOOKUP(CCA!A72,CatalogoCCA,5,FALSE)=CCA!F72,0,1),0)) -> 0 | O61: =IF(CCA!A72="",0,IF(CCA!C72="Compromisso do grupo",IF(LEN(TRIM(CCA!E72))<20,1,0),0)) -> 0 | P61: =IF(CCA!A72="",0,IFERROR(IF(MATCH(CCA!D72,MilestonesCCA,0)<MATCH(CCA!$D$3,MilestonesCCA,0),IF(CCA!G72<>"Entregue",1,0),0),0)) -> 0 | Q61: =IF(CCA!A72="",0,IFERROR(IF(MATCH(CCA!D72,MilestonesCCA,0)=MATCH(CCA!$D$3,MilestonesCCA,0),IF(CCA!G72="Previsto",1,0),0),0)) -> 0 | R61: =IF(CCA!A72="",0,IFERROR(IF(MATCH(CCA!D72,MilestonesCCA,0)>MATCH(CCA!$D$3,MilestonesCCA,0),IF(CCA!G72="Entregue",1,0),0),0)) -> 0 | T61: =IF(CCA!A72="",0,IF(COUNTIF(CCA!$A$16:$A$165,CCA!A72)>1,1,0)) -> 0 | U61: =IF(CCA!A72="",0,IF(OR(ISNUMBER(SEARCH("<",CCA!B72)),ISNUMBER(SEARCH(">",CCA!B72)),ISNUMBER(SEARCH("<",CCA!F72)),ISNUMBER(SEARCH(">",CCA!F72))),1,0)) -> 0
G62: 74 | H62: =IF(COUNTA(CCA!A73:G73)=0,0,IF(COUNTA(CCA!A73:G73)<7,1,0)) -> 0 | I62: =IF(CCA!A73="",0,IF(COUNTIF(OrigensCCA,CCA!C73)=0,1,0)) -> 0 | J62: =IF(CCA!A73="",0,IF(COUNTIF(MilestonesCCA,CCA!D73)=0,1,0)) -> 0 | K62: =IF(CCA!A73="",0,IF(COUNTIF(EstadosCCA,CCA!G73)=0,1,0)) -> 0 | L62: =IF(CCA!A73="",0,IF(CCA!C73="Regulamento da UC",IF(LEFT(CCA!A73,3)="OF-",0,1),IF(CCA!C73="Compromisso do grupo",IF(LEFT(CCA!A73,3)="AD-",0,1),0))) -> 0 | M62: =IF(LEFT(CCA!A73,3)<>"OF-",0,IFERROR(IF(VLOOKUP(CCA!A73,CatalogoCCA,4,FALSE)=CCA!D73,0,1),0)) -> 0 | N62: =IF(LEFT(CCA!A73,3)<>"OF-",0,IFERROR(IF(VLOOKUP(CCA!A73,CatalogoCCA,5,FALSE)=CCA!F73,0,1),0)) -> 0 | O62: =IF(CCA!A73="",0,IF(CCA!C73="Compromisso do grupo",IF(LEN(TRIM(CCA!E73))<20,1,0),0)) -> 0 | P62: =IF(CCA!A73="",0,IFERROR(IF(MATCH(CCA!D73,MilestonesCCA,0)<MATCH(CCA!$D$3,MilestonesCCA,0),IF(CCA!G73<>"Entregue",1,0),0),0)) -> 0 | Q62: =IF(CCA!A73="",0,IFERROR(IF(MATCH(CCA!D73,MilestonesCCA,0)=MATCH(CCA!$D$3,MilestonesCCA,0),IF(CCA!G73="Previsto",1,0),0),0)) -> 0 | R62: =IF(CCA!A73="",0,IFERROR(IF(MATCH(CCA!D73,MilestonesCCA,0)>MATCH(CCA!$D$3,MilestonesCCA,0),IF(CCA!G73="Entregue",1,0),0),0)) -> 0 | T62: =IF(CCA!A73="",0,IF(COUNTIF(CCA!$A$16:$A$165,CCA!A73)>1,1,0)) -> 0 | U62: =IF(CCA!A73="",0,IF(OR(ISNUMBER(SEARCH("<",CCA!B73)),ISNUMBER(SEARCH(">",CCA!B73)),ISNUMBER(SEARCH("<",CCA!F73)),ISNUMBER(SEARCH(">",CCA!F73))),1,0)) -> 0
G63: 75 | H63: =IF(COUNTA(CCA!A74:G74)=0,0,IF(COUNTA(CCA!A74:G74)<7,1,0)) -> 0 | I63: =IF(CCA!A74="",0,IF(COUNTIF(OrigensCCA,CCA!C74)=0,1,0)) -> 0 | J63: =IF(CCA!A74="",0,IF(COUNTIF(MilestonesCCA,CCA!D74)=0,1,0)) -> 0 | K63: =IF(CCA!A74="",0,IF(COUNTIF(EstadosCCA,CCA!G74)=0,1,0)) -> 0 | L63: =IF(CCA!A74="",0,IF(CCA!C74="Regulamento da UC",IF(LEFT(CCA!A74,3)="OF-",0,1),IF(CCA!C74="Compromisso do grupo",IF(LEFT(CCA!A74,3)="AD-",0,1),0))) -> 0 | M63: =IF(LEFT(CCA!A74,3)<>"OF-",0,IFERROR(IF(VLOOKUP(CCA!A74,CatalogoCCA,4,FALSE)=CCA!D74,0,1),0)) -> 0 | N63: =IF(LEFT(CCA!A74,3)<>"OF-",0,IFERROR(IF(VLOOKUP(CCA!A74,CatalogoCCA,5,FALSE)=CCA!F74,0,1),0)) -> 0 | O63: =IF(CCA!A74="",0,IF(CCA!C74="Compromisso do grupo",IF(LEN(TRIM(CCA!E74))<20,1,0),0)) -> 0 | P63: =IF(CCA!A74="",0,IFERROR(IF(MATCH(CCA!D74,MilestonesCCA,0)<MATCH(CCA!$D$3,MilestonesCCA,0),IF(CCA!G74<>"Entregue",1,0),0),0)) -> 0 | Q63: =IF(CCA!A74="",0,IFERROR(IF(MATCH(CCA!D74,MilestonesCCA,0)=MATCH(CCA!$D$3,MilestonesCCA,0),IF(CCA!G74="Previsto",1,0),0),0)) -> 0 | R63: =IF(CCA!A74="",0,IFERROR(IF(MATCH(CCA!D74,MilestonesCCA,0)>MATCH(CCA!$D$3,MilestonesCCA,0),IF(CCA!G74="Entregue",1,0),0),0)) -> 0 | T63: =IF(CCA!A74="",0,IF(COUNTIF(CCA!$A$16:$A$165,CCA!A74)>1,1,0)) -> 0 | U63: =IF(CCA!A74="",0,IF(OR(ISNUMBER(SEARCH("<",CCA!B74)),ISNUMBER(SEARCH(">",CCA!B74)),ISNUMBER(SEARCH("<",CCA!F74)),ISNUMBER(SEARCH(">",CCA!F74))),1,0)) -> 0
G64: 76 | H64: =IF(COUNTA(CCA!A75:G75)=0,0,IF(COUNTA(CCA!A75:G75)<7,1,0)) -> 0 | I64: =IF(CCA!A75="",0,IF(COUNTIF(OrigensCCA,CCA!C75)=0,1,0)) -> 0 | J64: =IF(CCA!A75="",0,IF(COUNTIF(MilestonesCCA,CCA!D75)=0,1,0)) -> 0 | K64: =IF(CCA!A75="",0,IF(COUNTIF(EstadosCCA,CCA!G75)=0,1,0)) -> 0 | L64: =IF(CCA!A75="",0,IF(CCA!C75="Regulamento da UC",IF(LEFT(CCA!A75,3)="OF-",0,1),IF(CCA!C75="Compromisso do grupo",IF(LEFT(CCA!A75,3)="AD-",0,1),0))) -> 0 | M64: =IF(LEFT(CCA!A75,3)<>"OF-",0,IFERROR(IF(VLOOKUP(CCA!A75,CatalogoCCA,4,FALSE)=CCA!D75,0,1),0)) -> 0 | N64: =IF(LEFT(CCA!A75,3)<>"OF-",0,IFERROR(IF(VLOOKUP(CCA!A75,CatalogoCCA,5,FALSE)=CCA!F75,0,1),0)) -> 0 | O64: =IF(CCA!A75="",0,IF(CCA!C75="Compromisso do grupo",IF(LEN(TRIM(CCA!E75))<20,1,0),0)) -> 0 | P64: =IF(CCA!A75="",0,IFERROR(IF(MATCH(CCA!D75,MilestonesCCA,0)<MATCH(CCA!$D$3,MilestonesCCA,0),IF(CCA!G75<>"Entregue",1,0),0),0)) -> 0 | Q64: =IF(CCA!A75="",0,IFERROR(IF(MATCH(CCA!D75,MilestonesCCA,0)=MATCH(CCA!$D$3,MilestonesCCA,0),IF(CCA!G75="Previsto",1,0),0),0)) -> 0 | R64: =IF(CCA!A75="",0,IFERROR(IF(MATCH(CCA!D75,MilestonesCCA,0)>MATCH(CCA!$D$3,MilestonesCCA,0),IF(CCA!G75="Entregue",1,0),0),0)) -> 0 | T64: =IF(CCA!A75="",0,IF(COUNTIF(CCA!$A$16:$A$165,CCA!A75)>1,1,0)) -> 0 | U64: =IF(CCA!A75="",0,IF(OR(ISNUMBER(SEARCH("<",CCA!B75)),ISNUMBER(SEARCH(">",CCA!B75)),ISNUMBER(SEARCH("<",CCA!F75)),ISNUMBER(SEARCH(">",CCA!F75))),1,0)) -> 0
G65: 77 | H65: =IF(COUNTA(CCA!A76:G76)=0,0,IF(COUNTA(CCA!A76:G76)<7,1,0)) -> 0 | I65: =IF(CCA!A76="",0,IF(COUNTIF(OrigensCCA,CCA!C76)=0,1,0)) -> 0 | J65: =IF(CCA!A76="",0,IF(COUNTIF(MilestonesCCA,CCA!D76)=0,1,0)) -> 0 | K65: =IF(CCA!A76="",0,IF(COUNTIF(EstadosCCA,CCA!G76)=0,1,0)) -> 0 | L65: =IF(CCA!A76="",0,IF(CCA!C76="Regulamento da UC",IF(LEFT(CCA!A76,3)="OF-",0,1),IF(CCA!C76="Compromisso do grupo",IF(LEFT(CCA!A76,3)="AD-",0,1),0))) -> 0 | M65: =IF(LEFT(CCA!A76,3)<>"OF-",0,IFERROR(IF(VLOOKUP(CCA!A76,CatalogoCCA,4,FALSE)=CCA!D76,0,1),0)) -> 0 | N65: =IF(LEFT(CCA!A76,3)<>"OF-",0,IFERROR(IF(VLOOKUP(CCA!A76,CatalogoCCA,5,FALSE)=CCA!F76,0,1),0)) -> 0 | O65: =IF(CCA!A76="",0,IF(CCA!C76="Compromisso do grupo",IF(LEN(TRIM(CCA!E76))<20,1,0),0)) -> 0 | P65: =IF(CCA!A76="",0,IFERROR(IF(MATCH(CCA!D76,MilestonesCCA,0)<MATCH(CCA!$D$3,MilestonesCCA,0),IF(CCA!G76<>"Entregue",1,0),0),0)) -> 0 | Q65: =IF(CCA!A76="",0,IFERROR(IF(MATCH(CCA!D76,MilestonesCCA,0)=MATCH(CCA!$D$3,MilestonesCCA,0),IF(CCA!G76="Previsto",1,0),0),0)) -> 0 | R65: =IF(CCA!A76="",0,IFERROR(IF(MATCH(CCA!D76,MilestonesCCA,0)>MATCH(CCA!$D$3,MilestonesCCA,0),IF(CCA!G76="Entregue",1,0),0),0)) -> 0 | T65: =IF(CCA!A76="",0,IF(COUNTIF(CCA!$A$16:$A$165,CCA!A76)>1,1,0)) -> 0 | U65: =IF(CCA!A76="",0,IF(OR(ISNUMBER(SEARCH("<",CCA!B76)),ISNUMBER(SEARCH(">",CCA!B76)),ISNUMBER(SEARCH("<",CCA!F76)),ISNUMBER(SEARCH(">",CCA!F76))),1,0)) -> 0
G66: 78 | H66: =IF(COUNTA(CCA!A77:G77)=0,0,IF(COUNTA(CCA!A77:G77)<7,1,0)) -> 0 | I66: =IF(CCA!A77="",0,IF(COUNTIF(OrigensCCA,CCA!C77)=0,1,0)) -> 0 | J66: =IF(CCA!A77="",0,IF(COUNTIF(MilestonesCCA,CCA!D77)=0,1,0)) -> 0 | K66: =IF(CCA!A77="",0,IF(COUNTIF(EstadosCCA,CCA!G77)=0,1,0)) -> 0 | L66: =IF(CCA!A77="",0,IF(CCA!C77="Regulamento da UC",IF(LEFT(CCA!A77,3)="OF-",0,1),IF(CCA!C77="Compromisso do grupo",IF(LEFT(CCA!A77,3)="AD-",0,1),0))) -> 0 | M66: =IF(LEFT(CCA!A77,3)<>"OF-",0,IFERROR(IF(VLOOKUP(CCA!A77,CatalogoCCA,4,FALSE)=CCA!D77,0,1),0)) -> 0 | N66: =IF(LEFT(CCA!A77,3)<>"OF-",0,IFERROR(IF(VLOOKUP(CCA!A77,CatalogoCCA,5,FALSE)=CCA!F77,0,1),0)) -> 0 | O66: =IF(CCA!A77="",0,IF(CCA!C77="Compromisso do grupo",IF(LEN(TRIM(CCA!E77))<20,1,0),0)) -> 0 | P66: =IF(CCA!A77="",0,IFERROR(IF(MATCH(CCA!D77,MilestonesCCA,0)<MATCH(CCA!$D$3,MilestonesCCA,0),IF(CCA!G77<>"Entregue",1,0),0),0)) -> 0 | Q66: =IF(CCA!A77="",0,IFERROR(IF(MATCH(CCA!D77,MilestonesCCA,0)=MATCH(CCA!$D$3,MilestonesCCA,0),IF(CCA!G77="Previsto",1,0),0),0)) -> 0 | R66: =IF(CCA!A77="",0,IFERROR(IF(MATCH(CCA!D77,MilestonesCCA,0)>MATCH(CCA!$D$3,MilestonesCCA,0),IF(CCA!G77="Entregue",1,0),0),0)) -> 0 | T66: =IF(CCA!A77="",0,IF(COUNTIF(CCA!$A$16:$A$165,CCA!A77)>1,1,0)) -> 0 | U66: =IF(CCA!A77="",0,IF(OR(ISNUMBER(SEARCH("<",CCA!B77)),ISNUMBER(SEARCH(">",CCA!B77)),ISNUMBER(SEARCH("<",CCA!F77)),ISNUMBER(SEARCH(">",CCA!F77))),1,0)) -> 0
G67: 79 | H67: =IF(COUNTA(CCA!A78:G78)=0,0,IF(COUNTA(CCA!A78:G78)<7,1,0)) -> 0 | I67: =IF(CCA!A78="",0,IF(COUNTIF(OrigensCCA,CCA!C78)=0,1,0)) -> 0 | J67: =IF(CCA!A78="",0,IF(COUNTIF(MilestonesCCA,CCA!D78)=0,1,0)) -> 0 | K67: =IF(CCA!A78="",0,IF(COUNTIF(EstadosCCA,CCA!G78)=0,1,0)) -> 0 | L67: =IF(CCA!A78="",0,IF(CCA!C78="Regulamento da UC",IF(LEFT(CCA!A78,3)="OF-",0,1),IF(CCA!C78="Compromisso do grupo",IF(LEFT(CCA!A78,3)="AD-",0,1),0))) -> 0 | M67: =IF(LEFT(CCA!A78,3)<>"OF-",0,IFERROR(IF(VLOOKUP(CCA!A78,CatalogoCCA,4,FALSE)=CCA!D78,0,1),0)) -> 0 | N67: =IF(LEFT(CCA!A78,3)<>"OF-",0,IFERROR(IF(VLOOKUP(CCA!A78,CatalogoCCA,5,FALSE)=CCA!F78,0,1),0)) -> 0 | O67: =IF(CCA!A78="",0,IF(CCA!C78="Compromisso do grupo",IF(LEN(TRIM(CCA!E78))<20,1,0),0)) -> 0 | P67: =IF(CCA!A78="",0,IFERROR(IF(MATCH(CCA!D78,MilestonesCCA,0)<MATCH(CCA!$D$3,MilestonesCCA,0),IF(CCA!G78<>"Entregue",1,0),0),0)) -> 0 | Q67: =IF(CCA!A78="",0,IFERROR(IF(MATCH(CCA!D78,MilestonesCCA,0)=MATCH(CCA!$D$3,MilestonesCCA,0),IF(CCA!G78="Previsto",1,0),0),0)) -> 0 | R67: =IF(CCA!A78="",0,IFERROR(IF(MATCH(CCA!D78,MilestonesCCA,0)>MATCH(CCA!$D$3,MilestonesCCA,0),IF(CCA!G78="Entregue",1,0),0),0)) -> 0 | T67: =IF(CCA!A78="",0,IF(COUNTIF(CCA!$A$16:$A$165,CCA!A78)>1,1,0)) -> 0 | U67: =IF(CCA!A78="",0,IF(OR(ISNUMBER(SEARCH("<",CCA!B78)),ISNUMBER(SEARCH(">",CCA!B78)),ISNUMBER(SEARCH("<",CCA!F78)),ISNUMBER(SEARCH(">",CCA!F78))),1,0)) -> 0
G68: 80 | H68: =IF(COUNTA(CCA!A79:G79)=0,0,IF(COUNTA(CCA!A79:G79)<7,1,0)) -> 0 | I68: =IF(CCA!A79="",0,IF(COUNTIF(OrigensCCA,CCA!C79)=0,1,0)) -> 0 | J68: =IF(CCA!A79="",0,IF(COUNTIF(MilestonesCCA,CCA!D79)=0,1,0)) -> 0 | K68: =IF(CCA!A79="",0,IF(COUNTIF(EstadosCCA,CCA!G79)=0,1,0)) -> 0 | L68: =IF(CCA!A79="",0,IF(CCA!C79="Regulamento da UC",IF(LEFT(CCA!A79,3)="OF-",0,1),IF(CCA!C79="Compromisso do grupo",IF(LEFT(CCA!A79,3)="AD-",0,1),0))) -> 0 | M68: =IF(LEFT(CCA!A79,3)<>"OF-",0,IFERROR(IF(VLOOKUP(CCA!A79,CatalogoCCA,4,FALSE)=CCA!D79,0,1),0)) -> 0 | N68: =IF(LEFT(CCA!A79,3)<>"OF-",0,IFERROR(IF(VLOOKUP(CCA!A79,CatalogoCCA,5,FALSE)=CCA!F79,0,1),0)) -> 0 | O68: =IF(CCA!A79="",0,IF(CCA!C79="Compromisso do grupo",IF(LEN(TRIM(CCA!E79))<20,1,0),0)) -> 0 | P68: =IF(CCA!A79="",0,IFERROR(IF(MATCH(CCA!D79,MilestonesCCA,0)<MATCH(CCA!$D$3,MilestonesCCA,0),IF(CCA!G79<>"Entregue",1,0),0),0)) -> 0 | Q68: =IF(CCA!A79="",0,IFERROR(IF(MATCH(CCA!D79,MilestonesCCA,0)=MATCH(CCA!$D$3,MilestonesCCA,0),IF(CCA!G79="Previsto",1,0),0),0)) -> 0 | R68: =IF(CCA!A79="",0,IFERROR(IF(MATCH(CCA!D79,MilestonesCCA,0)>MATCH(CCA!$D$3,MilestonesCCA,0),IF(CCA!G79="Entregue",1,0),0),0)) -> 0 | T68: =IF(CCA!A79="",0,IF(COUNTIF(CCA!$A$16:$A$165,CCA!A79)>1,1,0)) -> 0 | U68: =IF(CCA!A79="",0,IF(OR(ISNUMBER(SEARCH("<",CCA!B79)),ISNUMBER(SEARCH(">",CCA!B79)),ISNUMBER(SEARCH("<",CCA!F79)),ISNUMBER(SEARCH(">",CCA!F79))),1,0)) -> 0
